Workbook
Name BD_Relation: #REF!
Name BD_Relation: #REF!
Name Date: #REF!
Name Date: #REF!
Name dccap: #REF!
Name dccap: #REF!
Name Digos: #REF!
Name Digos: #REF!
Name engg: #REF!
Name engg: #REF!
Name Equipment: #REF!
Name Equipment: #REF!
Name error: #REF!
Name error: #REF!
Name Gstc: #REF!
Name Gstc: #REF!
Name Gstc: #REF!
Name Gstc: #REF!
Name Gstc: #REF!
Name Inverter: #REF!
Name Inverter: #REF!
Name invlook: #REF!
Name invlook: #REF!
Name JB: #REF!
Name JB: #REF!
Name jbp: #REF!
Name jbp: #REF!
Name P1_SnW4240: #REF!
Name P1_SnW4240: #REF!
Name P1SnW4240: #REF!
Name P1SnW4240: #REF!
Name P1SnW51: #REF!
Name P1SnW51: #REF!
Name P1SnW68: #REF!
Name P1SnW68: #REF!
Name Pstc: #REF!
Name Pstc: #REF!
Name Pstc: #REF!
Name Pstc: #REF!
Name Pstc: #REF!
Name SCDA: #REF!
Name SCDA: #REF!
Name SCDA: #REF!
Name Slicer_Affected_WTG: #N/A
Name Slicer_Calendor_Year: #N/A
Name Slicer_Date: #N/A
Name Slicer_Error_Text: #N/A
Name Slicer_Finacial_Year: #N/A
Name Slicer_Month: #N/A
Name Slicer_Operating_Year: #N/A
Name status: #REF!
Name status: #REF!
Name stp: #REF!
Name stp: #REF!
Name String: #REF!
Name String: #REF!
Name zzzzz: #REF!
Name zzzzz: #REF!

Sheet O2Summary
A2: Performance Summary PWEGPL
A3: Month | B3: 45839
A4: Date | B4: 45861
A5: Financial Year | B5: Year-3
A6: Year Start Date | B6: 45748
A7: Year End Date | B7: 46112
A9: Sr. No. | B9: Particular | C9: Target | D9: Measured | E9: Deviation | F9: Remarks
A10: 1 | B10: E_Grid Daily (MWh) | C10: =_xlfn.XLOOKUP($B$4,'Daily KPI'!$A:$A,'Daily KPI'!$AD:$AD)/1000 -> 585.79782 | D10: =_xlfn.XLOOKUP($B$4,'Daily KPI'!$A:$A,'Daily KPI'!$AA:$AA)/1000 -> 338.4 | E10: =D10/C10-1 -> -0.42232629
B11: E_Grid MTD(MWh) | C11: =MonthlyKPI!E4 -> 13473.35 | D11: =MonthlyKPI!F4 -> 10432.8 | E11: =D11/C11-1 -> -0.22567141
B12: E_Grid YTD (MWh) | C12: =AnnualKPI!E4 -> 56048.304 | D12: =AnnualKPI!F4 -> 49551.6 | E12: =D12/C12-1 -> -0.1159126
A13: 2 | B13: Wind Speed Daily | C13: =_xlfn.XLOOKUP($B$3,'Modelling New'!$D:$D,'Modelling New'!AC:AC) -> 7.1310649 | D13: =_xlfn.XLOOKUP($B$4,'Daily KPI'!$A:$A,'Daily KPI'!M:M) -> 4.3253846 | E13: =(D13-C13)/(C13) -> -0.39344478
B14: Wind Speed MTD | C14: =MonthlyKPI!C4 -> 7.1310649 | D14: =MonthlyKPI!D4 -> 4.8426352 | E14: =(D14-C14)/(C14) -> -0.32090995
B15: Wind Speed YTD | C15: =AnnualKPI!C4 -> 6.283612 | D15: =AnnualKPI!D4 -> 5.0615124 | E15: =(D15-C15)/(C15) -> -0.19448999
A16: 3 | B16: PA Daily | C16: =_xlfn.XLOOKUP($B$3,'Modelling New'!$D:$D,'Modelling New'!$AE:$AE) -> 0.9603 | D16: =_xlfn.XLOOKUP($B$4,'Daily KPI'!$A:$A,'Daily KPI'!$O:$O) -> 0.96853651 | E16: =(D16-C16)/(C16) -> 0.0085770157
B17: PA MTD | C17: =_xlfn.XLOOKUP($B$3,'Modelling New'!$D:$D,'Modelling New'!$AE:$AE) -> 0.9603 | D17: =MonthlyKPI!$P$4 -> 0.92563214 | E17: =(D17-C17)/(C17) -> -0.036101073
B18: PA YTD | C18: =_xlfn.XLOOKUP($B$3,'Modelling New'!$D:$D,'Modelling New'!$AE:$AE) -> 0.9603 | D18: =AnnualKPI!$P$4 -> 0.92112749 | E18: =(D18-C18)/(C18) -> -0.040791951
A19: 4 | B19: MA Daily | C19: =_xlfn.XLOOKUP($B$3,'Modelling New'!$D:$D,'Modelling New'!$AH:$AH) -> 0.97 | D19: =_xlfn.XLOOKUP($B$4,'Daily KPI'!$A:$A,'Daily KPI'!$P:$P) -> 0.96853651 | E19: =(D19-C19)/(C19) -> -0.0015087544
B20: MA MTD | C20: =_xlfn.XLOOKUP($B$3,'Modelling New'!$D:$D,'Modelling New'!$AH:$AH) -> 0.97 | D20: =MonthlyKPI!L4 -> 0.92780386 | E20: =(D20-C20)/(C20) -> -0.043501176
B21: MA YTD | C21: =_xlfn.XLOOKUP($B$3,'Modelling New'!$D:$D,'Modelling New'!$AH:$AH) -> 0.97 | D21: =AnnualKPI!L4 -> 0.92633082 | E21: =(D21-C21)/(C21) -> -0.045019769
A22: 5 | B22: EGA Daily | C22: =_xlfn.XLOOKUP($B$3,'Modelling New'!$D:$D,'Modelling New'!$AF:$AF) -> 0.995 | D22: =_xlfn.XLOOKUP($B$4,'Daily KPI'!$A:$A,'Daily KPI'!$R:$R) -> 1 | E22: =(D22-C22)/(C22) -> 0.0050251256
B23: EGA MTD | C23: =_xlfn.XLOOKUP($B$3,'Modelling New'!$D:$D,'Modelling New'!$AF:$AF) -> 0.995 | D23: =MonthlyKPI!J4 -> 1 | E23: =(D23-C23)/(C23) -> 0.0050251256
B24: EGA YTD | C24: =_xlfn.XLOOKUP($B$3,'Modelling New'!$D:$D,'Modelling New'!$AF:$AF) -> 0.995 | D24: =AnnualKPI!J4 -> 1 | E24: =(D24-C24)/(C24) -> 0.0050251256
A25: 6 | B25: IGA Daily | C25: =_xlfn.XLOOKUP($B$3,'Modelling New'!$D:$D,'Modelling New'!$AI:$AI) -> 0.99 | D25: =_xlfn.XLOOKUP($B$4,'Daily KPI'!$A:$A,'Daily KPI'!$Q:$Q) -> 1 | E25: =(D25-C25)/(C25) -> 0.01010101
B26: IGA MTD | C26: =_xlfn.XLOOKUP($B$3,'Modelling New'!$D:$D,'Modelling New'!$AI:$AI) -> 0.99 | D26: =MonthlyKPI!N4 -> 0.99765929 | E26: =(D26-C26)/(C26) -> 0.0077366563
B27: IGA YTD | C27: =_xlfn.XLOOKUP($B$3,'Modelling New'!$D:$D,'Modelling New'!$AI:$AI) -> 0.99 | D27: =AnnualKPI!N4 -> 0.99438286 | E27: =(D27-C27)/(C27) -> 0.0044271266
A28: 7 | B28: CUF Daily | C28: =IFERROR(_xlfn.XLOOKUP($B$4,'Daily KPI'!$A:$A,'Daily KPI'!$AF:$AF),"") -> 0.31292619 | D28: =_xlfn.XLOOKUP($B$4,'Daily KPI'!$A:$A,'Daily KPI'!$W:$W) -> 0.18076923 | E28: =D28/C28-1 -> -0.42232629
B29: CUF MTD | C29: =MonthlyKPI!$G$4 -> 0.31292619 | D29: =MonthlyKPI!H4 -> 0.24230769 | E29: =(D29-C29)/(C29) -> -0.22567141
B30: CUF YTD | C30: =AnnualKPI!$G$4 -> 0.26263451 | D30: =AnnualKPI!H4 -> 0.23219186 | E30: =(D30-C30)/(C30) -> -0.1159126
A31: 8 | B31: Line Loss Daily | C31: 0.05 | D31: =_xlfn.XLOOKUP($B$4,'Daily KPI'!$A:$A,'Daily KPI'!$AN:$AN) -> 0.030347487 | E31: =-(D31-C31)/(C31) -> 0.39305025
B32: Line Loss MTD | C32: 0.05 | D32: =MonthlyKPI!$U$4 -> 0.01457006 | E32: =-(D32-C32)/(C32) -> 0.70859881
B33: Line Loss YTD | C33: 0.05 | D33: =AnnualKPI!$R$4 -> 0.019015501 | E33: =-(D33-C33)/(C33) -> 0.61968997
A34: 9 | B34: Reactive Power Daily | C34: 0.05 | D34: =_xlfn.XLOOKUP($B$4,'Daily KPI'!$A:$A,'Daily KPI'!$AO:$AO) -> 0 | E34: =-(D34-C34)/(C34) -> 1
B35: Reactive Power MTD | C35: 0.05 | D35: =MonthlyKPI!$V$4 -> 1.9336924e-05 | E35: =-(D35-C35)/(C35) -> 0.99961326
B36: Reactive Power YTD | C36: 0.05 | D36: =AnnualKPI!$S$4 -> 4.4700547e-05 | E36: =-(D36-C36)/(C36) -> 0.99910599
A37: 10 | B37: Expected Energy Daily | C37: =IFERROR(_xlfn.XLOOKUP($B$4,'Daily KPI'!$A:$A,'Daily KPI'!$AI:$AI),"") -> 348.99 | D37: =IFERROR(_xlfn.XLOOKUP($B$4,'Daily KPI'!$A:$A,'Daily KPI'!$X:$X)/1000,"") -> 348.991 | E37: =(D37-C37)/(C37) -> 2.8654116e-06
B38: Expected Energy MTD | C38: =MonthlyKPI!$T$4 -> 10547.338 | D38: =IFERROR(SUMIF('Daily KPI'!$D:$D,O2Summary!$B$3,'Daily KPI'!$X:$X)/1000,"") -> 10547.345 | E38: =(D38-C38)/(C38) -> 6.6367457e-07
B39: Expected Energy YTD | C39: =AnnualKPI!$Q$4 -> 50209.056 | D39: =IFERROR(SUMIFS('Daily KPI'!$X:$X,'Daily KPI'!$A:$A,">="&O2Summary!$B$6,'Daily KPI'!$A:$A,"<="&O2Summary!B4)/1000,"") -> 50381.682 | E39: =(D39-C39)/(C39) -> 0.0034381447

Sheet AnnualKPI
A1: Till Date | B1: =O2Summary!B4 -> 45861 | C1: =O2Summary!B3 -> 45839
A2: PWEGPL Performance Summary-YTD
A3: Year | B3: Days | C3: Estimated WS(m/s) | D3: Measured WS (m/s) | E3: Budgeted Energy (MWh) | F3: Measured Energy (MWh) | G3: Target CUF (%) | H3: Measured CUF (%) | I3: Target GA (%) | J3: Measured GA (%) | K3: Target MA (%) | L3: Measured MA (%) | M3: Target IGA(%) | N3: Measured IGA (%) | O3: Target PA(%) | P3: Measured PA (%) | Q3: Expected Energy | R3: Loss (%) | S3: Reactive Power (%)
A4: =YEAR(B1)+IF(MONTH(B1)>=4,1,0) -> 2026 | B4: =B1-(O2Summary!B6)+1 -> 114 | C4: =_xlfn.XLOOKUP($C$1,'Modelling New'!$D:$D,'Modelling New'!$AD:$AD) -> 6.283612 | D4: =AVERAGEIFS('Daily KPI'!$M:$M,'Daily KPI'!$A:$A,">="&O2Summary!$B$6,'Daily KPI'!$A:$A,"<="&AnnualKPI!$B$1) -> 5.0615124 | E4: =_xlfn.XLOOKUP($C$1,'Modelling New'!$D:$D,'Modelling New'!$V:$V) -> 56048.304 | F4: =SUMIFS('Daily KPI'!$AA:$AA,'Daily KPI'!$A:$A,">="&O2Summary!$B$6,'Daily KPI'!$A:$A,"<="&AnnualKPI!$B$1)/1000 -> 49551.6 | G4: =_xlfn.XLOOKUP($C$1,'Modelling New'!$D:$D,'Modelling New'!$Y:$Y) -> 0.26263451 | H4: =IFERROR(F4/(B4*24*'Basic Data'!$K$3),"") -> 0.23219186 | I4: =_xlfn.XLOOKUP($C$1,'Modelling New'!$D:$D,'Modelling New'!$AF:$AF) -> 0.995 | J4: =AVERAGEIFS('Daily KPI'!$R:$R,'Daily KPI'!$A:$A,">="&O2Summary!$B$6,'Daily KPI'!$A:$A,"<="&AnnualKPI!$B$1) -> 1 | K4: =_xlfn.XLOOKUP($C$1,'Modelling New'!$D:$D,'Modelling New'!$AH:$AH) -> 0.97 | L4: =AVERAGEIFS('Daily KPI'!$P:$P,'Daily KPI'!$A:$A,">="&O2Summary!$B$6,'Daily KPI'!$A:$A,"<="&AnnualKPI!$B$1) -> 0.92633082 | M4: =_xlfn.XLOOKUP($C$1,'Modelling New'!$D:$D,'Modelling New'!$AI:$AI) -> 0.99 | N4: =AVERAGEIFS('Daily KPI'!$Q:$Q,'Daily KPI'!$A:$A,">="&O2Summary!$B$6,'Daily KPI'!$A:$A,"<="&AnnualKPI!$B$1) -> 0.99438286 | O4: =K4*M4 -> 0.9603 | P4: =L4*N4 -> 0.92112749 | Q4: =SUMIFS('Daily KPI'!$AI:$AI,'Daily KPI'!$A:$A,">="&O2Summary!$B$6,'Daily KPI'!$A:$A,"<="&AnnualKPI!$B$1) -> 50209.056 | R4: =AVERAGEIFS('Daily KPI'!$AN:$AN,'Daily KPI'!$A:$A,">="&O2Summary!$B$6,'Daily KPI'!$A:$A,"<="&AnnualKPI!$B$1) -> 0.019015501 | S4: =AVERAGEIFS('Daily KPI'!$AO:$AO,'Daily KPI'!$A:$A,">="&O2Summary!$B$6,'Daily KPI'!$A:$A,"<="&AnnualKPI!$B$1) -> 4.4700547e-05

Sheet MonthlyKPI
A1: Till Date | B1: =O2Summary!B4 -> 45861 | C1: 0 | D1: 0 | E1: 0 | F1: 0
A2: PWEGPL Performance Summary (MTD)
A3: Year | B3: Days | C3: Estimated WS(m/s) | D3: Measured WS (m/s) | E3: Budgeted Energy (MWh) | F3: Measured Energy (MWh) | G3: Target CUF (%) | H3: Measured CUF (%) | I3: Target GA (%) | J3: Measured GA (%) | K3: Target MA (%) | L3: Measured MA (%) | M3: Target IGA (%) | N3: Measured IGA (%) | O3: Target PA(%) | P3: Measured PA (%) | Q3: WTG Total (MWh) | R3: Line Losses(%) | S3: E_WS_Corrected | T3: Expected Energy | U3: Loss (%) | V3: Reactive Power (%)
A4: =O2Summary!B3 -> 45839 | B4: =DAY(B1) -> 23 | C4: =_xlfn.XLOOKUP($A$4,'Modelling New'!$D:$D,'Modelling New'!$AC:$AC) -> 7.1310649 | D4: =AVERAGEIF('Daily KPI'!$D:$D,$A$4,'Daily KPI'!$M:$M) -> 4.8426352 | E4: =_xlfn.XLOOKUP($A$4,'Modelling New'!$D:$D,'Modelling New'!$U:$U) -> 13473.35 | F4: =SUMIFS('Daily KPI'!$AA:$AA,'Daily KPI'!$D:$D,$A$4)/1000 -> 10432.8 | G4: =_xlfn.XLOOKUP($A$4,'Modelling New'!$D:$D,'Modelling New'!$X:$X) -> 0.31292619 | H4: =F4/(24*B4*'Basic Data'!$K$3) -> 0.24230769 | I4: =_xlfn.XLOOKUP($A$4,'Modelling New'!$D:$D,'Modelling New'!$AF:$AF) -> 0.995 | J4: =AVERAGEIFS('Daily KPI'!$R:$R,'Daily KPI'!$A:$A,"<="&MonthlyKPI!$B$1,'Daily KPI'!$D:$D,$A$4) -> 1 | K4: =_xlfn.XLOOKUP($A$4,'Modelling New'!$D:$D,'Modelling New'!$AH:$AH) -> 0.97 | L4: =AVERAGEIFS('Daily KPI'!$P:$P,'Daily KPI'!$A:$A,"<="&MonthlyKPI!$B$1,'Daily KPI'!$D:$D,$A$4) -> 0.92780386 | M4: =_xlfn.XLOOKUP($A$4,'Modelling New'!$D:$D,'Modelling New'!$AI:$AI) -> 0.99 | N4: =AVERAGEIFS('Daily KPI'!$Q:$Q,'Daily KPI'!$A:$A,"<="&MonthlyKPI!$B$1,'Daily KPI'!$D:$D,$A$4) -> 0.99765929 | O4: =K4*M4 -> 0.9603 | P4: =L4*N4 -> 0.92563214 | Q4: =SUMIFS('Daily KPI'!$X:$X,'Daily KPI'!$D:$D,$A$4)/1000 -> 10547.345 | R4: =Q4/F4-1 -> 0.010979315 | S4: =SUMIFS(Input_Raw!DE:DE,Input_Raw!A:A,">="&A4,Input_Raw!A:A,"<="&B1)/1000 -> 10.547338 | T4: =SUMIFS('Daily KPI'!$AI:$AI,'Daily KPI'!$D:$D,$A$4) -> 10547.338 | U4: =IFERROR(AVERAGEIFS('Daily KPI'!$AN:$AN,'Daily KPI'!$D:$D,MonthlyKPI!$A$4,'Daily KPI'!$A:$A,"<="&MonthlyKPI!$B$1),"") -> 0.01457006 | V4: =AVERAGEIFS('Daily KPI'!$AO:$AO,'Daily KPI'!$A:$A,"<="&MonthlyKPI!$B$1,'Daily KPI'!$D:$D,$A$4) -> 1.9336924e-05
A7: Start Date | B7: =B8-6 -> 45855
A8: End Date | B8: =B1 -> 45861
A9: PWEGPL Performance Summary (WTD)
A10: Year | B10: Days | C10: Estimated WS(m/s) | D10: Measured WS (m/s) | E10: Budgeted Energy (MWh) | F10: Measured Energy (MWh) | G10: Target CUF (%) | H10: Measured CUF (%) | I10: Target GA (%) | J10: Measured GA (%) | K10: Target MA (%) | L10: Measured MA (%) | M10: Target IGA (%) | N10: Measured IGA (%) | O10: Target PA(%) | P10: Measured PA (%) | Q10: E_WS_Corrected
A11: =A4 -> 45839 | B11: =(B8-B7)+1 -> 7 | C11: =_xlfn.XLOOKUP($A$11,'Modelling New'!$D:$D,'Modelling New'!$AC:$AC) -> 7.1310649 | D11: =AVERAGEIFS('Daily KPI'!$M:$M,'Daily KPI'!$A:$A,">="&$B$7,'Daily KPI'!$A:$A,"<="&$B$8) -> 3.7401935 | E11: =SUMIFS('Daily KPI'!$AD:$AD,'Daily KPI'!$A:$A,">="&$B$7,'Daily KPI'!$A:$A,"<="&$B$8)/1000 -> 4100.5847 | F11: =SUMIFS('Daily KPI'!$AA:$AA,'Daily KPI'!$A:$A,">="&$B$7,'Daily KPI'!$A:$A,"<="&$B$8)/1000 -> 1326 | G11: =E11/(24*$B$11*'Basic Data'!$K$3) -> 0.31292619 | H11: =F11/(24*B11*'Basic Data'!$K$3) -> 0.10119048 | I11: =_xlfn.XLOOKUP($A$4,'Modelling New'!$D:$D,'Modelling New'!$AF:$AF) -> 0.995 | J11: =AVERAGEIFS('Daily KPI'!$R:$R,'Daily KPI'!$A:$A,">="&$B$7,'Daily KPI'!$A:$A,"<="&$B$8) -> 1 | K11: =_xlfn.XLOOKUP($A$4,'Modelling New'!$D:$D,'Modelling New'!$AH:$AH) -> 0.97 | L11: =AVERAGEIFS('Daily KPI'!$P:$P,'Daily KPI'!$A:$A,">="&$B$7,'Daily KPI'!$A:$A,"<="&$B$8) -> 0.95039706 | M11: =_xlfn.XLOOKUP($A$4,'Modelling New'!$D:$D,'Modelling New'!$AI:$AI) -> 0.99 | N11: =AVERAGEIFS('Daily KPI'!$Q:$Q,'Daily KPI'!$A:$A,">="&$B$7,'Daily KPI'!$A:$A,"<="&$B$8) -> 0.9980398 | O11: =K11*M11 -> 0.9603 | P11: =L11*N11 -> 0.94853409 | Q11: =SUMIFS(Input_Raw!DE:DE,Input_Raw!A:A,">="&B7,Input_Raw!A:A,"<="&B8)/1000 -> 1.37441
A14: Start Date | B14: =B15-29 -> 45832
A15: End Date | B15: =B8 -> 45861
A16: PWEGPL Performance Summary (LTD)
A17: Year | B17: Days | C17: Estimated WS(m/s) | D17: Measured WS (m/s) | E17: Budgeted Energy (MWh) | F17: Measured Energy (MWh) | G17: Target CUF (%) | H17: Measured CUF (%) | I17: Target GA (%) | J17: Measured GA (%) | K17: Target MA (%) | L17: Measured MA (%) | M17: Target IGA (%) | N17: Measured IGA (%) | O17: Target PA(%) | P17: Measured PA (%)
A18: =A11 -> 45839 | B18: =(B15-B14)+1 -> 30 | C18: =_xlfn.XLOOKUP($A$18,'Modelling New'!$D:$D,'Modelling New'!$AC:$AC) -> 7.1310649 | D18: =AVERAGEIFS('Daily KPI'!$M:$M,'Daily KPI'!$A:$A,">="&$B$14,'Daily KPI'!$A:$A,"<="&$B$15) -> 5.2312526 | E18: =SUMIFS('Daily KPI'!$AD:$AD,'Daily KPI'!$A:$A,">="&$B$14,'Daily KPI'!$A:$A,"<="&$B$15)/1000 -> 16982.277 | F18: =SUMIFS('Daily KPI'!$AA:$AA,'Daily KPI'!$A:$A,">="&$B$14,'Daily KPI'!$A:$A,"<="&$B$15)/1000 -> 15886.8 | G18: =E18/(24*$B$18*'Basic Data'!$K$3) -> 0.30239098 | H18: =F18/(24*B18*'Basic Data'!$K$3) -> 0.28288462 | I18: =_xlfn.XLOOKUP($A$4,'Modelling New'!$D:$D,'Modelling New'!$AF:$AF) -> 0.995 | J18: =AVERAGEIFS('Daily KPI'!$R:$R,'Daily KPI'!$A:$A,">="&$B$14,'Daily KPI'!$A:$A,"<="&$B$15) -> 1 | K18: =_xlfn.XLOOKUP($A$4,'Modelling New'!$D:$D,'Modelling New'!$AH:$AH) -> 0.97 | L18: =AVERAGEIFS('Daily KPI'!$P:$P,'Daily KPI'!$A:$A,">="&$B$14,'Daily KPI'!$A:$A,"<="&$B$15) -> 0.9248899 | M18: =_xlfn.XLOOKUP($A$4,'Modelling New'!$D:$D,'Modelling New'!$AI:$AI) -> 0.99 | N18: =AVERAGEIFS('Daily KPI'!$Q:$Q,'Daily KPI'!$A:$A,">="&$B$14,'Daily KPI'!$A:$A,"<="&$B$15) -> 0.99713065 | O18: =K18*M18 -> 0.9603 | P18: =L18*N18 -> 0.92223607

Sheet Analytices
A2: Start Date | B2: =O2Summary!B3 -> 45839
A3: End Date | B3: =O2Summary!B4 -> 45861 | C3: =((B3-B2)+1)*24 -> 552 | D3: =MEDIAN(B21:AN21) -> 5.2
A4: WTG No. | B4: G01 | C4: G02 | D4: G03 | E4: G04 | F4: G05 | G4: G06 | H4: G07 | I4: G08 | J4: G09 | K4: G10 | L4: G11 | M4: G12 | N4: G13 | O4: G14 | P4: G15 | Q4: G16 | R4: G17 | S4: G18 | T4: G19 | U4: G20 | V4: G21 | W4: G22 | X4: G23 | Y4: G25 | Z4: G26 | AA4: G27 | AB4: G28 | AC4: G29 | AD4: G30 | AE4: G31 | AF4: G32 | AG4: G33 | AH4: G34 | AI4: G35 | AJ4: G36 | AK4: G37 | AL4: G38 | AM4: G39 | AN4: G40
A5: MA | B5: =IFERROR(($C$3-B6)/$C$3,1) -> 0.97753623 | C5: =IFERROR(($C$3-C6)/$C$3,1) -> 0.9968599 | D5: =IFERROR(($C$3-D6)/$C$3,1) -> 0.99682971 | E5: =IFERROR(($C$3-E6)/$C$3,1) -> 0.97379227 | F5: =IFERROR(($C$3-F6)/$C$3,1) -> 0.99894324 | G5: =IFERROR(($C$3-G6)/$C$3,1) -> 0.99326691 | H5: =IFERROR(($C$3-H6)/$C$3,1) -> 1 | I5: =IFERROR(($C$3-I6)/$C$3,1) -> 1 | ... AN5: =IFERROR(($C$3-AN6)/$C$3,1) -> 0.99842995
A6: WTG BD Hours | B6: =SUMIFS(WTG_BD!$T:$T,WTG_BD!$F:$F,">="&Analytices!$B$2,WTG_BD!$F:$F,"<="&Analytices!$B$3,WTG_BD!$G:$G,B4) -> 12.4 | C6: =SUMIFS(WTG_BD!$T:$T,WTG_BD!$F:$F,">="&Analytices!$B$2,WTG_BD!$F:$F,"<="&Analytices!$B$3,WTG_BD!$G:$G,C4) -> 1.7333333 | D6: =SUMIFS(WTG_BD!$T:$T,WTG_BD!$F:$F,">="&Analytices!$B$2,WTG_BD!$F:$F,"<="&Analytices!$B$3,WTG_BD!$G:$G,D4) -> 1.75 | E6: =SUMIFS(WTG_BD!$T:$T,WTG_BD!$F:$F,">="&Analytices!$B$2,WTG_BD!$F:$F,"<="&Analytices!$B$3,WTG_BD!$G:$G,E4) -> 14.466667 | F6: =SUMIFS(WTG_BD!$T:$T,WTG_BD!$F:$F,">="&Analytices!$B$2,WTG_BD!$F:$F,"<="&Analytices!$B$3,WTG_BD!$G:$G,F4) -> 0.58333333 | G6: =SUMIFS(WTG_BD!$T:$T,WTG_BD!$F:$F,">="&Analytices!$B$2,WTG_BD!$F:$F,"<="&Analytices!$B$3,WTG_BD!$G:$G,G4) -> 3.7166667 | H6: =SUMIFS(WTG_BD!$T:$T,WTG_BD!$F:$F,">="&Analytices!$B$2,WTG_BD!$F:$F,"<="&Analytices!$B$3,WTG_BD!$G:$G,H4) -> 0 | I6: =SUMIFS(WTG_BD!$T:$T,WTG_BD!$F:$F,">="&Analytices!$B$2,WTG_BD!$F:$F,"<="&Analytices!$B$3,WTG_BD!$G:$G,I4) -> 0 | ... AN6: =SUMIFS(WTG_BD!$T:$T,WTG_BD!$F:$F,">="&Analytices!$B$2,WTG_BD!$F:$F,"<="&Analytices!$B$3,WTG_BD!$G:$G,AN4) -> 0.86666667
A7: IGA | B7: =($C$3-SUM(B8:B12))/$C$3 -> 0.99667874 | C7: =($C$3-SUM(C8:C12))/$C$3 -> 0.99667874 | D7: =($C$3-SUM(D8:D12))/$C$3 -> 0.99667874 | E7: =($C$3-SUM(E8:E12))/$C$3 -> 0.99667874 | F7: =($C$3-SUM(F8:F12))/$C$3 -> 0.99852053 | G7: =($C$3-SUM(G8:G12))/$C$3 -> 0.99667874 | H7: =($C$3-SUM(H8:H12))/$C$3 -> 0.99667874 | I7: =($C$3-SUM(I8:I12))/$C$3 -> 0.99667874 | ... AN7: =($C$3-SUM(AN8:AN12))/$C$3 -> 1
A8: METERING YARD
A9: FEEDER | B9: =SUMIFS(IGA_BD!$Q:$Q,IGA_BD!$G:$G,(VLOOKUP(B$4,'Basic Data'!$A:$F,6,0)),IGA_BD!$F:$F,">="&Analytices!$B$2,IGA_BD!$F:$F,"<="&Analytices!$B$3) -> 1.8333333 | C9: =SUMIFS(IGA_BD!$Q:$Q,IGA_BD!$G:$G,(VLOOKUP(C$4,'Basic Data'!$A:$F,6,0)),IGA_BD!$F:$F,">="&Analytices!$B$2,IGA_BD!$F:$F,"<="&Analytices!$B$3) -> 1.8333333 | D9: =SUMIFS(IGA_BD!$Q:$Q,IGA_BD!$G:$G,(VLOOKUP(D$4,'Basic Data'!$A:$F,6,0)),IGA_BD!$F:$F,">="&Analytices!$B$2,IGA_BD!$F:$F,"<="&Analytices!$B$3) -> 1.8333333 | E9: =SUMIFS(IGA_BD!$Q:$Q,IGA_BD!$G:$G,(VLOOKUP(E$4,'Basic Data'!$A:$F,6,0)),IGA_BD!$F:$F,">="&Analytices!$B$2,IGA_BD!$F:$F,"<="&Analytices!$B$3) -> 1.8333333 | F9: =SUMIFS(IGA_BD!$Q:$Q,IGA_BD!$G:$G,(VLOOKUP(F$4,'Basic Data'!$A:$F,6,0)),IGA_BD!$F:$F,">="&Analytices!$B$2,IGA_BD!$F:$F,"<="&Analytices!$B$3) -> 0.81666667 | G9: =SUMIFS(IGA_BD!$Q:$Q,IGA_BD!$G:$G,(VLOOKUP(G$4,'Basic Data'!$A:$F,6,0)),IGA_BD!$F:$F,">="&Analytices!$B$2,IGA_BD!$F:$F,"<="&Analytices!$B$3) -> 1.8333333 | H9: =SUMIFS(IGA_BD!$Q:$Q,IGA_BD!$G:$G,(VLOOKUP(H$4,'Basic Data'!$A:$F,6,0)),IGA_BD!$F:$F,">="&Analytices!$B$2,IGA_BD!$F:$F,"<="&Analytices!$B$3) -> 1.8333333 | I9: =SUMIFS(IGA_BD!$Q:$Q,IGA_BD!$G:$G,(VLOOKUP(I$4,'Basic Data'!$A:$F,6,0)),IGA_BD!$F:$F,">="&Analytices!$B$2,IGA_BD!$F:$F,"<="&Analytices!$B$3) -> 1.8333333 | ... AN9: =SUMIFS(IGA_BD!$Q:$Q,IGA_BD!$G:$G,(VLOOKUP(AN$4,'Basic Data'!$A:$F,6,0)),IGA_BD!$F:$F,">="&Analytices!$B$2,IGA_BD!$F:$F,"<="&Analytices!$B$3) -> 0
A10: OG
A11: TRANSFER | B11: =SUMIFS(Grid_BD!$R:$R,Grid_BD!$G:$G,(VLOOKUP(B$4,'Basic Data'!$A:$G,7,0)),Grid_BD!$F:$F,">="&Analytices!$B$2,Grid_BD!$F:$F,"<="&Analytices!$B$3) -> 0 | C11: =SUMIFS(Grid_BD!$R:$R,Grid_BD!$G:$G,(VLOOKUP(C$4,'Basic Data'!$A:$G,7,0)),Grid_BD!$F:$F,">="&Analytices!$B$2,Grid_BD!$F:$F,"<="&Analytices!$B$3) -> 0 | D11: =SUMIFS(Grid_BD!$R:$R,Grid_BD!$G:$G,(VLOOKUP(D$4,'Basic Data'!$A:$G,7,0)),Grid_BD!$F:$F,">="&Analytices!$B$2,Grid_BD!$F:$F,"<="&Analytices!$B$3) -> 0 | E11: =SUMIFS(Grid_BD!$R:$R,Grid_BD!$G:$G,(VLOOKUP(E$4,'Basic Data'!$A:$G,7,0)),Grid_BD!$F:$F,">="&Analytices!$B$2,Grid_BD!$F:$F,"<="&Analytices!$B$3) -> 0 | F11: =SUMIFS(Grid_BD!$R:$R,Grid_BD!$G:$G,(VLOOKUP(F$4,'Basic Data'!$A:$G,7,0)),Grid_BD!$F:$F,">="&Analytices!$B$2,Grid_BD!$F:$F,"<="&Analytices!$B$3) -> 0 | G11: =SUMIFS(Grid_BD!$R:$R,Grid_BD!$G:$G,(VLOOKUP(G$4,'Basic Data'!$A:$G,7,0)),Grid_BD!$F:$F,">="&Analytices!$B$2,Grid_BD!$F:$F,"<="&Analytices!$B$3) -> 0 | H11: =SUMIFS(Grid_BD!$R:$R,Grid_BD!$G:$G,(VLOOKUP(H$4,'Basic Data'!$A:$G,7,0)),Grid_BD!$F:$F,">="&Analytices!$B$2,Grid_BD!$F:$F,"<="&Analytices!$B$3) -> 0 | I11: =SUMIFS(Grid_BD!$R:$R,Grid_BD!$G:$G,(VLOOKUP(I$4,'Basic Data'!$A:$G,7,0)),Grid_BD!$F:$F,">="&Analytices!$B$2,Grid_BD!$F:$F,"<="&Analytices!$B$3) -> 0 | ... AN11: =SUMIFS(Grid_BD!$R:$R,Grid_BD!$G:$G,(VLOOKUP(AN$4,'Basic Data'!$A:$G,7,0)),Grid_BD!$F:$F,">="&Analytices!$B$2,Grid_BD!$F:$F,"<="&Analytices!$B$3) -> 0
A12: USS
A13: EGA | B13: =(C3-B14)/C3 -> 1 | C13: =$B$13 -> 1 | D13: =$B$13 -> 1 | E13: =$B$13 -> 1 | F13: =$B$13 -> 1 | G13: =$B$13 -> 1 | H13: =$B$13 -> 1 | I13: =$B$13 -> 1 | J13: =$B$13 -> 1 | ... AN13: =$B$13 -> 1
A14: External Grid | B14: =(SUMIFS(Grid_BD!$R:$R,Grid_BD!$F:$F,">="&Analytices!B2,Grid_BD!$F:$F,"<="&Analytices!B3,Grid_BD!$G:$G,"Line1")) -> 0 | C14: =$B$14 -> 0 | D14: =$B$14 -> 0 | E14: =$B$14 -> 0 | F14: =$B$14 -> 0 | G14: =$B$14 -> 0 | H14: =$B$14 -> 0 | I14: =$B$14 -> 0 | J14: =$B$14 -> 0 | ... AN14: =$B$14 -> 0
A15: Generation | B15: =SUMIFS(Input_Raw!F:F,Input_Raw!$A:$A,">="&Analytices!$B$2,Input_Raw!$A:$A,"<="&Analytices!$B$3) -> 303129 | C15: =SUMIFS(Input_Raw!G:G,Input_Raw!$A:$A,">="&Analytices!$B$2,Input_Raw!$A:$A,"<="&Analytices!$B$3) -> 311445 | D15: =SUMIFS(Input_Raw!H:H,Input_Raw!$A:$A,">="&Analytices!$B$2,Input_Raw!$A:$A,"<="&Analytices!$B$3) -> 307719 | E15: =SUMIFS(Input_Raw!I:I,Input_Raw!$A:$A,">="&Analytices!$B$2,Input_Raw!$A:$A,"<="&Analytices!$B$3) -> 301658 | F15: =SUMIFS(Input_Raw!J:J,Input_Raw!$A:$A,">="&Analytices!$B$2,Input_Raw!$A:$A,"<="&Analytices!$B$3) -> 280932 | G15: =SUMIFS(Input_Raw!K:K,Input_Raw!$A:$A,">="&Analytices!$B$2,Input_Raw!$A:$A,"<="&Analytices!$B$3) -> 309527 | H15: =SUMIFS(Input_Raw!L:L,Input_Raw!$A:$A,">="&Analytices!$B$2,Input_Raw!$A:$A,"<="&Analytices!$B$3) -> 311717 | I15: =SUMIFS(Input_Raw!M:M,Input_Raw!$A:$A,">="&Analytices!$B$2,Input_Raw!$A:$A,"<="&Analytices!$B$3) -> 312813 | J15: =SUMIFS(Input_Raw!N:N,Input_Raw!$A:$A,">="&Analytices!$B$2,Input_Raw!$A:$A,"<="&Analytices!$B$3) -> 330654 | K15: =SUMIFS(Input_Raw!O:O,Input_Raw!$A:$A,">="&Analytices!$B$2,Input_Raw!$A:$A,"<="&Analytices!$B$3) -> 310698 | L15: =SUMIFS(Input_Raw!P:P,Input_Raw!$A:$A,">="&Analytices!$B$2,Input_Raw!$A:$A,"<="&Analytices!$B$3) -> 312144 | M15: =SUMIFS(Input_Raw!Q:Q,Input_Raw!$A:$A,">="&Analytices!$B$2,Input_Raw!$A:$A,"<="&Analytices!$B$3) -> 333390 | N15: =SUMIFS(Input_Raw!R:R,Input_Raw!$A:$A,">="&Analytices!$B$2,Input_Raw!$A:$A,"<="&Analytices!$B$3) -> 336578 | O15: =SUMIFS(Input_Raw!S:S,Input_Raw!$A:$A,">="&Analytices!$B$2,Input_Raw!$A:$A,"<="&Analytices!$B$3) -> 336656 | P15: =SUMIFS(Input_Raw!T:T,Input_Raw!$A:$A,">="&Analytices!$B$2,Input_Raw!$A:$A,"<="&Analytices!$B$3) -> 335733 | Q15: =SUMIFS(Input_Raw!U:U,Input_Raw!$A:$A,">="&Analytices!$B$2,Input_Raw!$A:$A,"<="&Analytices!$B$3) -> 327337 | R15: =SUMIFS(Input_Raw!V:V,Input_Raw!$A:$A,">="&Analytices!$B$2,Input_Raw!$A:$A,"<="&Analytices!$B$3) -> 41319 | S15: =SUMIFS(Input_Raw!W:W,Input_Raw!$A:$A,">="&Analytices!$B$2,Input_Raw!$A:$A,"<="&Analytices!$B$3) -> 332833 | T15: =SUMIFS(Input_Raw!X:X,Input_Raw!$A:$A,">="&Analytices!$B$2,Input_Raw!$A:$A,"<="&Analytices!$B$3) -> 337581 | U15: =SUMIFS(Input_Raw!Y:Y,Input_Raw!$A:$A,">="&Analytices!$B$2,Input_Raw!$A:$A,"<="&Analytices!$B$3) -> 336506 | V15: =SUMIFS(Input_Raw!Z:Z,Input_Raw!$A:$A,">="&Analytices!$B$2,Input_Raw!$A:$A,"<="&Analytices!$B$3) -> 282689 | W15: =SUMIFS(Input_Raw!AA:AA,Input_Raw!$A:$A,">="&Analytices!$B$2,Input_Raw!$A:$A,"<="&Analytices!$B$3) -> 279819 | X15: =SUMIFS(Input_Raw!AB:AB,Input_Raw!$A:$A,">="&Analytices!$B$2,Input_Raw!$A:$A,"<="&Analytices!$B$3) -> 281605 | Y15: =SUMIFS(Input_Raw!AC:AC,Input_Raw!$A:$A,">="&Analytices!$B$2,Input_Raw!$A:$A,"<="&Analytices!$B$3) -> 282495 | Z15: =SUMIFS(Input_Raw!AD:AD,Input_Raw!$A:$A,">="&Analytices!$B$2,Input_Raw!$A:$A,"<="&Analytices!$B$3) -> 246026 | AA15: =SUMIFS(Input_Raw!AE:AE,Input_Raw!$A:$A,">="&Analytices!$B$2,Input_Raw!$A:$A,"<="&Analytices!$B$3) -> 279145 | AB15: =SUMIFS(Input_Raw!AF:AF,Input_Raw!$A:$A,">="&Analytices!$B$2,Input_Raw!$A:$A,"<="&Analytices!$B$3) -> 280467 | AC15: =SUMIFS(Input_Raw!AG:AG,Input_Raw!$A:$A,">="&Analytices!$B$2,Input_Raw!$A:$A,"<="&Analytices!$B$3) -> 0 | AD15: =SUMIFS(Input_Raw!AH:AH,Input_Raw!$A:$A,">="&Analytices!$B$2,Input_Raw!$A:$A,"<="&Analytices!$B$3) -> 274624 | AE15: =SUMIFS(Input_Raw!AI:AI,Input_Raw!$A:$A,">="&Analytices!$B$2,Input_Raw!$A:$A,"<="&Analytices!$B$3) -> 24908 | AF15: =SUMIFS(Input_Raw!AJ:AJ,Input_Raw!$A:$A,">="&Analytices!$B$2,Input_Raw!$A:$A,"<="&Analytices!$B$3) -> 237034 | AG15: =SUMIFS(Input_Raw!AK:AK,Input_Raw!$A:$A,">="&Analytices!$B$2,Input_Raw!$A:$A,"<="&Analytices!$B$3) -> 246357 | AH15: =SUMIFS(Input_Raw!AL:AL,Input_Raw!$A:$A,">="&Analytices!$B$2,Input_Raw!$A:$A,"<="&Analytices!$B$3) -> 247172 | AI15: =SUMIFS(Input_Raw!AM:AM,Input_Raw!$A:$A,">="&Analytices!$B$2,Input_Raw!$A:$A,"<="&Analytices!$B$3) -> 244984 | AJ15: =SUMIFS(Input_Raw!AN:AN,Input_Raw!$A:$A,">="&Analytices!$B$2,Input_Raw!$A:$A,"<="&Analytices!$B$3) -> 247157 | AK15: =SUMIFS(Input_Raw!AO:AO,Input_Raw!$A:$A,">="&Analytices!$B$2,Input_Raw!$A:$A,"<="&Analytices!$B$3) -> 246900 | AL15: =SUMIFS(Input_Raw!AP:AP,Input_Raw!$A:$A,">="&Analytices!$B$2,Input_Raw!$A:$A,"<="&Analytices!$B$3) -> 245740 | AM15: =SUMIFS(Input_Raw!AQ:AQ,Input_Raw!$A:$A,">="&Analytices!$B$2,Input_Raw!$A:$A,"<="&Analytices!$B$3) -> 244944 | AN15: =SUMIFS(Input_Raw!AR:AR,Input_Raw!$A:$A,">="&Analytices!$B$2,Input_Raw!$A:$A,"<="&Analytices!$B$3) -> 244910
A16: PA | B16: =IFERROR(($C$3-(SUM(B8:B12,B14,B6)))/$C$3,1) -> 0.97421498 | C16: =IFERROR(($C$3-(SUM(C8:C12,C14,C6)))/$C$3,1) -> 0.99353865 | D16: =IFERROR(($C$3-(SUM(D8:D12,D14,D6)))/$C$3,1) -> 0.99350845 | E16: =IFERROR(($C$3-(SUM(E8:E12,E14,E6)))/$C$3,1) -> 0.97047101 | F16: =IFERROR(($C$3-(SUM(F8:F12,F14,F6)))/$C$3,1) -> 0.99746377 | G16: =IFERROR(($C$3-(SUM(G8:G12,G14,G6)))/$C$3,1) -> 0.98994565 | H16: =IFERROR(($C$3-(SUM(H8:H12,H14,H6)))/$C$3,1) -> 0.99667874 | I16: =IFERROR(($C$3-(SUM(I8:I12,I14,I6)))/$C$3,1) -> 0.99667874 | ... AN16: =IFERROR(($C$3-(SUM(AN8:AN12,AN14,AN6)))/$C$3,1) -> 0.99842995
A17: Sum of BD | B17: =SUMIFS(WTG_BD!$T:$T,WTG_BD!$F:$F,">="&Analytices!$B$2,WTG_BD!$F:$F,"<="&Analytices!$B$3,WTG_BD!$G:$G,B4,WTG_BD!$M:$M,'Basic Data'!$N$10) -> 12.4 | C17: =SUMIFS(WTG_BD!$T:$T,WTG_BD!$F:$F,">="&Analytices!$B$2,WTG_BD!$F:$F,"<="&Analytices!$B$3,WTG_BD!$G:$G,C4,WTG_BD!$M:$M,'Basic Data'!$N$10) -> 1.7333333 | D17: =SUMIFS(WTG_BD!$T:$T,WTG_BD!$F:$F,">="&Analytices!$B$2,WTG_BD!$F:$F,"<="&Analytices!$B$3,WTG_BD!$G:$G,D4,WTG_BD!$M:$M,'Basic Data'!$N$10) -> 0 | E17: =SUMIFS(WTG_BD!$T:$T,WTG_BD!$F:$F,">="&Analytices!$B$2,WTG_BD!$F:$F,"<="&Analytices!$B$3,WTG_BD!$G:$G,E4,WTG_BD!$M:$M,'Basic Data'!$N$10) -> 14.466667 | F17: =SUMIFS(WTG_BD!$T:$T,WTG_BD!$F:$F,">="&Analytices!$B$2,WTG_BD!$F:$F,"<="&Analytices!$B$3,WTG_BD!$G:$G,F4,WTG_BD!$M:$M,'Basic Data'!$N$10) -> 0.58333333 | G17: =SUMIFS(WTG_BD!$T:$T,WTG_BD!$F:$F,">="&Analytices!$B$2,WTG_BD!$F:$F,"<="&Analytices!$B$3,WTG_BD!$G:$G,G4,WTG_BD!$M:$M,'Basic Data'!$N$10) -> 3.7166667 | H17: =SUMIFS(WTG_BD!$T:$T,WTG_BD!$F:$F,">="&Analytices!$B$2,WTG_BD!$F:$F,"<="&Analytices!$B$3,WTG_BD!$G:$G,H4,WTG_BD!$M:$M,'Basic Data'!$N$10) -> 0 | I17: =SUMIFS(WTG_BD!$T:$T,WTG_BD!$F:$F,">="&Analytices!$B$2,WTG_BD!$F:$F,"<="&Analytices!$B$3,WTG_BD!$G:$G,I4,WTG_BD!$M:$M,'Basic Data'!$N$10) -> 0 | ... AN17: =SUMIFS(WTG_BD!$T:$T,WTG_BD!$F:$F,">="&Analytices!$B$2,WTG_BD!$F:$F,"<="&Analytices!$B$3,WTG_BD!$G:$G,AN4,WTG_BD!$M:$M,'Basic Data'!$N$10) -> 0.86666667
A18: Count of BD | B18: =COUNTIFS(WTG_BD!$F:$F,">="&Analytices!$B$2,WTG_BD!$F:$F,"<="&Analytices!$B$3,WTG_BD!$G:$G,B4,WTG_BD!$M:$M,'Basic Data'!$N$10) -> 7 | C18: =COUNTIFS(WTG_BD!$F:$F,">="&Analytices!$B$2,WTG_BD!$F:$F,"<="&Analytices!$B$3,WTG_BD!$G:$G,C4,WTG_BD!$M:$M,'Basic Data'!$N$10) -> 1 | D18: =COUNTIFS(WTG_BD!$F:$F,">="&Analytices!$B$2,WTG_BD!$F:$F,"<="&Analytices!$B$3,WTG_BD!$G:$G,D4,WTG_BD!$M:$M,'Basic Data'!$N$10) -> 0 | E18: =COUNTIFS(WTG_BD!$F:$F,">="&Analytices!$B$2,WTG_BD!$F:$F,"<="&Analytices!$B$3,WTG_BD!$G:$G,E4,WTG_BD!$M:$M,'Basic Data'!$N$10) -> 5 | F18: =COUNTIFS(WTG_BD!$F:$F,">="&Analytices!$B$2,WTG_BD!$F:$F,"<="&Analytices!$B$3,WTG_BD!$G:$G,F4,WTG_BD!$M:$M,'Basic Data'!$N$10) -> 1 | G18: =COUNTIFS(WTG_BD!$F:$F,">="&Analytices!$B$2,WTG_BD!$F:$F,"<="&Analytices!$B$3,WTG_BD!$G:$G,G4,WTG_BD!$M:$M,'Basic Data'!$N$10) -> 2 | H18: =COUNTIFS(WTG_BD!$F:$F,">="&Analytices!$B$2,WTG_BD!$F:$F,"<="&Analytices!$B$3,WTG_BD!$G:$G,H4,WTG_BD!$M:$M,'Basic Data'!$N$10) -> 0 | I18: =COUNTIFS(WTG_BD!$F:$F,">="&Analytices!$B$2,WTG_BD!$F:$F,"<="&Analytices!$B$3,WTG_BD!$G:$G,I4,WTG_BD!$M:$M,'Basic Data'!$N$10) -> 0 | ... AN18: =COUNTIFS(WTG_BD!$F:$F,">="&Analytices!$B$2,WTG_BD!$F:$F,"<="&Analytices!$B$3,WTG_BD!$G:$G,AN4,WTG_BD!$M:$M,'Basic Data'!$N$10) -> 1
A19: MTTR WTG | B19: =IFERROR(B17/B18,0) -> 1.7714286 | C19: =IFERROR(C17/C18,0) -> 1.7333333 | D19: =IFERROR(D17/D18,0) -> 0 | E19: =IFERROR(E17/E18,0) -> 2.8933333 | F19: =IFERROR(F17/F18,0) -> 0.58333333 | G19: =IFERROR(G17/G18,0) -> 1.8583333 | H19: =IFERROR(H17/H18,0) -> 0 | I19: =IFERROR(I17/I18,0) -> 0 | ... AN19: =IFERROR(AN17/AN18,0) -> 0.86666667
A20: MTBF WTG | B20: =IFERROR(($C$3-B17)/B18,$C$3) -> 77.085714 | C20: =IFERROR(($C$3-C17)/C18,$C$3) -> 550.26667 | D20: =IFERROR(($C$3-D17)/D18,$C$3) -> 552 | E20: =IFERROR(($C$3-E17)/E18,$C$3) -> 107.50667 | F20: =IFERROR(($C$3-F17)/F18,$C$3) -> 551.41667 | G20: =IFERROR(($C$3-G17)/G18,$C$3) -> 274.14167 | H20: =IFERROR(($C$3-H17)/H18,$C$3) -> 552 | I20: =IFERROR(($C$3-I17)/I18,$C$3) -> 552 | ... AN20: =IFERROR(($C$3-AN17)/AN18,$C$3) -> 551.13333
A21: WS (M/S) | B21: =ROUND(AVERAGEIFS(Input_Raw!AS:AS,Input_Raw!$A:$A,">="&Analytices!$B$2,Input_Raw!$A:$A,"<="&Analytices!$B$3),1) -> 5.3 | C21: =ROUND(AVERAGEIFS(Input_Raw!AT:AT,Input_Raw!$A:$A,">="&Analytices!$B$2,Input_Raw!$A:$A,"<="&Analytices!$B$3),1) -> 5.3 | D21: =ROUND(AVERAGEIFS(Input_Raw!AU:AU,Input_Raw!$A:$A,">="&Analytices!$B$2,Input_Raw!$A:$A,"<="&Analytices!$B$3),1) -> 5.1 | E21: =ROUND(AVERAGEIFS(Input_Raw!AV:AV,Input_Raw!$A:$A,">="&Analytices!$B$2,Input_Raw!$A:$A,"<="&Analytices!$B$3),1) -> 5.2 | F21: =ROUND(AVERAGEIFS(Input_Raw!AW:AW,Input_Raw!$A:$A,">="&Analytices!$B$2,Input_Raw!$A:$A,"<="&Analytices!$B$3),1) -> 5.2 | G21: =ROUND(AVERAGEIFS(Input_Raw!AX:AX,Input_Raw!$A:$A,">="&Analytices!$B$2,Input_Raw!$A:$A,"<="&Analytices!$B$3),1) -> 5.3 | H21: =ROUND(AVERAGEIFS(Input_Raw!AY:AY,Input_Raw!$A:$A,">="&Analytices!$B$2,Input_Raw!$A:$A,"<="&Analytices!$B$3),1) -> 5 | I21: =ROUND(AVERAGEIFS(Input_Raw!AZ:AZ,Input_Raw!$A:$A,">="&Analytices!$B$2,Input_Raw!$A:$A,"<="&Analytices!$B$3),1) -> 5.3 | J21: =ROUND(AVERAGEIFS(Input_Raw!BA:BA,Input_Raw!$A:$A,">="&Analytices!$B$2,Input_Raw!$A:$A,"<="&Analytices!$B$3),1) -> 5 | K21: =ROUND(AVERAGEIFS(Input_Raw!BB:BB,Input_Raw!$A:$A,">="&Analytices!$B$2,Input_Raw!$A:$A,"<="&Analytices!$B$3),1) -> 5.3 | L21: =ROUND(AVERAGEIFS(Input_Raw!BC:BC,Input_Raw!$A:$A,">="&Analytices!$B$2,Input_Raw!$A:$A,"<="&Analytices!$B$3),1) -> 5.4 | M21: =ROUND(AVERAGEIFS(Input_Raw!BD:BD,Input_Raw!$A:$A,">="&Analytices!$B$2,Input_Raw!$A:$A,"<="&Analytices!$B$3),1) -> 5.2 | N21: =ROUND(AVERAGEIFS(Input_Raw!BE:BE,Input_Raw!$A:$A,">="&Analytices!$B$2,Input_Raw!$A:$A,"<="&Analytices!$B$3),1) -> 5.3 | O21: =ROUND(AVERAGEIFS(Input_Raw!BF:BF,Input_Raw!$A:$A,">="&Analytices!$B$2,Input_Raw!$A:$A,"<="&Analytices!$B$3),1) -> 5.4 | P21: =ROUND(AVERAGEIFS(Input_Raw!BG:BG,Input_Raw!$A:$A,">="&Analytices!$B$2,Input_Raw!$A:$A,"<="&Analytices!$B$3),1) -> 5.4 | Q21: =ROUND(AVERAGEIFS(Input_Raw!BH:BH,Input_Raw!$A:$A,">="&Analytices!$B$2,Input_Raw!$A:$A,"<="&Analytices!$B$3),1) -> 5.2 | R21: =ROUND(AVERAGEIFS(Input_Raw!BI:BI,Input_Raw!$A:$A,">="&Analytices!$B$2,Input_Raw!$A:$A,"<="&Analytices!$B$3),1) -> 1.2 | S21: =ROUND(AVERAGEIFS(Input_Raw!BJ:BJ,Input_Raw!$A:$A,">="&Analytices!$B$2,Input_Raw!$A:$A,"<="&Analytices!$B$3),1) -> 5.5 | T21: =ROUND(AVERAGEIFS(Input_Raw!BK:BK,Input_Raw!$A:$A,">="&Analytices!$B$2,Input_Raw!$A:$A,"<="&Analytices!$B$3),1) -> 5.7 | U21: =ROUND(AVERAGEIFS(Input_Raw!BL:BL,Input_Raw!$A:$A,">="&Analytices!$B$2,Input_Raw!$A:$A,"<="&Analytices!$B$3),1) -> 5.5 | V21: =ROUND(AVERAGEIFS(Input_Raw!BM:BM,Input_Raw!$A:$A,">="&Analytices!$B$2,Input_Raw!$A:$A,"<="&Analytices!$B$3),1) -> 5.4 | W21: =ROUND(AVERAGEIFS(Input_Raw!BN:BN,Input_Raw!$A:$A,">="&Analytices!$B$2,Input_Raw!$A:$A,"<="&Analytices!$B$3),1) -> 5.3 | X21: =ROUND(AVERAGEIFS(Input_Raw!BO:BO,Input_Raw!$A:$A,">="&Analytices!$B$2,Input_Raw!$A:$A,"<="&Analytices!$B$3),1) -> 4.6 | Y21: =ROUND(AVERAGEIFS(Input_Raw!BP:BP,Input_Raw!$A:$A,">="&Analytices!$B$2,Input_Raw!$A:$A,"<="&Analytices!$B$3),1) -> 5.2 | Z21: =ROUND(AVERAGEIFS(Input_Raw!BQ:BQ,Input_Raw!$A:$A,">="&Analytices!$B$2,Input_Raw!$A:$A,"<="&Analytices!$B$3),1) -> 5.1 | AA21: =ROUND(AVERAGEIFS(Input_Raw!BR:BR,Input_Raw!$A:$A,">="&Analytices!$B$2,Input_Raw!$A:$A,"<="&Analytices!$B$3),1) -> 5.1 | AB21: =ROUND(AVERAGEIFS(Input_Raw!BS:BS,Input_Raw!$A:$A,">="&Analytices!$B$2,Input_Raw!$A:$A,"<="&Analytices!$B$3),1) -> 4.9 | AC21: =ROUND(AVERAGEIFS(Input_Raw!BT:BT,Input_Raw!$A:$A,">="&Analytices!$B$2,Input_Raw!$A:$A,"<="&Analytices!$B$3),1) -> 0 | AD21: =ROUND(AVERAGEIFS(Input_Raw!BU:BU,Input_Raw!$A:$A,">="&Analytices!$B$2,Input_Raw!$A:$A,"<="&Analytices!$B$3),1) -> 5 | AE21: =ROUND(AVERAGEIFS(Input_Raw!BV:BV,Input_Raw!$A:$A,">="&Analytices!$B$2,Input_Raw!$A:$A,"<="&Analytices!$B$3),1) -> 0.3 | AF21: =ROUND(AVERAGEIFS(Input_Raw!BW:BW,Input_Raw!$A:$A,">="&Analytices!$B$2,Input_Raw!$A:$A,"<="&Analytices!$B$3),1) -> 5 | AG21: =ROUND(AVERAGEIFS(Input_Raw!BX:BX,Input_Raw!$A:$A,">="&Analytices!$B$2,Input_Raw!$A:$A,"<="&Analytices!$B$3),1) -> 5.1 | AH21: =ROUND(AVERAGEIFS(Input_Raw!BY:BY,Input_Raw!$A:$A,">="&Analytices!$B$2,Input_Raw!$A:$A,"<="&Analytices!$B$3),1) -> 5.3 | AI21: =ROUND(AVERAGEIFS(Input_Raw!BZ:BZ,Input_Raw!$A:$A,">="&Analytices!$B$2,Input_Raw!$A:$A,"<="&Analytices!$B$3),1) -> 5.3 | AJ21: =ROUND(AVERAGEIFS(Input_Raw!CA:CA,Input_Raw!$A:$A,">="&Analytices!$B$2,Input_Raw!$A:$A,"<="&Analytices!$B$3),1) -> 5.2 | AK21: =ROUND(AVERAGEIFS(Input_Raw!CB:CB,Input_Raw!$A:$A,">="&Analytices!$B$2,Input_Raw!$A:$A,"<="&Analytices!$B$3),1) -> 5.3 | AL21: =ROUND(AVERAGEIFS(Input_Raw!CC:CC,Input_Raw!$A:$A,">="&Analytices!$B$2,Input_Raw!$A:$A,"<="&Analytices!$B$3),1) -> 5 | AM21: =ROUND(AVERAGEIFS(Input_Raw!CD:CD,Input_Raw!$A:$A,">="&Analytices!$B$2,Input_Raw!$A:$A,"<="&Analytices!$B$3),1) -> 4.9 | AN21: =ROUND(AVERAGEIFS(Input_Raw!CE:CE,Input_Raw!$A:$A,">="&Analytices!$B$2,Input_Raw!$A:$A,"<="&Analytices!$B$3),1) -> 5.1
A23: Fault Analysis
A24: 45017
D25: Put hour Here | F25: Default hour for full Data
D26: =F26 -> 20256 | F26: =((TODAY()-1)-(A24))*24 -> 20256
A27: Finacial Year | B27: (Multiple Items)
A29: Row Labels | B29: Sum of Breakdown Time | C29: Count of Error Text | D29: MTTR | E29: MTBF
A30: Active Crowbar Failure | B30: 0.21666667 | C30: 1 | D30: =B30/C30 -> 0.21666667 | E30: =$D$26/C30 -> 20256
A31: Active Crowbar IGBT Errors | B31: 9.3333333 | C31: 2 | D31: =B31/C31 -> 4.6666667 | E31: =$D$26/C31 -> 10128
A32: Analogue Card Failure | B32: 6.0666667 | C32: 2 | D32: =B32/C32 -> 3.0333333 | E32: =$D$26/C32 -> 10128
A33: Automatic Secondaries Not OK Too Long | B33: 33.933333 | C33: 20 | D33: =B33/C33 -> 1.6966667 | E33: =$D$26/C33 -> 1012.8
A34: Automatic Unwinding | B34: 14.616667 | C34: 7 | D34: =B34/C34 -> 2.0880952 | E34: =$D$26/C34 -> 2893.7143
A35: Blade Position Meas. Error | B35: 22.416667 | C35: 6 | D35: =B35/C35 -> 3.7361111 | E35: =$D$26/C35 -> 3376
A36: Bus Error - Interbus Failure | B36: 325.73333 | C36: 93 | D36: =B36/C36 -> 3.502509 | E36: =$D$26/C36 -> 217.80645
A37: Bus Preload Protection Thermal Relay Failure | B37: 31.283333 | C37: 12 | D37: =B37/C37 -> 2.6069444 | E37: =$D$26/C37 -> 1688
A38: CAN Communication Failure | B38: 30.95 | C38: 19 | D38: =B38/C38 -> 1.6289474 | E38: =$D$26/C38 -> 1066.1053
A39: CCW Feedback Failure | B39: 72.816667 | C39: 10 | D39: =B39/C39 -> 7.2816667 | E39: =$D$26/C39 -> 2025.6
A40: Change Pause-Remote Control Reset | B40: 5.1666667 | C40: 1 | D40: =B40/C40 -> 5.1666667 | E40: =$D$26/C40 -> 20256
A41: Controlled Emergency Series Battery Failure | B41: 13.316667 | C41: 5 | D41: =B41/C41 -> 2.6633333 | E41: =$D$26/C41 -> 4051.2
... A106: Yawing Sensor Failure | B106: 9.2166667 | C106: 2 | D106: =B106/C106 -> 4.6083333 | E106: =$D$26/C106 -> 10128
A107: (blank) | B107: 0 | D107: =B107/C107 -> #DIV/0! | E107: =$D$26/C107 -> #DIV/0!
...

Sheet Input_Raw
A1: 1 | B1: =A1+1 -> 2 | C1: =B1+1 -> 3 | D1: =C1+1 -> 4 | E1: =D1+1 -> 5 | F1: =E1+1 -> 6 | G1: =F1+1 -> 7 | H1: =G1+1 -> 8 | I1: =H1+1 -> 9 | ... DB1: =DA1+1 -> 106
F3: Energy Generated by individual Turbine | AS3: Wind Speed (M/s) | CJ3: Meter Readings | CR3: Calculated Energy Numbers
A4: Date | B4: Finacial Year | C4: Calendor Year | D4: Month Year | E4: Days | F4: G01 | G4: G02 | H4: G03 | I4: G04 | J4: G05 | K4: G06 | L4: G07 | M4: G08 | N4: G09 | O4: G10 | P4: G11 | Q4: G12 | R4: G13 | S4: G14 | T4: G15 | U4: G16 | V4: G17 | W4: G18 | X4: G19 | Y4: G20 | Z4: G21 | AA4: G22 | AB4: G23 | AC4: G25 | AD4: G26 | AE4: G27 | AF4: G28 | AG4: G29 | AH4: G30 | AI4: G31 | AJ4: G32 | AK4: G33 | AL4: G34 | AM4: G35 | AN4: G36 | AO4: G37 | AP4: G38 | AQ4: G39 | AR4: G40 | AS4: WS_G01 | AT4: WS_G02 | AU4: WS_G03 | AV4: WS_G04 | AW4: WS_G05 | AX4: WS_G06 | AY4: WS_G07 | AZ4: WS_G08 | BA4: WS_G09 | BB4: WS_G10 | BC4: WS_G11 | BD4: WS_G12 | BE4: WS_G13 | BF4: WS_G14 | BG4: WS_G15 | BH4: WS_G16 | BI4: WS_G17 | BJ4: WS_G18 | BK4: WS_G19 | BL4: WS_G20 | BM4: WS_G21 | BN4: WS_G22 | BO4: WS_G23 | BP4: WS_G25 | BQ4: WS_G26 | BR4: WS_G27 | BS4: WS_G28 | BT4: WS_G29 | BU4: WS_G30 | BV4: WS_G31 | BW4: WS_G32 | BX4: WS_G33 | BY4: WS_G34 | BZ4: WS_G35 | CA4: WS_G36 | CB4: WS_G37 | CC4: WS_G38 | CD4: WS_G39 | CE4: WS_G40 | CF4: WTG Total Gneration (KWh) | CG4: Wind Speed Average cumulative (m/S)2 | CH4: Wind Speed Max (m/S) | CI4: Rain (mm) | CJ4: 33 kV_Wind_F1_Export reading | CK4: 33 kV_Wind_F1_Import reading | CL4: 33 kV_Wind_F2_Export_reading | CM4: 33 kV_Wind_F2_Import_reading | CN4: 33 kV_Wind_F3_Export_Reading | CO4: 33 kV_Wind_F3_Import_Reading | CP4: 33 kV_Wind_F4_Export Reading | CQ4: 33 kV_Wind_F4_Import Reading | CR4: 33 kV_F1_Total_Export (KWh) | CS4: 33 kV_Wind_F1_Import (KWh) | CT4: 33 kV_F2_Total_Export (KWh)2 | CU4: 33 kV_Wind_F2_Import (KWh) | CV4: 33 kV_Wind_F3_Export (KWh) | CW4: 33 kV_Wind_F3_Import (KWh)2 | CX4: 33 kV_Wind_F4_Export (KWh) | CY4: 33 kV_Wind_F4_Import (KWh)2 | CZ4: 33 kV_Wind_Total_Export (KWh) | DA4: 33 kV_Wind_Total_Import (KWh) | DB4: 33 kV Line Loss (%) | DC4: Forecasting Data count received on Forecasting Portal | DD4: Forecasting Penalties (INR) | DE4: Expected Energy As Per Power Curve (MWh) | DF4: Reactive Energy (MVArH) | DG4: Operational Capacity | DH4: Column1
A5: 45745 | B5: =YEAR([1]!Input_Raw[[#This Row],[Date]])+IF(MONTH([1]!Input_Raw[[#This Row],[Date]])>=4,1,0) -> 2025 | C5: =YEAR([1]!Input_Raw[[#This Row],[Date]]) -> 2025 | D5: =A5-DAY(A5)+1 -> 45717 | E5: =DAY(EOMONTH([1]!Input_Raw[[#This Row],[Date]],0)) -> 31 | F5: 3576 | G5: 5244 | H5: 3376 | I5: 3992 | J5: 2114 | K5: 3446 | L5: 4316 | M5: 4376 | N5: 3336 | O5: 2784 | P5: 3724 | Q5: 4284 | R5: 4556 | S5: 5446 | T5: 4725 | U5: 3332 | V5: 3446 | W5: 3780 | X5: 4017 | Y5: 5100 | Z5: 4216 | AA5: 2780 | AB5: 1846 | AC5: 2882 | AD5: 2546 | AE5: 3164 | AF5: 2420 | AG5: 0 | AH5: 2614 | AI5: 0 | AJ5: 2684 | AK5: 2107 | AL5: 2688 | AM5: 2976 | AN5: 2792 | AO5: 2818 | AP5: 2858 | AQ5: 2612 | AR5: 2788 | AS5: 3.93 | AT5: 3.99 | AU5: 3.9 | AV5: 3.78 | AW5: 3.4 | AX5: 4.13 | AY5: 3.8 | AZ5: 4.05 | BA5: 3.76 | BB5: 3.86 | BC5: 4.06 | BD5: 3.98 | BE5: 4.04 | BF5: 4.03 | BG5: 3.88 | BH5: 4.18 | BI5: 3.41 | BJ5: 4.09 | BK5: 4.29 | BL5: 4.06 | BM5: 4.5 | BN5: 3.75 | BO5: 3.14 | BP5: 3.53 | BQ5: 3.02 | BR5: 3.42 | BS5: 3.48 | BT5: 0 | BU5: 3.31 | BV5: 0 | BW5: 3.29 | BX5: 3.51 | BY5: 3.38 | BZ5: 3.42 | CA5: 3.69 | CB5: 3.98 | CC5: 3.43 | CD5: 3.41 | CE5: 3.47 | CF5: =SUM(Input_Raw[[#This Row],[G01]:[G40]]) -> 125761 | CG5: =IFERROR(AVERAGE(Input_Raw[[#This Row],[WS_G01]:[WS_G40]]),"") -> 3.5474359 | CJ5: 237611 | CK5: 2156 | CL5: 278009 | CM5: 2188 | CN5: 253479 | CO5: 1795 | CP5: 289037 | CQ5: 1839 | CR5: =IF(((Input_Raw[[#This Row],[33 kV_Wind_F1_Export reading]]-#REF!)*1200)>0,(Input_Raw[[#This Row],[33 kV_Wind_F1_Export reading]]-#REF!)*1200,0) -> #REF! | CS5: =IF(((Input_Raw[[#This Row],[33 kV_Wind_F1_Import reading]]-#REF!)*1200)>0,(Input_Raw[[#This Row],[33 kV_Wind_F1_Import reading]]-#REF!)*1200,0) -> #REF! | CT5: =IF(((Input_Raw[[#This Row],[33 kV_Wind_F2_Export_reading]]-#REF!)*1200)>0,(Input_Raw[[#This Row],[33 kV_Wind_F2_Export_reading]]-#REF!)*1200,0) -> #REF! | CU5: =IF(((Input_Raw[[#This Row],[33 kV_Wind_F2_Import_reading]]-#REF!)*1200)>0,(Input_Raw[[#This Row],[33 kV_Wind_F2_Import_reading]]-#REF!)*1200,0) -> #REF! | CV5: =IF(((Input_Raw[[#This Row],[33 kV_Wind_F3_Export_Reading]]-#REF!)*1200)>0,(Input_Raw[[#This Row],[33 kV_Wind_F3_Export_Reading]]-#REF!)*1200,0) -> #REF! | CW5: =IF(((Input_Raw[[#This Row],[33 kV_Wind_F3_Import_Reading]]-#REF!)*1200)>0,(Input_Raw[[#This Row],[33 kV_Wind_F3_Import_Reading]]-#REF!)*1200,0) -> #REF! | CX5: =IF(((Input_Raw[[#This Row],[33 kV_Wind_F4_Export Reading]]-#REF!)*1200)>0,(Input_Raw[[#This Row],[33 kV_Wind_F4_Export Reading]]-#REF!)*1200,0) -> #REF! | CY5: =IF(((Input_Raw[[#This Row],[33 kV_Wind_F4_Import Reading]]-#REF!)*1200)>0,(Input_Raw[[#This Row],[33 kV_Wind_F4_Import Reading]]-#REF!)*1200,0) -> #REF! | CZ5: =Input_Raw[[#This Row],[33 kV_F1_Total_Export (KWh)]]+Input_Raw[[#This Row],[33 kV_F2_Total_Export (KWh)2]]+Input_Raw[[#This Row],[33 kV_Wind_F3_Export (KWh)]]+Input_Raw[[#This Row],[33 kV_Wind_F4_Export (KWh)]] -> #REF! | DA5: =Input_Raw[[#This Row],[33 kV_Wind_F1_Import (KWh)]]+Input_Raw[[#This Row],[33 kV_Wind_F2_Import (KWh)]]+Input_Raw[[#This Row],[33 kV_Wind_F3_Import (KWh)2]]+Input_Raw[[#This Row],[33 kV_Wind_F4_Import (KWh)2]] -> #REF! | DB5: =IFERROR(1-Input_Raw[[#This Row],[33 kV_Wind_Total_Export (KWh)]]/Input_Raw[[#This Row],[WTG Total Gneration (KWh)]],0) -> 0 | DC5: 0 | DD5: 0 | DG5: 80
A6: =A5+1 -> 45746 | B6: =YEAR([1]!Input_Raw[[#This Row],[Date]])+IF(MONTH([1]!Input_Raw[[#This Row],[Date]])>=4,1,0) -> 2025 | C6: =YEAR([1]!Input_Raw[[#This Row],[Date]]) -> 2025 | D6: =A6-DAY(A6)+1 -> 45717 | E6: =DAY(EOMONTH([1]!Input_Raw[[#This Row],[Date]],0)) -> 31 | F6: 2552 | G6: 3752 | H6: 2170 | I6: 3336 | J6: 2196 | K6: 2804 | L6: 3645 | M6: 3288 | N6: 3376 | O6: 3000 | P6: 2864 | Q6: 3892 | R6: 3398 | S6: 3550 | T6: 3998 | U6: 3892 | V6: 3980 | W6: 3348 | X6: 3505 | Y6: 3775 | Z6: 3630 | AA6: 2556 | AB6: 1802 | AC6: 2822 | AD6: 2672 | AE6: 2662 | AF6: 1552 | AG6: 0 | AH6: 2712 | AI6: 0 | AJ6: 2760 | AK6: 2289 | AL6: 2512 | AM6: 2838 | AN6: 3150 | AO6: 2882 | AP6: 2772 | AQ6: 2708 | AR6: 2791 | AS6: 3.21 | AT6: 3.42 | AU6: 3.52 | AV6: 3.63 | AW6: 3.23 | AX6: 3.53 | AY6: 3.4 | AZ6: 3.17 | BA6: 3.02 | BB6: 3.2 | BC6: 3.52 | BD6: 3.17 | BE6: 4.36 | BF6: 4.09 | BG6: 4.46 | BH6: 4.36 | BI6: 4.67 | BJ6: 4.28 | BK6: 4.44 | BL6: 4.5 | BM6: 4.11 | BN6: 3.93 | BO6: 4.13 | BP6: 4.08 | BQ6: 3.47 | BR6: 3.92 | BS6: 3.89 | BT6: 0 | BU6: 3.8 | BV6: 0 | BW6: 3.61 | BX6: 3.69 | BY6: 3.51 | BZ6: 3.72 | CA6: 3.87 | CB6: 3.73 | CC6: 3.54 | CD6: 3.45 | CE6: 3.53 | CF6: =SUM(Input_Raw[[#This Row],[G01]:[G40]]) -> 111431 | CG6: =IFERROR(AVERAGE(Input_Raw[[#This Row],[WS_G01]:[WS_G40]]),"") -> 3.5682051 | CJ6: 237629 | CK6: 2157 | CL6: 278030 | CM6: 2189 | CN6: 253501 | CO6: 1796 | CP6: 289059 | CQ6: 1840 | CR6: =IF(((Input_Raw[[#This Row],[33 kV_Wind_F1_Export reading]]-CJ5)*1200)>0,(Input_Raw[[#This Row],[33 kV_Wind_F1_Export reading]]-CJ5)*1200,0) -> 21600 | CS6: =IF(((Input_Raw[[#This Row],[33 kV_Wind_F1_Import reading]]-CK5)*1200)>0,(Input_Raw[[#This Row],[33 kV_Wind_F1_Import reading]]-CK5)*1200,0) -> 1200 | CT6: =IF(((Input_Raw[[#This Row],[33 kV_Wind_F2_Export_reading]]-CL5)*1200)>0,(Input_Raw[[#This Row],[33 kV_Wind_F2_Export_reading]]-CL5)*1200,0) -> 25200 | CU6: =IF(((Input_Raw[[#This Row],[33 kV_Wind_F2_Import_reading]]-CM5)*1200)>0,(Input_Raw[[#This Row],[33 kV_Wind_F2_Import_reading]]-CM5)*1200,0) -> 1200 | CV6: =IF(((Input_Raw[[#This Row],[33 kV_Wind_F3_Export_Reading]]-CN5)*1200)>0,(Input_Raw[[#This Row],[33 kV_Wind_F3_Export_Reading]]-CN5)*1200,0) -> 26400 | CW6: =IF(((Input_Raw[[#This Row],[33 kV_Wind_F3_Import_Reading]]-CO5)*1200)>0,(Input_Raw[[#This Row],[33 kV_Wind_F3_Import_Reading]]-CO5)*1200,0) -> 1200 | CX6: =IF(((Input_Raw[[#This Row],[33 kV_Wind_F4_Export Reading]]-CP5)*1200)>0,(Input_Raw[[#This Row],[33 kV_Wind_F4_Export Reading]]-CP5)*1200,0) -> 26400 | CY6: =IF(((Input_Raw[[#This Row],[33 kV_Wind_F4_Import Reading]]-CQ5)*1200)>0,(Input_Raw[[#This Row],[33 kV_Wind_F4_Import Reading]]-CQ5)*1200,0) -> 1200 | CZ6: =Input_Raw[[#This Row],[33 kV_F1_Total_Export (KWh)]]+Input_Raw[[#This Row],[33 kV_F2_Total_Export (KWh)2]]+Input_Raw[[#This Row],[33 kV_Wind_F3_Export (KWh)]]+Input_Raw[[#This Row],[33 kV_Wind_F4_Export (KWh)]] -> 99600 | DA6: =Input_Raw[[#This Row],[33 kV_Wind_F1_Import (KWh)]]+Input_Raw[[#This Row],[33 kV_Wind_F2_Import (KWh)]]+Input_Raw[[#This Row],[33 kV_Wind_F3_Import (KWh)2]]+Input_Raw[[#This Row],[33 kV_Wind_F4_Import (KWh)2]] -> 4800 | DB6: =IFERROR(1-Input_Raw[[#This Row],[33 kV_Wind_Total_Export (KWh)]]/Input_Raw[[#This Row],[WTG Total Gneration (KWh)]],0) -> 0.10617333 | DC6: 96 | DD6: 2931 | DG6: 80
A7: =A6+1 -> 45747 | B7: =YEAR([1]!Input_Raw[[#This Row],[Date]])+IF(MONTH([1]!Input_Raw[[#This Row],[Date]])>=4,1,0) -> 2025 | C7: =YEAR([1]!Input_Raw[[#This Row],[Date]]) -> 2025 | D7: =A7-DAY(A7)+1 -> 45717 | E7: =DAY(EOMONTH([1]!Input_Raw[[#This Row],[Date]],0)) -> 31 | F7: 9436 | G7: 10444 | H7: 8994 | I7: 7992 | J7: 5532 | K7: 8810 | L7: 6040 | M7: 8864 | N7: 8552 | O7: 7384 | P7: 9876 | Q7: 5883 | R7: 7698 | S7: 7408 | T7: 6173 | U7: 7064 | V7: 8016 | W7: 6908 | X7: 8564 | Y7: 10477 | Z7: 6850 | AA7: 3920 | AB7: 4886 | AC7: 7082 | AD7: 5480 | AE7: 6348 | AF7: 6006 | AG7: 0 | AH7: 4162 | AI7: 0 | AJ7: 5080 | AK7: 6703 | AL7: 7996 | AM7: 4764 | AN7: 4792 | AO7: 5596 | AP7: 6680 | AQ7: 7552 | AR7: 4105 | AS7: 4.76 | AT7: 4.88 | AU7: 4.8 | AV7: 4.65 | AW7: 4.27 | AX7: 5.04 | AY7: 5.09 | AZ7: 4.76 | BA7: 4.82 | BB7: 4.8 | BC7: 4.93 | BD7: 4.74 | BE7: 4.55 | BF7: 4.63 | BG7: 4.57 | BH7: 4.63 | BI7: 4.82 | BJ7: 4.84 | BK7: 4.83 | BL7: 5.1 | BM7: 4.76 | BN7: 4.34 | BO7: 4.24 | BP7: 4.48 | BQ7: 4.55 | BR7: 4.34 | BS7: 4.26 | BT7: 0 | BU7: 3.79 | BV7: 0 | BW7: 4.37 | BX7: 4.3 | BY7: 4.48 | BZ7: 4.78 | CA7: 4.74 | CB7: 4.25 | CC7: 4.44 | CD7: 4.59 | CE7: 5.03 | CF7: =SUM(Input_Raw[[#This Row],[G01]:[G40]]) -> 258117 | CG7: =IFERROR(AVERAGE(Input_Raw[[#This Row],[WS_G01]:[WS_G40]]),"") -> 4.3910256 | CJ7: 237670 | CK7: 2158 | CL7: 278051 | CM7: 2189 | CN7: 253571 | CO7: 1796 | CP7: 289136 | CQ7: 1841 | CR7: =IF(((Input_Raw[[#This Row],[33 kV_Wind_F1_Export reading]]-CJ6)*1200)>0,(Input_Raw[[#This Row],[33 kV_Wind_F1_Export reading]]-CJ6)*1200,0) -> 49200 | CS7: =IF(((Input_Raw[[#This Row],[33 kV_Wind_F1_Import reading]]-CK6)*1200)>0,(Input_Raw[[#This Row],[33 kV_Wind_F1_Import reading]]-CK6)*1200,0) -> 1200 | CT7: =IF(((Input_Raw[[#This Row],[33 kV_Wind_F2_Export_reading]]-CL6)*1200)>0,(Input_Raw[[#This Row],[33 kV_Wind_F2_Export_reading]]-CL6)*1200,0) -> 25200 | CU7: =IF(((Input_Raw[[#This Row],[33 kV_Wind_F2_Import_reading]]-CM6)*1200)>0,(Input_Raw[[#This Row],[33 kV_Wind_F2_Import_reading]]-CM6)*1200,0) -> 0 | CV7: =IF(((Input_Raw[[#This Row],[33 kV_Wind_F3_Export_Reading]]-CN6)*1200)>0,(Input_Raw[[#This Row],[33 kV_Wind_F3_Export_Reading]]-CN6)*1200,0) -> 84000 | CW7: =IF(((Input_Raw[[#This Row],[33 kV_Wind_F3_Import_Reading]]-CO6)*1200)>0,(Input_Raw[[#This Row],[33 kV_Wind_F3_Import_Reading]]-CO6)*1200,0) -> 0 | CX7: =IF(((Input_Raw[[#This Row],[33 kV_Wind_F4_Export Reading]]-CP6)*1200)>0,(Input_Raw[[#This Row],[33 kV_Wind_F4_Export Reading]]-CP6)*1200,0) -> 92400 | CY7: =IF(((Input_Raw[[#This Row],[33 kV_Wind_F4_Import Reading]]-CQ6)*1200)>0,(Input_Raw[[#This Row],[33 kV_Wind_F4_Import Reading]]-CQ6)*1200,0) -> 1200 | CZ7: =Input_Raw[[#This Row],[33 kV_F1_Total_Export (KWh)]]+Input_Raw[[#This Row],[33 kV_F2_Total_Export (KWh)2]]+Input_Raw[[#This Row],[33 kV_Wind_F3_Export (KWh)]]+Input_Raw[[#This Row],[33 kV_Wind_F4_Export (KWh)]] -> 250800 | DA7: =Input_Raw[[#This Row],[33 kV_Wind_F1_Import (KWh)]]+Input_Raw[[#This Row],[33 kV_Wind_F2_Import (KWh)]]+Input_Raw[[#This Row],[33 kV_Wind_F3_Import (KWh)2]]+Input_Raw[[#This Row],[33 kV_Wind_F4_Import (KWh)2]] -> 2400 | DB7: =IFERROR(1-Input_Raw[[#This Row],[33 kV_Wind_Total_Export (KWh)]]/Input_Raw[[#This Row],[WTG Total Gneration (KWh)]],0) -> 0.02834761 | DC7: 96 | DD7: 17068 | DG7: 80
A8: =A7+1 -> 45748 | B8: =YEAR([1]!Input_Raw[[#This Row],[Date]])+IF(MONTH([1]!Input_Raw[[#This Row],[Date]])>=4,1,0) -> 2026 | C8: =YEAR([1]!Input_Raw[[#This Row],[Date]]) -> 2025 | D8: =A8-DAY(A8)+1 -> 45748 | E8: =DAY(EOMONTH([1]!Input_Raw[[#This Row],[Date]],0)) -> 30 | F8: 3664 | G8: 7960 | H8: 5356 | I8: 5976 | J8: 4726 | K8: 7228 | L8: 6951 | M8: 6252 | N8: 5836 | O8: 6356 | P8: 6456 | Q8: 6719 | R8: 5686 | S8: 4942 | T8: 4039 | U8: 5316 | V8: 6766 | W8: 6572 | X8: 6788 | Y8: 7386 | Z8: 5148 | AA8: 4276 | AB8: 5832 | AC8: 7202 | AD8: 5834 | AE8: 6752 | AF8: 6260 | AG8: 0 | AH8: 3918 | AI8: 0 | AJ8: 5518 | AK8: 6091 | AL8: 7280 | AM8: 5474 | AN8: 3390 | AO8: 7150 | AP8: 5240 | AQ8: 6772 | AR8: 3752 | AS8: 4.58 | AT8: 4.46 | AU8: 3.97 | AV8: 4.15 | AW8: 3.78 | AX8: 4.38 | AY8: 4.4 | AZ8: 4.13 | BA8: 4.08 | BB8: 3.95 | BC8: 4.01 | BD8: 4.04 | BE8: 3.98 | BF8: 3.84 | BG8: 3.92 | BH8: 3.95 | BI8: 4.15 | BJ8: 4.01 | BK8: 3.99 | BL8: 4.01 | BM8: 3.76 | BN8: 3.87 | BO8: 3.95 | BP8: 4.26 | BQ8: 4.2 | BR8: 4.22 | BS8: 4.21 | BT8: 0 | BU8: 5.44 | BV8: 0 | BW8: 4.17 | BX8: 4.15 | BY8: 4.32 | BZ8: 4.55 | CA8: 6.32 | CB8: 4.45 | CC8: 4.87 | CD8: 4.31 | CE8: 5.39 | CF8: =SUM(Input_Raw[[#This Row],[G01]:[G40]]) -> 216864 | CG8: =IFERROR(AVERAGE(Input_Raw[[#This Row],[WS_G01]:[WS_G40]]),"") -> 4.0569231 | CJ8: 237715 | CK8: 2159 | CL8: 278085 | CM8: 2190 | CN8: 253615 | CO8: 1797 | CP8: 289182 | CQ8: 1841 | CR8: =IF(((Input_Raw[[#This Row],[33 kV_Wind_F1_Export reading]]-CJ7)*1200)>0,(Input_Raw[[#This Row],[33 kV_Wind_F1_Export reading]]-CJ7)*1200,0) -> 54000 | CS8: =IF(((Input_Raw[[#This Row],[33 kV_Wind_F1_Import reading]]-CK7)*1200)>0,(Input_Raw[[#This Row],[33 kV_Wind_F1_Import reading]]-CK7)*1200,0) -> 1200 | CT8: =IF(((Input_Raw[[#This Row],[33 kV_Wind_F2_Export_reading]]-CL7)*1200)>0,(Input_Raw[[#This Row],[33 kV_Wind_F2_Export_reading]]-CL7)*1200,0) -> 40800 | CU8: =IF(((Input_Raw[[#This Row],[33 kV_Wind_F2_Import_reading]]-CM7)*1200)>0,(Input_Raw[[#This Row],[33 kV_Wind_F2_Import_reading]]-CM7)*1200,0) -> 1200 | CV8: =IF(((Input_Raw[[#This Row],[33 kV_Wind_F3_Export_Reading]]-CN7)*1200)>0,(Input_Raw[[#This Row],[33 kV_Wind_F3_Export_Reading]]-CN7)*1200,0) -> 52800 | CW8: =IF(((Input_Raw[[#This Row],[33 kV_Wind_F3_Import_Reading]]-CO7)*1200)>0,(Input_Raw[[#This Row],[33 kV_Wind_F3_Import_Reading]]-CO7)*1200,0) -> 1200 | CX8: =IF(((Input_Raw[[#This Row],[33 kV_Wind_F4_Export Reading]]-CP7)*1200)>0,(Input_Raw[[#This Row],[33 kV_Wind_F4_Export Reading]]-CP7)*1200,0) -> 55200 | CY8: =IF(((Input_Raw[[#This Row],[33 kV_Wind_F4_Import Reading]]-CQ7)*1200)>0,(Input_Raw[[#This Row],[33 kV_Wind_F4_Import Reading]]-CQ7)*1200,0) -> 0 | CZ8: =Input_Raw[[#This Row],[33 kV_F1_Total_Export (KWh)]]+Input_Raw[[#This Row],[33 kV_F2_Total_Export (KWh)2]]+Input_Raw[[#This Row],[33 kV_Wind_F3_Export (KWh)]]+Input_Raw[[#This Row],[33 kV_Wind_F4_Export (KWh)]] -> 202800 | DA8: =Input_Raw[[#This Row],[33 kV_Wind_F1_Import (KWh)]]+Input_Raw[[#This Row],[33 kV_Wind_F2_Import (KWh)]]+Input_Raw[[#This Row],[33 kV_Wind_F3_Import (KWh)2]]+Input_Raw[[#This Row],[33 kV_Wind_F4_Import (KWh)2]] -> 3600 | DB8: =IFERROR(1-Input_Raw[[#This Row],[33 kV_Wind_Total_Export (KWh)]]/Input_Raw[[#This Row],[WTG Total Gneration (KWh)]],0) -> 0.064851704 | DC8: 96 | DD8: 12280 | DE8: 217.953 | DG8: 78
A9: =A8+1 -> 45749 | B9: =YEAR([1]!Input_Raw[[#This Row],[Date]])+IF(MONTH([1]!Input_Raw[[#This Row],[Date]])>=4,1,0) -> 2026 | C9: =YEAR([1]!Input_Raw[[#This Row],[Date]]) -> 2025 | D9: =A9-DAY(A9)+1 -> 45748 | E9: =DAY(EOMONTH([1]!Input_Raw[[#This Row],[Date]],0)) -> 30 | F9: 12200 | G9: 10784 | H9: 10570 | I9: 5956 | J9: 11540 | K9: 12082 | L9: 12510 | M9: 12108 | N9: 14236 | O9: 10960 | P9: 14128 | Q9: 14485 | R9: 11088 | S9: 12636 | T9: 14796 | U9: 7036 | V9: 15820 | W9: 16424 | X9: 17394 | Y9: 17007 | Z9: 14520 | AA9: 1916 | AB9: 11964 | AC9: 11672 | AD9: 12938 | AE9: 10732 | AF9: 10142 | AG9: 0 | AH9: 10722 | AI9: 0 | AJ9: 2722 | AK9: 10250 | AL9: 11038 | AM9: 10894 | AN9: 13146 | AO9: 11114 | AP9: 11404 | AQ9: 11460 | AR9: 8516 | AS9: 5.59 | AT9: 6.18 | AU9: 5.43 | AV9: 5.42 | AW9: 5.97 | AX9: 6.06 | AY9: 5.51 | AZ9: 5.15 | BA9: 5.98 | BB9: 5.33 | BC9: 6.31 | BD9: 5.92 | BE9: 5.96 | BF9: 5.77 | BG9: 5.83 | BH9: 5.9 | BI9: 6.05 | BJ9: 5.8 | BK9: 5.74 | BL9: 6.66 | BM9: 5.05 | BN9: 6.2 | BO9: 6.1 | BP9: 5.88 | BQ9: 6 | BR9: 5.88 | BS9: 5.94 | BT9: 0 | BU9: 5.74 | BV9: 0 | BW9: 5.52 | BX9: 5.76 | BY9: 6.04 | BZ9: 6.02 | CA9: 5.85 | CB9: 6.03 | CC9: 5.99 | CD9: 5.42 | CE9: 6.19 | CF9: =SUM(Input_Raw[[#This Row],[G01]:[G40]]) -> 428910 | CG9: =IFERROR(AVERAGE(Input_Raw[[#This Row],[WS_G01]:[WS_G40]]),"") -> 5.5428205 | CJ9: 237798 | CK9: 2159 | CL9: 278152 | CM9: 2190 | CN9: 253699 | CO9: 1797 | CP9: 289297 | CQ9: 1841 | CR9: =IF(((Input_Raw[[#This Row],[33 kV_Wind_F1_Export reading]]-CJ8)*1200)>0,(Input_Raw[[#This Row],[33 kV_Wind_F1_Export reading]]-CJ8)*1200,0) -> 99600 | CS9: =IF(((Input_Raw[[#This Row],[33 kV_Wind_F1_Import reading]]-CK8)*1200)>0,(Input_Raw[[#This Row],[33 kV_Wind_F1_Import reading]]-CK8)*1200,0) -> 0 | CT9: =IF(((Input_Raw[[#This Row],[33 kV_Wind_F2_Export_reading]]-CL8)*1200)>0,(Input_Raw[[#This Row],[33 kV_Wind_F2_Export_reading]]-CL8)*1200,0) -> 80400 | CU9: =IF(((Input_Raw[[#This Row],[33 kV_Wind_F2_Import_reading]]-CM8)*1200)>0,(Input_Raw[[#This Row],[33 kV_Wind_F2_Import_reading]]-CM8)*1200,0) -> 0 | CV9: =IF(((Input_Raw[[#This Row],[33 kV_Wind_F3_Export_Reading]]-CN8)*1200)>0,(Input_Raw[[#This Row],[33 kV_Wind_F3_Export_Reading]]-CN8)*1200,0) -> 100800 | CW9: =IF(((Input_Raw[[#This Row],[33 kV_Wind_F3_Import_Reading]]-CO8)*1200)>0,(Input_Raw[[#This Row],[33 kV_Wind_F3_Import_Reading]]-CO8)*1200,0) -> 0 | CX9: =IF(((Input_Raw[[#This Row],[33 kV_Wind_F4_Export Reading]]-CP8)*1200)>0,(Input_Raw[[#This Row],[33 kV_Wind_F4_Export Reading]]-CP8)*1200,0) -> 138000 | CY9: =IF(((Input_Raw[[#This Row],[33 kV_Wind_F4_Import Reading]]-CQ8)*1200)>0,(Input_Raw[[#This Row],[33 kV_Wind_F4_Import Reading]]-CQ8)*1200,0) -> 0 | CZ9: =Input_Raw[[#This Row],[33 kV_F1_Total_Export (KWh)]]+Input_Raw[[#This Row],[33 kV_F2_Total_Export (KWh)2]]+Input_Raw[[#This Row],[33 kV_Wind_F3_Export (KWh)]]+Input_Raw[[#This Row],[33 kV_Wind_F4_Export (KWh)]] -> 418800 | DA9: =Input_Raw[[#This Row],[33 kV_Wind_F1_Import (KWh)]]+Input_Raw[[#This Row],[33 kV_Wind_F2_Import (KWh)]]+Input_Raw[[#This Row],[33 kV_Wind_F3_Import (KWh)2]]+Input_Raw[[#This Row],[33 kV_Wind_F4_Import (KWh)2]] -> 0 | DB9: =IFERROR(1-Input_Raw[[#This Row],[33 kV_Wind_Total_Export (KWh)]]/Input_Raw[[#This Row],[WTG Total Gneration (KWh)]],0) -> 0.023571379 | DC9: 96 | DD9: 47311 | DE9: 422.859 | DG9: 78
A10: =A9+1 -> 45750 | B10: =YEAR([1]!Input_Raw[[#This Row],[Date]])+IF(MONTH([1]!Input_Raw[[#This Row],[Date]])>=4,1,0) -> 2026 | C10: =YEAR([1]!Input_Raw[[#This Row],[Date]]) -> 2025 | D10: =A10-DAY(A10)+1 -> 45748 | E10: =DAY(EOMONTH([1]!Input_Raw[[#This Row],[Date]],0)) -> 30 | F10: 7048 | G10: 9292 | H10: 6462 | I10: 6772 | J10: 7822 | K10: 2735 | L10: 3420 | M10: 6800 | N10: 8864 | O10: 6280 | P10: 7464 | Q10: 8930 | R10: 8852 | S10: 8384 | T10: 8346 | U10: 6660 | V10: 10152 | W10: 6368 | X10: 10280 | Y10: 9239 | Z10: 7800 | AA10: 6952 | AB10: 7522 | AC10: 6640 | AD10: 7248 | AE10: 6588 | AF10: 6354 | AG10: 0 | AH10: 6816 | AI10: 0 | AJ10: 4938 | AK10: 5908 | AL10: 3472 | AM10: 6490 | AN10: 7198 | AO10: 6498 | AP10: 4518 | AQ10: 6232 | AR10: 6148 | AS10: 4.76 | AT10: 4.88 | AU10: 4.8 | AV10: 4.65 | AW10: 4.27 | AX10: 5.04 | AY10: 5.09 | AZ10: 4.76 | BA10: 4.82 | BB10: 4.8 | BC10: 4.93 | BD10: 4.74 | BE10: 4.55 | BF10: 4.63 | BG10: 4.57 | BH10: 4.63 | BI10: 4.82 | BJ10: 4.84 | BK10: 4.83 | BL10: 5.1 | BM10: 4.76 | BN10: 4.34 | BO10: 4.24 | BP10: 4.48 | BQ10: 4.55 | BR10: 4.34 | BS10: 4.26 | BT10: 0 | BU10: 3.79 | BV10: 0 | BW10: 4.37 | BX10: 4.3 | BY10: 4.48 | BZ10: 4.78 | CA10: 4.74 | CB10: 4.25 | CC10: 4.44 | CD10: 4.59 | CE10: 5.03 | CF10: =SUM(Input_Raw[[#This Row],[G01]:[G40]]) -> 257492 | CG10: =IFERROR(AVERAGE(Input_Raw[[#This Row],[WS_G01]:[WS_G40]]),"") -> 4.3910256 | CJ10: 237846 | CK10: 2160 | CL10: 278199 | CM10: 2190 | CN10: 253740 | CO10: 1798 | CP10: 289370 | CQ10: 1842 | CR10: =IF(((Input_Raw[[#This Row],[33 kV_Wind_F1_Export reading]]-CJ9)*1200)>0,(Input_Raw[[#This Row],[33 kV_Wind_F1_Export reading]]-CJ9)*1200,0) -> 57600 | CS10: =IF(((Input_Raw[[#This Row],[33 kV_Wind_F1_Import reading]]-CK9)*1200)>0,(Input_Raw[[#This Row],[33 kV_Wind_F1_Import reading]]-CK9)*1200,0) -> 1200 | CT10: =IF(((Input_Raw[[#This Row],[33 kV_Wind_F2_Export_reading]]-CL9)*1200)>0,(Input_Raw[[#This Row],[33 kV_Wind_F2_Export_reading]]-CL9)*1200,0) -> 56400 | CU10: =IF(((Input_Raw[[#This Row],[33 kV_Wind_F2_Import_reading]]-CM9)*1200)>0,(Input_Raw[[#This Row],[33 kV_Wind_F2_Import_reading]]-CM9)*1200,0) -> 0 | CV10: =IF(((Input_Raw[[#This Row],[33 kV_Wind_F3_Export_Reading]]-CN9)*1200)>0,(Input_Raw[[#This Row],[33 kV_Wind_F3_Export_Reading]]-CN9)*1200,0) -> 49200 | CW10: =IF(((Input_Raw[[#This Row],[33 kV_Wind_F3_Import_Reading]]-CO9)*1200)>0,(Input_Raw[[#This Row],[33 kV_Wind_F3_Import_Reading]]-CO9)*1200,0) -> 1200 | CX10: =IF(((Input_Raw[[#This Row],[33 kV_Wind_F4_Export Reading]]-CP9)*1200)>0,(Input_Raw[[#This Row],[33 kV_Wind_F4_Export Reading]]-CP9)*1200,0) -> 87600 | CY10: =IF(((Input_Raw[[#This Row],[33 kV_Wind_F4_Import Reading]]-CQ9)*1200)>0,(Input_Raw[[#This Row],[33 kV_Wind_F4_Import Reading]]-CQ9)*1200,0) -> 1200 | CZ10: =Input_Raw[[#This Row],[33 kV_F1_Total_Export (KWh)]]+Input_Raw[[#This Row],[33 kV_F2_Total_Export (KWh)2]]+Input_Raw[[#This Row],[33 kV_Wind_F3_Export (KWh)]]+Input_Raw[[#This Row],[33 kV_Wind_F4_Export (KWh)]] -> 250800 | DA10: =Input_Raw[[#This Row],[33 kV_Wind_F1_Import (KWh)]]+Input_Raw[[#This Row],[33 kV_Wind_F2_Import (KWh)]]+Input_Raw[[#This Row],[33 kV_Wind_F3_Import (KWh)2]]+Input_Raw[[#This Row],[33 kV_Wind_F4_Import (KWh)2]] -> 3600 | DB10: =IFERROR(1-Input_Raw[[#This Row],[33 kV_Wind_Total_Export (KWh)]]/Input_Raw[[#This Row],[WTG Total Gneration (KWh)]],0) -> 0.025989157 | DC10: 96 | DD10: 16092 | DE10: 255.178 | DG10: 78
