Workbook
Name BD_Relation: [1]Basic_Data!$B$3:$B$14
Name BD_Relation: [1]Basic_Data!$B$3:$B$14
Name BD_Relation: #REF!
Name BD_Relation: [1]Basic_Data!$B$3:$B$14
Name Date: [1]Basic_Data!$D$3:$D$33
Name Date: [1]Basic_Data!$D$3:$D$33
Name Date: #REF!
Name Date: [1]Basic_Data!$D$3:$D$33
Name dccap: [2]DGR!$D$7:$D$14
Name dccap: [2]DGR!$D$7:$D$14
Name dccap: #REF!
Name dccap: [2]DGR!$D$7:$D$14
Name Digos: '[3]Basic Data'!#REF!
Name Digos: '[3]Basic Data'!#REF!
Name Digos: #REF!
Name Digos: '[3]Basic Data'!#REF!
Name engg: [1]Basic_Data!$L$3:$L$16
Name engg: [1]Basic_Data!$L$3:$L$16
Name engg: #REF!
Name engg: [1]Basic_Data!$L$3:$L$16
Name Equipment: [1]Basic_Data!$F$3:$F$5
Name Equipment: [1]Basic_Data!$F$3:$F$5
Name Equipment: #REF!
Name Equipment: [1]Basic_Data!$F$3:$F$5
Name error: [1]Basic_Data!$M$3:$M$33
Name error: [1]Basic_Data!$M$3:$M$33
Name error: #REF!
Name error: [1]Basic_Data!$M$3:$M$33
Name Gstc: #REF!
Name Gstc: #REF!
Name Gstc: #REF!
Name Gstc: #REF!
Name Gstc: #REF!
Name Inverter: [1]Basic_Data!$H$3:$H$8
Name Inverter: [1]Basic_Data!$H$3:$H$8
Name Inverter: #REF!
Name Inverter: [1]Basic_Data!$H$3:$H$8
Name invlook: [2]DGR!$B$7:$D$14
Name invlook: [2]DGR!$B$7:$D$14
Name invlook: #REF!
Name invlook: [2]DGR!$B$7:$D$14
Name JB: [1]Basic_Data!$I$3:$I$68
Name JB: [1]Basic_Data!$I$3:$I$68
Name JB: #REF!
Name JB: [1]Basic_Data!$I$3:$I$68
Name jbp: [2]Basic_Data!$I$3:$J$66
Name jbp: [2]Basic_Data!$I$3:$J$66
Name jbp: #REF!
Name jbp: [2]Basic_Data!$I$3:$J$66
Name P1_SnW4240: '[3]Basic Data'!#REF!
Name P1_SnW4240: '[3]Basic Data'!#REF!
Name P1_SnW4240: #REF!
Name P1_SnW4240: '[3]Basic Data'!#REF!
Name P1SnW4240: '[3]Basic Data'!#REF!
Name P1SnW4240: '[3]Basic Data'!#REF!
Name P1SnW4240: #REF!
Name P1SnW4240: '[3]Basic Data'!#REF!
Name P1SnW51: '[3]Basic Data'!#REF!
Name P1SnW51: '[3]Basic Data'!#REF!
Name P1SnW51: #REF!

Sheet O2Summary
A2: Performance Summary TGPXIIPL
A3: Month | B3: 45839
A4: Date | B4: 45861
A5: Financial Year | B5: Year-1
A6: Year Start Date | B6: 45748
A7: Year End Date | B7: 46112
A9: Sr. No. | B9: Particular | C9: Target | D9: Measured | E9: Deviation | F9: Remarks
A10: 1 | B10: E_Grid Daily (MWh) | C10: =_xlfn.XLOOKUP($B$4,'Daily KPI'!$A:$A,'Daily KPI'!$AD:$AD)/1000 -> 963.88317 | D10: =_xlfn.XLOOKUP($B$4,'Daily KPI'!$A:$A,'Daily KPI'!$AA:$AA)/1000 -> 921.15 | E10: =D10/C10-1 -> -0.044334386
B11: E_Grid MTD(MWh) | C11: =MonthlyKPI!$E$4 -> 22169.313 | D11: =MonthlyKPI!F4 -> 14165.55 | E11: =D11/C11-1 -> -0.36102891
B12: E_Grid YTD (MWh) | C12: =AnnualKPI!$E$4 -> 95320.581 | D12: =AnnualKPI!F4 -> 78096.6 | E12: =D12/C12-1 -> -0.1806953
A13: 2 | B13: Wind Speed Daily | C13: =_xlfn.XLOOKUP($B$3,'Modelling New'!$D:$D,'Modelling New'!$J:$J) -> 8.18 | D13: =_xlfn.XLOOKUP($B$4,'Daily KPI'!$A:$A,'Daily KPI'!$M:$M) -> 7.7791907 | E13: =(D13-C13)/(C13) -> -0.048998691
B14: Wind Speed MTD | C14: =MonthlyKPI!C4 -> 8.18 | D14: =MonthlyKPI!D4 -> 6.5746369 | E14: =(D14-C14)/(C14) -> -0.19625466
B15: Wind Speed YTD | C15: =AnnualKPI!C4 -> 7.2925 | D15: =AnnualKPI!D4 -> 6.791176 | E15: =(D15-C15)/(C15) -> -0.068745156
A16: 3 | B16: PA Daily | C16: =_xlfn.XLOOKUP($B$3,'Modelling New'!$D:$D,'Modelling New'!$AE:$AE) -> 0.9603 | D16: =_xlfn.XLOOKUP($B$4,'Daily KPI'!$A:$A,'Daily KPI'!$O:$O) -> 0.9981291 | E16: =(D16-C16)/(C16) -> 0.039393002
B17: PA MTD | C17: =_xlfn.XLOOKUP($B$3,'Modelling New'!$D:$D,'Modelling New'!$AE:$AE) -> 0.9603 | D17: =MonthlyKPI!P4 -> 0.96580179 | E17: =(D17-C17)/(C17) -> 0.0057292437
B18: PA YTD | C18: =_xlfn.XLOOKUP($B$3,'Modelling New'!$D:$D,'Modelling New'!$AE:$AE) -> 0.9603 | D18: =AnnualKPI!P4 -> 0.94492141 | E18: =(D18-C18)/(C18) -> -0.016014356
A19: 4 | B19: EGA Daily | C19: =_xlfn.XLOOKUP($B$3,'Modelling New'!$D:$D,'Modelling New'!$AF:$AF) -> 0.995 | D19: =_xlfn.XLOOKUP($B$4,'Daily KPI'!$A:$A,'Daily KPI'!$R:$R) -> 1 | E19: =(D19-C19)/(C19) -> 0.0050251256
B20: EGA MTD | C20: =_xlfn.XLOOKUP($B$3,'Modelling New'!$D:$D,'Modelling New'!$AF:$AF) -> 0.995 | D20: =MonthlyKPI!J4 -> 1 | E20: =(D20-C20)/(C20) -> 0.0050251256
B21: EGA YTD | C21: =_xlfn.XLOOKUP($B$3,'Modelling New'!$D:$D,'Modelling New'!$AF:$AF) -> 0.995 | D21: =AnnualKPI!J4 -> 1 | E21: =(D21-C21)/(C21) -> 0.0050251256
A22: 5 | B22: IGA Daily | C22: =_xlfn.XLOOKUP($B$3,'Modelling New'!$D:$D,'Modelling New'!$AI:$AI) -> 0.99 | D22: =_xlfn.XLOOKUP($B$4,'Daily KPI'!$A:$A,'Daily KPI'!$Q:$Q) -> 1 | E22: =(D22-C22)/(C22) -> 0.01010101
B23: IGA MTD | C23: =_xlfn.XLOOKUP($B$3,'Modelling New'!$D:$D,'Modelling New'!$AI:$AI) -> 0.99 | D23: =MonthlyKPI!N4 -> 0.99549068 | E23: =(D23-C23)/(C23) -> 0.0055461371
B24: IGA YTD | C24: =_xlfn.XLOOKUP($B$3,'Modelling New'!$D:$D,'Modelling New'!$AI:$AI) -> 0.99 | D24: =AnnualKPI!N4 -> 0.97397844 | E24: =(D24-C24)/(C24) -> -0.016183396
A25: 6 | B25: MA Daily | C25: =_xlfn.XLOOKUP($B$3,'Modelling New'!$D:$D,'Modelling New'!$AH:$AH) -> 0.97 | D25: =_xlfn.XLOOKUP($B$4,'Daily KPI'!$A:$A,'Daily KPI'!$P:$P) -> 0.9981291 | E25: =(D25-C25)/(C25) -> 0.028999072
B26: MA MTD | C26: =_xlfn.XLOOKUP($B$3,'Modelling New'!$D:$D,'Modelling New'!$AH:$AH) -> 0.97 | D26: =MonthlyKPI!$L$4 -> 0.97017663 | E26: =(D26-C26)/(C26) -> 0.00018209668
B27: MA YTD | C27: =_xlfn.XLOOKUP($B$3,'Modelling New'!$D:$D,'Modelling New'!$AH:$AH) -> 0.97 | D27: =AnnualKPI!$L$4 -> 0.97016667 | E27: =(D27-C27)/(C27) -> 0.00017182005
A28: 7 | B28: CUF Daily | C28: =_xlfn.XLOOKUP($B$4,'Daily KPI'!$A:$A,'Daily KPI'!$AF:$AF) -> 0.57210539 | D28: =_xlfn.XLOOKUP($B$4,'Daily KPI'!$A:$A,'Daily KPI'!$W:$W) -> 0.54674145 | E28: =(D28-C28)/(C28) -> -0.044334386
B29: CUF MTD | C29: =MonthlyKPI!$G$4 -> 0.57210539 | D29: =MonthlyKPI!H4 -> 0.36555881 | E29: =(D29-C29)/(C29) -> -0.36102891
B30: CUF YTD | C30: =AnnualKPI!$G$4 -> 0.49628766 | D30: =AnnualKPI!H4 -> 0.40661081 | E30: =(D30-C30)/(C30) -> -0.1806953
A31: 8 | B31: Line Loss Daily | C31: =_xlfn.XLOOKUP($B$4,'Daily KPI'!$A:$A,'Daily KPI'!$AP:$AP) -> 0.05 | D31: =_xlfn.XLOOKUP($B$4,'Daily KPI'!$A:$A,'Daily KPI'!$AN:$AN) -> 0.028067499 | E31: =-(D31-C31)/(C31) -> 0.43865003
B32: Line Loss MTD | C32: =_xlfn.XLOOKUP($B$3,'Modelling New'!$D:$D,'Modelling New'!$AK:$AK) -> 0.05 | D32: =MonthlyKPI!$U$4 -> 0.02588579 | E32: =-(D32-C32)/(C32) -> 0.48228421
B33: Line Loss YTD | C33: =_xlfn.XLOOKUP($B$3,'Modelling New'!$D:$D,'Modelling New'!$AK:$AK) -> 0.05 | D33: =AnnualKPI!$R$4 -> 0.034314259 | E33: =-(D33-C33)/(C33) -> 0.31371481
A34: 9 | B34: Reactive Power Daily | C34: =_xlfn.XLOOKUP($B$4,'Daily KPI'!$A:$A,'Daily KPI'!$AQ:$AQ) -> 0.05 | D34: =_xlfn.XLOOKUP($B$4,'Daily KPI'!$A:$A,'Daily KPI'!$AO:$AO) -> 0.022315946 | E34: =-(D34-C34)/(C34) -> 0.55368108
B35: Reactive Power MTD | C35: =_xlfn.XLOOKUP($B$3,'Modelling New'!$D:$D,'Modelling New'!$AL:$AL) -> 0.05 | D35: =MonthlyKPI!$V$4 -> 0.0094907557 | E35: =-(D35-C35)/(C35) -> 0.81018489
B36: Reactive Power YTD | C36: =_xlfn.XLOOKUP($B$3,'Modelling New'!$D:$D,'Modelling New'!$AL:$AL) -> 0.05 | D36: =AnnualKPI!$S$4 -> 0.0079531024 | E36: =-(D36-C36)/(C36) -> 0.84093795
A37: 10 | B37: Expected Energy Daily | C37: =IFERROR(_xlfn.XLOOKUP($B$4,'Daily KPI'!$A:$A,'Daily KPI'!$AI:$AI),"") -> 986.77 | D37: =IFERROR(_xlfn.XLOOKUP($B$4,'Daily KPI'!A:A,'Daily KPI'!$X:$X)/1000,"") -> 947.751 | E37: =(D37-C37)/(C37) -> -0.039542143
B38: Expected Energy MTD | C38: =MonthlyKPI!$T$4 -> 15451.86 | D38: =IFERROR(SUMIF('Daily KPI'!D:D,$B$3,'Daily KPI'!$X:$X)/1000,"") -> 14543.762 | E38: =(D38-C38)/(C38) -> -0.058769494
B39: Expected Energy YTD | C39: =AnnualKPI!$Q$4 -> 84876.064 | D39: =IFERROR(SUMIFS('Daily KPI'!$X:$X,'Daily KPI'!$A:$A,">="&O2Summary!$B$6,'Daily KPI'!$A:$A,"<="&O2Summary!$B$4)/1000,"") -> 80683.689 | E39: =(D39-C39)/(C39) -> -0.049394084

Sheet MonthlyKPI
A1: Till Date | B1: =O2Summary!B4 -> 45861 | C1: 0 | D1: 0 | E1: 0 | F1: 0
A2: TGPXIIPL Performance Summary (MTD)
A3: Year | B3: Days | C3: Estimated WS(m/s) | D3: Measured WS (m/s) | E3: Budgeted Energy (MWh) | F3: Measured Energy (MWh) | G3: Target CUF (%) | H3: Measured CUF (%) | I3: Target GA (%) | J3: Measured GA (%) | K3: Target MA (%) | L3: Measured MA (%) | M3: Target IGA (%) | N3: Measured IGA (%) | O3: Target PA(%) | P3: Measured PA (%) | Q3: WTG Total (MWh) | R3: Line Losses(%) | S3: E_WS_Corrected | T3: Expected Energy | U3: Loss (%) | V3: Reactive Power (%)
A4: =O2Summary!B3 -> 45839 | B4: =DAY(B1) -> 23 | C4: =IFERROR(_xlfn.XLOOKUP($A$4,'Modelling New'!$D:$D,'Modelling New'!$AC:$AC),"") -> 8.18 | D4: =AVERAGEIF('Daily KPI'!$D:$D,$A$4,'Daily KPI'!$M:$M) -> 6.5746369 | E4: =IFERROR(_xlfn.XLOOKUP($A$4,'Modelling New'!$D:$D,'Modelling New'!$U:$U),"") -> 22169.313 | F4: =SUMIFS('Daily KPI'!$AA:$AA,'Daily KPI'!$D:$D,$A$4)/1000 -> 14165.55 | G4: =IFERROR(_xlfn.XLOOKUP($A$4,'Modelling New'!$D:$D,'Modelling New'!$X:$X),"") -> 0.57210539 | H4: =F4/(24*B4*(_xlfn.XLOOKUP($B$1,'Daily KPI'!$A:$A,'Daily KPI'!$AR:$AR))) -> 0.36555881 | I4: =_xlfn.XLOOKUP($A$4,'Modelling New'!$D:$D,'Modelling New'!$AF:$AF) -> 0.995 | J4: =AVERAGEIFS('Daily KPI'!$R:$R,'Daily KPI'!$A:$A,"<="&MonthlyKPI!$B$1,'Daily KPI'!$D:$D,$A$4) -> 1 | K4: =_xlfn.XLOOKUP($A$4,'Modelling New'!$D:$D,'Modelling New'!$AH:$AH) -> 0.97 | L4: =AVERAGEIFS('Daily KPI'!$P:$P,'Daily KPI'!$A:$A,"<="&MonthlyKPI!$B$1,'Daily KPI'!$D:$D,$A$4) -> 0.97017663 | M4: =_xlfn.XLOOKUP($A$4,'Modelling New'!$D:$D,'Modelling New'!$AI:$AI) -> 0.99 | N4: =AVERAGEIFS('Daily KPI'!$Q:$Q,'Daily KPI'!$A:$A,"<="&MonthlyKPI!$B$1,'Daily KPI'!$D:$D,$A$4) -> 0.99549068 | O4: =K4*M4 -> 0.9603 | P4: =L4*N4 -> 0.96580179 | Q4: =SUMIFS('Daily KPI'!$X:$X,'Daily KPI'!$D:$D,$A$4)/1000 -> 14543.762 | R4: =Q4/F4-1 -> 0.026699422 | S4: =SUMIFS(Input_Raw!BQ:BQ,Input_Raw!A:A,">="&A4,Input_Raw!A:A,"<="&B1) -> 15451.86 | T4: =SUMIFS('Daily KPI'!$AI:$AI,'Daily KPI'!$D:$D,$A$4) -> 15451.86 | U4: =IFERROR(AVERAGEIFS('Daily KPI'!$AN:$AN,'Daily KPI'!$D:$D,MonthlyKPI!$A$4,'Daily KPI'!$A:$A,"<="&MonthlyKPI!$B$1),"") -> 0.02588579 | V4: =AVERAGEIFS('Daily KPI'!$AO:$AO,'Daily KPI'!$A:$A,"<="&MonthlyKPI!$B$1,'Daily KPI'!$D:$D,$A$4) -> 0.0094907557
A7: Start Date | B7: =B8-6 -> 45855
A8: End Date | B8: =B1 -> 45861
A9: TGPXIIPL Performance Summary (WTD)
A10: Year | B10: Days | C10: Estimated WS(m/s) | D10: Measured WS (m/s) | E10: Budgeted Energy (MWh) | F10: Measured Energy (MWh) | G10: Target CUF (%) | H10: Measured CUF (%) | I10: Target GA (%) | J10: Measured GA (%) | K10: Target MA (%) | L10: Measured MA (%) | M10: Target IGA (%) | N10: Measured IGA (%) | O10: Target PA(%) | P10: Measured PA (%) | Q10: E_WS_Corrected
A11: =A4 -> 45839 | B11: =(B8-B7)+1 -> 7 | C11: =IFERROR(_xlfn.XLOOKUP($A$11,'Modelling New'!$D:$D,'Modelling New'!$AC:$AC),"") -> 8.18 | D11: =AVERAGEIFS('Daily KPI'!$M:$M,'Daily KPI'!$A:$A,">="&$B$7,'Daily KPI'!$A:$A,"<="&$B$8) -> 6.1080528 | E11: =SUMIFS('Daily KPI'!$AD:$AD,'Daily KPI'!$A:$A,">="&$B$7,'Daily KPI'!$A:$A,"<="&$B$8)/1000 -> 6747.1822 | F11: =SUMIFS('Daily KPI'!$AA:$AA,'Daily KPI'!$A:$A,">="&$B$7,'Daily KPI'!$A:$A,"<="&$B$8)/1000 -> 3759.3 | G11: =E11/(24*$B$11*'Basic Data'!$K$3) -> 0.57210539 | H11: =F11/(24*B11*'Basic Data'!$K$3) -> 0.31875763 | I11: =_xlfn.XLOOKUP($A$4,'Modelling New'!$D:$D,'Modelling New'!$AF:$AF) -> 0.995 | J11: =AVERAGEIFS('Daily KPI'!$R:$R,'Daily KPI'!$A:$A,">="&$B$7,'Daily KPI'!$A:$A,"<="&$B$8) -> 1 | K11: =_xlfn.XLOOKUP($A$4,'Modelling New'!$D:$D,'Modelling New'!$AH:$AH) -> 0.97 | L11: =AVERAGEIFS('Daily KPI'!$P:$P,'Daily KPI'!$A:$A,">="&$B$7,'Daily KPI'!$A:$A,"<="&$B$8) -> 0.99038662 | M11: =_xlfn.XLOOKUP($A$4,'Modelling New'!$D:$D,'Modelling New'!$AI:$AI) -> 0.99 | N11: =AVERAGEIFS('Daily KPI'!$Q:$Q,'Daily KPI'!$A:$A,">="&$B$7,'Daily KPI'!$A:$A,"<="&$B$8) -> 0.99766864 | O11: =K11*M11 -> 0.9603 | P11: =L11*N11 -> 0.98807767 | Q11: =SUMIFS(Input_Raw!BQ:BQ,Input_Raw!A:A,">="&B7,Input_Raw!A:A,"<="&B8) -> 4009.94
A14: Start Date | B14: =B15-29 -> 45832
A15: End Date | B15: =B8 -> 45861
A16: TGPXIIPL Performance Summary (LTD)
A17: Year | B17: Days | C17: Estimated WS(m/s) | D17: Measured WS (m/s) | E17: Budgeted Energy (MWh) | F17: Measured Energy (MWh) | G17: Target CUF (%) | H17: Measured CUF (%) | I17: Target GA (%) | J17: Measured GA (%) | K17: Target MA (%) | L17: Measured MA (%) | M17: Target IGA (%) | N17: Measured IGA (%) | O17: Target PA(%) | P17: Measured PA (%)
A18: =A11 -> 45839 | B18: =(B15-B14)+1 -> 30 | C18: =_xlfn.XLOOKUP($A$18,'Modelling New'!$D:$D,'Modelling New'!$AC:$AC) -> 8.18 | D18: =AVERAGEIFS('Daily KPI'!$M:$M,'Daily KPI'!$A:$A,">="&$B$14,'Daily KPI'!$A:$A,"<="&$B$15) -> 6.8225918 | E18: =SUMIFS('Daily KPI'!$AD:$AD,'Daily KPI'!$A:$A,">="&$B$14,'Daily KPI'!$A:$A,"<="&$B$15)/1000 -> 27780.606 | F18: =SUMIFS('Daily KPI'!$X:$X,'Daily KPI'!$A:$A,">="&$B$14,'Daily KPI'!$A:$A,"<="&$B$15)/1000 -> 21028.027 | G18: =E18/(24*$B$18*'Basic Data'!$K$3) -> 0.54963212 | H18: =F18/(24*B18*'Basic Data'!$K$3) -> 0.41603409 | I18: 0.997 | J18: =AVERAGEIFS('Daily KPI'!$R:$R,'Daily KPI'!$A:$A,">="&$B$14,'Daily KPI'!$A:$A,"<="&$B$15) -> 1 | K18: 0.986 | L18: =AVERAGEIFS('Daily KPI'!$P:$P,'Daily KPI'!$A:$A,">="&$B$14,'Daily KPI'!$A:$A,"<="&$B$15) -> 0.96570832 | M18: 0.995 | N18: =AVERAGEIFS('Daily KPI'!$Q:$Q,'Daily KPI'!$A:$A,">="&$B$14,'Daily KPI'!$A:$A,"<="&$B$15) -> 0.99654285 | O18: =K18*M18 -> 0.98107 | P18: =L18*N18 -> 0.96236972

Sheet Daily KPI
A1: Date | B1: Financial Year | C1: Calendar Year | D1: Month Year | E1: Days | F1: Operating Hours | G1: GHI-UP (KWh/m2) | H1: GHI-Down(KWh/m2) | I1: POA-UP(KWh/m2) | J1: POA-Down(KWh/m2) | K1: Amb_Temp(°C) | L1: Mod_Temp(°C) | M1: WS_Avg(m/s) | N1: WS_Max(m/s) | O1: PA(%) | P1: MA (%) | Q1: IGA (%) | R1: EGA(%) | S1: EMA (%) | T1: TA (%) | U1: PR(%) | V1: WPR(%) | W1: CUF(%) | X1: Gen_Exp (kWh) | Y1: Mtr_Export (kWh) | Z1: Mtr_Import (kWh) | AA1: Mtr_Net_Exp (KWh) | AB1: Operational Capacity (MW) | AC1: Bugt_Resource | AD1: Bugt_Energy | AE1: Bugt PR | AF1: Bugt CUF | AG1: Bugt_PA | AH1: Bugt_EGA | AI1: Expected Energy | AJ1: Actual Energy WPR | AK1: RA (%) | AL1: Mod Clean Dry (Num) | AM1: Mod Clean Wet (Num) | AN1: Line Loss(%) | AO1: Reactive Power (%) | AP1: Bugt Line loss (%) (Wind) | AQ1: Bugt Reactive Power (%) (Wind) | AR1: Bugt Capacity | AS1: CC*Bugt
A2: 45745 | B2: =YEAR(Table13[[#This Row],[Date]])+IF(MONTH(Table13[[#This Row],[Date]])>=4,1,0) -> 2025 | C2: =YEAR(Table13[[#This Row],[Date]]) -> 2025 | D2: =Table13[[#This Row],[Date]]-DAY(Table13[[#This Row],[Date]])+1 -> 45717 | E2: =DAY(EOMONTH(A2,0)) -> 31 | M2: =IFERROR(_xlfn.XLOOKUP($A2,Input_Raw!$A:$A,Input_Raw!BG:BG),"") -> 7.14 | N2: =IFERROR(_xlfn.XLOOKUP($A2,Input_Raw!$A:$A,Input_Raw!BH:BH),"") -> 0 | O2: =IFERROR(P2*Q2,"") -> 1 | P2: =IFERROR(1-SUMIF(WTG_BD!$F:$F,$A2,WTG_BD!$AA:$AA)/($AA2+SUMIF(WTG_BD!$F:$F,$A2,WTG_BD!$AA:$AA)),"") -> 1 | Q2: =IFERROR(1-SUMIF(IGA_BD!$F:$F,$A2,IGA_BD!$X:$X)/($AA2+SUMIF(IGA_BD!$F:$F,$A2,IGA_BD!$X:$X)),"") -> 1 | R2: =IFERROR(1-SUMIF(Grid_BD!$F:$F,$A2,Grid_BD!$Y:$Y)/($AA2+SUMIF(Grid_BD!$F:$F,$A2,Grid_BD!$Y:$Y)),"") -> 1 | W2: =IFERROR(AA2/(24*AR2*1000),"") -> 0.45806624 | X2: =IFERROR(_xlfn.XLOOKUP($A2,Input_Raw!$A:$A,Input_Raw!$BF:$BF),"") -> 801666 | Y2: =IFERROR(_xlfn.XLOOKUP($A2,Input_Raw!$A:$A,Input_Raw!BJ:BJ),"") -> 771750 | Z2: =IFERROR(_xlfn.XLOOKUP($A2,Input_Raw!$A:$A,Input_Raw!BK:BK),"") -> 0 | AA2: =IFERROR(_xlfn.XLOOKUP($A2,Input_Raw!$A:$A,Input_Raw!BL:BL),"") -> 771750 | AB2: =IFERROR(_xlfn.XLOOKUP($A2,Input_Raw!$A:$A,Input_Raw!$BO:$BO),"") -> 70.2 | AC2: =IFERROR(_xlfn.XLOOKUP($D2,'Modelling New'!$D:$D,'Modelling New'!$J:$J),"") -> 6.89 | AD2: =IFERROR(_xlfn.XLOOKUP($D2,'Modelling New'!$D:$D,'Modelling New'!$T:$T)*1000,"") -> 632771.03 | AF2: =IFERROR(_xlfn.XLOOKUP($D2,'Modelling New'!$D:$D,'Modelling New'!$W:$W),"") -> 0.37557635 | AG2: =IFERROR(_xlfn.XLOOKUP($D2,'Modelling New'!$D:$D,'Modelling New'!$AE:$AE),"") -> 0.9603 | AH2: =IFERROR(_xlfn.XLOOKUP($D2,'Modelling New'!$D:$D,'Modelling New'!$AF:$AF),"") -> 0.995 | AI2: =IFERROR(_xlfn.XLOOKUP($A2,Input_Raw!$A:$A,Input_Raw!$BQ:$BQ),"") -> 843.53353 | AN2: =IFERROR(_xlfn.XLOOKUP($A2,Input_Raw!$A:$A,Input_Raw!$BN:$BN),"") -> 0.037317287 | AO2: =IFERROR((_xlfn.XLOOKUP($A2,'WTG Reactive Power'!$A:$A,'WTG Reactive Power'!$AE:$AE))/Table13[[#This Row],[Gen_Exp (kWh)]],"") -> 0 | AP2: =IFERROR(_xlfn.XLOOKUP($D2,'Modelling New'!$D:$D,'Modelling New'!$AK:$AK),"") -> 0.05 | AQ2: =IFERROR(_xlfn.XLOOKUP($D2,'Modelling New'!$D:$D,'Modelling New'!$AL:$AL),"") -> 0.05 | AR2: =IFERROR(_xlfn.XLOOKUP($D2,'Modelling New'!$D:$D,'Modelling New'!$N:$N),"") -> 70.2
A3: =A2+1 -> 45746 | B3: =YEAR(Table13[[#This Row],[Date]])+IF(MONTH(Table13[[#This Row],[Date]])>=4,1,0) -> 2025 | C3: =YEAR(Table13[[#This Row],[Date]]) -> 2025 | D3: =Table13[[#This Row],[Date]]-DAY(Table13[[#This Row],[Date]])+1 -> 45717 | E3: =DAY(EOMONTH(A3,0)) -> 31 | M3: =IFERROR(_xlfn.XLOOKUP($A3,Input_Raw!$A:$A,Input_Raw!BG:BG),"") -> 5.9436966 | N3: =IFERROR(_xlfn.XLOOKUP($A3,Input_Raw!$A:$A,Input_Raw!BH:BH),"") -> 0 | O3: =IFERROR(P3*Q3,"") -> 1 | P3: =IFERROR(1-SUMIF(WTG_BD!$F:$F,$A3,WTG_BD!$AA:$AA)/($AA3+SUMIF(WTG_BD!$F:$F,$A3,WTG_BD!$AA:$AA)),"") -> 1 | Q3: =IFERROR(1-SUMIF(IGA_BD!$F:$F,$A3,IGA_BD!$X:$X)/($AA3+SUMIF(IGA_BD!$F:$F,$A3,IGA_BD!$X:$X)),"") -> 1 | R3: =IFERROR(1-SUMIF(Grid_BD!$F:$F,$A3,Grid_BD!$Y:$Y)/($AA3+SUMIF(Grid_BD!$F:$F,$A3,Grid_BD!$Y:$Y)),"") -> 1 | W3: =IFERROR(AA3/(24*AR3*1000),"") -> 0.31784188 | X3: =IFERROR(_xlfn.XLOOKUP($A3,Input_Raw!$A:$A,Input_Raw!$BF:$BF),"") -> 552111 | Y3: =IFERROR(_xlfn.XLOOKUP($A3,Input_Raw!$A:$A,Input_Raw!BJ:BJ),"") -> 535500 | Z3: =IFERROR(_xlfn.XLOOKUP($A3,Input_Raw!$A:$A,Input_Raw!BK:BK),"") -> 0 | AA3: =IFERROR(_xlfn.XLOOKUP($A3,Input_Raw!$A:$A,Input_Raw!BL:BL),"") -> 535500 | AB3: =IFERROR(_xlfn.XLOOKUP($A3,Input_Raw!$A:$A,Input_Raw!$BO:$BO),"") -> 70.2 | AC3: =IFERROR(_xlfn.XLOOKUP($D3,'Modelling New'!$D:$D,'Modelling New'!$J:$J),"") -> 6.89 | AD3: =IFERROR(_xlfn.XLOOKUP($D3,'Modelling New'!$D:$D,'Modelling New'!$T:$T)*1000,"") -> 632771.03 | AF3: =IFERROR(_xlfn.XLOOKUP($D3,'Modelling New'!$D:$D,'Modelling New'!$W:$W),"") -> 0.37557635 | AG3: =IFERROR(_xlfn.XLOOKUP($D3,'Modelling New'!$D:$D,'Modelling New'!$AE:$AE),"") -> 0.9603 | AH3: =IFERROR(_xlfn.XLOOKUP($D3,'Modelling New'!$D:$D,'Modelling New'!$AF:$AF),"") -> 0.995 | AI3: =IFERROR(_xlfn.XLOOKUP($A3,Input_Raw!$A:$A,Input_Raw!$BQ:$BQ),"") -> 562.59158 | AN3: =IFERROR(_xlfn.XLOOKUP($A3,Input_Raw!$A:$A,Input_Raw!$BN:$BN),"") -> 0.030086341 | AO3: =IFERROR((_xlfn.XLOOKUP($A3,'WTG Reactive Power'!$A:$A,'WTG Reactive Power'!$AE:$AE))/Table13[[#This Row],[Gen_Exp (kWh)]],"") -> 0 | AP3: =IFERROR(_xlfn.XLOOKUP($D3,'Modelling New'!$D:$D,'Modelling New'!$AK:$AK),"") -> 0.05 | AQ3: =IFERROR(_xlfn.XLOOKUP($D3,'Modelling New'!$D:$D,'Modelling New'!$AL:$AL),"") -> 0.05 | AR3: =IFERROR(_xlfn.XLOOKUP($D3,'Modelling New'!$D:$D,'Modelling New'!$N:$N),"") -> 70.2
A4: =A3+1 -> 45747 | B4: =YEAR(Table13[[#This Row],[Date]])+IF(MONTH(Table13[[#This Row],[Date]])>=4,1,0) -> 2025 | C4: =YEAR(Table13[[#This Row],[Date]]) -> 2025 | D4: =Table13[[#This Row],[Date]]-DAY(Table13[[#This Row],[Date]])+1 -> 45717 | E4: =DAY(EOMONTH(A4,0)) -> 31 | M4: =IFERROR(_xlfn.XLOOKUP($A4,Input_Raw!$A:$A,Input_Raw!BG:BG),"") -> 6.5130021 | N4: =IFERROR(_xlfn.XLOOKUP($A4,Input_Raw!$A:$A,Input_Raw!BH:BH),"") -> 0 | O4: =IFERROR(P4*Q4,"") -> 1 | P4: =IFERROR(1-SUMIF(WTG_BD!$F:$F,$A4,WTG_BD!$AA:$AA)/($AA4+SUMIF(WTG_BD!$F:$F,$A4,WTG_BD!$AA:$AA)),"") -> 1 | Q4: =IFERROR(1-SUMIF(IGA_BD!$F:$F,$A4,IGA_BD!$X:$X)/($AA4+SUMIF(IGA_BD!$F:$F,$A4,IGA_BD!$X:$X)),"") -> 1 | R4: =IFERROR(1-SUMIF(Grid_BD!$F:$F,$A4,Grid_BD!$Y:$Y)/($AA4+SUMIF(Grid_BD!$F:$F,$A4,Grid_BD!$Y:$Y)),"") -> 1 | W4: =IFERROR(AA4/(24*AR4*1000),"") -> 0.3838141 | X4: =IFERROR(_xlfn.XLOOKUP($A4,Input_Raw!$A:$A,Input_Raw!$BF:$BF),"") -> 667722 | Y4: =IFERROR(_xlfn.XLOOKUP($A4,Input_Raw!$A:$A,Input_Raw!BJ:BJ),"") -> 646650 | Z4: =IFERROR(_xlfn.XLOOKUP($A4,Input_Raw!$A:$A,Input_Raw!BK:BK),"") -> 0 | AA4: =IFERROR(_xlfn.XLOOKUP($A4,Input_Raw!$A:$A,Input_Raw!BL:BL),"") -> 646650 | AB4: =IFERROR(_xlfn.XLOOKUP($A4,Input_Raw!$A:$A,Input_Raw!$BO:$BO),"") -> 70.2 | AC4: =IFERROR(_xlfn.XLOOKUP($D4,'Modelling New'!$D:$D,'Modelling New'!$J:$J),"") -> 6.89 | AD4: =IFERROR(_xlfn.XLOOKUP($D4,'Modelling New'!$D:$D,'Modelling New'!$T:$T)*1000,"") -> 632771.03 | AF4: =IFERROR(_xlfn.XLOOKUP($D4,'Modelling New'!$D:$D,'Modelling New'!$W:$W),"") -> 0.37557635 | AG4: =IFERROR(_xlfn.XLOOKUP($D4,'Modelling New'!$D:$D,'Modelling New'!$AE:$AE),"") -> 0.9603 | AH4: =IFERROR(_xlfn.XLOOKUP($D4,'Modelling New'!$D:$D,'Modelling New'!$AF:$AF),"") -> 0.995 | AI4: =IFERROR(_xlfn.XLOOKUP($A4,Input_Raw!$A:$A,Input_Raw!$BQ:$BQ),"") -> 675.40492 | AN4: =IFERROR(_xlfn.XLOOKUP($A4,Input_Raw!$A:$A,Input_Raw!$BN:$BN),"") -> 0.031558044 | AO4: =IFERROR((_xlfn.XLOOKUP($A4,'WTG Reactive Power'!$A:$A,'WTG Reactive Power'!$AE:$AE))/Table13[[#This Row],[Gen_Exp (kWh)]],"") -> 0 | AP4: =IFERROR(_xlfn.XLOOKUP($D4,'Modelling New'!$D:$D,'Modelling New'!$AK:$AK),"") -> 0.05 | AQ4: =IFERROR(_xlfn.XLOOKUP($D4,'Modelling New'!$D:$D,'Modelling New'!$AL:$AL),"") -> 0.05 | AR4: =IFERROR(_xlfn.XLOOKUP($D4,'Modelling New'!$D:$D,'Modelling New'!$N:$N),"") -> 70.2
A5: =A4+1 -> 45748 | B5: =YEAR(Table13[[#This Row],[Date]])+IF(MONTH(Table13[[#This Row],[Date]])>=4,1,0) -> 2026 | C5: =YEAR(Table13[[#This Row],[Date]]) -> 2025 | D5: =Table13[[#This Row],[Date]]-DAY(Table13[[#This Row],[Date]])+1 -> 45748 | E5: =DAY(EOMONTH(A5,0)) -> 30 | M5: =IFERROR(_xlfn.XLOOKUP($A5,Input_Raw!$A:$A,Input_Raw!BG:BG),"") -> 6.0269097 | N5: =IFERROR(_xlfn.XLOOKUP($A5,Input_Raw!$A:$A,Input_Raw!BH:BH),"") -> 0 | O5: =IFERROR(P5*Q5,"") -> 0.98286451 | P5: =IFERROR(1-SUMIF(WTG_BD!$F:$F,$A5,WTG_BD!$AA:$AA)/($AA5+SUMIF(WTG_BD!$F:$F,$A5,WTG_BD!$AA:$AA)),"") -> 0.98286451 | Q5: =IFERROR(1-SUMIF(IGA_BD!$F:$F,$A5,IGA_BD!$X:$X)/($AA5+SUMIF(IGA_BD!$F:$F,$A5,IGA_BD!$X:$X)),"") -> 1 | R5: =IFERROR(1-SUMIF(Grid_BD!$F:$F,$A5,Grid_BD!$Y:$Y)/($AA5+SUMIF(Grid_BD!$F:$F,$A5,Grid_BD!$Y:$Y)),"") -> 1 | W5: =IFERROR(AA5/(24*AR5*1000),"") -> 0.31196581 | X5: =IFERROR(_xlfn.XLOOKUP($A5,Input_Raw!$A:$A,Input_Raw!$BF:$BF),"") -> 544118 | Y5: =IFERROR(_xlfn.XLOOKUP($A5,Input_Raw!$A:$A,Input_Raw!BJ:BJ),"") -> 525600 | Z5: =IFERROR(_xlfn.XLOOKUP($A5,Input_Raw!$A:$A,Input_Raw!BK:BK),"") -> 0 | AA5: =IFERROR(_xlfn.XLOOKUP($A5,Input_Raw!$A:$A,Input_Raw!BL:BL),"") -> 525600 | AB5: =IFERROR(_xlfn.XLOOKUP($A5,Input_Raw!$A:$A,Input_Raw!$BO:$BO),"") -> 70.2 | AC5: =IFERROR(_xlfn.XLOOKUP($D5,'Modelling New'!$D:$D,'Modelling New'!$J:$J),"") -> 6.65 | AD5: =IFERROR(_xlfn.XLOOKUP($D5,'Modelling New'!$D:$D,'Modelling New'!$T:$T)*1000,"") -> 697760.54 | AF5: =IFERROR(_xlfn.XLOOKUP($D5,'Modelling New'!$D:$D,'Modelling New'!$W:$W),"") -> 0.41415037 | AG5: =IFERROR(_xlfn.XLOOKUP($D5,'Modelling New'!$D:$D,'Modelling New'!$AE:$AE),"") -> 0.9603 | AH5: =IFERROR(_xlfn.XLOOKUP($D5,'Modelling New'!$D:$D,'Modelling New'!$AF:$AF),"") -> 0.995 | AI5: =IFERROR(_xlfn.XLOOKUP($A5,Input_Raw!$A:$A,Input_Raw!$BQ:$BQ),"") -> 664.42114 | AN5: =IFERROR(_xlfn.XLOOKUP($A5,Input_Raw!$A:$A,Input_Raw!$BN:$BN),"") -> 0.034033059 | AO5: =IFERROR((_xlfn.XLOOKUP($A5,'WTG Reactive Power'!$A:$A,'WTG Reactive Power'!$AE:$AE))/Table13[[#This Row],[Gen_Exp (kWh)]],"") -> 0 | AP5: =IFERROR(_xlfn.XLOOKUP($D5,'Modelling New'!$D:$D,'Modelling New'!$AK:$AK),"") -> 0.05 | AQ5: =IFERROR(_xlfn.XLOOKUP($D5,'Modelling New'!$D:$D,'Modelling New'!$AL:$AL),"") -> 0.05 | AR5: =IFERROR(_xlfn.XLOOKUP($D5,'Modelling New'!$D:$D,'Modelling New'!$N:$N),"") -> 70.2
A6: =A5+1 -> 45749 | B6: =YEAR(Table13[[#This Row],[Date]])+IF(MONTH(Table13[[#This Row],[Date]])>=4,1,0) -> 2026 | C6: =YEAR(Table13[[#This Row],[Date]]) -> 2025 | D6: =Table13[[#This Row],[Date]]-DAY(Table13[[#This Row],[Date]])+1 -> 45748 | E6: =DAY(EOMONTH(A6,0)) -> 30 | M6: =IFERROR(_xlfn.XLOOKUP($A6,Input_Raw!$A:$A,Input_Raw!BG:BG),"") -> 4.4381926 | N6: =IFERROR(_xlfn.XLOOKUP($A6,Input_Raw!$A:$A,Input_Raw!BH:BH),"") -> 0 | O6: =IFERROR(P6*Q6,"") -> 0.98144557 | P6: =IFERROR(1-SUMIF(WTG_BD!$F:$F,$A6,WTG_BD!$AA:$AA)/($AA6+SUMIF(WTG_BD!$F:$F,$A6,WTG_BD!$AA:$AA)),"") -> 0.98144557 | Q6: =IFERROR(1-SUMIF(IGA_BD!$F:$F,$A6,IGA_BD!$X:$X)/($AA6+SUMIF(IGA_BD!$F:$F,$A6,IGA_BD!$X:$X)),"") -> 1 | R6: =IFERROR(1-SUMIF(Grid_BD!$F:$F,$A6,Grid_BD!$Y:$Y)/($AA6+SUMIF(Grid_BD!$F:$F,$A6,Grid_BD!$Y:$Y)),"") -> 1 | W6: =IFERROR(AA6/(24*AR6*1000),"") -> 0.16372863 | X6: =IFERROR(_xlfn.XLOOKUP($A6,Input_Raw!$A:$A,Input_Raw!$BF:$BF),"") -> 285682 | Y6: =IFERROR(_xlfn.XLOOKUP($A6,Input_Raw!$A:$A,Input_Raw!BJ:BJ),"") -> 275850 | Z6: =IFERROR(_xlfn.XLOOKUP($A6,Input_Raw!$A:$A,Input_Raw!BK:BK),"") -> 0 | AA6: =IFERROR(_xlfn.XLOOKUP($A6,Input_Raw!$A:$A,Input_Raw!BL:BL),"") -> 275850 | AB6: =IFERROR(_xlfn.XLOOKUP($A6,Input_Raw!$A:$A,Input_Raw!$BO:$BO),"") -> 70.2 | AC6: =IFERROR(_xlfn.XLOOKUP($D6,'Modelling New'!$D:$D,'Modelling New'!$J:$J),"") -> 6.65 | AD6: =IFERROR(_xlfn.XLOOKUP($D6,'Modelling New'!$D:$D,'Modelling New'!$T:$T)*1000,"") -> 697760.54 | AF6: =IFERROR(_xlfn.XLOOKUP($D6,'Modelling New'!$D:$D,'Modelling New'!$W:$W),"") -> 0.41415037 | AG6: =IFERROR(_xlfn.XLOOKUP($D6,'Modelling New'!$D:$D,'Modelling New'!$AE:$AE),"") -> 0.9603 | AH6: =IFERROR(_xlfn.XLOOKUP($D6,'Modelling New'!$D:$D,'Modelling New'!$AF:$AF),"") -> 0.995 | AI6: =IFERROR(_xlfn.XLOOKUP($A6,Input_Raw!$A:$A,Input_Raw!$BQ:$BQ),"") -> 294.64036 | AN6: =IFERROR(_xlfn.XLOOKUP($A6,Input_Raw!$A:$A,Input_Raw!$BN:$BN),"") -> 0.034415889 | AO6: =IFERROR((_xlfn.XLOOKUP($A6,'WTG Reactive Power'!$A:$A,'WTG Reactive Power'!$AE:$AE))/Table13[[#This Row],[Gen_Exp (kWh)]],"") -> 0 | AP6: =IFERROR(_xlfn.XLOOKUP($D6,'Modelling New'!$D:$D,'Modelling New'!$AK:$AK),"") -> 0.05 | AQ6: =IFERROR(_xlfn.XLOOKUP($D6,'Modelling New'!$D:$D,'Modelling New'!$AL:$AL),"") -> 0.05 | AR6: =IFERROR(_xlfn.XLOOKUP($D6,'Modelling New'!$D:$D,'Modelling New'!$N:$N),"") -> 70.2
A7: =A6+1 -> 45750 | B7: =YEAR(Table13[[#This Row],[Date]])+IF(MONTH(Table13[[#This Row],[Date]])>=4,1,0) -> 2026 | C7: =YEAR(Table13[[#This Row],[Date]]) -> 2025 | D7: =Table13[[#This Row],[Date]]-DAY(Table13[[#This Row],[Date]])+1 -> 45748 | E7: =DAY(EOMONTH(A7,0)) -> 30 | M7: =IFERROR(_xlfn.XLOOKUP($A7,Input_Raw!$A:$A,Input_Raw!BG:BG),"") -> 4.8481903 | N7: =IFERROR(_xlfn.XLOOKUP($A7,Input_Raw!$A:$A,Input_Raw!BH:BH),"") -> 0 | O7: =IFERROR(P7*Q7,"") -> 0.97615985 | P7: =IFERROR(1-SUMIF(WTG_BD!$F:$F,$A7,WTG_BD!$AA:$AA)/($AA7+SUMIF(WTG_BD!$F:$F,$A7,WTG_BD!$AA:$AA)),"") -> 0.97651772 | Q7: =IFERROR(1-SUMIF(IGA_BD!$F:$F,$A7,IGA_BD!$X:$X)/($AA7+SUMIF(IGA_BD!$F:$F,$A7,IGA_BD!$X:$X)),"") -> 0.99963353 | R7: =IFERROR(1-SUMIF(Grid_BD!$F:$F,$A7,Grid_BD!$Y:$Y)/($AA7+SUMIF(Grid_BD!$F:$F,$A7,Grid_BD!$Y:$Y)),"") -> 1 | W7: =IFERROR(AA7/(24*AR7*1000),"") -> 0.20512821 | X7: =IFERROR(_xlfn.XLOOKUP($A7,Input_Raw!$A:$A,Input_Raw!$BF:$BF),"") -> 357239 | Y7: =IFERROR(_xlfn.XLOOKUP($A7,Input_Raw!$A:$A,Input_Raw!BJ:BJ),"") -> 346050 | Z7: =IFERROR(_xlfn.XLOOKUP($A7,Input_Raw!$A:$A,Input_Raw!BK:BK),"") -> 450 | AA7: =IFERROR(_xlfn.XLOOKUP($A7,Input_Raw!$A:$A,Input_Raw!BL:BL),"") -> 345600 | AB7: =IFERROR(_xlfn.XLOOKUP($A7,Input_Raw!$A:$A,Input_Raw!$BO:$BO),"") -> 70.2 | AC7: =IFERROR(_xlfn.XLOOKUP($D7,'Modelling New'!$D:$D,'Modelling New'!$J:$J),"") -> 6.65 | AD7: =IFERROR(_xlfn.XLOOKUP($D7,'Modelling New'!$D:$D,'Modelling New'!$T:$T)*1000,"") -> 697760.54 | AF7: =IFERROR(_xlfn.XLOOKUP($D7,'Modelling New'!$D:$D,'Modelling New'!$W:$W),"") -> 0.41415037 | AG7: =IFERROR(_xlfn.XLOOKUP($D7,'Modelling New'!$D:$D,'Modelling New'!$AE:$AE),"") -> 0.9603 | AH7: =IFERROR(_xlfn.XLOOKUP($D7,'Modelling New'!$D:$D,'Modelling New'!$AF:$AF),"") -> 0.995 | AI7: =IFERROR(_xlfn.XLOOKUP($A7,Input_Raw!$A:$A,Input_Raw!$BQ:$BQ),"") -> 371.21 | AN7: =IFERROR(_xlfn.XLOOKUP($A7,Input_Raw!$A:$A,Input_Raw!$BN:$BN),"") -> 0.031320768 | AO7: =IFERROR((_xlfn.XLOOKUP($A7,'WTG Reactive Power'!$A:$A,'WTG Reactive Power'!$AE:$AE))/Table13[[#This Row],[Gen_Exp (kWh)]],"") -> 0 | AP7: =IFERROR(_xlfn.XLOOKUP($D7,'Modelling New'!$D:$D,'Modelling New'!$AK:$AK),"") -> 0.05 | AQ7: =IFERROR(_xlfn.XLOOKUP($D7,'Modelling New'!$D:$D,'Modelling New'!$AL:$AL),"") -> 0.05 | AR7: =IFERROR(_xlfn.XLOOKUP($D7,'Modelling New'!$D:$D,'Modelling New'!$N:$N),"") -> 70.2
A8: =A7+1 -> 45751 | B8: =YEAR(Table13[[#This Row],[Date]])+IF(MONTH(Table13[[#This Row],[Date]])>=4,1,0) -> 2026 | C8: =YEAR(Table13[[#This Row],[Date]]) -> 2025 | D8: =Table13[[#This Row],[Date]]-DAY(Table13[[#This Row],[Date]])+1 -> 45748 | E8: =DAY(EOMONTH(A8,0)) -> 30 | M8: =IFERROR(_xlfn.XLOOKUP($A8,Input_Raw!$A:$A,Input_Raw!BG:BG),"") -> 4.2849993 | N8: =IFERROR(_xlfn.XLOOKUP($A8,Input_Raw!$A:$A,Input_Raw!BH:BH),"") -> 0 | O8: =IFERROR(P8*Q8,"") -> 0.9759052 | P8: =IFERROR(1-SUMIF(WTG_BD!$F:$F,$A8,WTG_BD!$AA:$AA)/($AA8+SUMIF(WTG_BD!$F:$F,$A8,WTG_BD!$AA:$AA)),"") -> 0.9759052 | Q8: =IFERROR(1-SUMIF(IGA_BD!$F:$F,$A8,IGA_BD!$X:$X)/($AA8+SUMIF(IGA_BD!$F:$F,$A8,IGA_BD!$X:$X)),"") -> 1 | R8: =IFERROR(1-SUMIF(Grid_BD!$F:$F,$A8,Grid_BD!$Y:$Y)/($AA8+SUMIF(Grid_BD!$F:$F,$A8,Grid_BD!$Y:$Y)),"") -> 1 | W8: =IFERROR(AA8/(24*AR8*1000),"") -> 0.15251068 | X8: =IFERROR(_xlfn.XLOOKUP($A8,Input_Raw!$A:$A,Input_Raw!$BF:$BF),"") -> 269263 | Y8: =IFERROR(_xlfn.XLOOKUP($A8,Input_Raw!$A:$A,Input_Raw!BJ:BJ),"") -> 257400 | Z8: =IFERROR(_xlfn.XLOOKUP($A8,Input_Raw!$A:$A,Input_Raw!BK:BK),"") -> 450 | AA8: =IFERROR(_xlfn.XLOOKUP($A8,Input_Raw!$A:$A,Input_Raw!BL:BL),"") -> 256950 | AB8: =IFERROR(_xlfn.XLOOKUP($A8,Input_Raw!$A:$A,Input_Raw!$BO:$BO),"") -> 70.2 | AC8: =IFERROR(_xlfn.XLOOKUP($D8,'Modelling New'!$D:$D,'Modelling New'!$J:$J),"") -> 6.65 | AD8: =IFERROR(_xlfn.XLOOKUP($D8,'Modelling New'!$D:$D,'Modelling New'!$T:$T)*1000,"") -> 697760.54 | AF8: =IFERROR(_xlfn.XLOOKUP($D8,'Modelling New'!$D:$D,'Modelling New'!$W:$W),"") -> 0.41415037 | AG8: =IFERROR(_xlfn.XLOOKUP($D8,'Modelling New'!$D:$D,'Modelling New'!$AE:$AE),"") -> 0.9603 | AH8: =IFERROR(_xlfn.XLOOKUP($D8,'Modelling New'!$D:$D,'Modelling New'!$AF:$AF),"") -> 0.995 | AI8: =IFERROR(_xlfn.XLOOKUP($A8,Input_Raw!$A:$A,Input_Raw!$BQ:$BQ),"") -> 281.07 | AN8: =IFERROR(_xlfn.XLOOKUP($A8,Input_Raw!$A:$A,Input_Raw!$BN:$BN),"") -> 0.044057297 | AO8: =IFERROR((_xlfn.XLOOKUP($A8,'WTG Reactive Power'!$A:$A,'WTG Reactive Power'!$AE:$AE))/Table13[[#This Row],[Gen_Exp (kWh)]],"") -> 0.0048463398 | AP8: =IFERROR(_xlfn.XLOOKUP($D8,'Modelling New'!$D:$D,'Modelling New'!$AK:$AK),"") -> 0.05 | AQ8: =IFERROR(_xlfn.XLOOKUP($D8,'Modelling New'!$D:$D,'Modelling New'!$AL:$AL),"") -> 0.05 | AR8: =IFERROR(_xlfn.XLOOKUP($D8,'Modelling New'!$D:$D,'Modelling New'!$N:$N),"") -> 70.2
A9: =A8+1 -> 45752 | B9: =YEAR(Table13[[#This Row],[Date]])+IF(MONTH(Table13[[#This Row],[Date]])>=4,1,0) -> 2026 | C9: =YEAR(Table13[[#This Row],[Date]]) -> 2025 | D9: =Table13[[#This Row],[Date]]-DAY(Table13[[#This Row],[Date]])+1 -> 45748 | E9: =DAY(EOMONTH(A9,0)) -> 30 | M9: =IFERROR(_xlfn.XLOOKUP($A9,Input_Raw!$A:$A,Input_Raw!BG:BG),"") -> 4.3638956 | N9: =IFERROR(_xlfn.XLOOKUP($A9,Input_Raw!$A:$A,Input_Raw!BH:BH),"") -> 0 | O9: =IFERROR(P9*Q9,"") -> 0.94684073 | P9: =IFERROR(1-SUMIF(WTG_BD!$F:$F,$A9,WTG_BD!$AA:$AA)/($AA9+SUMIF(WTG_BD!$F:$F,$A9,WTG_BD!$AA:$AA)),"") -> 0.9560255 | Q9: =IFERROR(1-SUMIF(IGA_BD!$F:$F,$A9,IGA_BD!$X:$X)/($AA9+SUMIF(IGA_BD!$F:$F,$A9,IGA_BD!$X:$X)),"") -> 0.99039276 | R9: =IFERROR(1-SUMIF(Grid_BD!$F:$F,$A9,Grid_BD!$Y:$Y)/($AA9+SUMIF(Grid_BD!$F:$F,$A9,Grid_BD!$Y:$Y)),"") -> 1 | W9: =IFERROR(AA9/(24*AR9*1000),"") -> 0.12713675 | X9: =IFERROR(_xlfn.XLOOKUP($A9,Input_Raw!$A:$A,Input_Raw!$BF:$BF),"") -> 223271 | Y9: =IFERROR(_xlfn.XLOOKUP($A9,Input_Raw!$A:$A,Input_Raw!BJ:BJ),"") -> 214200 | Z9: =IFERROR(_xlfn.XLOOKUP($A9,Input_Raw!$A:$A,Input_Raw!BK:BK),"") -> 0 | AA9: =IFERROR(_xlfn.XLOOKUP($A9,Input_Raw!$A:$A,Input_Raw!BL:BL),"") -> 214200 | AB9: =IFERROR(_xlfn.XLOOKUP($A9,Input_Raw!$A:$A,Input_Raw!$BO:$BO),"") -> 70.2 | AC9: =IFERROR(_xlfn.XLOOKUP($D9,'Modelling New'!$D:$D,'Modelling New'!$J:$J),"") -> 6.65 | AD9: =IFERROR(_xlfn.XLOOKUP($D9,'Modelling New'!$D:$D,'Modelling New'!$T:$T)*1000,"") -> 697760.54 | AF9: =IFERROR(_xlfn.XLOOKUP($D9,'Modelling New'!$D:$D,'Modelling New'!$W:$W),"") -> 0.41415037 | AG9: =IFERROR(_xlfn.XLOOKUP($D9,'Modelling New'!$D:$D,'Modelling New'!$AE:$AE),"") -> 0.9603 | AH9: =IFERROR(_xlfn.XLOOKUP($D9,'Modelling New'!$D:$D,'Modelling New'!$AF:$AF),"") -> 0.995 | AI9: =IFERROR(_xlfn.XLOOKUP($A9,Input_Raw!$A:$A,Input_Raw!$BQ:$BQ),"") -> 230.95 | AN9: =IFERROR(_xlfn.XLOOKUP($A9,Input_Raw!$A:$A,Input_Raw!$BN:$BN),"") -> 0.040627757 | AO9: =IFERROR((_xlfn.XLOOKUP($A9,'WTG Reactive Power'!$A:$A,'WTG Reactive Power'!$AE:$AE))/Table13[[#This Row],[Gen_Exp (kWh)]],"") -> 0.0040303488 | AP9: =IFERROR(_xlfn.XLOOKUP($D9,'Modelling New'!$D:$D,'Modelling New'!$AK:$AK),"") -> 0.05 | AQ9: =IFERROR(_xlfn.XLOOKUP($D9,'Modelling New'!$D:$D,'Modelling New'!$AL:$AL),"") -> 0.05 | AR9: =IFERROR(_xlfn.XLOOKUP($D9,'Modelling New'!$D:$D,'Modelling New'!$N:$N),"") -> 70.2
A10: =A9+1 -> 45753 | B10: =YEAR(Table13[[#This Row],[Date]])+IF(MONTH(Table13[[#This Row],[Date]])>=4,1,0) -> 2026 | C10: =YEAR(Table13[[#This Row],[Date]]) -> 2025 | D10: =Table13[[#This Row],[Date]]-DAY(Table13[[#This Row],[Date]])+1 -> 45748 | E10: =DAY(EOMONTH(A10,0)) -> 30 | M10: =IFERROR(_xlfn.XLOOKUP($A10,Input_Raw!$A:$A,Input_Raw!BG:BG),"") -> 6.4385764 | N10: =IFERROR(_xlfn.XLOOKUP($A10,Input_Raw!$A:$A,Input_Raw!BH:BH),"") -> 0 | O10: =IFERROR(P10*Q10,"") -> 0.98397972 | P10: =IFERROR(1-SUMIF(WTG_BD!$F:$F,$A10,WTG_BD!$AA:$AA)/($AA10+SUMIF(WTG_BD!$F:$F,$A10,WTG_BD!$AA:$AA)),"") -> 0.98397972 | Q10: =IFERROR(1-SUMIF(IGA_BD!$F:$F,$A10,IGA_BD!$X:$X)/($AA10+SUMIF(IGA_BD!$F:$F,$A10,IGA_BD!$X:$X)),"") -> 1 | R10: =IFERROR(1-SUMIF(Grid_BD!$F:$F,$A10,Grid_BD!$Y:$Y)/($AA10+SUMIF(Grid_BD!$F:$F,$A10,Grid_BD!$Y:$Y)),"") -> 1 | W10: =IFERROR(AA10/(24*AR10*1000),"") -> 0.35790598 | X10: =IFERROR(_xlfn.XLOOKUP($A10,Input_Raw!$A:$A,Input_Raw!$BF:$BF),"") -> 620284 | Y10: =IFERROR(_xlfn.XLOOKUP($A10,Input_Raw!$A:$A,Input_Raw!BJ:BJ),"") -> 603000 | Z10: =IFERROR(_xlfn.XLOOKUP($A10,Input_Raw!$A:$A,Input_Raw!BK:BK),"") -> 0 | AA10: =IFERROR(_xlfn.XLOOKUP($A10,Input_Raw!$A:$A,Input_Raw!BL:BL),"") -> 603000 | AB10: =IFERROR(_xlfn.XLOOKUP($A10,Input_Raw!$A:$A,Input_Raw!$BO:$BO),"") -> 70.2 | AC10: =IFERROR(_xlfn.XLOOKUP($D10,'Modelling New'!$D:$D,'Modelling New'!$J:$J),"") -> 6.65 | AD10: =IFERROR(_xlfn.XLOOKUP($D10,'Modelling New'!$D:$D,'Modelling New'!$T:$T)*1000,"") -> 697760.54 | AF10: =IFERROR(_xlfn.XLOOKUP($D10,'Modelling New'!$D:$D,'Modelling New'!$W:$W),"") -> 0.41415037 | AG10: =IFERROR(_xlfn.XLOOKUP($D10,'Modelling New'!$D:$D,'Modelling New'!$AE:$AE),"") -> 0.9603 | AH10: =IFERROR(_xlfn.XLOOKUP($D10,'Modelling New'!$D:$D,'Modelling New'!$AF:$AF),"") -> 0.995 | AI10: =IFERROR(_xlfn.XLOOKUP($A10,Input_Raw!$A:$A,Input_Raw!$BQ:$BQ),"") -> 667.03 | AN10: =IFERROR(_xlfn.XLOOKUP($A10,Input_Raw!$A:$A,Input_Raw!$BN:$BN),"") -> 0.027864656 | AO10: =IFERROR((_xlfn.XLOOKUP($A10,'WTG Reactive Power'!$A:$A,'WTG Reactive Power'!$AE:$AE))/Table13[[#This Row],[Gen_Exp (kWh)]],"") -> 0.0050781577 | AP10: =IFERROR(_xlfn.XLOOKUP($D10,'Modelling New'!$D:$D,'Modelling New'!$AK:$AK),"") -> 0.05 | AQ10: =IFERROR(_xlfn.XLOOKUP($D10,'Modelling New'!$D:$D,'Modelling New'!$AL:$AL),"") -> 0.05 | AR10: =IFERROR(_xlfn.XLOOKUP($D10,'Modelling New'!$D:$D,'Modelling New'!$N:$N),"") -> 70.2
A11: =A10+1 -> 45754 | B11: =YEAR(Table13[[#This Row],[Date]])+IF(MONTH(Table13[[#This Row],[Date]])>=4,1,0) -> 2026 | C11: =YEAR(Table13[[#This Row],[Date]]) -> 2025 | D11: =Table13[[#This Row],[Date]]-DAY(Table13[[#This Row],[Date]])+1 -> 45748 | E11: =DAY(EOMONTH(A11,0)) -> 30 | M11: =IFERROR(_xlfn.XLOOKUP($A11,Input_Raw!$A:$A,Input_Raw!BG:BG),"") -> 7.1744298 | N11: =IFERROR(_xlfn.XLOOKUP($A11,Input_Raw!$A:$A,Input_Raw!BH:BH),"") -> 0 | O11: =IFERROR(P11*Q11,"") -> 0.96775065 | P11: =IFERROR(1-SUMIF(WTG_BD!$F:$F,$A11,WTG_BD!$AA:$AA)/($AA11+SUMIF(WTG_BD!$F:$F,$A11,WTG_BD!$AA:$AA)),"") -> 0.9754159 | Q11: =IFERROR(1-SUMIF(IGA_BD!$F:$F,$A11,IGA_BD!$X:$X)/($AA11+SUMIF(IGA_BD!$F:$F,$A11,IGA_BD!$X:$X)),"") -> 0.99214155 | R11: =IFERROR(1-SUMIF(Grid_BD!$F:$F,$A11,Grid_BD!$Y:$Y)/($AA11+SUMIF(Grid_BD!$F:$F,$A11,Grid_BD!$Y:$Y)),"") -> 1 | W11: =IFERROR(AA11/(24*AR11*1000),"") -> 0.47649573 | X11: =IFERROR(_xlfn.XLOOKUP($A11,Input_Raw!$A:$A,Input_Raw!$BF:$BF),"") -> 834723 | Y11: =IFERROR(_xlfn.XLOOKUP($A11,Input_Raw!$A:$A,Input_Raw!BJ:BJ),"") -> 802800 | Z11: =IFERROR(_xlfn.XLOOKUP($A11,Input_Raw!$A:$A,Input_Raw!BK:BK),"") -> 0 | AA11: =IFERROR(_xlfn.XLOOKUP($A11,Input_Raw!$A:$A,Input_Raw!BL:BL),"") -> 802800 | AB11: =IFERROR(_xlfn.XLOOKUP($A11,Input_Raw!$A:$A,Input_Raw!$BO:$BO),"") -> 70.2 | AC11: =IFERROR(_xlfn.XLOOKUP($D11,'Modelling New'!$D:$D,'Modelling New'!$J:$J),"") -> 6.65 | AD11: =IFERROR(_xlfn.XLOOKUP($D11,'Modelling New'!$D:$D,'Modelling New'!$T:$T)*1000,"") -> 697760.54 | AF11: =IFERROR(_xlfn.XLOOKUP($D11,'Modelling New'!$D:$D,'Modelling New'!$W:$W),"") -> 0.41415037 | AG11: =IFERROR(_xlfn.XLOOKUP($D11,'Modelling New'!$D:$D,'Modelling New'!$AE:$AE),"") -> 0.9603 | AH11: =IFERROR(_xlfn.XLOOKUP($D11,'Modelling New'!$D:$D,'Modelling New'!$AF:$AF),"") -> 0.995 | AI11: =IFERROR(_xlfn.XLOOKUP($A11,Input_Raw!$A:$A,Input_Raw!$BQ:$BQ),"") -> 890.54 | AN11: =IFERROR(_xlfn.XLOOKUP($A11,Input_Raw!$A:$A,Input_Raw!$BN:$BN),"") -> 0.038243825 | AO11: =IFERROR((_xlfn.XLOOKUP($A11,'WTG Reactive Power'!$A:$A,'WTG Reactive Power'!$AE:$AE))/Table13[[#This Row],[Gen_Exp (kWh)]],"") -> 0.038275979 | AP11: =IFERROR(_xlfn.XLOOKUP($D11,'Modelling New'!$D:$D,'Modelling New'!$AK:$AK),"") -> 0.05 | AQ11: =IFERROR(_xlfn.XLOOKUP($D11,'Modelling New'!$D:$D,'Modelling New'!$AL:$AL),"") -> 0.05 | AR11: =IFERROR(_xlfn.XLOOKUP($D11,'Modelling New'!$D:$D,'Modelling New'!$N:$N),"") -> 70.2
A12: =A11+1 -> 45755 | B12: =YEAR(Table13[[#This Row],[Date]])+IF(MONTH(Table13[[#This Row],[Date]])>=4,1,0) -> 2026 | C12: =YEAR(Table13[[#This Row],[Date]]) -> 2025 | D12: =Table13[[#This Row],[Date]]-DAY(Table13[[#This Row],[Date]])+1 -> 45748 | E12: =DAY(EOMONTH(A12,0)) -> 30 | M12: =IFERROR(_xlfn.XLOOKUP($A12,Input_Raw!$A:$A,Input_Raw!BG:BG),"") -> 7.079092 | N12: =IFERROR(_xlfn.XLOOKUP($A12,Input_Raw!$A:$A,Input_Raw!BH:BH),"") -> 0 | O12: =IFERROR(P12*Q12,"") -> 0.97183445 | P12: =IFERROR(1-SUMIF(WTG_BD!$F:$F,$A12,WTG_BD!$AA:$AA)/($AA12+SUMIF(WTG_BD!$F:$F,$A12,WTG_BD!$AA:$AA)),"") -> 0.97183445 | Q12: =IFERROR(1-SUMIF(IGA_BD!$F:$F,$A12,IGA_BD!$X:$X)/($AA12+SUMIF(IGA_BD!$F:$F,$A12,IGA_BD!$X:$X)),"") -> 1 | R12: =IFERROR(1-SUMIF(Grid_BD!$F:$F,$A12,Grid_BD!$Y:$Y)/($AA12+SUMIF(Grid_BD!$F:$F,$A12,Grid_BD!$Y:$Y)),"") -> 1 | W12: =IFERROR(AA12/(24*AR12*1000),"") -> 0.47088675 | X12: =IFERROR(_xlfn.XLOOKUP($A12,Input_Raw!$A:$A,Input_Raw!$BF:$BF),"") -> 823138 | Y12: =IFERROR(_xlfn.XLOOKUP($A12,Input_Raw!$A:$A,Input_Raw!BJ:BJ),"") -> 793800 | Z12: =IFERROR(_xlfn.XLOOKUP($A12,Input_Raw!$A:$A,Input_Raw!BK:BK),"") -> 450 | AA12: =IFERROR(_xlfn.XLOOKUP($A12,Input_Raw!$A:$A,Input_Raw!BL:BL),"") -> 793350 | AB12: =IFERROR(_xlfn.XLOOKUP($A12,Input_Raw!$A:$A,Input_Raw!$BO:$BO),"") -> 70.2 | AC12: =IFERROR(_xlfn.XLOOKUP($D12,'Modelling New'!$D:$D,'Modelling New'!$J:$J),"") -> 6.65 | AD12: =IFERROR(_xlfn.XLOOKUP($D12,'Modelling New'!$D:$D,'Modelling New'!$T:$T)*1000,"") -> 697760.54 | AF12: =IFERROR(_xlfn.XLOOKUP($D12,'Modelling New'!$D:$D,'Modelling New'!$W:$W),"") -> 0.41415037 | AG12: =IFERROR(_xlfn.XLOOKUP($D12,'Modelling New'!$D:$D,'Modelling New'!$AE:$AE),"") -> 0.9603 | AH12: =IFERROR(_xlfn.XLOOKUP($D12,'Modelling New'!$D:$D,'Modelling New'!$AF:$AF),"") -> 0.995 | AI12: =IFERROR(_xlfn.XLOOKUP($A12,Input_Raw!$A:$A,Input_Raw!$BQ:$BQ),"") -> 885.16 | AN12: =IFERROR(_xlfn.XLOOKUP($A12,Input_Raw!$A:$A,Input_Raw!$BN:$BN),"") -> 0.035641654 | AO12: =IFERROR((_xlfn.XLOOKUP($A12,'WTG Reactive Power'!$A:$A,'WTG Reactive Power'!$AE:$AE))/Table13[[#This Row],[Gen_Exp (kWh)]],"") -> 0.003279936 | AP12: =IFERROR(_xlfn.XLOOKUP($D12,'Modelling New'!$D:$D,'Modelling New'!$AK:$AK),"") -> 0.05 | AQ12: =IFERROR(_xlfn.XLOOKUP($D12,'Modelling New'!$D:$D,'Modelling New'!$AL:$AL),"") -> 0.05 | AR12: =IFERROR(_xlfn.XLOOKUP($D12,'Modelling New'!$D:$D,'Modelling New'!$N:$N),"") -> 70.2
A13: =A12+1 -> 45756 | B13: =YEAR(Table13[[#This Row],[Date]])+IF(MONTH(Table13[[#This Row],[Date]])>=4,1,0) -> 2026 | C13: =YEAR(Table13[[#This Row],[Date]]) -> 2025 | D13: =Table13[[#This Row],[Date]]-DAY(Table13[[#This Row],[Date]])+1 -> 45748 | E13: =DAY(EOMONTH(A13,0)) -> 30 | M13: =IFERROR(_xlfn.XLOOKUP($A13,Input_Raw!$A:$A,Input_Raw!BG:BG),"") -> 7.08996 | N13: =IFERROR(_xlfn.XLOOKUP($A13,Input_Raw!$A:$A,Input_Raw!BH:BH),"") -> 0 | O13: =IFERROR(P13*Q13,"") -> 0.98745154 | P13: =IFERROR(1-SUMIF(WTG_BD!$F:$F,$A13,WTG_BD!$AA:$AA)/($AA13+SUMIF(WTG_BD!$F:$F,$A13,WTG_BD!$AA:$AA)),"") -> 0.98745154 | Q13: =IFERROR(1-SUMIF(IGA_BD!$F:$F,$A13,IGA_BD!$X:$X)/($AA13+SUMIF(IGA_BD!$F:$F,$A13,IGA_BD!$X:$X)),"") -> 1 | R13: =IFERROR(1-SUMIF(Grid_BD!$F:$F,$A13,Grid_BD!$Y:$Y)/($AA13+SUMIF(Grid_BD!$F:$F,$A13,Grid_BD!$Y:$Y)),"") -> 1 | W13: =IFERROR(AA13/(24*AR13*1000),"") -> 0.44070513 | X13: =IFERROR(_xlfn.XLOOKUP($A13,Input_Raw!$A:$A,Input_Raw!$BF:$BF),"") -> 766278 | Y13: =IFERROR(_xlfn.XLOOKUP($A13,Input_Raw!$A:$A,Input_Raw!BJ:BJ),"") -> 742500 | Z13: =IFERROR(_xlfn.XLOOKUP($A13,Input_Raw!$A:$A,Input_Raw!BK:BK),"") -> 0 | AA13: =IFERROR(_xlfn.XLOOKUP($A13,Input_Raw!$A:$A,Input_Raw!BL:BL),"") -> 742500 | AB13: =IFERROR(_xlfn.XLOOKUP($A13,Input_Raw!$A:$A,Input_Raw!$BO:$BO),"") -> 70.2 | AC13: =IFERROR(_xlfn.XLOOKUP($D13,'Modelling New'!$D:$D,'Modelling New'!$J:$J),"") -> 6.65 | AD13: =IFERROR(_xlfn.XLOOKUP($D13,'Modelling New'!$D:$D,'Modelling New'!$T:$T)*1000,"") -> 697760.54 | AF13: =IFERROR(_xlfn.XLOOKUP($D13,'Modelling New'!$D:$D,'Modelling New'!$W:$W),"") -> 0.41415037 | AG13: =IFERROR(_xlfn.XLOOKUP($D13,'Modelling New'!$D:$D,'Modelling New'!$AE:$AE),"") -> 0.9603 | AH13: =IFERROR(_xlfn.XLOOKUP($D13,'Modelling New'!$D:$D,'Modelling New'!$AF:$AF),"") -> 0.995 | AI13: =IFERROR(_xlfn.XLOOKUP($A13,Input_Raw!$A:$A,Input_Raw!$BQ:$BQ),"") -> 808 | AN13: =IFERROR(_xlfn.XLOOKUP($A13,Input_Raw!$A:$A,Input_Raw!$BN:$BN),"") -> 0.031030514 | AO13: =IFERROR((_xlfn.XLOOKUP($A13,'WTG Reactive Power'!$A:$A,'WTG Reactive Power'!$AE:$AE))/Table13[[#This Row],[Gen_Exp (kWh)]],"") -> 0.0035233166 | AP13: =IFERROR(_xlfn.XLOOKUP($D13,'Modelling New'!$D:$D,'Modelling New'!$AK:$AK),"") -> 0.05 | AQ13: =IFERROR(_xlfn.XLOOKUP($D13,'Modelling New'!$D:$D,'Modelling New'!$AL:$AL),"") -> 0.05 | AR13: =IFERROR(_xlfn.XLOOKUP($D13,'Modelling New'!$D:$D,'Modelling New'!$N:$N),"") -> 70.2
A14: =A13+1 -> 45757 | B14: =YEAR(Table13[[#This Row],[Date]])+IF(MONTH(Table13[[#This Row],[Date]])>=4,1,0) -> 2026 | C14: =YEAR(Table13[[#This Row],[Date]]) -> 2025 | D14: =Table13[[#This Row],[Date]]-DAY(Table13[[#This Row],[Date]])+1 -> 45748 | E14: =DAY(EOMONTH(A14,0)) -> 30 | M14: =IFERROR(_xlfn.XLOOKUP($A14,Input_Raw!$A:$A,Input_Raw!BG:BG),"") -> 8.2136084 | N14: =IFERROR(_xlfn.XLOOKUP($A14,Input_Raw!$A:$A,Input_Raw!BH:BH),"") -> 0 | O14: =IFERROR(P14*Q14,"") -> 0.98076312 | P14: =IFERROR(1-SUMIF(WTG_BD!$F:$F,$A14,WTG_BD!$AA:$AA)/($AA14+SUMIF(WTG_BD!$F:$F,$A14,WTG_BD!$AA:$AA)),"") -> 0.98076312 | Q14: =IFERROR(1-SUMIF(IGA_BD!$F:$F,$A14,IGA_BD!$X:$X)/($AA14+SUMIF(IGA_BD!$F:$F,$A14,IGA_BD!$X:$X)),"") -> 1 | R14: =IFERROR(1-SUMIF(Grid_BD!$F:$F,$A14,Grid_BD!$Y:$Y)/($AA14+SUMIF(Grid_BD!$F:$F,$A14,Grid_BD!$Y:$Y)),"") -> 1 | W14: =IFERROR(AA14/(24*AR14*1000),"") -> 0.57852564 | X14: =IFERROR(_xlfn.XLOOKUP($A14,Input_Raw!$A:$A,Input_Raw!$BF:$BF),"") -> 1006142 | Y14: =IFERROR(_xlfn.XLOOKUP($A14,Input_Raw!$A:$A,Input_Raw!BJ:BJ),"") -> 974700 | Z14: =IFERROR(_xlfn.XLOOKUP($A14,Input_Raw!$A:$A,Input_Raw!BK:BK),"") -> 0 | AA14: =IFERROR(_xlfn.XLOOKUP($A14,Input_Raw!$A:$A,Input_Raw!BL:BL),"") -> 974700 | AB14: =IFERROR(_xlfn.XLOOKUP($A14,Input_Raw!$A:$A,Input_Raw!$BO:$BO),"") -> 70.2 | AC14: =IFERROR(_xlfn.XLOOKUP($D14,'Modelling New'!$D:$D,'Modelling New'!$J:$J),"") -> 6.65 | AD14: =IFERROR(_xlfn.XLOOKUP($D14,'Modelling New'!$D:$D,'Modelling New'!$T:$T)*1000,"") -> 697760.54 | AF14: =IFERROR(_xlfn.XLOOKUP($D14,'Modelling New'!$D:$D,'Modelling New'!$W:$W),"") -> 0.41415037 | AG14: =IFERROR(_xlfn.XLOOKUP($D14,'Modelling New'!$D:$D,'Modelling New'!$AE:$AE),"") -> 0.9603 | AH14: =IFERROR(_xlfn.XLOOKUP($D14,'Modelling New'!$D:$D,'Modelling New'!$AF:$AF),"") -> 0.995 | AI14: =IFERROR(_xlfn.XLOOKUP($A14,Input_Raw!$A:$A,Input_Raw!$BQ:$BQ),"") -> 1103.33 | AN14: =IFERROR(_xlfn.XLOOKUP($A14,Input_Raw!$A:$A,Input_Raw!$BN:$BN),"") -> 0.031250062 | AO14: =IFERROR((_xlfn.XLOOKUP($A14,'WTG Reactive Power'!$A:$A,'WTG Reactive Power'!$AE:$AE))/Table13[[#This Row],[Gen_Exp (kWh)]],"") -> 0.016548241 | AP14: =IFERROR(_xlfn.XLOOKUP($D14,'Modelling New'!$D:$D,'Modelling New'!$AK:$AK),"") -> 0.05 | AQ14: =IFERROR(_xlfn.XLOOKUP($D14,'Modelling New'!$D:$D,'Modelling New'!$AL:$AL),"") -> 0.05 | AR14: =IFERROR(_xlfn.XLOOKUP($D14,'Modelling New'!$D:$D,'Modelling New'!$N:$N),"") -> 70.2
... A369: =A368+1 -> 46112 | B369: =YEAR(Table13[[#This Row],[Date]])+IF(MONTH(Table13[[#This Row],[Date]])>=4,1,0) -> 2026 | C369: =YEAR(Table13[[#This Row],[Date]]) -> 2026 | D369: =Table13[[#This Row],[Date]]-DAY(Table13[[#This Row],[Date]])+1 -> 46082 | E369: =DAY(EOMONTH(A369,0)) -> 31 | M369: =IFERROR(_xlfn.XLOOKUP($A369,Input_Raw!$A:$A,Input_Raw!BG:BG),"") | N369: =IFERROR(_xlfn.XLOOKUP($A369,Input_Raw!$A:$A,Input_Raw!BH:BH),"") | O369: =IFERROR(P369*Q369,"") | P369: =IFERROR(1-SUMIF(WTG_BD!$F:$F,$A369,WTG_BD!$AA:$AA)/($AA369+SUMIF(WTG_BD!$F:$F,$A369,WTG_BD!$AA:$AA)),"") | Q369: =IFERROR(1-SUMIF(IGA_BD!$F:$F,$A369,IGA_BD!$X:$X)/($AA369+SUMIF(IGA_BD!$F:$F,$A369,IGA_BD!$X:$X)),"") | R369: =IFERROR(1-SUMIF(Grid_BD!$F:$F,$A369,Grid_BD!$Y:$Y)/($AA369+SUMIF(Grid_BD!$F:$F,$A369,Grid_BD!$Y:$Y)),"") | W369: =IFERROR(AA369/(24*AR369*1000),"") | X369: =IFERROR(_xlfn.XLOOKUP($A369,Input_Raw!$A:$A,Input_Raw!$BF:$BF),"") | Y369: =IFERROR(_xlfn.XLOOKUP($A369,Input_Raw!$A:$A,Input_Raw!BJ:BJ),"") | Z369: =IFERROR(_xlfn.XLOOKUP($A369,Input_Raw!$A:$A,Input_Raw!BK:BK),"") | AA369: =IFERROR(_xlfn.XLOOKUP($A369,Input_Raw!$A:$A,Input_Raw!BL:BL),"") | AB369: =IFERROR(_xlfn.XLOOKUP($A369,Input_Raw!$A:$A,Input_Raw!$BO:$BO),"") | AC369: =IFERROR(_xlfn.XLOOKUP($D369,'Modelling New'!$D:$D,'Modelling New'!$J:$J),"") -> 6.89 | AD369: =IFERROR(_xlfn.XLOOKUP($D369,'Modelling New'!$D:$D,'Modelling New'!$T:$T)*1000,"") -> 629607.19 | AF369: =IFERROR(_xlfn.XLOOKUP($D369,'Modelling New'!$D:$D,'Modelling New'!$W:$W),"") -> 0.37369847 | AG369: =IFERROR(_xlfn.XLOOKUP($D369,'Modelling New'!$D:$D,'Modelling New'!$AE:$AE),"") -> 0.9603 | AH369: =IFERROR(_xlfn.XLOOKUP($D369,'Modelling New'!$D:$D,'Modelling New'!$AF:$AF),"") -> 0.995 | AI369: =IFERROR(_xlfn.XLOOKUP($A369,Input_Raw!$A:$A,Input_Raw!$BQ:$BQ),"") | AN369: =IFERROR(_xlfn.XLOOKUP($A369,Input_Raw!$A:$A,Input_Raw!$BN:$BN),"") | AO369: =IFERROR((_xlfn.XLOOKUP($A369,'WTG Reactive Power'!$A:$A,'WTG Reactive Power'!$AE:$AE))/Table13[[#This Row],[Gen_Exp (kWh)]],"") | AP369: =IFERROR(_xlfn.XLOOKUP($D369,'Modelling New'!$D:$D,'Modelling New'!$AK:$AK),"") -> 0.05 | AQ369: =IFERROR(_xlfn.XLOOKUP($D369,'Modelling New'!$D:$D,'Modelling New'!$AL:$AL),"") -> 0.05 | AR369: =IFERROR(_xlfn.XLOOKUP($D369,'Modelling New'!$D:$D,'Modelling New'!$N:$N),"") -> 70.2

Sheet AnnualKPI
A1: Till Date | B1: =O2Summary!B4 -> 45861 | C1: =O2Summary!$B$3 -> 45839
A2: TGPXIIPL Performance Summary-YTD
A3: Year | B3: Days | C3: Estimated WS(m/s) | D3: Measured WS (m/s) | E3: Budgeted Energy (MWh) | F3: Measured Energy (MWh) | G3: Target CUF (%) | H3: Measured CUF (%) | I3: Target GA (%) | J3: Measured GA (%) | K3: Target MA (%) | L3: Measured MA (%) | M3: Target IGA(%) | N3: Measured IGA (%) | O3: Target PA(%) | P3: Measured PA (%) | Q3: Expected Energy | R3: Loss (%) | S3: Reactive Power (%)
A4: =YEAR(B1)+IF(MONTH(B1)>=4,1,0) -> 2026 | B4: =$B$1-(O2Summary!$B$6)+1 -> 114 | C4: =_xlfn.XLOOKUP($C$1,'Modelling New'!$D:$D,'Modelling New'!$AD:$AD) -> 7.2925 | D4: =AVERAGEIFS('Daily KPI'!$M:$M,'Daily KPI'!$A:$A,">="&O2Summary!$B$6,'Daily KPI'!$A:$A,"<="&AnnualKPI!$B$1) -> 6.791176 | E4: =_xlfn.XLOOKUP($C$1,'Modelling New'!$D:$D,'Modelling New'!$V:$V) -> 95320.581 | F4: =SUMIFS('Daily KPI'!$AA:$AA,'Daily KPI'!$A:$A,">="&O2Summary!$B$6,'Daily KPI'!$A:$A,"<="&AnnualKPI!$B$1)/1000 -> 78096.6 | G4: =_xlfn.XLOOKUP($C$1,'Modelling New'!$D:$D,'Modelling New'!$Y:$Y) -> 0.49628766 | H4: =IFERROR(F4/(B4*24*(_xlfn.XLOOKUP($B$1,'Daily KPI'!$A:$A,'Daily KPI'!$AR:$AR))),"") -> 0.40661081 | I4: =_xlfn.XLOOKUP($C$1,'Modelling New'!$D:$D,'Modelling New'!$AF:$AF) -> 0.995 | J4: =AVERAGEIFS('Daily KPI'!$R:$R,'Daily KPI'!$A:$A,">="&O2Summary!$B$6,'Daily KPI'!$A:$A,"<="&AnnualKPI!$B$1) -> 1 | K4: =_xlfn.XLOOKUP($C$1,'Modelling New'!$D:$D,'Modelling New'!$AH:$AH) -> 0.97 | L4: =AVERAGEIFS('Daily KPI'!$P:$P,'Daily KPI'!$A:$A,">="&O2Summary!$B$6,'Daily KPI'!$A:$A,"<="&AnnualKPI!$B$1) -> 0.97016667 | M4: =_xlfn.XLOOKUP($C$1,'Modelling New'!$D:$D,'Modelling New'!$AI:$AI) -> 0.99 | N4: =AVERAGEIFS('Daily KPI'!$Q:$Q,'Daily KPI'!$A:$A,">="&O2Summary!$B$6,'Daily KPI'!$A:$A,"<="&AnnualKPI!$B$1) -> 0.97397844 | O4: =K4*M4 -> 0.9603 | P4: =L4*N4 -> 0.94492141 | Q4: =SUMIFS('Daily KPI'!$AI:$AI,'Daily KPI'!$D:$D,">="&O2Summary!$B$6,'Daily KPI'!$A:$A,"<="&AnnualKPI!$B$1) -> 84876.064 | R4: =IFERROR(AVERAGEIFS('Daily KPI'!$AN:$AN,'Daily KPI'!$D:$D,O2Summary!$B$6,'Daily KPI'!$A:$A,"<="&AnnualKPI!$B$1),"") -> 0.034314259 | S4: =IFERROR(AVERAGEIFS('Daily KPI'!$AO:$AO,'Daily KPI'!$D:$D,O2Summary!$B$6,'Daily KPI'!$A:$A,"<="&AnnualKPI!$B$1),"") -> 0.0079531024

Sheet Analytices
A2: Start Date | B2: =O2Summary!B3 -> 45839
A3: End Date | B3: =O2Summary!B4 -> 45861 | C3: =((B3-B2)+1)*24 -> 552 | D3: =MEDIAN(B21:AA21) -> 6.5
A4: WTG No. | B4: O2_01 | C4: O2_02 | D4: O2_03 | E4: O2_04 | F4: O2_05 | G4: O2_06 | H4: O2_07 | I4: O2_08 | J4: O2_09 | K4: O2_10 | L4: O2_11 | M4: O2_12 | N4: O2_13 | O4: O2_14 | P4: O2_15 | Q4: O2_16 | R4: O2_17 | S4: O2_18 | T4: O2_19 | U4: O2_20 | V4: O2_21 | W4: O2_22 | X4: O2_23 | Y4: O2_24 | Z4: O2_25 | AA4: O2_26
A5: MA | B5: =IFERROR(($C$3-B6)/$C$3,1) -> 0.99978865 | C5: =IFERROR(($C$3-C6)/$C$3,1) -> 0.99978865 | D5: =IFERROR(($C$3-D6)/$C$3,1) -> 0.99978865 | E5: =IFERROR(($C$3-E6)/$C$3,1) -> 0.99978865 | F5: =IFERROR(($C$3-F6)/$C$3,1) -> 0.99978865 | G5: =IFERROR(($C$3-G6)/$C$3,1) -> 0.99978865 | H5: =IFERROR(($C$3-H6)/$C$3,1) -> 0.99978865 | I5: =IFERROR(($C$3-I6)/$C$3,1) -> 0.99978865 | ... AA5: =IFERROR(($C$3-AA6)/$C$3,1) -> 0.99978865
A6: WTG BD Hours | B6: =SUMIFS(WTG_BD!$T:$T,WTG_BD!$F:$F,">="&Analytices!$B$2,WTG_BD!$F:$F,"<="&Analytices!$B$3,WTG_BD!$G:$G,$B$4) -> 0.11666667 | C6: =SUMIFS(WTG_BD!$T:$T,WTG_BD!$F:$F,">="&Analytices!$B$2,WTG_BD!$F:$F,"<="&Analytices!$B$3,WTG_BD!$G:$G,$B$4) -> 0.11666667 | D6: =SUMIFS(WTG_BD!$T:$T,WTG_BD!$F:$F,">="&Analytices!$B$2,WTG_BD!$F:$F,"<="&Analytices!$B$3,WTG_BD!$G:$G,$B$4) -> 0.11666667 | E6: =SUMIFS(WTG_BD!$T:$T,WTG_BD!$F:$F,">="&Analytices!$B$2,WTG_BD!$F:$F,"<="&Analytices!$B$3,WTG_BD!$G:$G,$B$4) -> 0.11666667 | F6: =SUMIFS(WTG_BD!$T:$T,WTG_BD!$F:$F,">="&Analytices!$B$2,WTG_BD!$F:$F,"<="&Analytices!$B$3,WTG_BD!$G:$G,$B$4) -> 0.11666667 | G6: =SUMIFS(WTG_BD!$T:$T,WTG_BD!$F:$F,">="&Analytices!$B$2,WTG_BD!$F:$F,"<="&Analytices!$B$3,WTG_BD!$G:$G,$B$4) -> 0.11666667 | H6: =SUMIFS(WTG_BD!$T:$T,WTG_BD!$F:$F,">="&Analytices!$B$2,WTG_BD!$F:$F,"<="&Analytices!$B$3,WTG_BD!$G:$G,$B$4) -> 0.11666667 | I6: =SUMIFS(WTG_BD!$T:$T,WTG_BD!$F:$F,">="&Analytices!$B$2,WTG_BD!$F:$F,"<="&Analytices!$B$3,WTG_BD!$G:$G,$B$4) -> 0.11666667 | ... AA6: =SUMIFS(WTG_BD!$T:$T,WTG_BD!$F:$F,">="&Analytices!$B$2,WTG_BD!$F:$F,"<="&Analytices!$B$3,WTG_BD!$G:$G,$B$4) -> 0.11666667
A7: IGA | B7: =($C$3-SUM(B8:B12))/$C$3 -> 0.99544082 | C7: =($C$3-SUM(C8:C12))/$C$3 -> 0.99544082 | D7: =($C$3-SUM(D8:D12))/$C$3 -> 0.99544082 | E7: =($C$3-SUM(E8:E12))/$C$3 -> 0.9986413 | F7: =($C$3-SUM(F8:F12))/$C$3 -> 0.99544082 | G7: =($C$3-SUM(G8:G12))/$C$3 -> 0.9986413 | H7: =($C$3-SUM(H8:H12))/$C$3 -> 0.9986413 | I7: =($C$3-SUM(I8:I12))/$C$3 -> 0.9986413 | ... AA7: =($C$3-SUM(AA8:AA12))/$C$3 -> 0.9986413
A8: METERING YARD
A9: FEEDER | B9: =SUMIFS(IGA_BD!$Q:$Q,IGA_BD!$G:$G,(VLOOKUP(B$4,'Basic Data'!$A:$F,6,0)),IGA_BD!$F:$F,">="&Analytices!$B$2,IGA_BD!$F:$F,"<="&Analytices!$B$3) -> 2.5166667 | C9: =SUMIFS(IGA_BD!$Q:$Q,IGA_BD!$G:$G,(VLOOKUP(C$4,'Basic Data'!$A:$F,6,0)),IGA_BD!$F:$F,">="&Analytices!$B$2,IGA_BD!$F:$F,"<="&Analytices!$B$3) -> 2.5166667 | D9: =SUMIFS(IGA_BD!$Q:$Q,IGA_BD!$G:$G,(VLOOKUP(D$4,'Basic Data'!$A:$F,6,0)),IGA_BD!$F:$F,">="&Analytices!$B$2,IGA_BD!$F:$F,"<="&Analytices!$B$3) -> 2.5166667 | E9: =SUMIFS(IGA_BD!$Q:$Q,IGA_BD!$G:$G,(VLOOKUP(E$4,'Basic Data'!$A:$F,6,0)),IGA_BD!$F:$F,">="&Analytices!$B$2,IGA_BD!$F:$F,"<="&Analytices!$B$3) -> 0.75 | F9: =SUMIFS(IGA_BD!$Q:$Q,IGA_BD!$G:$G,(VLOOKUP(F$4,'Basic Data'!$A:$F,6,0)),IGA_BD!$F:$F,">="&Analytices!$B$2,IGA_BD!$F:$F,"<="&Analytices!$B$3) -> 2.5166667 | G9: =SUMIFS(IGA_BD!$Q:$Q,IGA_BD!$G:$G,(VLOOKUP(G$4,'Basic Data'!$A:$F,6,0)),IGA_BD!$F:$F,">="&Analytices!$B$2,IGA_BD!$F:$F,"<="&Analytices!$B$3) -> 0.75 | H9: =SUMIFS(IGA_BD!$Q:$Q,IGA_BD!$G:$G,(VLOOKUP(H$4,'Basic Data'!$A:$F,6,0)),IGA_BD!$F:$F,">="&Analytices!$B$2,IGA_BD!$F:$F,"<="&Analytices!$B$3) -> 0.75 | I9: =SUMIFS(IGA_BD!$Q:$Q,IGA_BD!$G:$G,(VLOOKUP(I$4,'Basic Data'!$A:$F,6,0)),IGA_BD!$F:$F,">="&Analytices!$B$2,IGA_BD!$F:$F,"<="&Analytices!$B$3) -> 0.75 | ... AA9: =SUMIFS(IGA_BD!$Q:$Q,IGA_BD!$G:$G,(VLOOKUP(AA$4,'Basic Data'!$A:$F,6,0)),IGA_BD!$F:$F,">="&Analytices!$B$2,IGA_BD!$F:$F,"<="&Analytices!$B$3) -> 0.75
A10: OG
A11: TRANSFER | B11: =SUMIFS(Grid_BD!$R:$R,Grid_BD!$G:$G,(VLOOKUP(B$4,'Basic Data'!$A:$G,7,0)),Grid_BD!$F:$F,">="&Analytices!$B$2,Grid_BD!$F:$F,"<="&Analytices!$B$3) -> 0 | C11: =SUMIFS(Grid_BD!$R:$R,Grid_BD!$G:$G,(VLOOKUP(C$4,'Basic Data'!$A:$G,7,0)),Grid_BD!$F:$F,">="&Analytices!$B$2,Grid_BD!$F:$F,"<="&Analytices!$B$3) -> 0 | D11: =SUMIFS(Grid_BD!$R:$R,Grid_BD!$G:$G,(VLOOKUP(D$4,'Basic Data'!$A:$G,7,0)),Grid_BD!$F:$F,">="&Analytices!$B$2,Grid_BD!$F:$F,"<="&Analytices!$B$3) -> 0 | E11: =SUMIFS(Grid_BD!$R:$R,Grid_BD!$G:$G,(VLOOKUP(E$4,'Basic Data'!$A:$G,7,0)),Grid_BD!$F:$F,">="&Analytices!$B$2,Grid_BD!$F:$F,"<="&Analytices!$B$3) -> 0 | F11: =SUMIFS(Grid_BD!$R:$R,Grid_BD!$G:$G,(VLOOKUP(F$4,'Basic Data'!$A:$G,7,0)),Grid_BD!$F:$F,">="&Analytices!$B$2,Grid_BD!$F:$F,"<="&Analytices!$B$3) -> 0 | G11: =SUMIFS(Grid_BD!$R:$R,Grid_BD!$G:$G,(VLOOKUP(G$4,'Basic Data'!$A:$G,7,0)),Grid_BD!$F:$F,">="&Analytices!$B$2,Grid_BD!$F:$F,"<="&Analytices!$B$3) -> 0 | H11: =SUMIFS(Grid_BD!$R:$R,Grid_BD!$G:$G,(VLOOKUP(H$4,'Basic Data'!$A:$G,7,0)),Grid_BD!$F:$F,">="&Analytices!$B$2,Grid_BD!$F:$F,"<="&Analytices!$B$3) -> 0 | I11: =SUMIFS(Grid_BD!$R:$R,Grid_BD!$G:$G,(VLOOKUP(I$4,'Basic Data'!$A:$G,7,0)),Grid_BD!$F:$F,">="&Analytices!$B$2,Grid_BD!$F:$F,"<="&Analytices!$B$3) -> 0 | ... AA11: =SUMIFS(Grid_BD!$R:$R,Grid_BD!$G:$G,(VLOOKUP(AA$4,'Basic Data'!$A:$G,7,0)),Grid_BD!$F:$F,">="&Analytices!$B$2,Grid_BD!$F:$F,"<="&Analytices!$B$3) -> 0
A12: USS
A13: EGA | B13: =(C3-B14)/C3 -> 1 | C13: =$B$13 -> 1 | D13: =$B$13 -> 1 | E13: =$B$13 -> 1 | F13: =$B$13 -> 1 | G13: =$B$13 -> 1 | H13: =$B$13 -> 1 | I13: =$B$13 -> 1 | J13: =$B$13 -> 1 | ... AA13: =$B$13 -> 1
A14: External Grid | B14: =(SUMIFS(Grid_BD!$R:$R,Grid_BD!$F:$F,">="&Analytices!B2,Grid_BD!$F:$F,"<="&Analytices!B3,Grid_BD!$G:$G,"Line1")) -> 0 | C14: =$B$14 -> 0 | D14: =$B$14 -> 0 | E14: =$B$14 -> 0 | F14: =$B$14 -> 0 | G14: =$B$14 -> 0 | H14: =$B$14 -> 0 | I14: =$B$14 -> 0 | J14: =$B$14 -> 0 | ... AA14: =$B$14 -> 0
A15: Generation | B15: =SUMIFS(Input_Raw!F:F,Input_Raw!$A:$A,">="&Analytices!$B$2,Input_Raw!$A:$A,"<="&Analytices!$B$3) -> 538202 | C15: =SUMIFS(Input_Raw!G:G,Input_Raw!$A:$A,">="&Analytices!$B$2,Input_Raw!$A:$A,"<="&Analytices!$B$3) -> 584367 | D15: =SUMIFS(Input_Raw!H:H,Input_Raw!$A:$A,">="&Analytices!$B$2,Input_Raw!$A:$A,"<="&Analytices!$B$3) -> 546143 | E15: =SUMIFS(Input_Raw!I:I,Input_Raw!$A:$A,">="&Analytices!$B$2,Input_Raw!$A:$A,"<="&Analytices!$B$3) -> 559671 | F15: =SUMIFS(Input_Raw!J:J,Input_Raw!$A:$A,">="&Analytices!$B$2,Input_Raw!$A:$A,"<="&Analytices!$B$3) -> 575622 | G15: =SUMIFS(Input_Raw!K:K,Input_Raw!$A:$A,">="&Analytices!$B$2,Input_Raw!$A:$A,"<="&Analytices!$B$3) -> 604758 | H15: =SUMIFS(Input_Raw!L:L,Input_Raw!$A:$A,">="&Analytices!$B$2,Input_Raw!$A:$A,"<="&Analytices!$B$3) -> 545662 | I15: =SUMIFS(Input_Raw!M:M,Input_Raw!$A:$A,">="&Analytices!$B$2,Input_Raw!$A:$A,"<="&Analytices!$B$3) -> 568099 | J15: =SUMIFS(Input_Raw!N:N,Input_Raw!$A:$A,">="&Analytices!$B$2,Input_Raw!$A:$A,"<="&Analytices!$B$3) -> 549901 | K15: =SUMIFS(Input_Raw!O:O,Input_Raw!$A:$A,">="&Analytices!$B$2,Input_Raw!$A:$A,"<="&Analytices!$B$3) -> 569256 | L15: =SUMIFS(Input_Raw!P:P,Input_Raw!$A:$A,">="&Analytices!$B$2,Input_Raw!$A:$A,"<="&Analytices!$B$3) -> 537635 | M15: =SUMIFS(Input_Raw!Q:Q,Input_Raw!$A:$A,">="&Analytices!$B$2,Input_Raw!$A:$A,"<="&Analytices!$B$3) -> 354138 | N15: =SUMIFS(Input_Raw!R:R,Input_Raw!$A:$A,">="&Analytices!$B$2,Input_Raw!$A:$A,"<="&Analytices!$B$3) -> 546641 | O15: =SUMIFS(Input_Raw!S:S,Input_Raw!$A:$A,">="&Analytices!$B$2,Input_Raw!$A:$A,"<="&Analytices!$B$3) -> 562653 | P15: =SUMIFS(Input_Raw!T:T,Input_Raw!$A:$A,">="&Analytices!$B$2,Input_Raw!$A:$A,"<="&Analytices!$B$3) -> 543802 | Q15: =SUMIFS(Input_Raw!U:U,Input_Raw!$A:$A,">="&Analytices!$B$2,Input_Raw!$A:$A,"<="&Analytices!$B$3) -> 575628 | R15: =SUMIFS(Input_Raw!V:V,Input_Raw!$A:$A,">="&Analytices!$B$2,Input_Raw!$A:$A,"<="&Analytices!$B$3) -> 633712 | S15: =SUMIFS(Input_Raw!W:W,Input_Raw!$A:$A,">="&Analytices!$B$2,Input_Raw!$A:$A,"<="&Analytices!$B$3) -> 582491 | T15: =SUMIFS(Input_Raw!X:X,Input_Raw!$A:$A,">="&Analytices!$B$2,Input_Raw!$A:$A,"<="&Analytices!$B$3) -> 625710 | U15: =SUMIFS(Input_Raw!Y:Y,Input_Raw!$A:$A,">="&Analytices!$B$2,Input_Raw!$A:$A,"<="&Analytices!$B$3) -> 420435 | V15: =SUMIFS(Input_Raw!Z:Z,Input_Raw!$A:$A,">="&Analytices!$B$2,Input_Raw!$A:$A,"<="&Analytices!$B$3) -> 601585 | W15: =SUMIFS(Input_Raw!AA:AA,Input_Raw!$A:$A,">="&Analytices!$B$2,Input_Raw!$A:$A,"<="&Analytices!$B$3) -> 581579 | X15: =SUMIFS(Input_Raw!AB:AB,Input_Raw!$A:$A,">="&Analytices!$B$2,Input_Raw!$A:$A,"<="&Analytices!$B$3) -> 559900 | Y15: =SUMIFS(Input_Raw!AC:AC,Input_Raw!$A:$A,">="&Analytices!$B$2,Input_Raw!$A:$A,"<="&Analytices!$B$3) -> 599982 | Z15: =SUMIFS(Input_Raw!AD:AD,Input_Raw!$A:$A,">="&Analytices!$B$2,Input_Raw!$A:$A,"<="&Analytices!$B$3) -> 612784 | AA15: =SUMIFS(Input_Raw!AE:AE,Input_Raw!$A:$A,">="&Analytices!$B$2,Input_Raw!$A:$A,"<="&Analytices!$B$3) -> 563406
A16: PA | B16: =IFERROR(($C$3-(SUM(B8:B12,B14,B6)))/$C$3,1) -> 0.99522947 | C16: =IFERROR(($C$3-(SUM(C8:C12,C14,C6)))/$C$3,1) -> 0.99522947 | D16: =IFERROR(($C$3-(SUM(D8:D12,D14,D6)))/$C$3,1) -> 0.99522947 | E16: =IFERROR(($C$3-(SUM(E8:E12,E14,E6)))/$C$3,1) -> 0.99842995 | F16: =IFERROR(($C$3-(SUM(F8:F12,F14,F6)))/$C$3,1) -> 0.99522947 | G16: =IFERROR(($C$3-(SUM(G8:G12,G14,G6)))/$C$3,1) -> 0.99842995 | H16: =IFERROR(($C$3-(SUM(H8:H12,H14,H6)))/$C$3,1) -> 0.99842995 | I16: =IFERROR(($C$3-(SUM(I8:I12,I14,I6)))/$C$3,1) -> 0.99842995 | ... AA16: =IFERROR(($C$3-(SUM(AA8:AA12,AA14,AA6)))/$C$3,1) -> 0.99842995
A17: Sum of BD | B17: =SUMIFS(WTG_BD!$T:$T,WTG_BD!$F:$F,">="&Analytices!$B$2,WTG_BD!$F:$F,"<="&Analytices!$B$3,WTG_BD!$G:$G,B4) -> 0.11666667 | C17: =SUMIFS(WTG_BD!$T:$T,WTG_BD!$F:$F,">="&Analytices!$B$2,WTG_BD!$F:$F,"<="&Analytices!$B$3,WTG_BD!$G:$G,C4) -> 14.166667 | D17: =SUMIFS(WTG_BD!$T:$T,WTG_BD!$F:$F,">="&Analytices!$B$2,WTG_BD!$F:$F,"<="&Analytices!$B$3,WTG_BD!$G:$G,D4) -> 15.15 | E17: =SUMIFS(WTG_BD!$T:$T,WTG_BD!$F:$F,">="&Analytices!$B$2,WTG_BD!$F:$F,"<="&Analytices!$B$3,WTG_BD!$G:$G,E4) -> 6.35 | F17: =SUMIFS(WTG_BD!$T:$T,WTG_BD!$F:$F,">="&Analytices!$B$2,WTG_BD!$F:$F,"<="&Analytices!$B$3,WTG_BD!$G:$G,F4) -> 3.2166667 | G17: =SUMIFS(WTG_BD!$T:$T,WTG_BD!$F:$F,">="&Analytices!$B$2,WTG_BD!$F:$F,"<="&Analytices!$B$3,WTG_BD!$G:$G,G4) -> 10.133333 | H17: =SUMIFS(WTG_BD!$T:$T,WTG_BD!$F:$F,">="&Analytices!$B$2,WTG_BD!$F:$F,"<="&Analytices!$B$3,WTG_BD!$G:$G,H4) -> 5.8833333 | I17: =SUMIFS(WTG_BD!$T:$T,WTG_BD!$F:$F,">="&Analytices!$B$2,WTG_BD!$F:$F,"<="&Analytices!$B$3,WTG_BD!$G:$G,I4) -> 3.1333333 | ... AA17: =SUMIFS(WTG_BD!$T:$T,WTG_BD!$F:$F,">="&Analytices!$B$2,WTG_BD!$F:$F,"<="&Analytices!$B$3,WTG_BD!$G:$G,AA4) -> 4.7666667
