Workbook
Name BD_Relation: [1]Basic_Data!$B$3:$B$14
Name Date: [1]Basic_Data!$D$3:$D$33
Name dccap: [2]DGR!$D$7:$D$14
Name Digos: '[3]Basic Data'!#REF!
Name engg: [1]Basic_Data!$L$3:$L$16
Name Equipment: [1]Basic_Data!$F$3:$F$5
Name error: [1]Basic_Data!$M$3:$M$33
Name Gstc: #REF!
Name Gstc: #REF!
Name Gstc: #REF!
Name Gstc: #REF!
Name Gstc: #REF!
Name Inverter: [1]Basic_Data!$H$3:$H$8
Name invlook: [2]DGR!$B$7:$D$14
Name JB: [1]Basic_Data!$I$3:$I$68
Name jbp: [2]Basic_Data!$I$3:$J$66
Name P1_SnW4240: '[3]Basic Data'!#REF!
Name P1SnW4240: '[3]Basic Data'!#REF!
Name P1SnW51: '[3]Basic Data'!#REF!
Name P1SnW68: '[3]Basic Data'!#REF!
Name Pstc: #REF!
Name Pstc: #REF!
Name Pstc: #REF!
Name Pstc: #REF!
Name Pstc: #REF!
Name SCDA: '[3]Basic Data'!#REF!
Name SCDA: '[3]Basic Data'!#REF!
Name status: [1]Basic_Data!$K$3:$K$4
Name stp: [2]Basic_Data!$K$3:$L$32
Name String: [1]Basic_Data!$J$3:$J$1019
Name zzzzz: [4]Basic_Data!$F$3:$F$5

Sheet O2Summary
A2: Performance Summary PWEPL
A3: Month | B3: 45870
A4: Date | B4: 45871
A5: Financial Year | B5: Year-3
A6: Year Start Date | B6: 45748
A7: Year End Date | B7: 46112
A9: Sr. No. | B9: Particular | C9: Target | D9: Measured | E9: Deviation | F9: Remarks
A10: 1 | B10: E_Grid Daily (MWh) | C10: =IFERROR(_xlfn.XLOOKUP($B$4,'Daily KPI'!$A:$A,'Daily KPI'!$AD:$AD)/1000,"") -> 1057.4705 | D10: =IFERROR(_xlfn.XLOOKUP($B$4,'Daily KPI'!$A:$A,'Daily KPI'!$AA:$AA)/1000,"") -> 466.775 | E10: =D10/C10-1 -> -0.55859289
B11: E_Grid MTD(MWh) | C11: =MonthlyKPI!E4 -> 2114.941 | D11: =MonthlyKPI!F4 -> 1202.399 | E11: =D11/C11-1 -> -0.43147397
B12: E_Grid YTD (MWh) | C12: =AnnualKPI!E4 -> 63451.607 | D12: =AnnualKPI!F4 -> 80814.47 | E12: =D12/C12-1 -> 0.27363944
A13: 2 | B13: Wind Speed Daily | C13: =IFERROR(_xlfn.XLOOKUP($B$3,'Modelling New'!$D:$D,'Modelling New'!J:J),"") -> 9.1 | D13: =IFERROR(_xlfn.XLOOKUP($B$4,'Daily KPI'!$A:$A,'Daily KPI'!$M:$M),"") -> 6.5170455 | E13: =(D13-C13)/(C13) -> -0.28384116
B14: Wind Speed MTD | C14: =MonthlyKPI!C4 -> 9.1 | D14: =MonthlyKPI!D4 -> 7.0390909 | E14: =(D14-C14)/(C14) -> -0.22647353
B15: Wind Speed YTD | C15: =AnnualKPI!C4 -> 6.9174962 | D15: =AnnualKPI!D4 -> 7.3157625 | E15: =(D15-C15)/(C15) -> 0.05757376
A16: 3 | B16: PA Daily | C16: =IFERROR(_xlfn.XLOOKUP(B4,'Daily KPI'!$A:$A,'Daily KPI'!$AG:$AG),"") -> 0.9603 | D16: =IFERROR(_xlfn.XLOOKUP($B$4,'Daily KPI'!$A:$A,'Daily KPI'!O:O),"") -> 0.9991994 | E16: =(D16-C16)/(C16) -> 0.040507549
B17: PA MTD | C17: =IFERROR(_xlfn.XLOOKUP($B$3,'Modelling New'!$D:$D,'Modelling New'!AE:AE),"") -> 0.9603 | D17: =MonthlyKPI!P4 -> 0.99856869 | E17: =(D17-C17)/(C17) -> 0.039850769
B18: PA YTD | C18: =IFERROR(_xlfn.XLOOKUP($B$3,'Modelling New'!$D:$D,'Modelling New'!AE:AE),"") -> 0.9603 | D18: =AnnualKPI!P4 -> 0.97532798 | E18: =(D18-C18)/(C18) -> 0.015649257
A19: 4 | B19: EGA Daily | C19: =IFERROR(_xlfn.XLOOKUP(B7,'Daily KPI'!$A:$A,'Daily KPI'!$AH:$AH),"") -> 0.995 | D19: =IFERROR(_xlfn.XLOOKUP($B$4,'Daily KPI'!$A:$A,'Daily KPI'!$R:$R),"") -> 1 | E19: =(D19-C19)/(C19) -> 0.0050251256
B20: EGA MTD | C20: =IFERROR(_xlfn.XLOOKUP($B$3,'Modelling New'!$D:$D,'Modelling New'!$AF:$AF),"") -> 0.995 | D20: =MonthlyKPI!J4 -> 1 | E20: =(D20-C20)/(C20) -> 0.0050251256
B21: EGA YTD | C21: =IFERROR(_xlfn.XLOOKUP($B$3,'Modelling New'!$D:$D,'Modelling New'!$AF:$AF),"") -> 0.995 | D21: =AnnualKPI!J4 -> 0.9944601 | E21: =(D21-C21)/(C21) -> -0.00054261573
A22: 5 | B22: IGA Daily | C22: =IFERROR(_xlfn.XLOOKUP($B$3,'Modelling New'!$D:$D,'Modelling New'!$AI:$AI),"") -> 0.99 | D22: =IFERROR(_xlfn.XLOOKUP($B$4,'Daily KPI'!$A:$A,'Daily KPI'!Q:Q),"") -> 1 | E22: =(D22-C22)/(C22) -> 0.01010101
B23: IGA MTD | C23: =IFERROR(_xlfn.XLOOKUP($B$3,'Modelling New'!$D:$D,'Modelling New'!$AI:$AI),"") -> 0.99 | D23: =MonthlyKPI!N4 -> 1 | E23: =(D23-C23)/(C23) -> 0.01010101
B24: IGA YTD | C24: =IFERROR(_xlfn.XLOOKUP($B$3,'Modelling New'!$D:$D,'Modelling New'!$AI:$AI),"") -> 0.99 | D24: =AnnualKPI!N4 -> 0.98484246 | E24: =(D24-C24)/(C24) -> -0.0052096362
A25: 6 | B25: MA Daily | C25: =IFERROR(_xlfn.XLOOKUP($B$3,'Modelling New'!$D:$D,'Modelling New'!$AH:$AH),"") -> 0.97 | D25: =IFERROR(_xlfn.XLOOKUP($B$4,'Daily KPI'!$A:$A,'Daily KPI'!P:P),"") -> 0.9991994 | E25: =(D25-C25)/(C25) -> 0.030102473
B26: MA MTD | C26: =IFERROR(_xlfn.XLOOKUP($B$3,'Modelling New'!$D:$D,'Modelling New'!$AH:$AH),"") -> 0.97 | D26: =MonthlyKPI!N4 -> 1 | E26: =(D26-C26)/(C26) -> 0.030927835
B27: MA YTD | C27: =IFERROR(_xlfn.XLOOKUP($B$3,'Modelling New'!$D:$D,'Modelling New'!$AH:$AH),"") -> 0.97 | D27: =AnnualKPI!N4 -> 0.98484246 | E27: =(D27-C27)/(C27) -> 0.015301505
A28: 7 | B28: CUF Daily | C28: =IFERROR(_xlfn.XLOOKUP($B$3,'Modelling New'!$D:$D,'Modelling New'!$W:$W),"") -> 0.62587032 | D28: =IFERROR(_xlfn.XLOOKUP($B$4,'Daily KPI'!$A:$A,'Daily KPI'!$W:$W),"") -> 0.27626361 | E28: =(D28-C28)/(C28) -> -0.55859289
B29: CUF MTD | C29: =MonthlyKPI!$G$4 -> 0.62587032 | D29: =MonthlyKPI!$H$4 -> 0.35582357 | E29: =(D29-C29)/(C29) -> -0.43147397
B30: CUF YTD | C30: =AnnualKPI!$G$4 -> 0.3028566 | D30: =AnnualKPI!$H$4 -> 0.38573011 | E30: =(D30-C30)/(C30) -> 0.27363944
A31: 8 | B31: Line Loss Daily | C31: =_xlfn.XLOOKUP($B$3,'Modelling New'!$D:$D,'Modelling New'!AK:AK) -> 0.05 | D31: =_xlfn.XLOOKUP($B$4,'Daily KPI'!$A:$A,'Daily KPI'!$AN:$AN) -> 0 | E31: =-(D31-C31)/(C31) -> 1
B32: Line Loss MTD | C32: =_xlfn.XLOOKUP($B$3,'Modelling New'!$D:$D,'Modelling New'!AK:AK) -> 0.05 | D32: =MonthlyKPI!$U$4 -> 0 | E32: =-(D32-C32)/(C32) -> 1
B33: Line Loss YTD | C33: =_xlfn.XLOOKUP($B$3,'Modelling New'!$D:$D,'Modelling New'!AK:AK) -> 0.05 | D33: =AnnualKPI!$R$4 -> 1.2534776e-17 | E33: =-(D33-C33)/(C33) -> 1
A34: 9 | B34: Reactive Power Daily | C34: =_xlfn.XLOOKUP(B4,'Daily KPI'!$A:$A,'Daily KPI'!AQ:AQ) -> 0.05 | D34: =_xlfn.XLOOKUP($B$4,'Daily KPI'!$A:$A,'Daily KPI'!$AO:$AO) -> 0.00018373001 | E34: =-(D34-C34)/(C34) -> 0.9963254
B35: Reactive Power MTD | C35: =_xlfn.XLOOKUP($B$3,'Modelling New'!$D:$D,'Modelling New'!$AL:$AL) -> 0.05 | D35: =MonthlyKPI!$V$4 -> 0.00018312401 | E35: =-(D35-C35)/(C35) -> 0.99633752
B36: Reactive Power YTD | C36: =_xlfn.XLOOKUP($B$3,'Modelling New'!$D:$D,'Modelling New'!$AL:$AL) -> 0.05 | D36: =AnnualKPI!$S$4 -> 0.00016297161 | E36: =-(D36-C36)/(C36) -> 0.99674057
A37: 10 | B37: Expected Energy Daily | C37: =_xlfn.XLOOKUP($B$4,'Daily KPI'!$A:$A,'Daily KPI'!$AI:$AI) -> 416.51 | D37: =IFERROR(_xlfn.XLOOKUP($B$4,'Daily KPI'!$A:$A,'Daily KPI'!$X:$X)/1000,"") -> 466.775 | E37: =(D37-C37)/(C37) -> 0.12068138
B38: Expected Energy MTD | C38: =MonthlyKPI!$T$4 -> 1081.61 | D38: =IFERROR(SUMIF('Daily KPI'!$D:$D,O2Summary!$B$3,'Daily KPI'!$X:$X)/1000,"") -> 1202.399 | E38: =(D38-C38)/(C38) -> 0.11167519
B39: Expected Energy YTD | C39: =AnnualKPI!$Q$4 -> 80764.02 | D39: =IFERROR(SUMIFS('Daily KPI'!$X:$X,'Daily KPI'!$A:$A,">="&O2Summary!$B$6,'Daily KPI'!$A:$A,"<="&O2Summary!$B$4)/1000,"") -> 80814.47 | E39: =(D39-C39)/(C39) -> 0.00062465935
B483: Feeder4

Sheet MonthlyKPI
A1: Till Date | B1: =O2Summary!B4 -> 45871 | C1: 0 | D1: 0 | E1: 0 | F1: 0
A2: PWEPL Performance Summary (MTD)
A3: Year | B3: Days | C3: Estimated WS(m/s) | D3: Measured WS (m/s) | E3: Budgeted Energy (MWh) | F3: Measured Energy (MWh) | G3: Target CUF (%) | H3: Measured CUF (%) | I3: Target GA (%) | J3: Measured GA (%) | K3: Target MA (%) | L3: Measured MA (%) | M3: Target IGA (%) | N3: Measured IGA (%) | O3: Target PA(%) | P3: Measured PA (%) | Q3: WTG Total (MWh) | R3: Line Losses(%) | S3: E_WS_Corrected | T3: Expected Energy | U3: Loss (%) | V3: Reactive Power (%)
A4: =O2Summary!B3 -> 45870 | B4: =DAY(B1) -> 2 | C4: =IFERROR(_xlfn.XLOOKUP($A$4,'Modelling New'!$D:$D,'Modelling New'!$J:$J),"") -> 9.1 | D4: =IFERROR(AVERAGEIF('Daily KPI'!$D:$D,$A$4,'Daily KPI'!$M:$M),"") -> 7.0390909 | E4: =IFERROR(_xlfn.XLOOKUP($A$4,'Modelling New'!$D:$D,'Modelling New'!$U:$U),"") -> 2114.941 | F4: =IFERROR(SUMIFS('Daily KPI'!$AA:$AA,'Daily KPI'!$D:$D,$A$4)/1000,"") -> 1202.399 | G4: =IFERROR(_xlfn.XLOOKUP($A$4,'Modelling New'!$D:$D,'Modelling New'!X:X),"") -> 0.62587032 | H4: =F4/(24*B4*'Basic Data'!$L$2) -> 0.35582357 | I4: =IFERROR(_xlfn.XLOOKUP($A$4,'Modelling New'!$D:$D,'Modelling New'!AF:AF),"") -> 0.995 | J4: =IFERROR(AVERAGEIFS('Daily KPI'!$R:$R,'Daily KPI'!$A:$A,"<="&MonthlyKPI!$B$1,'Daily KPI'!$D:$D,$A$4),"") -> 1 | K4: =IFERROR(_xlfn.XLOOKUP($A$4,'Modelling New'!$D:$D,'Modelling New'!$AH:$AH),"") -> 0.97 | L4: =IFERROR(AVERAGEIFS('Daily KPI'!$P:$P,'Daily KPI'!$A:$A,"<="&MonthlyKPI!$B$1,'Daily KPI'!$D:$D,$A$4),"") -> 0.99856869 | M4: =IFERROR(_xlfn.XLOOKUP($A$4,'Modelling New'!$D:$D,'Modelling New'!$AI:$AI),"") -> 0.99 | N4: =IFERROR(AVERAGEIFS('Daily KPI'!$Q:$Q,'Daily KPI'!$A:$A,"<="&MonthlyKPI!$B$1,'Daily KPI'!$D:$D,$A$4),"") -> 1 | O4: =IFERROR(_xlfn.XLOOKUP($A$4,'Modelling New'!$D:$D,'Modelling New'!$AE:$AE),"") -> 0.9603 | P4: =L4*N4 -> 0.99856869 | Q4: =SUMIFS('Daily KPI'!$X:$X,'Daily KPI'!$D:$D,$A$4)/1000 -> 1202.399 | R4: =Q4/F4-1 -> 0 | S4: =SUMIFS(Input_Raw!DP:DP,Input_Raw!A:A,">="&A4,Input_Raw!A:A,"<="&B1) -> 1081.61 | T4: =SUMIFS('Daily KPI'!$AI:$AI,'Daily KPI'!$D:$D,$A$4) -> 1081.61 | U4: =AVERAGEIFS('Daily KPI'!$AN:$AN,'Daily KPI'!$A:$A,"<="&MonthlyKPI!$B$1,'Daily KPI'!$D:$D,$A$4) -> 0 | V4: =AVERAGEIFS('Daily KPI'!$AO:$AO,'Daily KPI'!$A:$A,"<="&MonthlyKPI!$B$1,'Daily KPI'!$D:$D,$A$4) -> 0.00018312401
A7: Start Date | B7: =B8-6 -> 45865
A8: End Date | B8: =B1 -> 45871
A9: PWEPL Performance Summary (WTD)
A10: Year | B10: Days | C10: Estimated WS(m/s) | D10: Measured WS (m/s) | E10: Budgeted Energy (MWh) | F10: Measured Energy (MWh) | G10: Target CUF (%) | H10: Measured CUF (%) | I10: Target GA (%) | J10: Measured GA (%) | K10: Target MA (%) | L10: Measured MA (%) | M10: Target IGA (%) | N10: Measured IGA (%) | O10: Target PA(%) | P10: Measured PA (%) | Q10: E_WS_Corrected
A11: =A4 -> 45870 | B11: =(B8-B7)+1 -> 7 | C11: =IFERROR(_xlfn.XLOOKUP($A$11,'Modelling New'!$D:$D,'Modelling New'!$J:$J),"") -> 9.1 | D11: =AVERAGEIFS('Daily KPI'!$M:$M,'Daily KPI'!$A:$A,">="&$B$7,'Daily KPI'!$A:$A,"<="&$B$8) -> 11.111006 | E11: =SUMIFS('Daily KPI'!$AD:$AD,'Daily KPI'!$A:$A,">="&$B$7,'Daily KPI'!$A:$A,"<="&$B$8)/1000 -> 6639.411 | F11: =SUMIFS('Daily KPI'!$AA:$AA,'Daily KPI'!$A:$A,">="&$B$7,'Daily KPI'!$A:$A,"<="&$B$8)/1000 -> 8934.033 | G11: =E11/(24*$B$11*'Basic Data'!$L$2) -> 0.56136795 | H11: =F11/(24*B11*'Basic Data'!$L$2) -> 0.75538023 | I11: =IFERROR(_xlfn.XLOOKUP($A$11,'Modelling New'!$D:$D,'Modelling New'!AF:AF),"") -> 0.995 | J11: =IFERROR(AVERAGEIFS('Daily KPI'!$R:$R,'Daily KPI'!$A:$A,">="&$B$7,'Daily KPI'!$A:$A,"<="&$B$8),"") -> 1 | K11: =IFERROR(_xlfn.XLOOKUP($A$11,'Modelling New'!$D:$D,'Modelling New'!$AH:$AH),"") -> 0.97 | L11: =IFERROR(AVERAGEIFS('Daily KPI'!$P:$P,'Daily KPI'!$A:$A,">="&$B$7,'Daily KPI'!$A:$A,"<="&$B$8),"") -> 0.9883088 | M11: =IFERROR(_xlfn.XLOOKUP($A$11,'Modelling New'!$D:$D,'Modelling New'!$AI:$AI),"") -> 0.99 | N11: =IFERROR(AVERAGEIFS('Daily KPI'!$Q:$Q,'Daily KPI'!$A:$A,">="&$B$7,'Daily KPI'!$A:$A,"<="&$B$8),"") -> 0.9996634 | O11: =IFERROR(_xlfn.XLOOKUP($A$11,'Modelling New'!$D:$D,'Modelling New'!$AE:$AE),"") -> 0.9603 | P11: =L11*N11 -> 0.98797613 | Q11: =SUMIFS(Input_Raw!DP:DP,Input_Raw!A:A,">="&B7,Input_Raw!A:A,"<="&B8) -> 9005.39
A14: Start Date | B14: =B15-29 -> 45842
A15: End Date | B15: =B8 -> 45871
A16: PWEGPL Performance Summary (LTD)
A17: Year | B17: Days | C17: Estimated WS(m/s) | D17: Measured WS (m/s) | E17: Budgeted Energy (MWh) | F17: Measured Energy (MWh) | G17: Target CUF (%) | H17: Measured CUF (%) | I17: Target GA (%) | J17: Measured GA (%) | K17: Target MA (%) | L17: Measured MA (%) | M17: Target IGA (%) | N17: Measured IGA (%) | O17: Target PA(%) | P17: Measured PA (%)
A18: =A11 -> 45870 | B18: =(B15-B14)+1 -> 30 | C18: =_xlfn.XLOOKUP($A$18,'Modelling New'!$D:$D,'Modelling New'!$AC:$AC) -> 9.4530329 | D18: =AVERAGEIFS('Daily KPI'!$M:$M,'Daily KPI'!$A:$A,">="&$B$14,'Daily KPI'!$A:$A,"<="&$B$15) -> 9.5638939 | E18: =SUMIFS('Daily KPI'!$AD:$AD,'Daily KPI'!$A:$A,">="&$B$14,'Daily KPI'!$A:$A,"<="&$B$15)/1000 -> 27451.973 | F18: =SUMIFS('Daily KPI'!$AA:$AA,'Daily KPI'!$A:$A,">="&$B$14,'Daily KPI'!$A:$A,"<="&$B$15)/1000 -> 30955.576 | G18: =E18/(24*$B$18*'Basic Data'!$L$2) -> 0.54158722 | H18: =F18/(24*B18*'Basic Data'!$L$2) -> 0.61070818 | I18: 0.997 | J18: =AVERAGEIFS('Daily KPI'!$AH:$AH,'Daily KPI'!$A:$A,">="&$B$14,'Daily KPI'!$A:$A,"<="&$B$15) -> 0.995 | K18: 0.986 | L18: =AVERAGEIFS('Daily KPI'!$P:$P,'Daily KPI'!$A:$A,">="&$B$14,'Daily KPI'!$A:$A,"<="&$B$15) -> 0.99220953 | M18: 0.995 | N18: =AVERAGEIFS('Daily KPI'!$Q:$Q,'Daily KPI'!$A:$A,">="&$B$14,'Daily KPI'!$A:$A,"<="&$B$15) -> 0.99022388 | O18: =K18*M18 -> 0.98107 | P18: =L18*N18 -> 0.98250956

Sheet AnnualKPI
A1: Till Date | B1: =O2Summary!B4 -> 45871 | C1: =O2Summary!B3 -> 45870
A2: PWEPL Performance Summary-YTD
A3: Year | B3: Days | C3: Estimated WS(m/s) | D3: Measured WS (m/s) | E3: Budgeted Energy (MWh) | F3: Measured Energy (MWh) | G3: Target CUF (%) | H3: Measured CUF (%) | I3: Target GA (%) | J3: Measured GA (%) | K3: Target MA (%) | L3: Measured MA (%) | M3: Target IGA(%) | N3: Measured IGA (%) | O3: Target PA(%) | P3: Measured PA (%) | Q3: Expected Energy | R3: Loss (%) | S3: Reactive Power (%)
A4: =YEAR(B1)+IF(MONTH(B1)>=4,1,0) -> 2026 | B4: =($B$1-O2Summary!$B$6)+1 -> 124 | C4: =IFERROR(_xlfn.XLOOKUP($C$1,'Modelling New'!$D:$D,'Modelling New'!$AD:$AD),"") -> 6.9174962 | D4: =AVERAGEIFS('Daily KPI'!$M:$M,'Daily KPI'!$A:$A,">="&O2Summary!$B$6,'Daily KPI'!$A:$A,"<="&AnnualKPI!$B$1) -> 7.3157625 | E4: =_xlfn.XLOOKUP($C$1,'Modelling New'!$D:$D,'Modelling New'!$V:$V) -> 63451.607 | F4: =SUMIFS('Daily KPI'!$AA:$AA,'Daily KPI'!$A:$A,">="&O2Summary!$B$6,'Daily KPI'!$A:$A,"<="&AnnualKPI!$B$1)/1000 -> 80814.47 | G4: =_xlfn.XLOOKUP($C$1,'Modelling New'!$D:$D,'Modelling New'!$Y:$Y) -> 0.3028566 | H4: =IFERROR(F4/(B4*24*'Basic Data'!$L$2),"") -> 0.38573011 | I4: =IFERROR(_xlfn.XLOOKUP($C$1,'Modelling New'!$D:$D,'Modelling New'!AF:AF),"") -> 0.995 | J4: =AVERAGEIFS('Daily KPI'!$R:$R,'Daily KPI'!$A:$A,">="&O2Summary!$B$6,'Daily KPI'!$A:$A,"<="&AnnualKPI!$B$1) -> 0.9944601 | K4: =IFERROR(_xlfn.XLOOKUP($C$1,'Modelling New'!$D:$D,'Modelling New'!$AH:$AH),"") -> 0.97 | L4: =AVERAGEIFS('Daily KPI'!$P:$P,'Daily KPI'!$A:$A,">="&O2Summary!$B$6,'Daily KPI'!$A:$A,"<="&AnnualKPI!$B$1) -> 0.99033909 | M4: =IFERROR(_xlfn.XLOOKUP($C$1,'Modelling New'!$D:$D,'Modelling New'!$AI:$AI),"") -> 0.99 | N4: =AVERAGEIFS('Daily KPI'!$Q:$Q,'Daily KPI'!$A:$A,">="&O2Summary!$B$6,'Daily KPI'!$A:$A,"<="&AnnualKPI!$B$1) -> 0.98484246 | O4: =K4*M4 -> 0.9603 | P4: =L4*N4 -> 0.97532798 | Q4: =SUMIFS('Daily KPI'!$AI:$AI,'Daily KPI'!$A:$A,">="&O2Summary!$B$6,'Daily KPI'!$A:$A,"<="&AnnualKPI!$B$1) -> 80764.02 | R4: =AVERAGEIFS('Daily KPI'!AN:AN,'Daily KPI'!$A:$A,">="&O2Summary!$B$6,'Daily KPI'!$A:$A,"<="&AnnualKPI!$B$1) -> 1.2534776e-17 | S4: =AVERAGEIFS('Daily KPI'!AO:AO,'Daily KPI'!$A:$A,">="&O2Summary!$B$6,'Daily KPI'!$A:$A,"<="&AnnualKPI!$B$1) -> 0.00016297161

Sheet Analytics
A2: Start Date | B2: =B3-27 -> 45844
A3: End Date | B3: =O2Summary!B4 -> 45871 | C3: =((B3-B2)*1)*24 -> 648 | D3: =MEDIAN(B21:X21) -> 9.2371429
A4: WTG No. | B4: P-01 | C4: P-02 | D4: P-03 | E4: P-04 | F4: P-05 | G4: P-06 | H4: P-07 | I4: P-08 | J4: P-09 | K4: P-10 | L4: P-11 | M4: P-12 | N4: P-13 | O4: P-14 | P4: P-15 | Q4: P-16 | R4: P-17 | S4: P-18 | T4: P-19 | U4: P-20 | V4: P-22 | W4: P-23 | X4: P-25 | Y4: P-26 | Z4: P-27 | AA4: P-28 | AB4: P-31 | AC4: P-32 | AD4: P-34 | AE4: P-37 | AF4: P-38 | AG4: P-40 | AH4: P-41 | AI4: P-42 | AJ4: P-43 | AK4: P-45 | AL4: P-46 | AM4: P-47 | AN4: P-48 | AO4: P-50 | AP4: P-51 | AQ4: P-52 | AR4: P-55 | AS4: P-56
A5: MA | B5: =($C$3-B6)/$C$3 -> 0.99140947 | C5: =($C$3-C6)/$C$3 -> 1 | D5: =($C$3-D6)/$C$3 -> 0.99737654 | E5: =($C$3-E6)/$C$3 -> 0.95100309 | F5: =($C$3-F6)/$C$3 -> 1 | G5: =($C$3-G6)/$C$3 -> 0.98058128 | H5: =($C$3-H6)/$C$3 -> 0.9632716 | I5: =($C$3-I6)/$C$3 -> 0.99459877 | ... AS5: =($C$3-AS6)/$C$3 -> 0.99187243 | AT5: =AVERAGE(B5:AS5) -> 0.99350332
A6: WTG BD Hours | B6: =(SUMIFS(WTG_BD!$T:$T,WTG_BD!$G:$G,Analytics!B$4,WTG_BD!$F:$F,">="&Analytics!$B$2,WTG_BD!$F:$F,"<="&Analytics!$B$3)) -> 5.5666667 | C6: =(SUMIFS(WTG_BD!$T:$T,WTG_BD!$G:$G,Analytics!C$4,WTG_BD!$F:$F,">="&Analytics!$B$2,WTG_BD!$F:$F,"<="&Analytics!$B$3)) -> 0 | D6: =(SUMIFS(WTG_BD!$T:$T,WTG_BD!$G:$G,Analytics!D$4,WTG_BD!$F:$F,">="&Analytics!$B$2,WTG_BD!$F:$F,"<="&Analytics!$B$3)) -> 1.7 | E6: =(SUMIFS(WTG_BD!$T:$T,WTG_BD!$G:$G,Analytics!E$4,WTG_BD!$F:$F,">="&Analytics!$B$2,WTG_BD!$F:$F,"<="&Analytics!$B$3)) -> 31.75 | F6: =(SUMIFS(WTG_BD!$T:$T,WTG_BD!$G:$G,Analytics!F$4,WTG_BD!$F:$F,">="&Analytics!$B$2,WTG_BD!$F:$F,"<="&Analytics!$B$3)) -> 0 | G6: =(SUMIFS(WTG_BD!$T:$T,WTG_BD!$G:$G,Analytics!G$4,WTG_BD!$F:$F,">="&Analytics!$B$2,WTG_BD!$F:$F,"<="&Analytics!$B$3)) -> 12.583333 | H6: =(SUMIFS(WTG_BD!$T:$T,WTG_BD!$G:$G,Analytics!H$4,WTG_BD!$F:$F,">="&Analytics!$B$2,WTG_BD!$F:$F,"<="&Analytics!$B$3)) -> 23.8 | I6: =(SUMIFS(WTG_BD!$T:$T,WTG_BD!$G:$G,Analytics!I$4,WTG_BD!$F:$F,">="&Analytics!$B$2,WTG_BD!$F:$F,"<="&Analytics!$B$3)) -> 3.5 | ... AT6: =(SUMIFS(WTG_BD!$T:$T,WTG_BD!$G:$G,Analytics!AT$4,WTG_BD!$F:$F,">="&Analytics!$B$2,WTG_BD!$F:$F,"<="&Analytics!$B$3)) -> 0
A7: IGA | B7: =($C$3-SUM(B8:B12))/$C$3 -> 0.98045267 | C7: =($C$3-SUM(C8:C12))/$C$3 -> 0.98045267 | D7: =($C$3-SUM(D8:D12))/$C$3 -> 0.98045267 | E7: =($C$3-SUM(E8:E12))/$C$3 -> 0.99891975 | F7: =($C$3-SUM(F8:F12))/$C$3 -> 0.99768519 | G7: =($C$3-SUM(G8:G12))/$C$3 -> 0.99768519 | H7: =($C$3-SUM(H8:H12))/$C$3 -> 0.98045267 | I7: =($C$3-SUM(I8:I12))/$C$3 -> 1 | ... AS7: =($C$3-SUM(AS8:AS12))/$C$3 -> 0.98045267 | AT7: =AVERAGE(B7:AS7) -> 0.99345656
A8: METERING YARD | AT8: =AVERAGE(B8:AS8) -> #DIV/0!
A9: FEEDER | B9: =SUMIFS(IGA_BD!$Q:$Q,IGA_BD!$G:$G,(VLOOKUP(B$4,'Basic Data'!$A:$F,6,0)),IGA_BD!$F:$F,">="&Analytics!$B$2,IGA_BD!$F:$F,"<="&Analytics!$B$3) -> 12.666667 | C9: =SUMIFS(IGA_BD!$Q:$Q,IGA_BD!$G:$G,(VLOOKUP(C$4,'Basic Data'!$A:$F,6,0)),IGA_BD!$F:$F,">="&Analytics!$B$2,IGA_BD!$F:$F,"<="&Analytics!$B$3) -> 12.666667 | D9: =SUMIFS(IGA_BD!$Q:$Q,IGA_BD!$G:$G,(VLOOKUP(D$4,'Basic Data'!$A:$F,6,0)),IGA_BD!$F:$F,">="&Analytics!$B$2,IGA_BD!$F:$F,"<="&Analytics!$B$3) -> 12.666667 | E9: =SUMIFS(IGA_BD!$Q:$Q,IGA_BD!$G:$G,(VLOOKUP(E$4,'Basic Data'!$A:$F,6,0)),IGA_BD!$F:$F,">="&Analytics!$B$2,IGA_BD!$F:$F,"<="&Analytics!$B$3) -> 0.7 | F9: =SUMIFS(IGA_BD!$Q:$Q,IGA_BD!$G:$G,(VLOOKUP(F$4,'Basic Data'!$A:$F,6,0)),IGA_BD!$F:$F,">="&Analytics!$B$2,IGA_BD!$F:$F,"<="&Analytics!$B$3) -> 1.5 | G9: =SUMIFS(IGA_BD!$Q:$Q,IGA_BD!$G:$G,(VLOOKUP(G$4,'Basic Data'!$A:$F,6,0)),IGA_BD!$F:$F,">="&Analytics!$B$2,IGA_BD!$F:$F,"<="&Analytics!$B$3) -> 1.5 | H9: =SUMIFS(IGA_BD!$Q:$Q,IGA_BD!$G:$G,(VLOOKUP(H$4,'Basic Data'!$A:$F,6,0)),IGA_BD!$F:$F,">="&Analytics!$B$2,IGA_BD!$F:$F,"<="&Analytics!$B$3) -> 12.666667 | I9: =SUMIFS(IGA_BD!$Q:$Q,IGA_BD!$G:$G,(VLOOKUP(I$4,'Basic Data'!$A:$F,6,0)),IGA_BD!$F:$F,">="&Analytics!$B$2,IGA_BD!$F:$F,"<="&Analytics!$B$3) -> 0 | ... AT9: =SUMIFS(IGA_BD!$Q:$Q,IGA_BD!$G:$G,(VLOOKUP(AT$4,'Basic Data'!$A:$F,6,0)),IGA_BD!$F:$F,">="&Analytics!$B$2,IGA_BD!$F:$F,"<="&Analytics!$B$3) -> 0
A10: OG | AT10: =AVERAGE(B10:AS10) -> #DIV/0!
A11: TRANSFER | AT11: =AVERAGE(B11:AS11) -> #DIV/0!
A12: USS | AT12: =AVERAGE(B12:AS12) -> #DIV/0!
A13: EGA | B13: =($C$3-B14)/$C$3 -> 0.99830247 | C13: =($C$3-C14)/$C$3 -> 0.99830247 | D13: =($C$3-D14)/$C$3 -> 0.99830247 | E13: =($C$3-E14)/$C$3 -> 1 | F13: =($C$3-F14)/$C$3 -> 0.99742798 | G13: =($C$3-G14)/$C$3 -> 0.99742798 | H13: =($C$3-H14)/$C$3 -> 0.99830247 | I13: =($C$3-I14)/$C$3 -> 1 | ... AS13: =($C$3-AS14)/$C$3 -> 0.99830247 | AT13: =AVERAGE(B13:AS13) -> 0.99897236
A14: External Grid | B14: =SUMIFS(Grid_BD!$R:$R,Grid_BD!$G:$G,(VLOOKUP(B$4,'Basic Data'!$A:$F,6,0)),Grid_BD!$F:$F,">="&Analytics!$B$2,Grid_BD!$F:$F,"<="&Analytics!$B$3) -> 1.1 | C14: =SUMIFS(Grid_BD!$R:$R,Grid_BD!$G:$G,(VLOOKUP(C$4,'Basic Data'!$A:$F,6,0)),Grid_BD!$F:$F,">="&Analytics!$B$2,Grid_BD!$F:$F,"<="&Analytics!$B$3) -> 1.1 | D14: =SUMIFS(Grid_BD!$R:$R,Grid_BD!$G:$G,(VLOOKUP(D$4,'Basic Data'!$A:$F,6,0)),Grid_BD!$F:$F,">="&Analytics!$B$2,Grid_BD!$F:$F,"<="&Analytics!$B$3) -> 1.1 | E14: =SUMIFS(Grid_BD!$R:$R,Grid_BD!$G:$G,(VLOOKUP(E$4,'Basic Data'!$A:$F,6,0)),Grid_BD!$F:$F,">="&Analytics!$B$2,Grid_BD!$F:$F,"<="&Analytics!$B$3) -> 0 | F14: =SUMIFS(Grid_BD!$R:$R,Grid_BD!$G:$G,(VLOOKUP(F$4,'Basic Data'!$A:$F,6,0)),Grid_BD!$F:$F,">="&Analytics!$B$2,Grid_BD!$F:$F,"<="&Analytics!$B$3) -> 1.6666667 | G14: =SUMIFS(Grid_BD!$R:$R,Grid_BD!$G:$G,(VLOOKUP(G$4,'Basic Data'!$A:$F,6,0)),Grid_BD!$F:$F,">="&Analytics!$B$2,Grid_BD!$F:$F,"<="&Analytics!$B$3) -> 1.6666667 | H14: =SUMIFS(Grid_BD!$R:$R,Grid_BD!$G:$G,(VLOOKUP(H$4,'Basic Data'!$A:$F,6,0)),Grid_BD!$F:$F,">="&Analytics!$B$2,Grid_BD!$F:$F,"<="&Analytics!$B$3) -> 1.1 | I14: =SUMIFS(Grid_BD!$R:$R,Grid_BD!$G:$G,(VLOOKUP(I$4,'Basic Data'!$A:$F,6,0)),Grid_BD!$F:$F,">="&Analytics!$B$2,Grid_BD!$F:$F,"<="&Analytics!$B$3) -> 0 | ... AT14: =SUMIFS(Grid_BD!$R:$R,Grid_BD!$G:$G,(VLOOKUP(AT$4,'Basic Data'!$A:$F,6,0)),Grid_BD!$F:$F,">="&Analytics!$B$2,Grid_BD!$F:$F,"<="&Analytics!$B$3) -> 0
A15: Generation | B15: =SUMIFS(Input_Raw!F:F,Input_Raw!$A:$A,">="&Analytics!$B$2,Input_Raw!$A:$A,"<="&Analytics!$B$3) -> 723356 | C15: =SUMIFS(Input_Raw!G:G,Input_Raw!$A:$A,">="&Analytics!$B$2,Input_Raw!$A:$A,"<="&Analytics!$B$3) -> 633204 | D15: =SUMIFS(Input_Raw!H:H,Input_Raw!$A:$A,">="&Analytics!$B$2,Input_Raw!$A:$A,"<="&Analytics!$B$3) -> 615756 | E15: =SUMIFS(Input_Raw!I:I,Input_Raw!$A:$A,">="&Analytics!$B$2,Input_Raw!$A:$A,"<="&Analytics!$B$3) -> 618122 | F15: =SUMIFS(Input_Raw!J:J,Input_Raw!$A:$A,">="&Analytics!$B$2,Input_Raw!$A:$A,"<="&Analytics!$B$3) -> 739816 | G15: =SUMIFS(Input_Raw!K:K,Input_Raw!$A:$A,">="&Analytics!$B$2,Input_Raw!$A:$A,"<="&Analytics!$B$3) -> 654028 | H15: =SUMIFS(Input_Raw!L:L,Input_Raw!$A:$A,">="&Analytics!$B$2,Input_Raw!$A:$A,"<="&Analytics!$B$3) -> 598880 | I15: =SUMIFS(Input_Raw!M:M,Input_Raw!$A:$A,">="&Analytics!$B$2,Input_Raw!$A:$A,"<="&Analytics!$B$3) -> 582088 | J15: =SUMIFS(Input_Raw!N:N,Input_Raw!$A:$A,">="&Analytics!$B$2,Input_Raw!$A:$A,"<="&Analytics!$B$3) -> 485484 | K15: =SUMIFS(Input_Raw!O:O,Input_Raw!$A:$A,">="&Analytics!$B$2,Input_Raw!$A:$A,"<="&Analytics!$B$3) -> 540244 | L15: =SUMIFS(Input_Raw!P:P,Input_Raw!$A:$A,">="&Analytics!$B$2,Input_Raw!$A:$A,"<="&Analytics!$B$3) -> 647054 | M15: =SUMIFS(Input_Raw!Q:Q,Input_Raw!$A:$A,">="&Analytics!$B$2,Input_Raw!$A:$A,"<="&Analytics!$B$3) -> 683012 | N15: =SUMIFS(Input_Raw!R:R,Input_Raw!$A:$A,">="&Analytics!$B$2,Input_Raw!$A:$A,"<="&Analytics!$B$3) -> 646092 | O15: =SUMIFS(Input_Raw!S:S,Input_Raw!$A:$A,">="&Analytics!$B$2,Input_Raw!$A:$A,"<="&Analytics!$B$3) -> 592062 | P15: =SUMIFS(Input_Raw!T:T,Input_Raw!$A:$A,">="&Analytics!$B$2,Input_Raw!$A:$A,"<="&Analytics!$B$3) -> 562630 | Q15: =SUMIFS(Input_Raw!U:U,Input_Raw!$A:$A,">="&Analytics!$B$2,Input_Raw!$A:$A,"<="&Analytics!$B$3) -> 614230 | R15: =SUMIFS(Input_Raw!V:V,Input_Raw!$A:$A,">="&Analytics!$B$2,Input_Raw!$A:$A,"<="&Analytics!$B$3) -> 640014 | S15: =SUMIFS(Input_Raw!W:W,Input_Raw!$A:$A,">="&Analytics!$B$2,Input_Raw!$A:$A,"<="&Analytics!$B$3) -> 624916 | T15: =SUMIFS(Input_Raw!X:X,Input_Raw!$A:$A,">="&Analytics!$B$2,Input_Raw!$A:$A,"<="&Analytics!$B$3) -> 523880 | U15: =SUMIFS(Input_Raw!Y:Y,Input_Raw!$A:$A,">="&Analytics!$B$2,Input_Raw!$A:$A,"<="&Analytics!$B$3) -> 528256 | V15: =SUMIFS(Input_Raw!Z:Z,Input_Raw!$A:$A,">="&Analytics!$B$2,Input_Raw!$A:$A,"<="&Analytics!$B$3) -> 659840 | W15: =SUMIFS(Input_Raw!AA:AA,Input_Raw!$A:$A,">="&Analytics!$B$2,Input_Raw!$A:$A,"<="&Analytics!$B$3) -> 591032 | X15: =SUMIFS(Input_Raw!AB:AB,Input_Raw!$A:$A,">="&Analytics!$B$2,Input_Raw!$A:$A,"<="&Analytics!$B$3) -> 604848 | Y15: =SUMIFS(Input_Raw!AC:AC,Input_Raw!$A:$A,">="&Analytics!$B$2,Input_Raw!$A:$A,"<="&Analytics!$B$3) -> 645624 | Z15: =SUMIFS(Input_Raw!AD:AD,Input_Raw!$A:$A,">="&Analytics!$B$2,Input_Raw!$A:$A,"<="&Analytics!$B$3) -> 655340 | AA15: =SUMIFS(Input_Raw!AE:AE,Input_Raw!$A:$A,">="&Analytics!$B$2,Input_Raw!$A:$A,"<="&Analytics!$B$3) -> 613768 | AB15: =SUMIFS(Input_Raw!AF:AF,Input_Raw!$A:$A,">="&Analytics!$B$2,Input_Raw!$A:$A,"<="&Analytics!$B$3) -> 556026 | AC15: =SUMIFS(Input_Raw!AG:AG,Input_Raw!$A:$A,">="&Analytics!$B$2,Input_Raw!$A:$A,"<="&Analytics!$B$3) -> 546588 | AD15: =SUMIFS(Input_Raw!AH:AH,Input_Raw!$A:$A,">="&Analytics!$B$2,Input_Raw!$A:$A,"<="&Analytics!$B$3) -> 674220 | AE15: =SUMIFS(Input_Raw!AI:AI,Input_Raw!$A:$A,">="&Analytics!$B$2,Input_Raw!$A:$A,"<="&Analytics!$B$3) -> 611120 | AF15: =SUMIFS(Input_Raw!AJ:AJ,Input_Raw!$A:$A,">="&Analytics!$B$2,Input_Raw!$A:$A,"<="&Analytics!$B$3) -> 620028 | AG15: =SUMIFS(Input_Raw!AK:AK,Input_Raw!$A:$A,">="&Analytics!$B$2,Input_Raw!$A:$A,"<="&Analytics!$B$3) -> 534746 | AH15: =SUMIFS(Input_Raw!AL:AL,Input_Raw!$A:$A,">="&Analytics!$B$2,Input_Raw!$A:$A,"<="&Analytics!$B$3) -> 726500 | AI15: =SUMIFS(Input_Raw!AM:AM,Input_Raw!$A:$A,">="&Analytics!$B$2,Input_Raw!$A:$A,"<="&Analytics!$B$3) -> 703996 | AJ15: =SUMIFS(Input_Raw!AN:AN,Input_Raw!$A:$A,">="&Analytics!$B$2,Input_Raw!$A:$A,"<="&Analytics!$B$3) -> 537788 | AK15: =SUMIFS(Input_Raw!AO:AO,Input_Raw!$A:$A,">="&Analytics!$B$2,Input_Raw!$A:$A,"<="&Analytics!$B$3) -> 763904 | AL15: =SUMIFS(Input_Raw!AP:AP,Input_Raw!$A:$A,">="&Analytics!$B$2,Input_Raw!$A:$A,"<="&Analytics!$B$3) -> 760840 | AM15: =SUMIFS(Input_Raw!AQ:AQ,Input_Raw!$A:$A,">="&Analytics!$B$2,Input_Raw!$A:$A,"<="&Analytics!$B$3) -> 718520 | AN15: =SUMIFS(Input_Raw!AR:AR,Input_Raw!$A:$A,">="&Analytics!$B$2,Input_Raw!$A:$A,"<="&Analytics!$B$3) -> 752948 | AO15: =SUMIFS(Input_Raw!AS:AS,Input_Raw!$A:$A,">="&Analytics!$B$2,Input_Raw!$A:$A,"<="&Analytics!$B$3) -> 619734 | AP15: =SUMIFS(Input_Raw!AT:AT,Input_Raw!$A:$A,">="&Analytics!$B$2,Input_Raw!$A:$A,"<="&Analytics!$B$3) -> 677744 | AQ15: =SUMIFS(Input_Raw!AU:AU,Input_Raw!$A:$A,">="&Analytics!$B$2,Input_Raw!$A:$A,"<="&Analytics!$B$3) -> 658484 | AR15: =SUMIFS(Input_Raw!AV:AV,Input_Raw!$A:$A,">="&Analytics!$B$2,Input_Raw!$A:$A,"<="&Analytics!$B$3) -> 755984 | AS15: =SUMIFS(Input_Raw!AW:AW,Input_Raw!$A:$A,">="&Analytics!$B$2,Input_Raw!$A:$A,"<="&Analytics!$B$3) -> 698540 | AT15: =SUM(B15:AS15) -> 27941286
A16: PA | B16: =($C$3-(SUM(B8:B12,B14,B6)))/$C$3 -> 0.97016461 | C16: =($C$3-(SUM(C8:C12,C14,C6)))/$C$3 -> 0.97875514 | D16: =($C$3-(SUM(D8:D12,D14,D6)))/$C$3 -> 0.97613169 | E16: =($C$3-(SUM(E8:E12,E14,E6)))/$C$3 -> 0.94992284 | F16: =($C$3-(SUM(F8:F12,F14,F6)))/$C$3 -> 0.99511317 | G16: =($C$3-(SUM(G8:G12,G14,G6)))/$C$3 -> 0.97569444 | H16: =($C$3-(SUM(H8:H12,H14,H6)))/$C$3 -> 0.94202675 | I16: =($C$3-(SUM(I8:I12,I14,I6)))/$C$3 -> 0.99459877 | ... AS16: =($C$3-(SUM(AS8:AS12,AS14,AS6)))/$C$3 -> 0.97062757 | AT16: =AVERAGE(B16:AS16) -> 0.98593224
A17: Sum of BD | B17: =SUMIFS(WTG_BD!$T:$T,WTG_BD!$G:$G,Analytics!B$4,WTG_BD!$F:$F,">="&Analytics!$B$2,WTG_BD!$F:$F,"<="&Analytics!$B$3) -> 5.5666667 | C17: =SUMIFS(WTG_BD!$T:$T,WTG_BD!$G:$G,Analytics!C$4,WTG_BD!$F:$F,">="&Analytics!$B$2,WTG_BD!$F:$F,"<="&Analytics!$B$3) -> 0 | D17: =SUMIFS(WTG_BD!$T:$T,WTG_BD!$G:$G,Analytics!D$4,WTG_BD!$F:$F,">="&Analytics!$B$2,WTG_BD!$F:$F,"<="&Analytics!$B$3) -> 1.7 | E17: =SUMIFS(WTG_BD!$T:$T,WTG_BD!$G:$G,Analytics!E$4,WTG_BD!$F:$F,">="&Analytics!$B$2,WTG_BD!$F:$F,"<="&Analytics!$B$3) -> 31.75 | F17: =SUMIFS(WTG_BD!$T:$T,WTG_BD!$G:$G,Analytics!F$4,WTG_BD!$F:$F,">="&Analytics!$B$2,WTG_BD!$F:$F,"<="&Analytics!$B$3) -> 0 | G17: =SUMIFS(WTG_BD!$T:$T,WTG_BD!$G:$G,Analytics!G$4,WTG_BD!$F:$F,">="&Analytics!$B$2,WTG_BD!$F:$F,"<="&Analytics!$B$3) -> 12.583333 | H17: =SUMIFS(WTG_BD!$T:$T,WTG_BD!$G:$G,Analytics!H$4,WTG_BD!$F:$F,">="&Analytics!$B$2,WTG_BD!$F:$F,"<="&Analytics!$B$3) -> 23.8 | I17: =SUMIFS(WTG_BD!$T:$T,WTG_BD!$G:$G,Analytics!I$4,WTG_BD!$F:$F,">="&Analytics!$B$2,WTG_BD!$F:$F,"<="&Analytics!$B$3) -> 3.5 | ... AT17: =SUMIFS(WTG_BD!$T:$T,WTG_BD!$G:$G,Analytics!AT$4,WTG_BD!$F:$F,">="&Analytics!$B$2,WTG_BD!$F:$F,"<="&Analytics!$B$3) -> 0
A18: Count of BD | B18: =COUNTIFS(WTG_BD!$G:$G,Analytics!B$4,WTG_BD!$F:$F,">="&Analytics!$B$2,WTG_BD!$F:$F,"<="&Analytics!$B$3) -> 4 | C18: =COUNTIFS(WTG_BD!$G:$G,Analytics!C$4,WTG_BD!$F:$F,">="&Analytics!$B$2,WTG_BD!$F:$F,"<="&Analytics!$B$3) -> 0 | D18: =COUNTIFS(WTG_BD!$G:$G,Analytics!D$4,WTG_BD!$F:$F,">="&Analytics!$B$2,WTG_BD!$F:$F,"<="&Analytics!$B$3) -> 1 | E18: =COUNTIFS(WTG_BD!$G:$G,Analytics!E$4,WTG_BD!$F:$F,">="&Analytics!$B$2,WTG_BD!$F:$F,"<="&Analytics!$B$3) -> 9 | F18: =COUNTIFS(WTG_BD!$G:$G,Analytics!F$4,WTG_BD!$F:$F,">="&Analytics!$B$2,WTG_BD!$F:$F,"<="&Analytics!$B$3) -> 0 | G18: =COUNTIFS(WTG_BD!$G:$G,Analytics!G$4,WTG_BD!$F:$F,">="&Analytics!$B$2,WTG_BD!$F:$F,"<="&Analytics!$B$3) -> 3 | H18: =COUNTIFS(WTG_BD!$G:$G,Analytics!H$4,WTG_BD!$F:$F,">="&Analytics!$B$2,WTG_BD!$F:$F,"<="&Analytics!$B$3) -> 4 | I18: =COUNTIFS(WTG_BD!$G:$G,Analytics!I$4,WTG_BD!$F:$F,">="&Analytics!$B$2,WTG_BD!$F:$F,"<="&Analytics!$B$3) -> 6 | ... AT18: =COUNTIFS(WTG_BD!$G:$G,Analytics!AT$4,WTG_BD!$F:$F,">="&Analytics!$B$2,WTG_BD!$F:$F,"<="&Analytics!$B$3) -> 0
A19: MTTR WTG | B19: =IFERROR(B17/B18,0) -> 1.3916667 | C19: =IFERROR(C17/C18,0) -> 0 | D19: =IFERROR(D17/D18,0) -> 1.7 | E19: =IFERROR(E17/E18,0) -> 3.5277778 | F19: =IFERROR(F17/F18,0) -> 0 | G19: =IFERROR(G17/G18,0) -> 4.1944444 | H19: =IFERROR(H17/H18,0) -> 5.95 | I19: =IFERROR(I17/I18,0) -> 0.58333333 | ... AS19: =IFERROR(AS17/AS18,0) -> 1.7555556 | AT19: =AVERAGE(B19:AS19) -> 1.3402841
A20: MTBF WTG | B20: =IFERROR(($C$3-B17)/B18,$C$3) -> 160.60833 | C20: =IFERROR(($C$3-C17)/C18,$C$3) -> 648 | D20: =IFERROR(($C$3-D17)/D18,$C$3) -> 646.3 | E20: =IFERROR(($C$3-E17)/E18,$C$3) -> 68.472222 | F20: =IFERROR(($C$3-F17)/F18,$C$3) -> 648 | G20: =IFERROR(($C$3-G17)/G18,$C$3) -> 211.80556 | H20: =IFERROR(($C$3-H17)/H18,$C$3) -> 156.05 | I20: =IFERROR(($C$3-I17)/I18,$C$3) -> 107.41667 | ... AS20: =IFERROR(($C$3-AS17)/AS18,$C$3) -> 214.24444 | AT20: =AVERAGE(B20:AS20) -> 426.65062
A21: WS (M/S) | B21: =AVERAGEIFS(Input_Raw!AX:AX,Input_Raw!$A:$A,">="&Analytics!$B$2,Input_Raw!$A:$A,"<="&Analytics!$B$3) -> 9.8292857 | C21: =AVERAGEIFS(Input_Raw!AY:AY,Input_Raw!$A:$A,">="&Analytics!$B$2,Input_Raw!$A:$A,"<="&Analytics!$B$3) -> 9.4014286 | D21: =AVERAGEIFS(Input_Raw!AZ:AZ,Input_Raw!$A:$A,">="&Analytics!$B$2,Input_Raw!$A:$A,"<="&Analytics!$B$3) -> 9.1957143 | E21: =AVERAGEIFS(Input_Raw!BA:BA,Input_Raw!$A:$A,">="&Analytics!$B$2,Input_Raw!$A:$A,"<="&Analytics!$B$3) -> 9.6135714 | F21: =AVERAGEIFS(Input_Raw!BB:BB,Input_Raw!$A:$A,">="&Analytics!$B$2,Input_Raw!$A:$A,"<="&Analytics!$B$3) -> 9.8007143 | G21: =AVERAGEIFS(Input_Raw!BC:BC,Input_Raw!$A:$A,">="&Analytics!$B$2,Input_Raw!$A:$A,"<="&Analytics!$B$3) -> 10.048214 | H21: =AVERAGEIFS(Input_Raw!BD:BD,Input_Raw!$A:$A,">="&Analytics!$B$2,Input_Raw!$A:$A,"<="&Analytics!$B$3) -> 9.2371429 | I21: =AVERAGEIFS(Input_Raw!BE:BE,Input_Raw!$A:$A,">="&Analytics!$B$2,Input_Raw!$A:$A,"<="&Analytics!$B$3) -> 8.7728571 | J21: =AVERAGEIFS(Input_Raw!BF:BF,Input_Raw!$A:$A,">="&Analytics!$B$2,Input_Raw!$A:$A,"<="&Analytics!$B$3) -> 8.1271429 | K21: =AVERAGEIFS(Input_Raw!BG:BG,Input_Raw!$A:$A,">="&Analytics!$B$2,Input_Raw!$A:$A,"<="&Analytics!$B$3) -> 8.8946429 | L21: =AVERAGEIFS(Input_Raw!BH:BH,Input_Raw!$A:$A,">="&Analytics!$B$2,Input_Raw!$A:$A,"<="&Analytics!$B$3) -> 9.3285714 | M21: =AVERAGEIFS(Input_Raw!BI:BI,Input_Raw!$A:$A,">="&Analytics!$B$2,Input_Raw!$A:$A,"<="&Analytics!$B$3) -> 10.217857 | N21: =AVERAGEIFS(Input_Raw!BJ:BJ,Input_Raw!$A:$A,">="&Analytics!$B$2,Input_Raw!$A:$A,"<="&Analytics!$B$3) -> 8.9771429 | O21: =AVERAGEIFS(Input_Raw!BK:BK,Input_Raw!$A:$A,">="&Analytics!$B$2,Input_Raw!$A:$A,"<="&Analytics!$B$3) -> 9.0421429 | P21: =AVERAGEIFS(Input_Raw!BL:BL,Input_Raw!$A:$A,">="&Analytics!$B$2,Input_Raw!$A:$A,"<="&Analytics!$B$3) -> 9.2871429 | Q21: =AVERAGEIFS(Input_Raw!BM:BM,Input_Raw!$A:$A,">="&Analytics!$B$2,Input_Raw!$A:$A,"<="&Analytics!$B$3) -> 9.2667857 | R21: =AVERAGEIFS(Input_Raw!BN:BN,Input_Raw!$A:$A,">="&Analytics!$B$2,Input_Raw!$A:$A,"<="&Analytics!$B$3) -> 9.7657143 | S21: =AVERAGEIFS(Input_Raw!BO:BO,Input_Raw!$A:$A,">="&Analytics!$B$2,Input_Raw!$A:$A,"<="&Analytics!$B$3) -> 9.1685714 | T21: =AVERAGEIFS(Input_Raw!BP:BP,Input_Raw!$A:$A,">="&Analytics!$B$2,Input_Raw!$A:$A,"<="&Analytics!$B$3) -> 8.7328571 | U21: =AVERAGEIFS(Input_Raw!BQ:BQ,Input_Raw!$A:$A,">="&Analytics!$B$2,Input_Raw!$A:$A,"<="&Analytics!$B$3) -> 8.0157143 | V21: =AVERAGEIFS(Input_Raw!BR:BR,Input_Raw!$A:$A,">="&Analytics!$B$2,Input_Raw!$A:$A,"<="&Analytics!$B$3) -> 9.4321429 | W21: =AVERAGEIFS(Input_Raw!BS:BS,Input_Raw!$A:$A,">="&Analytics!$B$2,Input_Raw!$A:$A,"<="&Analytics!$B$3) -> 8.7592857 | X21: =AVERAGEIFS(Input_Raw!BT:BT,Input_Raw!$A:$A,">="&Analytics!$B$2,Input_Raw!$A:$A,"<="&Analytics!$B$3) -> 8.5807143 | Y21: =AVERAGEIFS(Input_Raw!BU:BU,Input_Raw!$A:$A,">="&Analytics!$B$2,Input_Raw!$A:$A,"<="&Analytics!$B$3) -> 9.4557143 | Z21: =AVERAGEIFS(Input_Raw!BV:BV,Input_Raw!$A:$A,">="&Analytics!$B$2,Input_Raw!$A:$A,"<="&Analytics!$B$3) -> 9.05 | AA21: =AVERAGEIFS(Input_Raw!BW:BW,Input_Raw!$A:$A,">="&Analytics!$B$2,Input_Raw!$A:$A,"<="&Analytics!$B$3) -> 9.3335714 | AB21: =AVERAGEIFS(Input_Raw!BX:BX,Input_Raw!$A:$A,">="&Analytics!$B$2,Input_Raw!$A:$A,"<="&Analytics!$B$3) -> 8.3792857 | AC21: =AVERAGEIFS(Input_Raw!BY:BY,Input_Raw!$A:$A,">="&Analytics!$B$2,Input_Raw!$A:$A,"<="&Analytics!$B$3) -> 8.4135714 | AD21: =AVERAGEIFS(Input_Raw!BZ:BZ,Input_Raw!$A:$A,">="&Analytics!$B$2,Input_Raw!$A:$A,"<="&Analytics!$B$3) -> 9.645 | AE21: =AVERAGEIFS(Input_Raw!CA:CA,Input_Raw!$A:$A,">="&Analytics!$B$2,Input_Raw!$A:$A,"<="&Analytics!$B$3) -> 9.0025 | AF21: =AVERAGEIFS(Input_Raw!CB:CB,Input_Raw!$A:$A,">="&Analytics!$B$2,Input_Raw!$A:$A,"<="&Analytics!$B$3) -> 9.375 | AG21: =AVERAGEIFS(Input_Raw!CC:CC,Input_Raw!$A:$A,">="&Analytics!$B$2,Input_Raw!$A:$A,"<="&Analytics!$B$3) -> 8.5410714 | AH21: =AVERAGEIFS(Input_Raw!CD:CD,Input_Raw!$A:$A,">="&Analytics!$B$2,Input_Raw!$A:$A,"<="&Analytics!$B$3) -> 10.087143 | AI21: =AVERAGEIFS(Input_Raw!CE:CE,Input_Raw!$A:$A,">="&Analytics!$B$2,Input_Raw!$A:$A,"<="&Analytics!$B$3) -> 9.9978571 | AJ21: =AVERAGEIFS(Input_Raw!CF:CF,Input_Raw!$A:$A,">="&Analytics!$B$2,Input_Raw!$A:$A,"<="&Analytics!$B$3) -> 8.2642857 | AK21: =AVERAGEIFS(Input_Raw!CG:CG,Input_Raw!$A:$A,">="&Analytics!$B$2,Input_Raw!$A:$A,"<="&Analytics!$B$3) -> 11.179643 | AL21: =AVERAGEIFS(Input_Raw!CH:CH,Input_Raw!$A:$A,">="&Analytics!$B$2,Input_Raw!$A:$A,"<="&Analytics!$B$3) -> 10.766071 | AM21: =AVERAGEIFS(Input_Raw!CI:CI,Input_Raw!$A:$A,">="&Analytics!$B$2,Input_Raw!$A:$A,"<="&Analytics!$B$3) -> 10.0025 | AN21: =AVERAGEIFS(Input_Raw!CJ:CJ,Input_Raw!$A:$A,">="&Analytics!$B$2,Input_Raw!$A:$A,"<="&Analytics!$B$3) -> 10.398214 | AO21: =AVERAGEIFS(Input_Raw!CK:CK,Input_Raw!$A:$A,">="&Analytics!$B$2,Input_Raw!$A:$A,"<="&Analytics!$B$3) -> 9.1785714 | AP21: =AVERAGEIFS(Input_Raw!CL:CL,Input_Raw!$A:$A,">="&Analytics!$B$2,Input_Raw!$A:$A,"<="&Analytics!$B$3) -> 9.8778571 | AQ21: =AVERAGEIFS(Input_Raw!CM:CM,Input_Raw!$A:$A,">="&Analytics!$B$2,Input_Raw!$A:$A,"<="&Analytics!$B$3) -> 9.615 | AR21: =AVERAGEIFS(Input_Raw!CN:CN,Input_Raw!$A:$A,">="&Analytics!$B$2,Input_Raw!$A:$A,"<="&Analytics!$B$3) -> 11.095357 | AS21: =AVERAGEIFS(Input_Raw!CO:CO,Input_Raw!$A:$A,">="&Analytics!$B$2,Input_Raw!$A:$A,"<="&Analytics!$B$3) -> 9.9664286 | AT21: =AVERAGE(B21:AS21) -> 9.3890909
A22: Line loss (%)
A23: Corelation (%)
A24: Reactive Power
A26: Fault Analysis
D28: Put hour Here | F28: Default hour for full Data
D29: =(MAX(#REF!)-#REF!)*24 -> #REF! | F29: =(MAX(#REF!)-#REF!)*24 -> #REF!
A30: Row Labels | B30: Sum of Breakdown Time | C30: Count of Error Text | D30: MTTR | E30: MTBF
A31: Gearbox oil overtemperature | B31: 289.1 | C31: 73 | D31: =B31/C31 -> 3.960274 | E31: =($D$29-B31)/C31 -> #REF!
A32: Line CCU collective faults | B32: 207.01667 | C32: 26 | D32: =B32/C32 -> 7.9621795 | E32: =($D$29-B32)/C32 -> #REF!
A33: PLC fault 24V Supply | B33: 84.225278 | C33: 12 | D33: =B33/C33 -> 7.0187731 | E33: =($D$29-B33)/C33 -> #REF!
A34: Anemometer defec | B34: 65.85 | C34: 8 | D34: =B34/C34 -> 8.23125 | E34: =($D$29-B34)/C34 -> #REF!
A35: Line CCU fault current | B35: 65.083333 | C35: 7 | D35: =B35/C35 -> 9.297619 | E35: =($D$29-B35)/C35 -> #REF!
A36: Pitch thyristor 3 fault | B36: 58.083333 | C36: 9 | D36: =B36/C36 -> 6.4537037 | E36: =($D$29-B36)/C36 -> #REF!
A37: Yaw tooth sensor 1 timeout | B37: 40.3 | C37: 20 | D37: =B37/C37 -> 2.015 | E37: =($D$29-B37)/C37 -> #REF!
A38: Rotor speeds not plausible | B38: 39.8 | C38: 7 | D38: =B38/C38 -> 5.6857143 | E38: =($D$29-B38)/C38 -> #REF!
A39: Communication fault wind measurement device | B39: 34.216667 | C39: 5 | D39: =B39/C39 -> 6.8433333 | E39: =($D$29-B39)/C39 -> #REF!
A40: No communication Cu | B40: 28.95 | C40: 2 | D40: =B40/C40 -> 14.475 | E40: =($D$29-B40)/C40 -> #REF!
A41: Pitch thyristor 1 fault | B41: 26.983333 | C41: 3 | D41: =B41/C41 -> 8.9944444 | E41: =($D$29-B41)/C41 -> #REF!
A42: Brake not released secondary brake | B42: 20.25 | C42: 2 | D42: =B42/C42 -> 10.125 | E42: =($D$29-B42)/C42 -> #REF!
... A79: Grand Total | B79: 1144.1086 | C79: 297 | D79: =B79/C79 -> 3.8522175 | E79: =($D$29-B79)/C79 -> #REF!
...

Sheet Daily KPI
A1: Date | B1: Financial Year | C1: Calendar Year | D1: Month Year | E1: Days | F1: Operating Hours | G1: GHI-UP (KWh/m2) | H1: GHI-Down(KWh/m2) | I1: POA-UP(KWh/m2) | J1: POA-Down(KWh/m2) | K1: Amb_Temp(°C) | L1: Mod_Temp(°C) | M1: WS_Avg(m/s) | N1: WS_Max(m/s) | O1: PA(%) | P1: MA (%) | Q1: IGA (%) | R1: EGA(%) | S1: EMA (%) | T1: TA (%) | U1: PR(%) | V1: WPR(%) | W1: CUF(%) | X1: Gen_Exp (kWh) | Y1: Mtr_Export (kWh) | Z1: Mtr_Import (kWh) | AA1: Mtr_Net_Exp (KWh) | AB1: Operational Capacity (MW) | AC1: Bugt_Resource | AD1: Bugt_Energy | AE1: Bugt PR | AF1: Bugt CUF | AG1: Bugt_PA | AH1: Bugt_EGA | AI1: Expected Energy | AJ1: Actual Energy WPR | AK1: RA (%) | AL1: Mod Clean Dry (Num) | AM1: Mod Clean Wet (Num) | AN1: Line Loss(%) | AO1: Reactive Power (%) | AP1: Bugt Line loss (%) (Wind) | AQ1: Bugt Reactive Power (%) (Wind) | AR1: Bugt Capacity | AS1: CC*Bugt
A2: 45745 | B2: =YEAR(Daily_KPI[[#This Row],[Date]])+IF(MONTH(Daily_KPI[[#This Row],[Date]])>=4,1,0) -> 2025 | C2: =YEAR(Daily_KPI[[#This Row],[Date]]) -> 2025 | D2: =Daily_KPI[[#This Row],[Date]]-DAY(Daily_KPI[[#This Row],[Date]])+1 -> 45717 | E2: =DAY(EOMONTH(A2,0)) -> 31 | M2: =IFERROR(_xlfn.XLOOKUP($A2,Input_Raw!$A:$A,Input_Raw!$CQ:$CQ),"") -> 4.6409091 | N2: =IFERROR(_xlfn.XLOOKUP($A2,Input_Raw!$A:$A,Input_Raw!$CR:$CR),"") -> 5.68 | O2: =IFERROR(P2*Q2,"") -> 0.9685133 | P2: =IFERROR(1-SUMIF(WTG_BD!$F:$F,$A2,WTG_BD!$AA:$AA)/($AA2+SUMIF(WTG_BD!$F:$F,$A2,WTG_BD!$AA:$AA)),"") -> 0.99330876 | Q2: =IFERROR(1-SUMIF(IGA_BD!$F:$F,$A2,IGA_BD!$W:$W)/($AA2+SUMIF(IGA_BD!$F:$F,$A2,IGA_BD!$W:$W)),"") -> 0.97503752 | R2: =IFERROR(1-SUMIF(Grid_BD!$F:$F,$A2,Grid_BD!$Y:$Y)/($AA2+SUMIF(Grid_BD!$F:$F,$A2,Grid_BD!$Y:$Y)),"") -> 1 | W2: =IFERROR(X2/(24*AB2*1000),"") -> 0.099985204 | X2: =IFERROR(_xlfn.XLOOKUP($A2,Input_Raw!$A:$A,Input_Raw!$CP:$CP)*1000,"") -> 168935 | Y2: =IFERROR(_xlfn.XLOOKUP($A2,Input_Raw!$A:$A,Input_Raw!DJ:DJ)*1000,"") -> 168935 | Z2: =IFERROR(_xlfn.XLOOKUP($A2,Input_Raw!$A:$A,Input_Raw!DK:DK)*1000,"") -> 0 | AA2: =IFERROR(Y2-Z2,"") -> 168935 | AB2: =IFERROR(_xlfn.XLOOKUP($A2,Input_Raw!$A:$A,Input_Raw!$DR:$DR),"") -> 70.4 | AC2: =IFERROR(_xlfn.XLOOKUP($D2,'Modelling New'!$D:$D,'Modelling New'!$J:$J),"") -> 4.565 | AD2: =IFERROR(_xlfn.XLOOKUP($D2,'Modelling New'!$D:$D,'Modelling New'!$T:$T)*1000,"") -> 177354.84 | AF2: =IFERROR(_xlfn.XLOOKUP($D2,'Modelling New'!$D:$D,'Modelling New'!$W:$W),"") -> 0.10496854 | AG2: =IFERROR(_xlfn.XLOOKUP($D2,'Modelling New'!$D:$D,'Modelling New'!$AE:$AE),"") -> 0.9603 | AH2: =IFERROR(_xlfn.XLOOKUP($D2,'Modelling New'!$D:$D,'Modelling New'!$AF:$AF),"") -> 0.995 | AI2: =IFERROR(_xlfn.XLOOKUP($A2,Input_Raw!$A:$A,Input_Raw!$DP:$DP),"") -> 156.79 | AN2: =IFERROR(_xlfn.XLOOKUP($A2,Input_Raw!$A:$A,Input_Raw!$DL:$DL),"") -> 0 | AO2: =IFERROR((_xlfn.XLOOKUP($A2,'WTG Reactive Power'!$A:$A,'WTG Reactive Power'!$AW:$AW))/X2,"") -> 0 | AP2: =IFERROR(_xlfn.XLOOKUP($D2,'Modelling New'!$D:$D,'Modelling New'!$AK:$AK),"") -> 0.05 | AQ2: =IFERROR(_xlfn.XLOOKUP($D2,'Modelling New'!$D:$D,'Modelling New'!$AL:$AL),"") -> 0.05 | AR2: =IFERROR(_xlfn.XLOOKUP($D2,'Modelling New'!$D:$D,'Modelling New'!$N:$N),"") -> 70.4
A3: =A2+1 -> 45746 | B3: =YEAR(Daily_KPI[[#This Row],[Date]])+IF(MONTH(Daily_KPI[[#This Row],[Date]])>=4,1,0) -> 2025 | C3: =YEAR(Daily_KPI[[#This Row],[Date]]) -> 2025 | D3: =Daily_KPI[[#This Row],[Date]]-DAY(Daily_KPI[[#This Row],[Date]])+1 -> 45717 | E3: =DAY(EOMONTH(A3,0)) -> 31 | M3: =IFERROR(_xlfn.XLOOKUP($A3,Input_Raw!$A:$A,Input_Raw!$CQ:$CQ),"") -> 4.9325 | N3: =IFERROR(_xlfn.XLOOKUP($A3,Input_Raw!$A:$A,Input_Raw!$CR:$CR),"") -> 6.15 | O3: =IFERROR(P3*Q3,"") -> 0.99496953 | P3: =IFERROR(1-SUMIF(WTG_BD!$F:$F,$A3,WTG_BD!$AA:$AA)/($AA3+SUMIF(WTG_BD!$F:$F,$A3,WTG_BD!$AA:$AA)),"") -> 1 | Q3: =IFERROR(1-SUMIF(IGA_BD!$F:$F,$A3,IGA_BD!$W:$W)/($AA3+SUMIF(IGA_BD!$F:$F,$A3,IGA_BD!$W:$W)),"") -> 0.99496953 | R3: =IFERROR(1-SUMIF(Grid_BD!$F:$F,$A3,Grid_BD!$Y:$Y)/($AA3+SUMIF(Grid_BD!$F:$F,$A3,Grid_BD!$Y:$Y)),"") -> 1 | W3: =IFERROR(X3/(24*AB3*1000),"") -> 0.11237985 | X3: =IFERROR(_xlfn.XLOOKUP($A3,Input_Raw!$A:$A,Input_Raw!$CP:$CP)*1000,"") -> 189877 | Y3: =IFERROR(_xlfn.XLOOKUP($A3,Input_Raw!$A:$A,Input_Raw!DJ:DJ)*1000,"") -> 189877 | Z3: =IFERROR(_xlfn.XLOOKUP($A3,Input_Raw!$A:$A,Input_Raw!DK:DK)*1000,"") -> 0 | AA3: =IFERROR(Y3-Z3,"") -> 189877 | AB3: =IFERROR(_xlfn.XLOOKUP($A3,Input_Raw!$A:$A,Input_Raw!$DR:$DR),"") -> 70.4 | AC3: =IFERROR(_xlfn.XLOOKUP($D3,'Modelling New'!$D:$D,'Modelling New'!$J:$J),"") -> 4.565 | AD3: =IFERROR(_xlfn.XLOOKUP($D3,'Modelling New'!$D:$D,'Modelling New'!$T:$T)*1000,"") -> 177354.84 | AF3: =IFERROR(_xlfn.XLOOKUP($D3,'Modelling New'!$D:$D,'Modelling New'!$W:$W),"") -> 0.10496854 | AG3: =IFERROR(_xlfn.XLOOKUP($D3,'Modelling New'!$D:$D,'Modelling New'!$AE:$AE),"") -> 0.9603 | AH3: =IFERROR(_xlfn.XLOOKUP($D3,'Modelling New'!$D:$D,'Modelling New'!$AF:$AF),"") -> 0.995 | AI3: =IFERROR(_xlfn.XLOOKUP($A3,Input_Raw!$A:$A,Input_Raw!$DP:$DP),"") -> 162.74 | AN3: =IFERROR(_xlfn.XLOOKUP($A3,Input_Raw!$A:$A,Input_Raw!$DL:$DL),"") -> 0 | AO3: =IFERROR((_xlfn.XLOOKUP($A3,'WTG Reactive Power'!$A:$A,'WTG Reactive Power'!$AW:$AW))/X3,"") -> 0 | AP3: =IFERROR(_xlfn.XLOOKUP($D3,'Modelling New'!$D:$D,'Modelling New'!$AK:$AK),"") -> 0.05 | AQ3: =IFERROR(_xlfn.XLOOKUP($D3,'Modelling New'!$D:$D,'Modelling New'!$AL:$AL),"") -> 0.05 | AR3: =IFERROR(_xlfn.XLOOKUP($D3,'Modelling New'!$D:$D,'Modelling New'!$N:$N),"") -> 70.4
A4: =A3+1 -> 45747 | B4: =YEAR(Daily_KPI[[#This Row],[Date]])+IF(MONTH(Daily_KPI[[#This Row],[Date]])>=4,1,0) -> 2025 | C4: =YEAR(Daily_KPI[[#This Row],[Date]]) -> 2025 | D4: =Daily_KPI[[#This Row],[Date]]-DAY(Daily_KPI[[#This Row],[Date]])+1 -> 45717 | E4: =DAY(EOMONTH(A4,0)) -> 31 | M4: =IFERROR(_xlfn.XLOOKUP($A4,Input_Raw!$A:$A,Input_Raw!$CQ:$CQ),"") -> 3.7163636 | N4: =IFERROR(_xlfn.XLOOKUP($A4,Input_Raw!$A:$A,Input_Raw!$CR:$CR),"") -> 4.75 | O4: =IFERROR(P4*Q4,"") -> 0.95403199 | P4: =IFERROR(1-SUMIF(WTG_BD!$F:$F,$A4,WTG_BD!$AA:$AA)/($AA4+SUMIF(WTG_BD!$F:$F,$A4,WTG_BD!$AA:$AA)),"") -> 0.99594967 | Q4: =IFERROR(1-SUMIF(IGA_BD!$F:$F,$A4,IGA_BD!$W:$W)/($AA4+SUMIF(IGA_BD!$F:$F,$A4,IGA_BD!$W:$W)),"") -> 0.95791185 | R4: =IFERROR(1-SUMIF(Grid_BD!$F:$F,$A4,Grid_BD!$Y:$Y)/($AA4+SUMIF(Grid_BD!$F:$F,$A4,Grid_BD!$Y:$Y)),"") -> 1 | W4: =IFERROR(X4/(24*AB4*1000),"") -> 0.051955492 | X4: =IFERROR(_xlfn.XLOOKUP($A4,Input_Raw!$A:$A,Input_Raw!$CP:$CP)*1000,"") -> 87784 | Y4: =IFERROR(_xlfn.XLOOKUP($A4,Input_Raw!$A:$A,Input_Raw!DJ:DJ)*1000,"") -> 87784 | Z4: =IFERROR(_xlfn.XLOOKUP($A4,Input_Raw!$A:$A,Input_Raw!DK:DK)*1000,"") -> 0 | AA4: =IFERROR(Y4-Z4,"") -> 87784 | AB4: =IFERROR(_xlfn.XLOOKUP($A4,Input_Raw!$A:$A,Input_Raw!$DR:$DR),"") -> 70.4 | AC4: =IFERROR(_xlfn.XLOOKUP($D4,'Modelling New'!$D:$D,'Modelling New'!$J:$J),"") -> 4.565 | AD4: =IFERROR(_xlfn.XLOOKUP($D4,'Modelling New'!$D:$D,'Modelling New'!$T:$T)*1000,"") -> 177354.84 | AF4: =IFERROR(_xlfn.XLOOKUP($D4,'Modelling New'!$D:$D,'Modelling New'!$W:$W),"") -> 0.10496854 | AG4: =IFERROR(_xlfn.XLOOKUP($D4,'Modelling New'!$D:$D,'Modelling New'!$AE:$AE),"") -> 0.9603 | AH4: =IFERROR(_xlfn.XLOOKUP($D4,'Modelling New'!$D:$D,'Modelling New'!$AF:$AF),"") -> 0.995 | AI4: =IFERROR(_xlfn.XLOOKUP($A4,Input_Raw!$A:$A,Input_Raw!$DP:$DP),"") -> 66.47 | AN4: =IFERROR(_xlfn.XLOOKUP($A4,Input_Raw!$A:$A,Input_Raw!$DL:$DL),"") -> -1.110223e-16 | AO4: =IFERROR((_xlfn.XLOOKUP($A4,'WTG Reactive Power'!$A:$A,'WTG Reactive Power'!$AW:$AW))/X4,"") -> 0 | AP4: =IFERROR(_xlfn.XLOOKUP($D4,'Modelling New'!$D:$D,'Modelling New'!$AK:$AK),"") -> 0.05 | AQ4: =IFERROR(_xlfn.XLOOKUP($D4,'Modelling New'!$D:$D,'Modelling New'!$AL:$AL),"") -> 0.05 | AR4: =IFERROR(_xlfn.XLOOKUP($D4,'Modelling New'!$D:$D,'Modelling New'!$N:$N),"") -> 70.4
A5: =A4+1 -> 45748 | B5: =YEAR(Daily_KPI[[#This Row],[Date]])+IF(MONTH(Daily_KPI[[#This Row],[Date]])>=4,1,0) -> 2026 | C5: =YEAR(Daily_KPI[[#This Row],[Date]]) -> 2025 | D5: =Daily_KPI[[#This Row],[Date]]-DAY(Daily_KPI[[#This Row],[Date]])+1 -> 45748 | E5: =DAY(EOMONTH(A5,0)) -> 30 | M5: =IFERROR(_xlfn.XLOOKUP($A5,Input_Raw!$A:$A,Input_Raw!$CQ:$CQ),"") -> 5.0677273 | N5: =IFERROR(_xlfn.XLOOKUP($A5,Input_Raw!$A:$A,Input_Raw!$CR:$CR),"") -> 6.47 | O5: =IFERROR(P5*Q5,"") -> 0.85430306 | P5: =IFERROR(1-SUMIF(WTG_BD!$F:$F,$A5,WTG_BD!$AA:$AA)/($AA5+SUMIF(WTG_BD!$F:$F,$A5,WTG_BD!$AA:$AA)),"") -> 0.98556093 | Q5: =IFERROR(1-SUMIF(IGA_BD!$F:$F,$A5,IGA_BD!$W:$W)/($AA5+SUMIF(IGA_BD!$F:$F,$A5,IGA_BD!$W:$W)),"") -> 0.86681912 | R5: =IFERROR(1-SUMIF(Grid_BD!$F:$F,$A5,Grid_BD!$Y:$Y)/($AA5+SUMIF(Grid_BD!$F:$F,$A5,Grid_BD!$Y:$Y)),"") -> 1 | W5: =IFERROR(X5/(24*AB5*1000),"") -> 0.14470585 | X5: =IFERROR(_xlfn.XLOOKUP($A5,Input_Raw!$A:$A,Input_Raw!$CP:$CP)*1000,"") -> 244495 | Y5: =IFERROR(_xlfn.XLOOKUP($A5,Input_Raw!$A:$A,Input_Raw!DJ:DJ)*1000,"") -> 244495 | Z5: =IFERROR(_xlfn.XLOOKUP($A5,Input_Raw!$A:$A,Input_Raw!DK:DK)*1000,"") -> 0 | AA5: =IFERROR(Y5-Z5,"") -> 244495 | AB5: =IFERROR(_xlfn.XLOOKUP($A5,Input_Raw!$A:$A,Input_Raw!$DR:$DR),"") -> 70.4 | AC5: =IFERROR(_xlfn.XLOOKUP($D5,'Modelling New'!$D:$D,'Modelling New'!$J:$J),"") -> 5.22 | AD5: =IFERROR(_xlfn.XLOOKUP($D5,'Modelling New'!$D:$D,'Modelling New'!$T:$T)*1000,"") -> 228113.28 | AF5: =IFERROR(_xlfn.XLOOKUP($D5,'Modelling New'!$D:$D,'Modelling New'!$W:$W),"") -> 0.13501023 | AG5: =IFERROR(_xlfn.XLOOKUP($D5,'Modelling New'!$D:$D,'Modelling New'!$AE:$AE),"") -> 0.9603 | AH5: =IFERROR(_xlfn.XLOOKUP($D5,'Modelling New'!$D:$D,'Modelling New'!$AF:$AF),"") -> 0.995 | AI5: =IFERROR(_xlfn.XLOOKUP($A5,Input_Raw!$A:$A,Input_Raw!$DP:$DP),"") -> 261.94 | AN5: =IFERROR(_xlfn.XLOOKUP($A5,Input_Raw!$A:$A,Input_Raw!$DL:$DL),"") -> -1.110223e-16 | AO5: =IFERROR((_xlfn.XLOOKUP($A5,'WTG Reactive Power'!$A:$A,'WTG Reactive Power'!$AW:$AW))/X5,"") -> 0.00015263608 | AP5: =IFERROR(_xlfn.XLOOKUP($D5,'Modelling New'!$D:$D,'Modelling New'!$AK:$AK),"") -> 0.05 | AQ5: =IFERROR(_xlfn.XLOOKUP($D5,'Modelling New'!$D:$D,'Modelling New'!$AL:$AL),"") -> 0.05 | AR5: =IFERROR(_xlfn.XLOOKUP($D5,'Modelling New'!$D:$D,'Modelling New'!$N:$N),"") -> 70.4
A6: =A5+1 -> 45749 | B6: =YEAR(Daily_KPI[[#This Row],[Date]])+IF(MONTH(Daily_KPI[[#This Row],[Date]])>=4,1,0) -> 2026 | C6: =YEAR(Daily_KPI[[#This Row],[Date]]) -> 2025 | D6: =Daily_KPI[[#This Row],[Date]]-DAY(Daily_KPI[[#This Row],[Date]])+1 -> 45748 | E6: =DAY(EOMONTH(A6,0)) -> 30 | M6: =IFERROR(_xlfn.XLOOKUP($A6,Input_Raw!$A:$A,Input_Raw!$CQ:$CQ),"") -> 5.4718182 | N6: =IFERROR(_xlfn.XLOOKUP($A6,Input_Raw!$A:$A,Input_Raw!$CR:$CR),"") -> 6.87 | O6: =IFERROR(P6*Q6,"") -> 0.9684354 | P6: =IFERROR(1-SUMIF(WTG_BD!$F:$F,$A6,WTG_BD!$AA:$AA)/($AA6+SUMIF(WTG_BD!$F:$F,$A6,WTG_BD!$AA:$AA)),"") -> 0.99116239 | Q6: =IFERROR(1-SUMIF(IGA_BD!$F:$F,$A6,IGA_BD!$W:$W)/($AA6+SUMIF(IGA_BD!$F:$F,$A6,IGA_BD!$W:$W)),"") -> 0.97707037 | R6: =IFERROR(1-SUMIF(Grid_BD!$F:$F,$A6,Grid_BD!$Y:$Y)/($AA6+SUMIF(Grid_BD!$F:$F,$A6,Grid_BD!$Y:$Y)),"") -> 1 | W6: =IFERROR(X6/(24*AB6*1000),"") -> 0.18685488 | X6: =IFERROR(_xlfn.XLOOKUP($A6,Input_Raw!$A:$A,Input_Raw!$CP:$CP)*1000,"") -> 315710 | Y6: =IFERROR(_xlfn.XLOOKUP($A6,Input_Raw!$A:$A,Input_Raw!DJ:DJ)*1000,"") -> 315710 | Z6: =IFERROR(_xlfn.XLOOKUP($A6,Input_Raw!$A:$A,Input_Raw!DK:DK)*1000,"") -> 0 | AA6: =IFERROR(Y6-Z6,"") -> 315710 | AB6: =IFERROR(_xlfn.XLOOKUP($A6,Input_Raw!$A:$A,Input_Raw!$DR:$DR),"") -> 70.4 | AC6: =IFERROR(_xlfn.XLOOKUP($D6,'Modelling New'!$D:$D,'Modelling New'!$J:$J),"") -> 5.22 | AD6: =IFERROR(_xlfn.XLOOKUP($D6,'Modelling New'!$D:$D,'Modelling New'!$T:$T)*1000,"") -> 228113.28 | AF6: =IFERROR(_xlfn.XLOOKUP($D6,'Modelling New'!$D:$D,'Modelling New'!$W:$W),"") -> 0.13501023 | AG6: =IFERROR(_xlfn.XLOOKUP($D6,'Modelling New'!$D:$D,'Modelling New'!$AE:$AE),"") -> 0.9603 | AH6: =IFERROR(_xlfn.XLOOKUP($D6,'Modelling New'!$D:$D,'Modelling New'!$AF:$AF),"") -> 0.995 | AI6: =IFERROR(_xlfn.XLOOKUP($A6,Input_Raw!$A:$A,Input_Raw!$DP:$DP),"") -> 310.38 | AN6: =IFERROR(_xlfn.XLOOKUP($A6,Input_Raw!$A:$A,Input_Raw!$DL:$DL),"") -> 2.220446e-16 | AO6: =IFERROR((_xlfn.XLOOKUP($A6,'WTG Reactive Power'!$A:$A,'WTG Reactive Power'!$AW:$AW))/X6,"") -> 0.00020143081 | AP6: =IFERROR(_xlfn.XLOOKUP($D6,'Modelling New'!$D:$D,'Modelling New'!$AK:$AK),"") -> 0.05 | AQ6: =IFERROR(_xlfn.XLOOKUP($D6,'Modelling New'!$D:$D,'Modelling New'!$AL:$AL),"") -> 0.05 | AR6: =IFERROR(_xlfn.XLOOKUP($D6,'Modelling New'!$D:$D,'Modelling New'!$N:$N),"") -> 70.4
A7: =A6+1 -> 45750 | B7: =YEAR(Daily_KPI[[#This Row],[Date]])+IF(MONTH(Daily_KPI[[#This Row],[Date]])>=4,1,0) -> 2026 | C7: =YEAR(Daily_KPI[[#This Row],[Date]]) -> 2025 | D7: =Daily_KPI[[#This Row],[Date]]-DAY(Daily_KPI[[#This Row],[Date]])+1 -> 45748 | E7: =DAY(EOMONTH(A7,0)) -> 30 | M7: =IFERROR(_xlfn.XLOOKUP($A7,Input_Raw!$A:$A,Input_Raw!$CQ:$CQ),"") -> 3.5081818 | N7: =IFERROR(_xlfn.XLOOKUP($A7,Input_Raw!$A:$A,Input_Raw!$CR:$CR),"") -> 4.18 | O7: =IFERROR(P7*Q7,"") -> 0.94448319 | P7: =IFERROR(1-SUMIF(WTG_BD!$F:$F,$A7,WTG_BD!$AA:$AA)/($AA7+SUMIF(WTG_BD!$F:$F,$A7,WTG_BD!$AA:$AA)),"") -> 0.98408339 | Q7: =IFERROR(1-SUMIF(IGA_BD!$F:$F,$A7,IGA_BD!$W:$W)/($AA7+SUMIF(IGA_BD!$F:$F,$A7,IGA_BD!$W:$W)),"") -> 0.9597593 | R7: =IFERROR(1-SUMIF(Grid_BD!$F:$F,$A7,Grid_BD!$Y:$Y)/($AA7+SUMIF(Grid_BD!$F:$F,$A7,Grid_BD!$Y:$Y)),"") -> 1 | W7: =IFERROR(X7/(24*AB7*1000),"") -> 0.045594815 | X7: =IFERROR(_xlfn.XLOOKUP($A7,Input_Raw!$A:$A,Input_Raw!$CP:$CP)*1000,"") -> 77037 | Y7: =IFERROR(_xlfn.XLOOKUP($A7,Input_Raw!$A:$A,Input_Raw!DJ:DJ)*1000,"") -> 77037 | Z7: =IFERROR(_xlfn.XLOOKUP($A7,Input_Raw!$A:$A,Input_Raw!DK:DK)*1000,"") -> 0 | AA7: =IFERROR(Y7-Z7,"") -> 77037 | AB7: =IFERROR(_xlfn.XLOOKUP($A7,Input_Raw!$A:$A,Input_Raw!$DR:$DR),"") -> 70.4 | AC7: =IFERROR(_xlfn.XLOOKUP($D7,'Modelling New'!$D:$D,'Modelling New'!$J:$J),"") -> 5.22 | AD7: =IFERROR(_xlfn.XLOOKUP($D7,'Modelling New'!$D:$D,'Modelling New'!$T:$T)*1000,"") -> 228113.28 | AF7: =IFERROR(_xlfn.XLOOKUP($D7,'Modelling New'!$D:$D,'Modelling New'!$W:$W),"") -> 0.13501023 | AG7: =IFERROR(_xlfn.XLOOKUP($D7,'Modelling New'!$D:$D,'Modelling New'!$AE:$AE),"") -> 0.9603 | AH7: =IFERROR(_xlfn.XLOOKUP($D7,'Modelling New'!$D:$D,'Modelling New'!$AF:$AF),"") -> 0.995 | AI7: =IFERROR(_xlfn.XLOOKUP($A7,Input_Raw!$A:$A,Input_Raw!$DP:$DP),"") -> 72.74 | AN7: =IFERROR(_xlfn.XLOOKUP($A7,Input_Raw!$A:$A,Input_Raw!$DL:$DL),"") -> 0 | AO7: =IFERROR((_xlfn.XLOOKUP($A7,'WTG Reactive Power'!$A:$A,'WTG Reactive Power'!$AW:$AW))/X7,"") -> 0.00019425753 | AP7: =IFERROR(_xlfn.XLOOKUP($D7,'Modelling New'!$D:$D,'Modelling New'!$AK:$AK),"") -> 0.05 | AQ7: =IFERROR(_xlfn.XLOOKUP($D7,'Modelling New'!$D:$D,'Modelling New'!$AL:$AL),"") -> 0.05 | AR7: =IFERROR(_xlfn.XLOOKUP($D7,'Modelling New'!$D:$D,'Modelling New'!$N:$N),"") -> 70.4
A8: =A7+1 -> 45751 | B8: =YEAR(Daily_KPI[[#This Row],[Date]])+IF(MONTH(Daily_KPI[[#This Row],[Date]])>=4,1,0) -> 2026 | C8: =YEAR(Daily_KPI[[#This Row],[Date]]) -> 2025 | D8: =Daily_KPI[[#This Row],[Date]]-DAY(Daily_KPI[[#This Row],[Date]])+1 -> 45748 | E8: =DAY(EOMONTH(A8,0)) -> 30 | M8: =IFERROR(_xlfn.XLOOKUP($A8,Input_Raw!$A:$A,Input_Raw!$CQ:$CQ),"") -> 4.1436364 | N8: =IFERROR(_xlfn.XLOOKUP($A8,Input_Raw!$A:$A,Input_Raw!$CR:$CR),"") -> 5.01 | O8: =IFERROR(P8*Q8,"") -> 0.93438565 | P8: =IFERROR(1-SUMIF(WTG_BD!$F:$F,$A8,WTG_BD!$AA:$AA)/($AA8+SUMIF(WTG_BD!$F:$F,$A8,WTG_BD!$AA:$AA)),"") -> 0.99976116 | Q8: =IFERROR(1-SUMIF(IGA_BD!$F:$F,$A8,IGA_BD!$W:$W)/($AA8+SUMIF(IGA_BD!$F:$F,$A8,IGA_BD!$W:$W)),"") -> 0.93460888 | R8: =IFERROR(1-SUMIF(Grid_BD!$F:$F,$A8,Grid_BD!$Y:$Y)/($AA8+SUMIF(Grid_BD!$F:$F,$A8,Grid_BD!$Y:$Y)),"") -> 1 | W8: =IFERROR(X8/(24*AB8*1000),"") -> 0.06936849 | X8: =IFERROR(_xlfn.XLOOKUP($A8,Input_Raw!$A:$A,Input_Raw!$CP:$CP)*1000,"") -> 117205 | Y8: =IFERROR(_xlfn.XLOOKUP($A8,Input_Raw!$A:$A,Input_Raw!DJ:DJ)*1000,"") -> 117205 | Z8: =IFERROR(_xlfn.XLOOKUP($A8,Input_Raw!$A:$A,Input_Raw!DK:DK)*1000,"") -> 0 | AA8: =IFERROR(Y8-Z8,"") -> 117205 | AB8: =IFERROR(_xlfn.XLOOKUP($A8,Input_Raw!$A:$A,Input_Raw!$DR:$DR),"") -> 70.4 | AC8: =IFERROR(_xlfn.XLOOKUP($D8,'Modelling New'!$D:$D,'Modelling New'!$J:$J),"") -> 5.22 | AD8: =IFERROR(_xlfn.XLOOKUP($D8,'Modelling New'!$D:$D,'Modelling New'!$T:$T)*1000,"") -> 228113.28 | AF8: =IFERROR(_xlfn.XLOOKUP($D8,'Modelling New'!$D:$D,'Modelling New'!$W:$W),"") -> 0.13501023 | AG8: =IFERROR(_xlfn.XLOOKUP($D8,'Modelling New'!$D:$D,'Modelling New'!$AE:$AE),"") -> 0.9603 | AH8: =IFERROR(_xlfn.XLOOKUP($D8,'Modelling New'!$D:$D,'Modelling New'!$AF:$AF),"") -> 0.995 | AI8: =IFERROR(_xlfn.XLOOKUP($A8,Input_Raw!$A:$A,Input_Raw!$DP:$DP),"") -> 115.35 | AN8: =IFERROR(_xlfn.XLOOKUP($A8,Input_Raw!$A:$A,Input_Raw!$DL:$DL),"") -> 0 | AO8: =IFERROR((_xlfn.XLOOKUP($A8,'WTG Reactive Power'!$A:$A,'WTG Reactive Power'!$AW:$AW))/X8,"") -> 0.00017643351 | AP8: =IFERROR(_xlfn.XLOOKUP($D8,'Modelling New'!$D:$D,'Modelling New'!$AK:$AK),"") -> 0.05 | AQ8: =IFERROR(_xlfn.XLOOKUP($D8,'Modelling New'!$D:$D,'Modelling New'!$AL:$AL),"") -> 0.05 | AR8: =IFERROR(_xlfn.XLOOKUP($D8,'Modelling New'!$D:$D,'Modelling New'!$N:$N),"") -> 70.4
A9: =A8+1 -> 45752 | B9: =YEAR(Daily_KPI[[#This Row],[Date]])+IF(MONTH(Daily_KPI[[#This Row],[Date]])>=4,1,0) -> 2026 | C9: =YEAR(Daily_KPI[[#This Row],[Date]]) -> 2025 | D9: =Daily_KPI[[#This Row],[Date]]-DAY(Daily_KPI[[#This Row],[Date]])+1 -> 45748 | E9: =DAY(EOMONTH(A9,0)) -> 30 | M9: =IFERROR(_xlfn.XLOOKUP($A9,Input_Raw!$A:$A,Input_Raw!$CQ:$CQ),"") -> 4.4490909 | N9: =IFERROR(_xlfn.XLOOKUP($A9,Input_Raw!$A:$A,Input_Raw!$CR:$CR),"") -> 5.5 | O9: =IFERROR(P9*Q9,"") -> 0.93031776 | P9: =IFERROR(1-SUMIF(WTG_BD!$F:$F,$A9,WTG_BD!$AA:$AA)/($AA9+SUMIF(WTG_BD!$F:$F,$A9,WTG_BD!$AA:$AA)),"") -> 0.94991093 | Q9: =IFERROR(1-SUMIF(IGA_BD!$F:$F,$A9,IGA_BD!$W:$W)/($AA9+SUMIF(IGA_BD!$F:$F,$A9,IGA_BD!$W:$W)),"") -> 0.97937368 | R9: =IFERROR(1-SUMIF(Grid_BD!$F:$F,$A9,Grid_BD!$Y:$Y)/($AA9+SUMIF(Grid_BD!$F:$F,$A9,Grid_BD!$Y:$Y)),"") -> 1 | W9: =IFERROR(X9/(24*AB9*1000),"") -> 0.075426728 | X9: =IFERROR(_xlfn.XLOOKUP($A9,Input_Raw!$A:$A,Input_Raw!$CP:$CP)*1000,"") -> 127441 | Y9: =IFERROR(_xlfn.XLOOKUP($A9,Input_Raw!$A:$A,Input_Raw!DJ:DJ)*1000,"") -> 127441 | Z9: =IFERROR(_xlfn.XLOOKUP($A9,Input_Raw!$A:$A,Input_Raw!DK:DK)*1000,"") -> 0 | AA9: =IFERROR(Y9-Z9,"") -> 127441 | AB9: =IFERROR(_xlfn.XLOOKUP($A9,Input_Raw!$A:$A,Input_Raw!$DR:$DR),"") -> 70.4 | AC9: =IFERROR(_xlfn.XLOOKUP($D9,'Modelling New'!$D:$D,'Modelling New'!$J:$J),"") -> 5.22 | AD9: =IFERROR(_xlfn.XLOOKUP($D9,'Modelling New'!$D:$D,'Modelling New'!$T:$T)*1000,"") -> 228113.28 | AF9: =IFERROR(_xlfn.XLOOKUP($D9,'Modelling New'!$D:$D,'Modelling New'!$W:$W),"") -> 0.13501023 | AG9: =IFERROR(_xlfn.XLOOKUP($D9,'Modelling New'!$D:$D,'Modelling New'!$AE:$AE),"") -> 0.9603 | AH9: =IFERROR(_xlfn.XLOOKUP($D9,'Modelling New'!$D:$D,'Modelling New'!$AF:$AF),"") -> 0.995 | AI9: =IFERROR(_xlfn.XLOOKUP($A9,Input_Raw!$A:$A,Input_Raw!$DP:$DP),"") -> 127.87 | AN9: =IFERROR(_xlfn.XLOOKUP($A9,Input_Raw!$A:$A,Input_Raw!$DL:$DL),"") -> 0 | AO9: =IFERROR((_xlfn.XLOOKUP($A9,'WTG Reactive Power'!$A:$A,'WTG Reactive Power'!$AW:$AW))/X9,"") -> 2.7043742e-05 | AP9: =IFERROR(_xlfn.XLOOKUP($D9,'Modelling New'!$D:$D,'Modelling New'!$AK:$AK),"") -> 0.05 | AQ9: =IFERROR(_xlfn.XLOOKUP($D9,'Modelling New'!$D:$D,'Modelling New'!$AL:$AL),"") -> 0.05 | AR9: =IFERROR(_xlfn.XLOOKUP($D9,'Modelling New'!$D:$D,'Modelling New'!$N:$N),"") -> 70.4
A10: =A9+1 -> 45753 | B10: =YEAR(Daily_KPI[[#This Row],[Date]])+IF(MONTH(Daily_KPI[[#This Row],[Date]])>=4,1,0) -> 2026 | C10: =YEAR(Daily_KPI[[#This Row],[Date]]) -> 2025 | D10: =Daily_KPI[[#This Row],[Date]]-DAY(Daily_KPI[[#This Row],[Date]])+1 -> 45748 | E10: =DAY(EOMONTH(A10,0)) -> 30 | M10: =IFERROR(_xlfn.XLOOKUP($A10,Input_Raw!$A:$A,Input_Raw!$CQ:$CQ),"") -> 3.8152273 | N10: =IFERROR(_xlfn.XLOOKUP($A10,Input_Raw!$A:$A,Input_Raw!$CR:$CR),"") -> 4.7 | O10: =IFERROR(P10*Q10,"") -> 0.96942977 | P10: =IFERROR(1-SUMIF(WTG_BD!$F:$F,$A10,WTG_BD!$AA:$AA)/($AA10+SUMIF(WTG_BD!$F:$F,$A10,WTG_BD!$AA:$AA)),"") -> 0.99866338 | Q10: =IFERROR(1-SUMIF(IGA_BD!$F:$F,$A10,IGA_BD!$W:$W)/($AA10+SUMIF(IGA_BD!$F:$F,$A10,IGA_BD!$W:$W)),"") -> 0.97072727 | R10: =IFERROR(1-SUMIF(Grid_BD!$F:$F,$A10,Grid_BD!$Y:$Y)/($AA10+SUMIF(Grid_BD!$F:$F,$A10,Grid_BD!$Y:$Y)),"") -> 1 | W10: =IFERROR(X10/(24*AB10*1000),"") -> 0.057486979 | X10: =IFERROR(_xlfn.XLOOKUP($A10,Input_Raw!$A:$A,Input_Raw!$CP:$CP)*1000,"") -> 97130 | Y10: =IFERROR(_xlfn.XLOOKUP($A10,Input_Raw!$A:$A,Input_Raw!DJ:DJ)*1000,"") -> 97130 | Z10: =IFERROR(_xlfn.XLOOKUP($A10,Input_Raw!$A:$A,Input_Raw!DK:DK)*1000,"") -> 0 | AA10: =IFERROR(Y10-Z10,"") -> 97130 | AB10: =IFERROR(_xlfn.XLOOKUP($A10,Input_Raw!$A:$A,Input_Raw!$DR:$DR),"") -> 70.4 | AC10: =IFERROR(_xlfn.XLOOKUP($D10,'Modelling New'!$D:$D,'Modelling New'!$J:$J),"") -> 5.22 | AD10: =IFERROR(_xlfn.XLOOKUP($D10,'Modelling New'!$D:$D,'Modelling New'!$T:$T)*1000,"") -> 228113.28 | AF10: =IFERROR(_xlfn.XLOOKUP($D10,'Modelling New'!$D:$D,'Modelling New'!$W:$W),"") -> 0.13501023 | AG10: =IFERROR(_xlfn.XLOOKUP($D10,'Modelling New'!$D:$D,'Modelling New'!$AE:$AE),"") -> 0.9603 | AH10: =IFERROR(_xlfn.XLOOKUP($D10,'Modelling New'!$D:$D,'Modelling New'!$AF:$AF),"") -> 0.995 | AI10: =IFERROR(_xlfn.XLOOKUP($A10,Input_Raw!$A:$A,Input_Raw!$DP:$DP),"") -> 89.31 | AN10: =IFERROR(_xlfn.XLOOKUP($A10,Input_Raw!$A:$A,Input_Raw!$DL:$DL),"") -> 0 | AO10: =IFERROR((_xlfn.XLOOKUP($A10,'WTG Reactive Power'!$A:$A,'WTG Reactive Power'!$AW:$AW))/X10,"") -> 5.9138638e-06 | AP10: =IFERROR(_xlfn.XLOOKUP($D10,'Modelling New'!$D:$D,'Modelling New'!$AK:$AK),"") -> 0.05 | AQ10: =IFERROR(_xlfn.XLOOKUP($D10,'Modelling New'!$D:$D,'Modelling New'!$AL:$AL),"") -> 0.05 | AR10: =IFERROR(_xlfn.XLOOKUP($D10,'Modelling New'!$D:$D,'Modelling New'!$N:$N),"") -> 70.4
