Workbook

Sheet O2Summary
A2: Performance Summary CEPPL
A3: Month | B3: 45839
A4: Date | B4: 45857
A5: Operation Year | B5: Year-3
A6: Year Start Date | B6: 45748
A7: Year End Date | B7: 46112
A9: Sr. No. | B9: Particular | C9: Target | D9: Measured | E9: Deviation | F9: Remarks | I9: Top Generator | J9: Generation (MWh) | K9: Least Generator | L9: Generation (MWh)
A10: 1 | B10: E_Grid Daily (MWh) | C10: =_xlfn.XLOOKUP($B$4,'Daily KPI'!$A:$A,'Daily KPI'!$AD:$AD)/1000 -> 815.98323 | D10: =_xlfn.XLOOKUP($B$4,'Daily KPI'!$A:$A,'Daily KPI'!$X:$X,"")*(1+MonthlyKPI!Q4)/1000 -> 571.9123 | E10: =D10/C10-1 -> -0.29911267 | I10: =_xlfn.XLOOKUP(1,Analytics!40:40,Analytics!$5:$5) -> KUD16 | J10: =_xlfn.XLOOKUP(I10,Analytics!$5:$5,Analytics!37:37)/1000 -> 29.6023 | K10: =_xlfn.XLOOKUP(23,Analytics!40:40,Analytics!$5:$5) -> KUD10 | L10: =_xlfn.XLOOKUP(K10,Analytics!$5:$5,Analytics!37:37)/1000 -> 22.1709
B11: E_Grid MTD(MWh) | C11: =MonthlyKPI!E4 -> 15503.681 | D11: =MonthlyKPI!F4*(1+MonthlyKPI!Q4) -> 15198.79 | E11: =D11/C11-1 -> -0.019665705 | I11: =_xlfn.XLOOKUP(1,Analytics!41:41,Analytics!$5:$5) -> KUD15 | J11: =_xlfn.XLOOKUP(I11,Analytics!$5:$5,Analytics!38:38)/1000 -> 731.7595 | K11: =_xlfn.XLOOKUP(23,Analytics!41:41,Analytics!$5:$5) -> KUD04 | L11: =_xlfn.XLOOKUP(K11,Analytics!$5:$5,Analytics!38:38)/1000 -> 622.0096
B12: E_Grid YTD (MWh) | C12: =AnnualKPI!E4 -> 58695.951 | D12: =AnnualKPI!F4*(1+AnnualKPI!Q4) -> 55137.544 | E12: =D12/C12-1 -> -0.06062441 | I12: =_xlfn.XLOOKUP(1,Analytics!42:42,Analytics!$5:$5) -> KUD15 | J12: =_xlfn.XLOOKUP(I12,Analytics!$5:$5,Analytics!39:39)/1000 -> 2730.6632 | K12: =_xlfn.XLOOKUP(23,Analytics!42:42,Analytics!$5:$5) -> KUD04 | L12: =_xlfn.XLOOKUP(K12,Analytics!$5:$5,Analytics!39:39)/1000 -> 2253.1536
A13: 2 | B13: Wind Speed Daily | C13: =_xlfn.XLOOKUP($B$3,'Modelling New'!$D:$D,'Modelling New'!$J:$J) -> 10.303759 | D13: =_xlfn.XLOOKUP($B$4,'Daily KPI'!$A:$A,'Daily KPI'!$M:$M,0) -> 7.1608696 | E13: =(D13-C13)/(C13) -> -0.3050236
B14: Wind Speed MTD | C14: =_xlfn.XLOOKUP($B$3,'Modelling New'!$D:$D,'Modelling New'!$AC:$AC) -> 10.303759 | D14: =MonthlyKPI!D4 -> 9.0608696 | E14: =(D14-C14)/(C14) -> -0.12062489 | L14: Last 7 Days Performance
B15: Wind Speed YTD | C15: =_xlfn.XLOOKUP($B$3,'Modelling New'!$D:$D,'Modelling New'!$AD:$AD) -> 8.1297392 | D15: =AnnualKPI!D4 -> 6.7503737 | E15: =(D15-C15)/(C15) -> -0.16966909 | I15: Energy Loss (MWh)
A16: 3 | B16: MA Daily | C16: =_xlfn.XLOOKUP($B$3,'Modelling New'!$D:$D,'Modelling New'!$AH:$AH) -> 0.97 | D16: =_xlfn.XLOOKUP($B$4,'Daily KPI'!$A:$A,'Daily KPI'!$P:$P,0) -> 0.99343494 | E16: =(D16-C16)/(C16) -> 0.02415973 | I16: =SUMIF(WTG_BD!F:F,O2Summary!B4,WTG_BD!AA:AA)/1000 -> 3.655
B17: MA MTD | C17: =_xlfn.XLOOKUP($B$3,'Modelling New'!$D:$D,'Modelling New'!$AH:$AH) -> 0.97 | D17: =MonthlyKPI!L4 -> 0.99597608 | E17: =(D17-C17)/(C17) -> 0.026779463 | I17: =SUMIFS(WTG_BD!AA:AA,WTG_BD!F:F,">="&O2Summary!B3,WTG_BD!F:F,"<="&O2Summary!B4)/1000 -> 59.2233
B18: MA YTD | C18: =_xlfn.XLOOKUP($B$3,'Modelling New'!$D:$D,'Modelling New'!$AH:$AH) -> 0.97 | D18: =AnnualKPI!L4 -> 0.99617669 | E18: =(D18-C18)/(C18) -> 0.026986275 | I18: =SUMIFS(WTG_BD!AA:AA,WTG_BD!F:F,">="&O2Summary!B6,WTG_BD!F:F,"<="&O2Summary!B4)/1000 -> 194.75508
A19: 4 | B19: EGA Daily | C19: =_xlfn.XLOOKUP($B$3,'Modelling New'!$D:$D,'Modelling New'!$AF:$AF) -> 0.995 | D19: =_xlfn.XLOOKUP($B$4,'Daily KPI'!$A:$A,'Daily KPI'!$R:$R,0) -> 1 | E19: =(D19-C19)/(C19) -> 0.0050251256 | I19: =SUMIF(Grid_BD!F:F,O2Summary!B4,Grid_BD!Y:Y)/1000 -> 0
B20: EGA MTD | C20: =_xlfn.XLOOKUP($B$3,'Modelling New'!$D:$D,'Modelling New'!$AF:$AF) -> 0.995 | D20: =MonthlyKPI!J4 -> 1 | E20: =(D20-C20)/(C20) -> 0.0050251256 | I20: =SUMIFS(Grid_BD!Y:Y,Grid_BD!F:F,">="&O2Summary!B3,Grid_BD!F:F,"<="&O2Summary!B4)/1000 -> 0
B21: EGA YTD | C21: =_xlfn.XLOOKUP($B$3,'Modelling New'!$D:$D,'Modelling New'!$AF:$AF) -> 0.995 | D21: =AnnualKPI!J4 -> 0.99192067 | E21: =(D21-C21)/(C21) -> -0.0030948027 | I21: =SUMIFS(Grid_BD!Y:Y,Grid_BD!F:F,">="&O2Summary!B6,Grid_BD!F:F,"<="&O2Summary!B4)/1000 -> 605.885
A22: 5 | B22: IGA Daily | C22: =_xlfn.XLOOKUP($B$3,'Modelling New'!$D:$D,'Modelling New'!$AI:$AI) -> 0.99 | D22: =_xlfn.XLOOKUP($B$4,'Daily KPI'!$A:$A,'Daily KPI'!$Q:$Q,0) -> 0.99613491 | E22: =(D22-C22)/(C22) -> 0.006196876 | I22: =SUMIF(IGA_BD!F:F,O2Summary!B4,IGA_BD!W:W)/1000 -> 2.146
B23: IGA MTD | C23: =_xlfn.XLOOKUP($B$3,'Modelling New'!$D:$D,'Modelling New'!$AI:$AI) -> 0.99 | D23: =MonthlyKPI!N4 -> 0.99418047 | E23: =(D23-C23)/(C23) -> 0.0042226998 | I23: =SUMIFS(IGA_BD!W:W,IGA_BD!F:F,">="&O2Summary!B3,IGA_BD!F:F,"<="&O2Summary!B4)/1000 -> 61.851
B24: IGA YTD | C24: =_xlfn.XLOOKUP($B$3,'Modelling New'!$D:$D,'Modelling New'!$AI:$AI) -> 0.99 | D24: =AnnualKPI!N4 -> 0.97135639 | E24: =(D24-C24)/(C24) -> -0.018831933 | I24: =SUMIFS(IGA_BD!W:W,IGA_BD!F:F,">="&O2Summary!B6,IGA_BD!F:F,"<="&O2Summary!B4)/1000 -> 922.654
A25: 6 | B25: CUF Daily | C25: =C10/24/'Basic Data'!$N$3 -> 0.67192295 | D25: =D10/24/_xlfn.XLOOKUP($B$4,RD[Date],RD[Connected Wind AC Capcity(MW)]) -> 0.47094228 | E25: =(D25-C25)/(C25) -> -0.29911267
B26: CUF MTD | C26: =C11/(24*DAY(B4))/'Basic Data'!$N$3 -> 0.67192295 | D26: =D11/(24*DAY(B4))/'Basic Data'!$N$3 -> 0.65870911 | E26: =(D26-C26)/(C26) -> -0.019665705
B27: CUF YTD | C27: =C12/(24*(B4-B6+1))/'Basic Data'!$N$3 -> 0.43939357 | D27: =D12/(24*(B4-B6+1))/'Basic Data'!$N$3 -> 0.4127556 | E27: =(D27-C27)/(C27) -> -0.06062441
A28: 7 | B28: Wind PA Daily | C28: =_xlfn.XLOOKUP($B$3,'Modelling New'!$D:$D,'Modelling New'!$AE:$AE) -> 0.9554985 | D28: =D16*D19*D22 -> 0.98959522 | E28: =(D28-C28)/(C28) -> 0.035684744 | I28: =SUM(I16,I19,I22) -> 5.801
B29: Wind PA MTD | C29: =_xlfn.XLOOKUP($B$3,'Modelling New'!$D:$D,'Modelling New'!$AE:$AE) -> 0.9554985 | D29: =D17*D20*D23 -> 0.99017997 | E29: =(D29-C29)/(C29) -> 0.036296728 | I29: =SUM(I17,I20,I23) -> 121.0743
B30: Wind PA YTD | C30: =_xlfn.XLOOKUP($B$3,'Modelling New'!$D:$D,'Modelling New'!$AE:$AE) -> 0.9554985 | D30: =D18*D21*D24 -> 0.95982468 | E30: =(D30-C30)/(C30) -> 0.0045276718 | I30: =SUM(I18,I21,I24) -> 1723.2941
A31: 8 | B31: Line Loss Daily | C31: =_xlfn.XLOOKUP(B4,'Daily KPI'!$A:$A,'Daily KPI'!AP:AP) -> 0.05 | D31: =_xlfn.XLOOKUP($B$4,'Daily KPI'!$A:$A,'Daily KPI'!AN:AN) -> 0.010952712 | E31: =-(D31-C31)/(C31) -> 0.78094576
B32: Line Loss MTD | C32: =_xlfn.XLOOKUP($B$3,'Modelling New'!$D:$D,'Modelling New'!AK:AK) -> 0.05 | D32: =MonthlyKPI!$T$4 -> 0.007315459 | E32: =-(D32-C32)/(C32) -> 0.85369082
B33: Line Loss YTD | C33: =_xlfn.XLOOKUP($B$3,'Modelling New'!$D:$D,'Modelling New'!AK:AK) -> 0.05 | D33: =AnnualKPI!$S$4 -> 0.0078330867 | E33: =-(D33-C33)/(C33) -> 0.84333827
A34: 9 | B34: Reactive Power Daily | C34: =_xlfn.XLOOKUP(B7,'Daily KPI'!$A:$A,'Daily KPI'!AQ:AQ) -> 0.05 | D34: =_xlfn.XLOOKUP($B$4,'Daily KPI'!$A:$A,'Daily KPI'!AO:AO) -> 0.12936646 | E34: =-(D34-C34)/(C34) -> -1.5873293
B35: Reactive Power MTD | C35: =_xlfn.XLOOKUP($B$3,'Modelling New'!$D:$D,'Modelling New'!AL:AL) -> 0.05 | D35: =MonthlyKPI!$U$4 -> 0.081969078 | E35: =-(D35-C35)/(C35) -> -0.63938156
B36: Reactive Power YTD | C36: =_xlfn.XLOOKUP($B$3,'Modelling New'!$D:$D,'Modelling New'!AL:AL) -> 0.05 | D36: =AnnualKPI!$T$4 -> 0.22238768 | E36: =-(D36-C36)/(C36) -> -3.4477536
A37: 10 | B37: Expected Energy Daily | C37: =_xlfn.XLOOKUP($B$4,'Daily KPI'!$A:$A,'Daily KPI'!$AI:$AI) -> 577.61 | D37: =IFERROR(_xlfn.XLOOKUP($B$4,'Daily KPI'!$A:$A,'Daily KPI'!$X:$X)/1000,"") -> 575.2194 | E37: =(D37-C37)/(C37) -> -0.0041387788
B38: Expected Energy MTD | C38: =MonthlyKPI!$S$4 -> 15304.79 | D38: =IFERROR(SUMIF('WTG Reactive Power'!$D:$D,O2Summary!$B$3,'Daily KPI'!$X:$X)/1000,"") -> 15286.678 | E38: =(D38-C38)/(C38) -> -0.0011834269
B39: Expected Energy YTD | C39: =AnnualKPI!$R$4 -> 56851.24 | D39: =IFERROR(SUMIFS('Daily KPI'!$X:$X,'Daily KPI'!$A:$A,">="&O2Summary!$B$6,'Daily KPI'!$A:$A,"<="&O2Summary!$B$4)/1000,"") -> 56392.442 | E39: =(D39-C39)/(C39) -> -0.0080701406
A44: Performance Summary CEPPL Customer wise
A45: Month | B45: =B3 -> 45839
A46: Date | B46: =B4 -> 45857
...

Sheet AnnualKPI
A1: Till Date | B1: =O2Summary!B4 -> 45857 | C1: =O2Summary!$B$3 -> 45839
A2: CEPL Performance Summary-YTD
A3: Year | B3: Days | C3: Estimated WS(m/s) | D3: Measured WS (m/s) | E3: Budgeted Energy (MWh) | F3: Measured Energy (MWh) | G3: Target CUF (%) | H3: Measured CUF (%) | I3: Target GA (%) | J3: Measured GA (%) | K3: Target MA (%) | L3: Measured MA (%) | M3: Target IGA(%) | N3: Measured IGA (%) | O3: E_Grid | P3: 33 KV Export | Q3: Line Loss | R3: Expected Energy | S3: Loss (%) | T3: Reactive Power (%)
A4: =YEAR($B$1)+IF(MONTH($B$1)>=4,1,0) -> 2026 | B4: =$B$1-(O2Summary!$B$6)+1 -> 110 | C4: =_xlfn.XLOOKUP($C$1,'Modelling New'!$D:$D,'Modelling New'!$AD:$AD) -> 8.1297392 | D4: =AVERAGEIFS('Daily KPI'!$M:$M,'Daily KPI'!$A:$A,">="&O2Summary!$B$6,'Daily KPI'!$A:$A,"<="&AnnualKPI!$B$1) -> 6.7503737 | E4: =_xlfn.XLOOKUP($C$1,'Modelling New'!$D:$D,'Modelling New'!$V:$V) -> 58695.951 | F4: =SUMIFS('Daily KPI'!$X:$X,'Daily KPI'!$A:$A,">="&O2Summary!$B$6,'Daily KPI'!$A:$A,"<="&AnnualKPI!$B$1)/1000 -> 56392.442 | G4: =_xlfn.XLOOKUP($C$1,'Modelling New'!$D:$D,'Modelling New'!$Y:$Y) -> 0.43939357 | H4: =IFERROR(F4/(B4*24*_xlfn.XLOOKUP($C$1,'Modelling New'!$D:$D,'Modelling New'!$N:$N)),"") -> 0.42214968 | I4: =_xlfn.XLOOKUP($C$1,'Modelling New'!$D:$D,'Modelling New'!$AF:$AF) -> 0.995 | J4: =AVERAGEIFS('Daily KPI'!$R:$R,'Daily KPI'!$A:$A,">="&O2Summary!$B$6,'Daily KPI'!$A:$A,"<="&AnnualKPI!$B$1) -> 0.99192067 | K4: =_xlfn.XLOOKUP($C$1,'Modelling New'!$D:$D,'Modelling New'!$AH:$AH) -> 0.97 | L4: =AVERAGEIFS('Daily KPI'!$P:$P,'Daily KPI'!$A:$A,">="&O2Summary!$B$6,'Daily KPI'!$A:$A,"<="&AnnualKPI!$B$1) -> 0.99617669 | M4: =_xlfn.XLOOKUP($C$1,'Modelling New'!$D:$D,'Modelling New'!$AI:$AI) -> 0.99 | N4: =AVERAGEIFS('Daily KPI'!$Q:$Q,'Daily KPI'!$A:$A,">="&O2Summary!$B$6,'Daily KPI'!$A:$A,"<="&AnnualKPI!$B$1) -> 0.97135639 | O4: =SUMIFS(Input_Raw!CS:CS,Input_Raw!E:E,">="&O2Summary!$B$6,Input_Raw!E:E,"<="&AnnualKPI!$B$1)/1000 -> 123988.8 | P4: =(SUMIFS(Input_Raw!$DD:$DD,Input_Raw!$E:$E,">="&O2Summary!$B$6,Input_Raw!$E:$E,"<="&AnnualKPI!$B$1)/1000)+F4 -> 126747.92 | Q4: =1-P4/O4 -> -0.022252958 | R4: =SUMIFS('Daily KPI'!$AI:$AI,'Daily KPI'!$A:$A,"<="&$B$1,'Daily KPI'!$B:$B,"="&$A$4) -> 56851.24 | S4: =AVERAGEIFS('Daily KPI'!AN:AN,'Daily KPI'!$A:$A,">="&O2Summary!$B$6,'Daily KPI'!$A:$A,"<="&AnnualKPI!$B$1) -> 0.0078330867 | T4: =AVERAGEIFS('Daily KPI'!AO:AO,'Daily KPI'!$A:$A,">="&O2Summary!$B$6,'Daily KPI'!$A:$A,"<="&AnnualKPI!$B$1) -> 0.22238768

Sheet MonthlyKPI
A1: Till Date | B1: =O2Summary!$B$4 -> 45857 | C1: 0 | D1: 0 | E1: 0 | F1: 0
A2: CEPL Performance Summary
A3: Year | B3: Days | C3: Estimated WS(m/s) | D3: Measured WS (m/s) | E3: Budgeted Energy (MWh) | F3: Measured Energy (MWh) | G3: Target CUF (%) | H3: Measured CUF (%) | I3: Target GA (%) | J3: Measured GA (%) | K3: Target MA (%) | L3: Measured MA (%) | M3: Target IGA (%) | N3: Measured IGA (%) | O3: E_Grid | P3: 33 KV Export | Q3: Line Loss | R3: E_WS_Corrected | S3: Expected Energy | T3: Loss (%) | U3: Reactive Power (%)
A4: =O2Summary!$B$3 -> 45839 | B4: =DAY(B1) -> 19 | C4: =_xlfn.XLOOKUP($A$4,'Modelling New'!$D:$D,'Modelling New'!AC:AC) -> 10.303759 | D4: =AVERAGEIF('Daily KPI'!$A:$A,$A$4,'Daily KPI'!$M:$M) -> 9.0608696 | E4: =_xlfn.XLOOKUP($A$4,'Modelling New'!$D:$D,'Modelling New'!$U:$U) -> 15503.681 | F4: =SUMIF('Daily KPI'!$D:$D,$A$4,'Daily KPI'!$X:$X)/1000 -> 15286.678 | G4: =_xlfn.XLOOKUP($A$4,'Modelling New'!$D:$D,'Modelling New'!$X:$X) -> 0.67192295 | H4: =F4/(24*B4*AVERAGEIF(RD[Month Year],$A$4,RD[Connected Wind AC Capcity(MW)])) -> 0.66251811 | I4: =_xlfn.XLOOKUP($A$4,'Modelling New'!$D:$D,'Modelling New'!$AF:$AF) -> 0.995 | J4: =AVERAGEIF('Daily KPI'!$D:$D,$A$4,'Daily KPI'!R:R) -> 1 | K4: =_xlfn.XLOOKUP($A$4,'Modelling New'!$D:$D,'Modelling New'!$AH:$AH) -> 0.97 | L4: =AVERAGEIF('Daily KPI'!$D:$D,$A$4,'Daily KPI'!$P:$P) -> 0.99597608 | M4: =_xlfn.XLOOKUP($A$4,'Modelling New'!$D:$D,'Modelling New'!$AI:$AI) -> 0.99 | N4: =AVERAGEIF('Daily KPI'!$D:$D,$A$4,'Daily KPI'!$Q:$Q) -> 0.99418047 | O4: =SUMIF(Input_Raw!C:C,A4,Input_Raw!CS:CS)/1000 -> 25104 | P4: =(SUMIF(Input_Raw!$C:$C,A4,Input_Raw!$DF:$DF)+SUMIF(Input_Raw!$C:$C,A4,Input_Raw!$DD:$DD))/1000 -> 25248.33 | Q4: =1-P4/O4 -> -0.005749283 | R4: =SUMIFS(Input_Raw!DG:DG,Input_Raw!E:E,">="&A4,Input_Raw!E:E,"<="&B1) -> 15304.79 | S4: =SUMIF('Daily KPI'!D:D,MonthlyKPI!A4,'Daily KPI'!AI:AI) -> 15304.79 | T4: =AVERAGEIF('Daily KPI'!$D:$D,$A$4,'Daily KPI'!AN:AN) -> 0.007315459 | U4: =AVERAGEIF('Daily KPI'!$D:$D,$A$4,'Daily KPI'!AO:AO) -> 0.081969078
A7: Start Date | B7: =B8-6 -> 45851 | P7: 31596.72
A8: End Date | B8: =B1 -> 45857
A9: CEPL Performance Summary
A10: Year | B10: Days | C10: Estimated WS(m/s) | D10: Measured WS (m/s) | E10: Budgeted Energy (MWh) | F10: Measured Energy (MWh) | G10: Target CUF (%) | H10: Measured CUF (%) | I10: Target GA (%) | J10: Measured GA (%) | K10: Target MA (%) | L10: Measured MA (%) | M10: Target IGA (%) | N10: Measured IGA (%) | O10: E_WS_Corrected
A11: =O2Summary!$B$3 -> 45839 | B11: =(B8-B7)+1 -> 7 | C11: =_xlfn.XLOOKUP($A$11,'Modelling New'!$D:$D,'Modelling New'!AC:AC) -> 10.303759 | D11: =AVERAGEIFS('Daily KPI'!$M:$M,'Daily KPI'!$A:$A,">="&$B$7,'Daily KPI'!$A:$A,"<="&$B$8) -> 7.4975155 | E11: =SUMIFS('Daily KPI'!$AD:$AD,'Daily KPI'!$A:$A,">="&$B$7,'Daily KPI'!$A:$A,"<="&$B$8)/1000 -> 5711.8826 | F11: =SUMIFS('Daily KPI'!$X:$X,'Daily KPI'!$A:$A,">="&B7,'Daily KPI'!$A:$A,"<="&B8)/1000 -> 4429.4361 | G11: =E11/(24*$B$11*50.6) -> 0.67192295 | H11: =F11/(24*B11*50.6) -> 0.52106109 | I11: =_xlfn.XLOOKUP($A$11,'Modelling New'!$D:$D,'Modelling New'!$AF:$AF) -> 0.995 | J11: =AVERAGEIFS('Daily KPI'!$R:$R,'Daily KPI'!$A:$A,">="&$B$7,'Daily KPI'!$A:$A,"<="&$B$8) -> 1 | K11: =_xlfn.XLOOKUP($A$11,'Modelling New'!$D:$D,'Modelling New'!$AH:$AH) -> 0.97 | L11: =AVERAGEIFS('Daily KPI'!$P:$P,'Daily KPI'!$A:$A,">="&$B$7,'Daily KPI'!$A:$A,"<="&$B$8) -> 0.99150747 | M11: =_xlfn.XLOOKUP($A$11,'Modelling New'!$D:$D,'Modelling New'!$AI:$AI) -> 0.99 | N11: =AVERAGEIFS('Daily KPI'!$Q:$Q,'Daily KPI'!$A:$A,">="&$B$7,'Daily KPI'!$A:$A,"<="&$B$8) -> 0.99242059 | O11: =SUMIFS(Input_Raw!DG:DG,Input_Raw!E:E,">="&B7,Input_Raw!E:E,"<="&B8) -> 4435.21

Sheet Analytics
A3: Start Date | B3: 45352 | C3: Hours | D3: WS Median
A4: End Date | B4: 45747 | C4: =((B4-B3)*1)*24 -> 9480 | D4: =MEDIAN(B30:X30) -> 4.576492 | AA4: o2re1 | AB4: o2re2 | AC4: o2re4 | AD4: o2re5 | AE4: o2re16
A5: WTG No. | B5: KUD01 | C5: KUD02 | D5: KUD03 | E5: KUD04 | F5: KUD05 | G5: KUD06 | H5: KUD07 | I5: KUD08 | J5: KUD09 | K5: KUD10 | L5: KUD11 | M5: KUD12 | N5: KUD13 | O5: KUD14 | P5: KUD15 | Q5: KUD16 | R5: KUD17 | S5: KUD18 | T5: KUD19 | U5: KUD20 | V5: KUD21 | W5: KUD22 | X5: KUD23
A6: Machine Availability - MA(%) | B6: =($C$4-(SUM(B7,B15)))/$C$4 -> 0.99995781 | C6: =($C$4-(SUM(C7,C15)))/$C$4 -> 1 | D6: =($C$4-(SUM(D7,D15)))/$C$4 -> 1 | E6: =($C$4-(SUM(E7,E15)))/$C$4 -> 1 | F6: =($C$4-(SUM(F7,F15)))/$C$4 -> 0.99996308 | G6: =($C$4-(SUM(G7,G15)))/$C$4 -> 1 | H6: =($C$4-(SUM(H7,H15)))/$C$4 -> 0.99996484 | I6: =($C$4-(SUM(I7,I15)))/$C$4 -> 0.99996308 | ... X6: =($C$4-(SUM(X7,X15)))/$C$4 -> 0.99995077 | AA6: =AVERAGE(B6,D6,K6:P6,T6:U6) -> 0.99995447 | AB6: =AVERAGE(Q6:R6) -> 1 | AC6: =AVERAGE(S6) -> 0.99995781 | AD6: =AVERAGE(C6,E6:G6,J6,V6:X6) -> 0.99989627 | AE6: =AVERAGE(H6:I6) -> 0.99996396
A7: WTG BD Hours | B7: =(SUMIFS(WTG_BD!$T:$T,WTG_BD!$G:$G,Analytics!B$5,WTG_BD!$F:$F,">="&Analytics!$B$3,WTG_BD!$F:$F,"<="&Analytics!$B$4)) -> 0.4 | C7: =(SUMIFS(WTG_BD!$T:$T,WTG_BD!$G:$G,Analytics!C$5,WTG_BD!$F:$F,">="&Analytics!$B$3,WTG_BD!$F:$F,"<="&Analytics!$B$4)) -> 0 | D7: =(SUMIFS(WTG_BD!$T:$T,WTG_BD!$G:$G,Analytics!D$5,WTG_BD!$F:$F,">="&Analytics!$B$3,WTG_BD!$F:$F,"<="&Analytics!$B$4)) -> 0 | E7: =(SUMIFS(WTG_BD!$T:$T,WTG_BD!$G:$G,Analytics!E$5,WTG_BD!$F:$F,">="&Analytics!$B$3,WTG_BD!$F:$F,"<="&Analytics!$B$4)) -> 0 | F7: =(SUMIFS(WTG_BD!$T:$T,WTG_BD!$G:$G,Analytics!F$5,WTG_BD!$F:$F,">="&Analytics!$B$3,WTG_BD!$F:$F,"<="&Analytics!$B$4)) -> 0.35 | G7: =(SUMIFS(WTG_BD!$T:$T,WTG_BD!$G:$G,Analytics!G$5,WTG_BD!$F:$F,">="&Analytics!$B$3,WTG_BD!$F:$F,"<="&Analytics!$B$4)) -> 0 | H7: =(SUMIFS(WTG_BD!$T:$T,WTG_BD!$G:$G,Analytics!H$5,WTG_BD!$F:$F,">="&Analytics!$B$3,WTG_BD!$F:$F,"<="&Analytics!$B$4)) -> 0.33333333 | I7: =(SUMIFS(WTG_BD!$T:$T,WTG_BD!$G:$G,Analytics!I$5,WTG_BD!$F:$F,">="&Analytics!$B$3,WTG_BD!$F:$F,"<="&Analytics!$B$4)) -> 0.35 | ... X7: =(SUMIFS(WTG_BD!$T:$T,WTG_BD!$G:$G,Analytics!X$5,WTG_BD!$F:$F,">="&Analytics!$B$3,WTG_BD!$F:$F,"<="&Analytics!$B$4)) -> 0.46666667 | AA7: =AVERAGE(B7,D7,K7:P7,T7:U7) -> 0.43166667 | AB7: =AVERAGE(Q7:R7) -> 0 | AC7: =AVERAGE(S7) -> 0.4 | AD7: =AVERAGE(C7,E7:G7,J7,V7:X7) -> 0.98333333 | AE7: =AVERAGE(H7:I7) -> 0.34166667
A8: Internal Grid Availability - IGA (%) | B8: =($C$4-(SUM(B9:B13)))/$C$4 -> 1 | C8: =($C$4-(SUM(C9:C13)))/$C$4 -> 1 | D8: =($C$4-(SUM(D9:D13)))/$C$4 -> 1 | E8: =($C$4-(SUM(E9:E13)))/$C$4 -> 1 | F8: =($C$4-(SUM(F9:F13)))/$C$4 -> 1 | G8: =($C$4-(SUM(G9:G13)))/$C$4 -> 1 | H8: =($C$4-(SUM(H9:H13)))/$C$4 -> 1 | I8: =($C$4-(SUM(I9:I13)))/$C$4 -> 1 | ... X8: =($C$4-(SUM(X9:X13)))/$C$4 -> 1 | AA8: =AVERAGE(B8,D8,K8:P8,T8:U8) -> 1 | AB8: =AVERAGE(Q8:R8) -> 1 | AC8: =AVERAGE(S8) -> 1 | AD8: =AVERAGE(C8,E8:G8,J8,V8:X8) -> 1 | AE8: =AVERAGE(H8:I8) -> 1
A9: METERING YARD | B9: =SUMIFS(IGA_BD!$Q:$Q,IGA_BD!$G:$G,(VLOOKUP(B$5,'Basic Data'!$A:$J,7,0)),IGA_BD!$F:$F,">="&Analytics!$B$3,IGA_BD!$F:$F,"<="&Analytics!$B$4) -> 0 | C9: =SUMIFS(IGA_BD!$Q:$Q,IGA_BD!$G:$G,(VLOOKUP(C$5,'Basic Data'!$A:$J,7,0)),IGA_BD!$F:$F,">="&Analytics!$B$3,IGA_BD!$F:$F,"<="&Analytics!$B$4) -> 0 | D9: =SUMIFS(IGA_BD!$Q:$Q,IGA_BD!$G:$G,(VLOOKUP(D$5,'Basic Data'!$A:$J,7,0)),IGA_BD!$F:$F,">="&Analytics!$B$3,IGA_BD!$F:$F,"<="&Analytics!$B$4) -> 0 | E9: =SUMIFS(IGA_BD!$Q:$Q,IGA_BD!$G:$G,(VLOOKUP(E$5,'Basic Data'!$A:$J,7,0)),IGA_BD!$F:$F,">="&Analytics!$B$3,IGA_BD!$F:$F,"<="&Analytics!$B$4) -> 0 | F9: =SUMIFS(IGA_BD!$Q:$Q,IGA_BD!$G:$G,(VLOOKUP(F$5,'Basic Data'!$A:$J,7,0)),IGA_BD!$F:$F,">="&Analytics!$B$3,IGA_BD!$F:$F,"<="&Analytics!$B$4) -> 0 | G9: =SUMIFS(IGA_BD!$Q:$Q,IGA_BD!$G:$G,(VLOOKUP(G$5,'Basic Data'!$A:$J,7,0)),IGA_BD!$F:$F,">="&Analytics!$B$3,IGA_BD!$F:$F,"<="&Analytics!$B$4) -> 0 | H9: =SUMIFS(IGA_BD!$Q:$Q,IGA_BD!$G:$G,(VLOOKUP(H$5,'Basic Data'!$A:$J,7,0)),IGA_BD!$F:$F,">="&Analytics!$B$3,IGA_BD!$F:$F,"<="&Analytics!$B$4) -> 0 | I9: =SUMIFS(IGA_BD!$Q:$Q,IGA_BD!$G:$G,(VLOOKUP(I$5,'Basic Data'!$A:$J,7,0)),IGA_BD!$F:$F,">="&Analytics!$B$3,IGA_BD!$F:$F,"<="&Analytics!$B$4) -> 0 | ... X9: =SUMIFS(IGA_BD!$Q:$Q,IGA_BD!$G:$G,(VLOOKUP(X$5,'Basic Data'!$A:$J,7,0)),IGA_BD!$F:$F,">="&Analytics!$B$3,IGA_BD!$F:$F,"<="&Analytics!$B$4) -> 0 | AA9: =AVERAGE(B9,D9,K9:P9,T9:U9) -> 0 | AB9: =AVERAGE(Q9:R9) -> 0 | AC9: =AVERAGE(S9) -> 0 | AD9: =AVERAGE(C9,E9:G9,J9,V9:X9) -> 0 | AE9: =AVERAGE(H9:I9) -> 0
A10: FEEDER | B10: =SUMIFS(IGA_BD!$Q:$Q,IGA_BD!$G:$G,(VLOOKUP(B$5,'Basic Data'!$A:$H,8,0)),IGA_BD!$F:$F,">="&Analytics!$B$3,IGA_BD!$F:$F,"<="&Analytics!$B$4) -> 0 | C10: =SUMIFS(IGA_BD!$Q:$Q,IGA_BD!$G:$G,(VLOOKUP(C$5,'Basic Data'!$A:$H,8,0)),IGA_BD!$F:$F,">="&Analytics!$B$3,IGA_BD!$F:$F,"<="&Analytics!$B$4) -> 0 | D10: =SUMIFS(IGA_BD!$Q:$Q,IGA_BD!$G:$G,(VLOOKUP(D$5,'Basic Data'!$A:$H,8,0)),IGA_BD!$F:$F,">="&Analytics!$B$3,IGA_BD!$F:$F,"<="&Analytics!$B$4) -> 0 | E10: =SUMIFS(IGA_BD!$Q:$Q,IGA_BD!$G:$G,(VLOOKUP(E$5,'Basic Data'!$A:$H,8,0)),IGA_BD!$F:$F,">="&Analytics!$B$3,IGA_BD!$F:$F,"<="&Analytics!$B$4) -> 0 | F10: =SUMIFS(IGA_BD!$Q:$Q,IGA_BD!$G:$G,(VLOOKUP(F$5,'Basic Data'!$A:$H,8,0)),IGA_BD!$F:$F,">="&Analytics!$B$3,IGA_BD!$F:$F,"<="&Analytics!$B$4) -> 0 | G10: =SUMIFS(IGA_BD!$Q:$Q,IGA_BD!$G:$G,(VLOOKUP(G$5,'Basic Data'!$A:$H,8,0)),IGA_BD!$F:$F,">="&Analytics!$B$3,IGA_BD!$F:$F,"<="&Analytics!$B$4) -> 0 | H10: =SUMIFS(IGA_BD!$Q:$Q,IGA_BD!$G:$G,(VLOOKUP(H$5,'Basic Data'!$A:$H,8,0)),IGA_BD!$F:$F,">="&Analytics!$B$3,IGA_BD!$F:$F,"<="&Analytics!$B$4) -> 0 | I10: =SUMIFS(IGA_BD!$Q:$Q,IGA_BD!$G:$G,(VLOOKUP(I$5,'Basic Data'!$A:$H,8,0)),IGA_BD!$F:$F,">="&Analytics!$B$3,IGA_BD!$F:$F,"<="&Analytics!$B$4) -> 0 | ... X10: =SUMIFS(IGA_BD!$Q:$Q,IGA_BD!$G:$G,(VLOOKUP(X$5,'Basic Data'!$A:$H,8,0)),IGA_BD!$F:$F,">="&Analytics!$B$3,IGA_BD!$F:$F,"<="&Analytics!$B$4) -> 0 | AA10: =AVERAGE(B10,D10,K10:P10,T10:U10) -> 0 | AB10: =AVERAGE(Q10:R10) -> 0 | AC10: =AVERAGE(S10) -> 0 | AD10: =AVERAGE(C10,E10:G10,J10,V10:X10) -> 0 | AE10: =AVERAGE(H10:I10) -> 0
A11: OG | B11: =SUMIFS(IGA_BD!$Q:$Q,IGA_BD!$G:$G,(VLOOKUP(B$5,'Basic Data'!$A:$I,9,0)),IGA_BD!$F:$F,">="&Analytics!$B$3,IGA_BD!$F:$F,"<="&Analytics!$B$4) -> 0 | C11: =SUMIFS(IGA_BD!$Q:$Q,IGA_BD!$G:$G,(VLOOKUP(C$5,'Basic Data'!$A:$I,9,0)),IGA_BD!$F:$F,">="&Analytics!$B$3,IGA_BD!$F:$F,"<="&Analytics!$B$4) -> 0 | D11: =SUMIFS(IGA_BD!$Q:$Q,IGA_BD!$G:$G,(VLOOKUP(D$5,'Basic Data'!$A:$I,9,0)),IGA_BD!$F:$F,">="&Analytics!$B$3,IGA_BD!$F:$F,"<="&Analytics!$B$4) -> 0 | E11: =SUMIFS(IGA_BD!$Q:$Q,IGA_BD!$G:$G,(VLOOKUP(E$5,'Basic Data'!$A:$I,9,0)),IGA_BD!$F:$F,">="&Analytics!$B$3,IGA_BD!$F:$F,"<="&Analytics!$B$4) -> 0 | F11: =SUMIFS(IGA_BD!$Q:$Q,IGA_BD!$G:$G,(VLOOKUP(F$5,'Basic Data'!$A:$I,9,0)),IGA_BD!$F:$F,">="&Analytics!$B$3,IGA_BD!$F:$F,"<="&Analytics!$B$4) -> 0 | G11: =SUMIFS(IGA_BD!$Q:$Q,IGA_BD!$G:$G,(VLOOKUP(G$5,'Basic Data'!$A:$I,9,0)),IGA_BD!$F:$F,">="&Analytics!$B$3,IGA_BD!$F:$F,"<="&Analytics!$B$4) -> 0 | H11: =SUMIFS(IGA_BD!$Q:$Q,IGA_BD!$G:$G,(VLOOKUP(H$5,'Basic Data'!$A:$I,9,0)),IGA_BD!$F:$F,">="&Analytics!$B$3,IGA_BD!$F:$F,"<="&Analytics!$B$4) -> 0 | I11: =SUMIFS(IGA_BD!$Q:$Q,IGA_BD!$G:$G,(VLOOKUP(I$5,'Basic Data'!$A:$I,9,0)),IGA_BD!$F:$F,">="&Analytics!$B$3,IGA_BD!$F:$F,"<="&Analytics!$B$4) -> 0 | ... X11: =SUMIFS(IGA_BD!$Q:$Q,IGA_BD!$G:$G,(VLOOKUP(X$5,'Basic Data'!$A:$I,9,0)),IGA_BD!$F:$F,">="&Analytics!$B$3,IGA_BD!$F:$F,"<="&Analytics!$B$4) -> 0 | AA11: =AVERAGE(B11,D11,K11:P11,T11:U11) -> 0 | AB11: =AVERAGE(Q11:R11) -> 0 | AC11: =AVERAGE(S11) -> 0 | AD11: =AVERAGE(C11,E11:G11,J11,V11:X11) -> 0 | AE11: =AVERAGE(H11:I11) -> 0
A12: TRANSFER | B12: =SUMIFS(IGA_BD!$Q:$Q,IGA_BD!$G:$G,(VLOOKUP(B$5,'Basic Data'!$A:$J,10,0)),IGA_BD!$F:$F,">="&Analytics!$B$3,IGA_BD!$F:$F,"<="&Analytics!$B$4) -> 0 | C12: =SUMIFS(IGA_BD!$Q:$Q,IGA_BD!$G:$G,(VLOOKUP(C$5,'Basic Data'!$A:$J,10,0)),IGA_BD!$F:$F,">="&Analytics!$B$3,IGA_BD!$F:$F,"<="&Analytics!$B$4) -> 0 | D12: =SUMIFS(IGA_BD!$Q:$Q,IGA_BD!$G:$G,(VLOOKUP(D$5,'Basic Data'!$A:$J,10,0)),IGA_BD!$F:$F,">="&Analytics!$B$3,IGA_BD!$F:$F,"<="&Analytics!$B$4) -> 0 | E12: =SUMIFS(IGA_BD!$Q:$Q,IGA_BD!$G:$G,(VLOOKUP(E$5,'Basic Data'!$A:$J,10,0)),IGA_BD!$F:$F,">="&Analytics!$B$3,IGA_BD!$F:$F,"<="&Analytics!$B$4) -> 0 | F12: =SUMIFS(IGA_BD!$Q:$Q,IGA_BD!$G:$G,(VLOOKUP(F$5,'Basic Data'!$A:$J,10,0)),IGA_BD!$F:$F,">="&Analytics!$B$3,IGA_BD!$F:$F,"<="&Analytics!$B$4) -> 0 | G12: =SUMIFS(IGA_BD!$Q:$Q,IGA_BD!$G:$G,(VLOOKUP(G$5,'Basic Data'!$A:$J,10,0)),IGA_BD!$F:$F,">="&Analytics!$B$3,IGA_BD!$F:$F,"<="&Analytics!$B$4) -> 0 | H12: =SUMIFS(IGA_BD!$Q:$Q,IGA_BD!$G:$G,(VLOOKUP(H$5,'Basic Data'!$A:$J,10,0)),IGA_BD!$F:$F,">="&Analytics!$B$3,IGA_BD!$F:$F,"<="&Analytics!$B$4) -> 0 | I12: =SUMIFS(IGA_BD!$Q:$Q,IGA_BD!$G:$G,(VLOOKUP(I$5,'Basic Data'!$A:$J,10,0)),IGA_BD!$F:$F,">="&Analytics!$B$3,IGA_BD!$F:$F,"<="&Analytics!$B$4) -> 0 | ... X12: =SUMIFS(IGA_BD!$Q:$Q,IGA_BD!$G:$G,(VLOOKUP(X$5,'Basic Data'!$A:$J,10,0)),IGA_BD!$F:$F,">="&Analytics!$B$3,IGA_BD!$F:$F,"<="&Analytics!$B$4) -> 0 | AA12: =AVERAGE(B12,D12,K12:P12,T12:U12) -> 0 | AB12: =AVERAGE(Q12:R12) -> 0 | AC12: =AVERAGE(S12) -> 0 | AD12: =AVERAGE(C12,E12:G12,J12,V12:X12) -> 0 | AE12: =AVERAGE(H12:I12) -> 0
A13: USS | B13: =SUMIFS(IGA_BD!$Q:$Q,IGA_BD!$F:$F,">="&Analytics!$B$3,IGA_BD!$F:$F,"<="&Analytics!$B$4,IGA_BD!$G:$G,Analytics!B$5) -> 0 | C13: =SUMIFS(IGA_BD!$Q:$Q,IGA_BD!$F:$F,">="&Analytics!$B$3,IGA_BD!$F:$F,"<="&Analytics!$B$4,IGA_BD!$G:$G,Analytics!C$5) -> 0 | D13: =SUMIFS(IGA_BD!$Q:$Q,IGA_BD!$F:$F,">="&Analytics!$B$3,IGA_BD!$F:$F,"<="&Analytics!$B$4,IGA_BD!$G:$G,Analytics!D$5) -> 0 | E13: =SUMIFS(IGA_BD!$Q:$Q,IGA_BD!$F:$F,">="&Analytics!$B$3,IGA_BD!$F:$F,"<="&Analytics!$B$4,IGA_BD!$G:$G,Analytics!E$5) -> 0 | F13: =SUMIFS(IGA_BD!$Q:$Q,IGA_BD!$F:$F,">="&Analytics!$B$3,IGA_BD!$F:$F,"<="&Analytics!$B$4,IGA_BD!$G:$G,Analytics!F$5) -> 0 | G13: =SUMIFS(IGA_BD!$Q:$Q,IGA_BD!$F:$F,">="&Analytics!$B$3,IGA_BD!$F:$F,"<="&Analytics!$B$4,IGA_BD!$G:$G,Analytics!G$5) -> 0 | H13: =SUMIFS(IGA_BD!$Q:$Q,IGA_BD!$F:$F,">="&Analytics!$B$3,IGA_BD!$F:$F,"<="&Analytics!$B$4,IGA_BD!$G:$G,Analytics!H$5) -> 0 | I13: =SUMIFS(IGA_BD!$Q:$Q,IGA_BD!$F:$F,">="&Analytics!$B$3,IGA_BD!$F:$F,"<="&Analytics!$B$4,IGA_BD!$G:$G,Analytics!I$5) -> 0 | ... X13: =SUMIFS(IGA_BD!$Q:$Q,IGA_BD!$F:$F,">="&Analytics!$B$3,IGA_BD!$F:$F,"<="&Analytics!$B$4,IGA_BD!$G:$G,Analytics!X$5) -> 0 | AA13: =AVERAGE(B13,D13,K13:P13,T13:U13) -> 0 | AB13: =AVERAGE(Q13:R13) -> 0 | AC13: =AVERAGE(S13) -> 0 | AD13: =AVERAGE(C13,E13:G13,J13,V13:X13) -> 0 | AE13: =AVERAGE(H13:I13) -> 0
A14: ROW | B14: =SUMIFS(WTG_BD!$T:$T,WTG_BD!$G:$G,Analytics!B$5,WTG_BD!$F:$F,">="&Analytics!$B$3,WTG_BD!$F:$F,"<="&Analytics!$B$4,WTG_BD!$N:$N,'Basic Data'!$X$4) -> 0 | C14: =SUMIFS(WTG_BD!$T:$T,WTG_BD!$G:$G,Analytics!C$5,WTG_BD!$F:$F,">="&Analytics!$B$3,WTG_BD!$F:$F,"<="&Analytics!$B$4,WTG_BD!$N:$N,'Basic Data'!$X$4) -> 0 | D14: =SUMIFS(WTG_BD!$T:$T,WTG_BD!$G:$G,Analytics!D$5,WTG_BD!$F:$F,">="&Analytics!$B$3,WTG_BD!$F:$F,"<="&Analytics!$B$4,WTG_BD!$N:$N,'Basic Data'!$X$4) -> 0 | E14: =SUMIFS(WTG_BD!$T:$T,WTG_BD!$G:$G,Analytics!E$5,WTG_BD!$F:$F,">="&Analytics!$B$3,WTG_BD!$F:$F,"<="&Analytics!$B$4,WTG_BD!$N:$N,'Basic Data'!$X$4) -> 0 | F14: =SUMIFS(WTG_BD!$T:$T,WTG_BD!$G:$G,Analytics!F$5,WTG_BD!$F:$F,">="&Analytics!$B$3,WTG_BD!$F:$F,"<="&Analytics!$B$4,WTG_BD!$N:$N,'Basic Data'!$X$4) -> 0 | G14: =SUMIFS(WTG_BD!$T:$T,WTG_BD!$G:$G,Analytics!G$5,WTG_BD!$F:$F,">="&Analytics!$B$3,WTG_BD!$F:$F,"<="&Analytics!$B$4,WTG_BD!$N:$N,'Basic Data'!$X$4) -> 0 | H14: =SUMIFS(WTG_BD!$T:$T,WTG_BD!$G:$G,Analytics!H$5,WTG_BD!$F:$F,">="&Analytics!$B$3,WTG_BD!$F:$F,"<="&Analytics!$B$4,WTG_BD!$N:$N,'Basic Data'!$X$4) -> 0 | I14: =SUMIFS(WTG_BD!$T:$T,WTG_BD!$G:$G,Analytics!I$5,WTG_BD!$F:$F,">="&Analytics!$B$3,WTG_BD!$F:$F,"<="&Analytics!$B$4,WTG_BD!$N:$N,'Basic Data'!$X$4) -> 0 | ... X14: =SUMIFS(WTG_BD!$T:$T,WTG_BD!$G:$G,Analytics!X$5,WTG_BD!$F:$F,">="&Analytics!$B$3,WTG_BD!$F:$F,"<="&Analytics!$B$4,WTG_BD!$N:$N,'Basic Data'!$X$4) -> 0 | AA14: =AVERAGE(B14,D14,K14:P14,T14:U14) -> 0 | AB14: =AVERAGE(Q14:R14) -> 0 | AC14: =AVERAGE(S14) -> 0 | AD14: =AVERAGE(C14,E14:G14,J14,V14:X14) -> 0.5 | AE14: =AVERAGE(H14:I14) -> 0
A15: Major Breakdown | B15: =SUMIFS(WTG_BD!$T:$T,WTG_BD!$G:$G,Analytics!B$5,WTG_BD!$F:$F,">="&Analytics!$B$3,WTG_BD!$F:$F,"<="&Analytics!$B$4,WTG_BD!$N:$N,'Basic Data'!$X$1) -> 0 | C15: =SUMIFS(WTG_BD!$T:$T,WTG_BD!$G:$G,Analytics!C$5,WTG_BD!$F:$F,">="&Analytics!$B$3,WTG_BD!$F:$F,"<="&Analytics!$B$4,WTG_BD!$N:$N,'Basic Data'!$X$1) -> 0 | D15: =SUMIFS(WTG_BD!$T:$T,WTG_BD!$G:$G,Analytics!D$5,WTG_BD!$F:$F,">="&Analytics!$B$3,WTG_BD!$F:$F,"<="&Analytics!$B$4,WTG_BD!$N:$N,'Basic Data'!$X$1) -> 0 | E15: =SUMIFS(WTG_BD!$T:$T,WTG_BD!$G:$G,Analytics!E$5,WTG_BD!$F:$F,">="&Analytics!$B$3,WTG_BD!$F:$F,"<="&Analytics!$B$4,WTG_BD!$N:$N,'Basic Data'!$X$1) -> 0 | F15: =SUMIFS(WTG_BD!$T:$T,WTG_BD!$G:$G,Analytics!F$5,WTG_BD!$F:$F,">="&Analytics!$B$3,WTG_BD!$F:$F,"<="&Analytics!$B$4,WTG_BD!$N:$N,'Basic Data'!$X$1) -> 0 | G15: =SUMIFS(WTG_BD!$T:$T,WTG_BD!$G:$G,Analytics!G$5,WTG_BD!$F:$F,">="&Analytics!$B$3,WTG_BD!$F:$F,"<="&Analytics!$B$4,WTG_BD!$N:$N,'Basic Data'!$X$1) -> 0 | H15: =SUMIFS(WTG_BD!$T:$T,WTG_BD!$G:$G,Analytics!H$5,WTG_BD!$F:$F,">="&Analytics!$B$3,WTG_BD!$F:$F,"<="&Analytics!$B$4,WTG_BD!$N:$N,'Basic Data'!$X$1) -> 0 | I15: =SUMIFS(WTG_BD!$T:$T,WTG_BD!$G:$G,Analytics!I$5,WTG_BD!$F:$F,">="&Analytics!$B$3,WTG_BD!$F:$F,"<="&Analytics!$B$4,WTG_BD!$N:$N,'Basic Data'!$X$1) -> 0 | ... X15: =SUMIFS(WTG_BD!$T:$T,WTG_BD!$G:$G,Analytics!X$5,WTG_BD!$F:$F,">="&Analytics!$B$3,WTG_BD!$F:$F,"<="&Analytics!$B$4,WTG_BD!$N:$N,'Basic Data'!$X$1) -> 0 | AA15: =AVERAGE(B15,D15,K15:P15,T15:U15) -> 0 | AB15: =AVERAGE(Q15:R15) -> 0 | AC15: =AVERAGE(S15) -> 0 | AD15: =AVERAGE(C15,E15:G15,J15,V15:X15) -> 0 | AE15: =AVERAGE(H15:I15) -> 0
A16: Externnal Grid Availability - EGA (%) | B16: =($C$4-(B20+B23))/$C$4 -> 1 | C16: =($C$4-(C20+C23))/$C$4 -> 1 | D16: =($C$4-(D20+D23))/$C$4 -> 1 | E16: =($C$4-(E20+E23))/$C$4 -> 1 | F16: =($C$4-(F20+F23))/$C$4 -> 1 | G16: =($C$4-(G20+G23))/$C$4 -> 1 | H16: =($C$4-(H20+H23))/$C$4 -> 1 | I16: =($C$4-(I20+I23))/$C$4 -> 1 | ... X16: =($C$4-(X20+X23))/$C$4 -> 1 | AA16: =AVERAGE(B16,D16,K16:P16,T16:U16) -> 1 | AB16: =AVERAGE(Q16:R16) -> 1 | AC16: =AVERAGE(S16) -> 1 | AD16: =AVERAGE(C16,E16:G16,J16,V16:X16) -> 1 | AE16: =AVERAGE(H16:I16) -> 1
A17: EGA including Curtailment order (%) | B17: =(B24-B21)/B24 -> 1 | C17: =(C24-C21)/C24 -> 1 | D17: =(D24-D21)/D24 -> 1 | E17: =(E24-E21)/E24 -> 1 | F17: =(F24-F21)/F24 -> 1 | G17: =(G24-G21)/G24 -> 1 | H17: =(H24-H21)/H24 -> 1 | I17: =(I24-I21)/I24 -> 1 | ... X17: =(X24-X21)/X24 -> 1 | AA17: =AVERAGE(B17,D17,K17:P17,T17:U17) -> 1 | AB17: =AVERAGE(Q17:R17) -> 1 | AC17: =AVERAGE(S17) -> 1 | AD17: =AVERAGE(C17,E17:G17,J17,V17:X17) -> 1 | AE17: =AVERAGE(H17:I17) -> 1
A18: EGA (Energy Availability) (%) | B18: =B17*B16 -> 1 | C18: =C17*C16 -> 1 | D18: =D17*D16 -> 1 | E18: =E17*E16 -> 1 | F18: =F17*F16 -> 1 | G18: =G17*G16 -> 1 | H18: =H17*H16 -> 1 | I18: =I17*I16 -> 1 | ... X18: =X17*X16 -> 1 | AA18: =AVERAGE(B18,D18,K18:P18,T18:U18) -> 1 | AB18: =AVERAGE(Q18:R18) -> 1 | AC18: =AVERAGE(S18) -> 1 | AD18: =AVERAGE(C18,E18:G18,J18,V18:X18) -> 1 | AE18: =AVERAGE(H18:I18) -> 1
A19: External Grid | B19: =SUM(B20:B23) -> 1 | C19: =$B$19 -> 1 | D19: =$B$19 -> 1 | E19: =$B$19 -> 1 | F19: =$B$19 -> 1 | G19: =$B$19 -> 1 | H19: =$B$19 -> 1 | I19: =$B$19 -> 1 | J19: =$B$19 -> 1 | ... X19: =$B$19 -> 1 | AA19: =AVERAGE(B19,D19,K19:P19,T19:U19) -> 1 | AB19: =AVERAGE(Q19:R19) -> 1 | AC19: =AVERAGE(S19) -> 1 | AD19: =AVERAGE(C19,E19:G19,J19,V19:X19) -> 1 | AE19: =AVERAGE(H19:I19) -> 1
A20: Breakdown | B20: =SUMIFS(Grid_BD!$R:$R,Grid_BD!$F:$F,">="&Analytics!$B$3,Grid_BD!$F:$F,"<="&Analytics!$B$4,Grid_BD!$L:$L,Analytics!$A20) -> 0 | C20: =SUMIFS(Grid_BD!$R:$R,Grid_BD!$F:$F,">="&Analytics!$B$3,Grid_BD!$F:$F,"<="&Analytics!$B$4,Grid_BD!$L:$L,Analytics!$A20) -> 0 | D20: =SUMIFS(Grid_BD!$R:$R,Grid_BD!$F:$F,">="&Analytics!$B$3,Grid_BD!$F:$F,"<="&Analytics!$B$4,Grid_BD!$L:$L,Analytics!$A20) -> 0 | E20: =SUMIFS(Grid_BD!$R:$R,Grid_BD!$F:$F,">="&Analytics!$B$3,Grid_BD!$F:$F,"<="&Analytics!$B$4,Grid_BD!$L:$L,Analytics!$A20) -> 0 | F20: =SUMIFS(Grid_BD!$R:$R,Grid_BD!$F:$F,">="&Analytics!$B$3,Grid_BD!$F:$F,"<="&Analytics!$B$4,Grid_BD!$L:$L,Analytics!$A20) -> 0 | G20: =SUMIFS(Grid_BD!$R:$R,Grid_BD!$F:$F,">="&Analytics!$B$3,Grid_BD!$F:$F,"<="&Analytics!$B$4,Grid_BD!$L:$L,Analytics!$A20) -> 0 | H20: =SUMIFS(Grid_BD!$R:$R,Grid_BD!$F:$F,">="&Analytics!$B$3,Grid_BD!$F:$F,"<="&Analytics!$B$4,Grid_BD!$L:$L,Analytics!$A20) -> 0 | I20: =SUMIFS(Grid_BD!$R:$R,Grid_BD!$F:$F,">="&Analytics!$B$3,Grid_BD!$F:$F,"<="&Analytics!$B$4,Grid_BD!$L:$L,Analytics!$A20) -> 0 | ... X20: =SUMIFS(Grid_BD!$R:$R,Grid_BD!$F:$F,">="&Analytics!$B$3,Grid_BD!$F:$F,"<="&Analytics!$B$4,Grid_BD!$L:$L,Analytics!$A20) -> 0 | AA20: =AVERAGE(B20,D20,K20:P20,T20:U20) -> 0 | AB20: =AVERAGE(Q20:R20) -> 0 | AC20: =AVERAGE(S20) -> 0 | AD20: =AVERAGE(C20,E20:G20,J20,V20:X20) -> 0 | AE20: =AVERAGE(H20:I20) -> 0
A21: Curtailment Order | B21: =SUMIFS(Grid_BD!$Y:$Y,Grid_BD!$F:$F,">="&Analytics!$B$3,Grid_BD!$F:$F,"<="&Analytics!$B$4,Grid_BD!$L:$L,Analytics!$A21) -> 0 | C21: =SUMIFS(Grid_BD!$Y:$Y,Grid_BD!$F:$F,">="&Analytics!$B$3,Grid_BD!$F:$F,"<="&Analytics!$B$4,Grid_BD!$L:$L,Analytics!$A21) -> 0 | D21: =SUMIFS(Grid_BD!$Y:$Y,Grid_BD!$F:$F,">="&Analytics!$B$3,Grid_BD!$F:$F,"<="&Analytics!$B$4,Grid_BD!$L:$L,Analytics!$A21) -> 0 | E21: =SUMIFS(Grid_BD!$Y:$Y,Grid_BD!$F:$F,">="&Analytics!$B$3,Grid_BD!$F:$F,"<="&Analytics!$B$4,Grid_BD!$L:$L,Analytics!$A21) -> 0 | F21: =SUMIFS(Grid_BD!$Y:$Y,Grid_BD!$F:$F,">="&Analytics!$B$3,Grid_BD!$F:$F,"<="&Analytics!$B$4,Grid_BD!$L:$L,Analytics!$A21) -> 0 | G21: =SUMIFS(Grid_BD!$Y:$Y,Grid_BD!$F:$F,">="&Analytics!$B$3,Grid_BD!$F:$F,"<="&Analytics!$B$4,Grid_BD!$L:$L,Analytics!$A21) -> 0 | H21: =SUMIFS(Grid_BD!$Y:$Y,Grid_BD!$F:$F,">="&Analytics!$B$3,Grid_BD!$F:$F,"<="&Analytics!$B$4,Grid_BD!$L:$L,Analytics!$A21) -> 0 | I21: =SUMIFS(Grid_BD!$Y:$Y,Grid_BD!$F:$F,">="&Analytics!$B$3,Grid_BD!$F:$F,"<="&Analytics!$B$4,Grid_BD!$L:$L,Analytics!$A21) -> 0 | ... X21: =SUMIFS(Grid_BD!$Y:$Y,Grid_BD!$F:$F,">="&Analytics!$B$3,Grid_BD!$F:$F,"<="&Analytics!$B$4,Grid_BD!$L:$L,Analytics!$A21) -> 0 | AA21: =AVERAGE(B21,D21,K21:P21,T21:U21) -> 0 | AB21: =AVERAGE(Q21:R21) -> 0 | AC21: =AVERAGE(S21) -> 0 | AD21: =AVERAGE(C21,E21:G21,J21,V21:X21) -> 0 | AE21: =AVERAGE(H21:I21) -> 0
A22: Curtailment Order GA | B22: =IFERROR(AVERAGEIFS(Grid_BD!$AA:$AA,Grid_BD!$F:$F,">="&Analytics!$B$3,Grid_BD!$F:$F,"<="&Analytics!$B$4,Grid_BD!$L:$L,'Basic Data'!$AB$2),1) -> 1 | C22: =IFERROR(AVERAGEIFS(Grid_BD!$AA:$AA,Grid_BD!$F:$F,">="&Analytics!$B$3,Grid_BD!$F:$F,"<="&Analytics!$B$4,Grid_BD!$L:$L,'Basic Data'!$AB$2),1) -> 1 | D22: =IFERROR(AVERAGEIFS(Grid_BD!$AA:$AA,Grid_BD!$F:$F,">="&Analytics!$B$3,Grid_BD!$F:$F,"<="&Analytics!$B$4,Grid_BD!$L:$L,'Basic Data'!$AB$2),1) -> 1 | E22: =IFERROR(AVERAGEIFS(Grid_BD!$AA:$AA,Grid_BD!$F:$F,">="&Analytics!$B$3,Grid_BD!$F:$F,"<="&Analytics!$B$4,Grid_BD!$L:$L,'Basic Data'!$AB$2),1) -> 1 | F22: =IFERROR(AVERAGEIFS(Grid_BD!$AA:$AA,Grid_BD!$F:$F,">="&Analytics!$B$3,Grid_BD!$F:$F,"<="&Analytics!$B$4,Grid_BD!$L:$L,'Basic Data'!$AB$2),1) -> 1 | G22: =IFERROR(AVERAGEIFS(Grid_BD!$AA:$AA,Grid_BD!$F:$F,">="&Analytics!$B$3,Grid_BD!$F:$F,"<="&Analytics!$B$4,Grid_BD!$L:$L,'Basic Data'!$AB$2),1) -> 1 | H22: =IFERROR(AVERAGEIFS(Grid_BD!$AA:$AA,Grid_BD!$F:$F,">="&Analytics!$B$3,Grid_BD!$F:$F,"<="&Analytics!$B$4,Grid_BD!$L:$L,'Basic Data'!$AB$2),1) -> 1 | I22: =IFERROR(AVERAGEIFS(Grid_BD!$AA:$AA,Grid_BD!$F:$F,">="&Analytics!$B$3,Grid_BD!$F:$F,"<="&Analytics!$B$4,Grid_BD!$L:$L,'Basic Data'!$AB$2),1) -> 1 | ... X22: =IFERROR(AVERAGEIFS(Grid_BD!$AA:$AA,Grid_BD!$F:$F,">="&Analytics!$B$3,Grid_BD!$F:$F,"<="&Analytics!$B$4,Grid_BD!$L:$L,'Basic Data'!$AB$2),1) -> 1 | AA22: =AVERAGE(B22,D22,K22:P22,T22:U22) -> 1 | AB22: =AVERAGE(Q22:R22) -> 1 | AC22: =AVERAGE(S22) -> 1 | AD22: =AVERAGE(C22,E22:G22,J22,V22:X22) -> 1 | AE22: =AVERAGE(H22:I22) -> 1
A23: Shutdown | B23: =SUMIFS(Grid_BD!$R:$R,Grid_BD!$F:$F,">="&Analytics!$B$3,Grid_BD!$F:$F,"<="&Analytics!$B$4,Grid_BD!$L:$L,Analytics!$A23) -> 0 | C23: =SUMIFS(Grid_BD!$R:$R,Grid_BD!$F:$F,">="&Analytics!$B$3,Grid_BD!$F:$F,"<="&Analytics!$B$4,Grid_BD!$L:$L,Analytics!$A23) -> 0 | D23: =SUMIFS(Grid_BD!$R:$R,Grid_BD!$F:$F,">="&Analytics!$B$3,Grid_BD!$F:$F,"<="&Analytics!$B$4,Grid_BD!$L:$L,Analytics!$A23) -> 0 | E23: =SUMIFS(Grid_BD!$R:$R,Grid_BD!$F:$F,">="&Analytics!$B$3,Grid_BD!$F:$F,"<="&Analytics!$B$4,Grid_BD!$L:$L,Analytics!$A23) -> 0 | F23: =SUMIFS(Grid_BD!$R:$R,Grid_BD!$F:$F,">="&Analytics!$B$3,Grid_BD!$F:$F,"<="&Analytics!$B$4,Grid_BD!$L:$L,Analytics!$A23) -> 0 | G23: =SUMIFS(Grid_BD!$R:$R,Grid_BD!$F:$F,">="&Analytics!$B$3,Grid_BD!$F:$F,"<="&Analytics!$B$4,Grid_BD!$L:$L,Analytics!$A23) -> 0 | H23: =SUMIFS(Grid_BD!$R:$R,Grid_BD!$F:$F,">="&Analytics!$B$3,Grid_BD!$F:$F,"<="&Analytics!$B$4,Grid_BD!$L:$L,Analytics!$A23) -> 0 | I23: =SUMIFS(Grid_BD!$R:$R,Grid_BD!$F:$F,">="&Analytics!$B$3,Grid_BD!$F:$F,"<="&Analytics!$B$4,Grid_BD!$L:$L,Analytics!$A23) -> 0 | ... X23: =SUMIFS(Grid_BD!$R:$R,Grid_BD!$F:$F,">="&Analytics!$B$3,Grid_BD!$F:$F,"<="&Analytics!$B$4,Grid_BD!$L:$L,Analytics!$A23) -> 0 | AA23: =AVERAGE(B23,D23,K23:P23,T23:U23) -> 0 | AB23: =AVERAGE(Q23:R23) -> 0 | AC23: =AVERAGE(S23) -> 0 | AD23: =AVERAGE(C23,E23:G23,J23,V23:X23) -> 0 | AE23: =AVERAGE(H23:I23) -> 0
A24: Generation (MWh) | B24: =SUMIFS(Input_Raw!H:H,Input_Raw!$E:$E,">="&Analytics!$B$3,Input_Raw!$E:$E,"<="&Analytics!$B$4)/1000 -> 25.785 | C24: =SUMIFS(Input_Raw!I:I,Input_Raw!$E:$E,">="&Analytics!$B$3,Input_Raw!$E:$E,"<="&Analytics!$B$4)/1000 -> 25.012 | D24: =SUMIFS(Input_Raw!J:J,Input_Raw!$E:$E,">="&Analytics!$B$3,Input_Raw!$E:$E,"<="&Analytics!$B$4)/1000 -> 20.727 | E24: =SUMIFS(Input_Raw!K:K,Input_Raw!$E:$E,">="&Analytics!$B$3,Input_Raw!$E:$E,"<="&Analytics!$B$4)/1000 -> 21.839 | F24: =SUMIFS(Input_Raw!L:L,Input_Raw!$E:$E,">="&Analytics!$B$3,Input_Raw!$E:$E,"<="&Analytics!$B$4)/1000 -> 20.474 | G24: =SUMIFS(Input_Raw!M:M,Input_Raw!$E:$E,">="&Analytics!$B$3,Input_Raw!$E:$E,"<="&Analytics!$B$4)/1000 -> 21.168 | H24: =SUMIFS(Input_Raw!N:N,Input_Raw!$E:$E,">="&Analytics!$B$3,Input_Raw!$E:$E,"<="&Analytics!$B$4)/1000 -> 20.4 | I24: =SUMIFS(Input_Raw!O:O,Input_Raw!$E:$E,">="&Analytics!$B$3,Input_Raw!$E:$E,"<="&Analytics!$B$4)/1000 -> 21.499 | J24: =SUMIFS(Input_Raw!P:P,Input_Raw!$E:$E,">="&Analytics!$B$3,Input_Raw!$E:$E,"<="&Analytics!$B$4)/1000 -> 20.279 | K24: =SUMIFS(Input_Raw!Q:Q,Input_Raw!$E:$E,">="&Analytics!$B$3,Input_Raw!$E:$E,"<="&Analytics!$B$4)/1000 -> 20.235 | L24: =SUMIFS(Input_Raw!R:R,Input_Raw!$E:$E,">="&Analytics!$B$3,Input_Raw!$E:$E,"<="&Analytics!$B$4)/1000 -> 20.857 | M24: =SUMIFS(Input_Raw!S:S,Input_Raw!$E:$E,">="&Analytics!$B$3,Input_Raw!$E:$E,"<="&Analytics!$B$4)/1000 -> 24.677 | N24: =SUMIFS(Input_Raw!T:T,Input_Raw!$E:$E,">="&Analytics!$B$3,Input_Raw!$E:$E,"<="&Analytics!$B$4)/1000 -> 20.481 | O24: =SUMIFS(Input_Raw!U:U,Input_Raw!$E:$E,">="&Analytics!$B$3,Input_Raw!$E:$E,"<="&Analytics!$B$4)/1000 -> 19.298 | P24: =SUMIFS(Input_Raw!V:V,Input_Raw!$E:$E,">="&Analytics!$B$3,Input_Raw!$E:$E,"<="&Analytics!$B$4)/1000 -> 24.364 | Q24: =SUMIFS(Input_Raw!W:W,Input_Raw!$E:$E,">="&Analytics!$B$3,Input_Raw!$E:$E,"<="&Analytics!$B$4)/1000 -> 24.713 | R24: =SUMIFS(Input_Raw!X:X,Input_Raw!$E:$E,">="&Analytics!$B$3,Input_Raw!$E:$E,"<="&Analytics!$B$4)/1000 -> 25.87 | S24: =SUMIFS(Input_Raw!Y:Y,Input_Raw!$E:$E,">="&Analytics!$B$3,Input_Raw!$E:$E,"<="&Analytics!$B$4)/1000 -> 20.397 | T24: =SUMIFS(Input_Raw!Z:Z,Input_Raw!$E:$E,">="&Analytics!$B$3,Input_Raw!$E:$E,"<="&Analytics!$B$4)/1000 -> 20.804 | U24: =SUMIFS(Input_Raw!AA:AA,Input_Raw!$E:$E,">="&Analytics!$B$3,Input_Raw!$E:$E,"<="&Analytics!$B$4)/1000 -> 21.926 | V24: =SUMIFS(Input_Raw!AB:AB,Input_Raw!$E:$E,">="&Analytics!$B$3,Input_Raw!$E:$E,"<="&Analytics!$B$4)/1000 -> 24.323 | W24: =SUMIFS(Input_Raw!AC:AC,Input_Raw!$E:$E,">="&Analytics!$B$3,Input_Raw!$E:$E,"<="&Analytics!$B$4)/1000 -> 19.273 | X24: =SUMIFS(Input_Raw!AD:AD,Input_Raw!$E:$E,">="&Analytics!$B$3,Input_Raw!$E:$E,"<="&Analytics!$B$4)/1000 -> 23.974 | AA24: =SUM(B24,D24,K24:P24,T24:U24) -> 219.154 | AB24: =SUM(Q24:R24) -> 50.583 | AC24: =SUM(S24) -> 20.397 | AD24: =SUM(C24,E24:G24,J24,V24:X24) -> 176.342 | AE24: =SUM(H24:I24) -> 41.899
A25: Plant Availability - PA (%) | B25: =(($C$4-SUM(B19:B20,B23,B7,B9:B15))/$C$4)*B22 -> 0.99985232 | C25: =(($C$4-SUM(C19:C20,C23,C7,C9:C15))/$C$4)*C22 -> 0.99989451 | D25: =(($C$4-SUM(D19:D20,D23,D7,D9:D15))/$C$4)*D22 -> 0.99989451 | E25: =(($C$4-SUM(E19:E20,E23,E7,E9:E15))/$C$4)*E22 -> 0.99989451 | F25: =(($C$4-SUM(F19:F20,F23,F7,F9:F15))/$C$4)*F22 -> 0.99985759 | G25: =(($C$4-SUM(G19:G20,G23,G7,G9:G15))/$C$4)*G22 -> 0.99989451 | H25: =(($C$4-SUM(H19:H20,H23,H7,H9:H15))/$C$4)*H22 -> 0.99985935 | I25: =(($C$4-SUM(I19:I20,I23,I7,I9:I15))/$C$4)*I22 -> 0.99985759 | ... X25: =(($C$4-SUM(X19:X20,X23,X7,X9:X15))/$C$4)*X22 -> 0.99984529 | AA25: =AVERAGE(B25,D25,K25:P25,T25:U25) -> 0.99984898 | AB25: =AVERAGE(Q25:R25) -> 0.99989451 | AC25: =AVERAGE(S25) -> 0.99985232 | AD25: =AVERAGE(C25,E25:G25,J25,V25:X25) -> 0.99973805 | AE25: =AVERAGE(H25:I25) -> 0.99985847
A26: Sum of BD | B26: =(SUMIFS(WTG_BD!$T:$T,WTG_BD!$G:$G,Analytics!B$5,WTG_BD!$F:$F,">="&Analytics!$B$3,WTG_BD!$F:$F,"<="&Analytics!$B$4,WTG_BD!$N:$N,"breakdown")) -> 0 | C26: =(SUMIFS(WTG_BD!$T:$T,WTG_BD!$G:$G,Analytics!C$5,WTG_BD!$F:$F,">="&Analytics!$B$3,WTG_BD!$F:$F,"<="&Analytics!$B$4,WTG_BD!$N:$N,"breakdown")) -> 0 | D26: =(SUMIFS(WTG_BD!$T:$T,WTG_BD!$G:$G,Analytics!D$5,WTG_BD!$F:$F,">="&Analytics!$B$3,WTG_BD!$F:$F,"<="&Analytics!$B$4,WTG_BD!$N:$N,"breakdown")) -> 0 | E26: =(SUMIFS(WTG_BD!$T:$T,WTG_BD!$G:$G,Analytics!E$5,WTG_BD!$F:$F,">="&Analytics!$B$3,WTG_BD!$F:$F,"<="&Analytics!$B$4,WTG_BD!$N:$N,"breakdown")) -> 0 | F26: =(SUMIFS(WTG_BD!$T:$T,WTG_BD!$G:$G,Analytics!F$5,WTG_BD!$F:$F,">="&Analytics!$B$3,WTG_BD!$F:$F,"<="&Analytics!$B$4,WTG_BD!$N:$N,"breakdown")) -> 0 | G26: =(SUMIFS(WTG_BD!$T:$T,WTG_BD!$G:$G,Analytics!G$5,WTG_BD!$F:$F,">="&Analytics!$B$3,WTG_BD!$F:$F,"<="&Analytics!$B$4,WTG_BD!$N:$N,"breakdown")) -> 0 | H26: =(SUMIFS(WTG_BD!$T:$T,WTG_BD!$G:$G,Analytics!H$5,WTG_BD!$F:$F,">="&Analytics!$B$3,WTG_BD!$F:$F,"<="&Analytics!$B$4,WTG_BD!$N:$N,"breakdown")) -> 0 | I26: =(SUMIFS(WTG_BD!$T:$T,WTG_BD!$G:$G,Analytics!I$5,WTG_BD!$F:$F,">="&Analytics!$B$3,WTG_BD!$F:$F,"<="&Analytics!$B$4,WTG_BD!$N:$N,"breakdown")) -> 0 | ... X26: =(SUMIFS(WTG_BD!$T:$T,WTG_BD!$G:$G,Analytics!X$5,WTG_BD!$F:$F,">="&Analytics!$B$3,WTG_BD!$F:$F,"<="&Analytics!$B$4,WTG_BD!$N:$N,"breakdown")) -> 0 | Y26: =SUM(B26:X26) -> 1.9833333 | AA26: =AVERAGE(B26,D26,K26:P26,T26:U26) -> 0 | AB26: =AVERAGE(Q26:R26) -> 0 | AC26: =AVERAGE(S26) -> 0 | AD26: =AVERAGE(C26,E26:G26,J26,V26:X26) -> 0.24791667 | AE26: =AVERAGE(H26:I26) -> 0
A27: Count of BD | B27: =COUNTIFS(WTG_BD!$G:$G,Analytics!B$5,WTG_BD!$F:$F,">="&Analytics!$B$3,WTG_BD!$F:$F,"<="&Analytics!$B$4,WTG_BD!$N:$N,"breakdown") -> 0 | C27: =COUNTIFS(WTG_BD!$G:$G,Analytics!C$5,WTG_BD!$F:$F,">="&Analytics!$B$3,WTG_BD!$F:$F,"<="&Analytics!$B$4,WTG_BD!$N:$N,"breakdown") -> 0 | D27: =COUNTIFS(WTG_BD!$G:$G,Analytics!D$5,WTG_BD!$F:$F,">="&Analytics!$B$3,WTG_BD!$F:$F,"<="&Analytics!$B$4,WTG_BD!$N:$N,"breakdown") -> 0 | E27: =COUNTIFS(WTG_BD!$G:$G,Analytics!E$5,WTG_BD!$F:$F,">="&Analytics!$B$3,WTG_BD!$F:$F,"<="&Analytics!$B$4,WTG_BD!$N:$N,"breakdown") -> 0 | F27: =COUNTIFS(WTG_BD!$G:$G,Analytics!F$5,WTG_BD!$F:$F,">="&Analytics!$B$3,WTG_BD!$F:$F,"<="&Analytics!$B$4,WTG_BD!$N:$N,"breakdown") -> 0 | G27: =COUNTIFS(WTG_BD!$G:$G,Analytics!G$5,WTG_BD!$F:$F,">="&Analytics!$B$3,WTG_BD!$F:$F,"<="&Analytics!$B$4,WTG_BD!$N:$N,"breakdown") -> 0 | H27: =COUNTIFS(WTG_BD!$G:$G,Analytics!H$5,WTG_BD!$F:$F,">="&Analytics!$B$3,WTG_BD!$F:$F,"<="&Analytics!$B$4,WTG_BD!$N:$N,"breakdown") -> 0 | I27: =COUNTIFS(WTG_BD!$G:$G,Analytics!I$5,WTG_BD!$F:$F,">="&Analytics!$B$3,WTG_BD!$F:$F,"<="&Analytics!$B$4,WTG_BD!$N:$N,"breakdown") -> 0 | ... X27: =COUNTIFS(WTG_BD!$G:$G,Analytics!X$5,WTG_BD!$F:$F,">="&Analytics!$B$3,WTG_BD!$F:$F,"<="&Analytics!$B$4,WTG_BD!$N:$N,"breakdown") -> 0 | Y27: =SUM(B27:X27) -> 1 | AA27: =AVERAGE(B27,D27,K27:P27,T27:U27) -> 0 | AB27: =AVERAGE(Q27:R27) -> 0 | AC27: =AVERAGE(S27) -> 0 | AD27: =AVERAGE(C27,E27:G27,J27,V27:X27) -> 0.125 | AE27: =AVERAGE(H27:I27) -> 0
A28: MTTR WTG (Hours) | B28: =IFERROR(B26/B27,0) -> 0 | C28: =IFERROR(C26/C27,0) -> 0 | D28: =IFERROR(D26/D27,0) -> 0 | E28: =IFERROR(E26/E27,0) -> 0 | F28: =IFERROR(F26/F27,0) -> 0 | G28: =IFERROR(G26/G27,0) -> 0 | H28: =IFERROR(H26/H27,0) -> 0 | I28: =IFERROR(I26/I27,0) -> 0 | ... Y28: =IFERROR(Y26/Y27,0) -> 1.9833333 | AA28: =SUM(B28,D28,K28:P28,T28:U28) -> 0 | AB28: =SUM(Q28:R28) -> 0 | AC28: =SUM(S28) -> 0 | AD28: =SUM(C28,E28:G28,J28,V28:X28) -> 1.9833333 | AE28: =SUM(H28:I28) -> 0
A29: MTBF WTG (Hours) | B29: =IFERROR(($C$4-B26)/B27,$C$4) -> 9480 | C29: =IFERROR(($C$4-C26)/C27,$C$4) -> 9480 | D29: =IFERROR(($C$4-D26)/D27,$C$4) -> 9480 | E29: =IFERROR(($C$4-E26)/E27,$C$4) -> 9480 | F29: =IFERROR(($C$4-F26)/F27,$C$4) -> 9480 | G29: =IFERROR(($C$4-G26)/G27,$C$4) -> 9480 | H29: =IFERROR(($C$4-H26)/H27,$C$4) -> 9480 | I29: =IFERROR(($C$4-I26)/I27,$C$4) -> 9480 | ... X29: =IFERROR(($C$4-X26)/X27,$C$4) -> 9480 | AA29: =SUM(B29,D29,K29:P29,T29:U29) -> 94800 | AB29: =SUM(Q29:R29) -> 18960 | AC29: =SUM(S29) -> 9480 | AD29: =SUM(C29,E29:G29,J29,V29:X29) -> 75838.017 | AE29: =SUM(H29:I29) -> 18960
A30: Wind Speed (m/s) | B30: =AVERAGEIFS(Input_Raw!AE:AE,Input_Raw!$E:$E,">="&Analytics!$B$3,Input_Raw!$E:$E,"<="&Analytics!$B$4) -> 4.7089793 | C30: =AVERAGEIFS(Input_Raw!AF:AF,Input_Raw!$E:$E,">="&Analytics!$B$3,Input_Raw!$E:$E,"<="&Analytics!$B$4) -> 4.6975793 | D30: =AVERAGEIFS(Input_Raw!AG:AG,Input_Raw!$E:$E,">="&Analytics!$B$3,Input_Raw!$E:$E,"<="&Analytics!$B$4) -> 4.6241448 | E30: =AVERAGEIFS(Input_Raw!AH:AH,Input_Raw!$E:$E,">="&Analytics!$B$3,Input_Raw!$E:$E,"<="&Analytics!$B$4) -> 4.375754 | F30: =AVERAGEIFS(Input_Raw!AI:AI,Input_Raw!$E:$E,">="&Analytics!$B$3,Input_Raw!$E:$E,"<="&Analytics!$B$4) -> 4.4242966 | G30: =AVERAGEIFS(Input_Raw!AJ:AJ,Input_Raw!$E:$E,">="&Analytics!$B$3,Input_Raw!$E:$E,"<="&Analytics!$B$4) -> 4.4857126 | H30: =AVERAGEIFS(Input_Raw!AK:AK,Input_Raw!$E:$E,">="&Analytics!$B$3,Input_Raw!$E:$E,"<="&Analytics!$B$4) -> 4.4802828 | I30: =AVERAGEIFS(Input_Raw!AL:AL,Input_Raw!$E:$E,">="&Analytics!$B$3,Input_Raw!$E:$E,"<="&Analytics!$B$4) -> 4.5475885 | J30: =AVERAGEIFS(Input_Raw!AM:AM,Input_Raw!$E:$E,">="&Analytics!$B$3,Input_Raw!$E:$E,"<="&Analytics!$B$4) -> 4.576492 | K30: =AVERAGEIFS(Input_Raw!AN:AN,Input_Raw!$E:$E,">="&Analytics!$B$3,Input_Raw!$E:$E,"<="&Analytics!$B$4) -> 4.4010299 | L30: =AVERAGEIFS(Input_Raw!AO:AO,Input_Raw!$E:$E,">="&Analytics!$B$3,Input_Raw!$E:$E,"<="&Analytics!$B$4) -> 4.5822092 | M30: =AVERAGEIFS(Input_Raw!AP:AP,Input_Raw!$E:$E,">="&Analytics!$B$3,Input_Raw!$E:$E,"<="&Analytics!$B$4) -> 4.594554 | N30: =AVERAGEIFS(Input_Raw!AQ:AQ,Input_Raw!$E:$E,">="&Analytics!$B$3,Input_Raw!$E:$E,"<="&Analytics!$B$4) -> 4.4120138 | O30: =AVERAGEIFS(Input_Raw!AR:AR,Input_Raw!$E:$E,">="&Analytics!$B$3,Input_Raw!$E:$E,"<="&Analytics!$B$4) -> 4.3286736 | P30: =AVERAGEIFS(Input_Raw!AS:AS,Input_Raw!$E:$E,">="&Analytics!$B$3,Input_Raw!$E:$E,"<="&Analytics!$B$4) -> 4.8205839 | Q30: =AVERAGEIFS(Input_Raw!AT:AT,Input_Raw!$E:$E,">="&Analytics!$B$3,Input_Raw!$E:$E,"<="&Analytics!$B$4) -> 4.714377 | R30: =AVERAGEIFS(Input_Raw!AU:AU,Input_Raw!$E:$E,">="&Analytics!$B$3,Input_Raw!$E:$E,"<="&Analytics!$B$4) -> 4.7879218 | S30: =AVERAGEIFS(Input_Raw!AV:AV,Input_Raw!$E:$E,">="&Analytics!$B$3,Input_Raw!$E:$E,"<="&Analytics!$B$4) -> 4.468554 | T30: =AVERAGEIFS(Input_Raw!AW:AW,Input_Raw!$E:$E,">="&Analytics!$B$3,Input_Raw!$E:$E,"<="&Analytics!$B$4) -> 4.4595218 | U30: =AVERAGEIFS(Input_Raw!AX:AX,Input_Raw!$E:$E,">="&Analytics!$B$3,Input_Raw!$E:$E,"<="&Analytics!$B$4) -> 4.527846 | V30: =AVERAGEIFS(Input_Raw!AY:AY,Input_Raw!$E:$E,">="&Analytics!$B$3,Input_Raw!$E:$E,"<="&Analytics!$B$4) -> 4.7895011 | W30: =AVERAGEIFS(Input_Raw!AZ:AZ,Input_Raw!$E:$E,">="&Analytics!$B$3,Input_Raw!$E:$E,"<="&Analytics!$B$4) -> 4.5881714 | X30: =AVERAGEIFS(Input_Raw!BA:BA,Input_Raw!$E:$E,">="&Analytics!$B$3,Input_Raw!$E:$E,"<="&Analytics!$B$4) -> 4.6878069 | AA30: =AVERAGE(B30,D30,K30:P30,T30:U30) -> 4.5459556 | AB30: =AVERAGE(Q30:R30) -> 4.7511494 | AC30: =AVERAGE(S30) -> 4.468554 | AD30: =AVERAGE(C30,E30:G30,J30,V30:X30) -> 4.5781642 | AE30: =AVERAGE(H30:I30) -> 4.5139356
A31: CUF (%) | B31: =B24/$C$4/2.2 -> 0.0012363349 | C31: =C24/$C$4/2.2 -> 0.0011992712 | D31: =D24/$C$4/2.2 -> 0.00099381473 | E31: =E24/$C$4/2.2 -> 0.0010471327 | F31: =F24/$C$4/2.2 -> 0.00098168393 | G31: =G24/$C$4/2.2 -> 0.0010149597 | H31: =H24/$C$4/2.2 -> 0.00097813579 | I31: =I24/$C$4/2.2 -> 0.0010308305 | ... X31: =X24/$C$4/2.2 -> 0.0011495013 | AA31: =AVERAGE(B31,D31,K31:P31,T31:U31) -> 0.0010507959 | AB31: =AVERAGE(Q31:R31) -> 0.0012126726 | AC31: =AVERAGE(S31) -> 0.00097799194 | AD31: =AVERAGE(C31,E31:G31,J31,V31:X31) -> 0.0010569021 | AE31: =AVERAGE(H31:I31) -> 0.0010044831
A32: Line loss (%)
A33: Corelation (%)
A34: Reactive Power
A37: Day | B37: =VLOOKUP(O2Summary!$B$4,Input_Raw!$E:$AD,Input_Raw!H1,0) -> 27311 | C37: =VLOOKUP(O2Summary!$B$4,Input_Raw!$E:$AD,Input_Raw!I1,0) -> 27759 | D37: =VLOOKUP(O2Summary!$B$4,Input_Raw!$E:$AD,Input_Raw!J1,0) -> 22546.4 | E37: =VLOOKUP(O2Summary!$B$4,Input_Raw!$E:$AD,Input_Raw!K1,0) -> 22807.9 | F37: =VLOOKUP(O2Summary!$B$4,Input_Raw!$E:$AD,Input_Raw!L1,0) -> 23961.7 | G37: =VLOOKUP(O2Summary!$B$4,Input_Raw!$E:$AD,Input_Raw!M1,0) -> 23660.1 | H37: =VLOOKUP(O2Summary!$B$4,Input_Raw!$E:$AD,Input_Raw!N1,0) -> 22378.8 | I37: =VLOOKUP(O2Summary!$B$4,Input_Raw!$E:$AD,Input_Raw!O1,0) -> 23178.5 | ... X37: =VLOOKUP(O2Summary!$B$4,Input_Raw!$E:$AD,Input_Raw!AD1,0) -> 28273.8
A38: MTD | B38: =SUMIFS(Input_Raw!H:H,Input_Raw!$E:$E,">="&MonthlyKPI!$A$4,Input_Raw!$E:$E,"<="&O2Summary!$B$4) -> 678140.4 | C38: =SUMIFS(Input_Raw!I:I,Input_Raw!$E:$E,">="&MonthlyKPI!$A$4,Input_Raw!$E:$E,"<="&O2Summary!$B$4) -> 697650.2 | D38: =SUMIFS(Input_Raw!J:J,Input_Raw!$E:$E,">="&MonthlyKPI!$A$4,Input_Raw!$E:$E,"<="&O2Summary!$B$4) -> 622348.6 | E38: =SUMIFS(Input_Raw!K:K,Input_Raw!$E:$E,">="&MonthlyKPI!$A$4,Input_Raw!$E:$E,"<="&O2Summary!$B$4) -> 622009.6 | F38: =SUMIFS(Input_Raw!L:L,Input_Raw!$E:$E,">="&MonthlyKPI!$A$4,Input_Raw!$E:$E,"<="&O2Summary!$B$4) -> 668878.3 | G38: =SUMIFS(Input_Raw!M:M,Input_Raw!$E:$E,">="&MonthlyKPI!$A$4,Input_Raw!$E:$E,"<="&O2Summary!$B$4) -> 635369.2 | H38: =SUMIFS(Input_Raw!N:N,Input_Raw!$E:$E,">="&MonthlyKPI!$A$4,Input_Raw!$E:$E,"<="&O2Summary!$B$4) -> 627087.8 | I38: =SUMIFS(Input_Raw!O:O,Input_Raw!$E:$E,">="&MonthlyKPI!$A$4,Input_Raw!$E:$E,"<="&O2Summary!$B$4) -> 663349.5 | J38: =SUMIFS(Input_Raw!P:P,Input_Raw!$E:$E,">="&MonthlyKPI!$A$4,Input_Raw!$E:$E,"<="&O2Summary!$B$4) -> 632072 | K38: =SUMIFS(Input_Raw!Q:Q,Input_Raw!$E:$E,">="&MonthlyKPI!$A$4,Input_Raw!$E:$E,"<="&O2Summary!$B$4) -> 648583 | L38: =SUMIFS(Input_Raw!R:R,Input_Raw!$E:$E,">="&MonthlyKPI!$A$4,Input_Raw!$E:$E,"<="&O2Summary!$B$4) -> 638556.1 | M38: =SUMIFS(Input_Raw!S:S,Input_Raw!$E:$E,">="&MonthlyKPI!$A$4,Input_Raw!$E:$E,"<="&O2Summary!$B$4) -> 651585.1 | N38: =SUMIFS(Input_Raw!T:T,Input_Raw!$E:$E,">="&MonthlyKPI!$A$4,Input_Raw!$E:$E,"<="&O2Summary!$B$4) -> 674176.2 | O38: =SUMIFS(Input_Raw!U:U,Input_Raw!$E:$E,">="&MonthlyKPI!$A$4,Input_Raw!$E:$E,"<="&O2Summary!$B$4) -> 645132.2 | P38: =SUMIFS(Input_Raw!V:V,Input_Raw!$E:$E,">="&MonthlyKPI!$A$4,Input_Raw!$E:$E,"<="&O2Summary!$B$4) -> 731759.5 | Q38: =SUMIFS(Input_Raw!W:W,Input_Raw!$E:$E,">="&MonthlyKPI!$A$4,Input_Raw!$E:$E,"<="&O2Summary!$B$4) -> 719996.4 | R38: =SUMIFS(Input_Raw!X:X,Input_Raw!$E:$E,">="&MonthlyKPI!$A$4,Input_Raw!$E:$E,"<="&O2Summary!$B$4) -> 722250.9 | S38: =SUMIFS(Input_Raw!Y:Y,Input_Raw!$E:$E,">="&MonthlyKPI!$A$4,Input_Raw!$E:$E,"<="&O2Summary!$B$4) -> 663108.9 | T38: =SUMIFS(Input_Raw!Z:Z,Input_Raw!$E:$E,">="&MonthlyKPI!$A$4,Input_Raw!$E:$E,"<="&O2Summary!$B$4) -> 682616.8 | U38: =SUMIFS(Input_Raw!AA:AA,Input_Raw!$E:$E,">="&MonthlyKPI!$A$4,Input_Raw!$E:$E,"<="&O2Summary!$B$4) -> 640894.7 | V38: =SUMIFS(Input_Raw!AB:AB,Input_Raw!$E:$E,">="&MonthlyKPI!$A$4,Input_Raw!$E:$E,"<="&O2Summary!$B$4) -> 659849 | W38: =SUMIFS(Input_Raw!AC:AC,Input_Raw!$E:$E,">="&MonthlyKPI!$A$4,Input_Raw!$E:$E,"<="&O2Summary!$B$4) -> 654251.6 | X38: =SUMIFS(Input_Raw!AD:AD,Input_Raw!$E:$E,">="&MonthlyKPI!$A$4,Input_Raw!$E:$E,"<="&O2Summary!$B$4) -> 707011.9
A39: YTD | B39: =SUMIFS(Input_Raw!H:H,Input_Raw!$E:$E,">="&O2Summary!$B$6,Input_Raw!$E:$E,"<="&O2Summary!$B$4) -> 2620666.7 | C39: =SUMIFS(Input_Raw!I:I,Input_Raw!$E:$E,">="&O2Summary!$B$6,Input_Raw!$E:$E,"<="&O2Summary!$B$4) -> 2578208.4 | D39: =SUMIFS(Input_Raw!J:J,Input_Raw!$E:$E,">="&O2Summary!$B$6,Input_Raw!$E:$E,"<="&O2Summary!$B$4) -> 2360481.6 | E39: =SUMIFS(Input_Raw!K:K,Input_Raw!$E:$E,">="&O2Summary!$B$6,Input_Raw!$E:$E,"<="&O2Summary!$B$4) -> 2253153.6 | F39: =SUMIFS(Input_Raw!L:L,Input_Raw!$E:$E,">="&O2Summary!$B$6,Input_Raw!$E:$E,"<="&O2Summary!$B$4) -> 2395786.8 | G39: =SUMIFS(Input_Raw!M:M,Input_Raw!$E:$E,">="&O2Summary!$B$6,Input_Raw!$E:$E,"<="&O2Summary!$B$4) -> 2359799.4 | H39: =SUMIFS(Input_Raw!N:N,Input_Raw!$E:$E,">="&O2Summary!$B$6,Input_Raw!$E:$E,"<="&O2Summary!$B$4) -> 2339954 | I39: =SUMIFS(Input_Raw!O:O,Input_Raw!$E:$E,">="&O2Summary!$B$6,Input_Raw!$E:$E,"<="&O2Summary!$B$4) -> 2490754.3 | J39: =SUMIFS(Input_Raw!P:P,Input_Raw!$E:$E,">="&O2Summary!$B$6,Input_Raw!$E:$E,"<="&O2Summary!$B$4) -> 2368795.4 | K39: =SUMIFS(Input_Raw!Q:Q,Input_Raw!$E:$E,">="&O2Summary!$B$6,Input_Raw!$E:$E,"<="&O2Summary!$B$4) -> 2391098.6 | L39: =SUMIFS(Input_Raw!R:R,Input_Raw!$E:$E,">="&O2Summary!$B$6,Input_Raw!$E:$E,"<="&O2Summary!$B$4) -> 2362650.9 | M39: =SUMIFS(Input_Raw!S:S,Input_Raw!$E:$E,">="&O2Summary!$B$6,Input_Raw!$E:$E,"<="&O2Summary!$B$4) -> 2454206.3 | N39: =SUMIFS(Input_Raw!T:T,Input_Raw!$E:$E,">="&O2Summary!$B$6,Input_Raw!$E:$E,"<="&O2Summary!$B$4) -> 2479185.6 | O39: =SUMIFS(Input_Raw!U:U,Input_Raw!$E:$E,">="&O2Summary!$B$6,Input_Raw!$E:$E,"<="&O2Summary!$B$4) -> 2367448.7 | P39: =SUMIFS(Input_Raw!V:V,Input_Raw!$E:$E,">="&O2Summary!$B$6,Input_Raw!$E:$E,"<="&O2Summary!$B$4) -> 2730663.2 | Q39: =SUMIFS(Input_Raw!W:W,Input_Raw!$E:$E,">="&O2Summary!$B$6,Input_Raw!$E:$E,"<="&O2Summary!$B$4) -> 2666231 | R39: =SUMIFS(Input_Raw!X:X,Input_Raw!$E:$E,">="&O2Summary!$B$6,Input_Raw!$E:$E,"<="&O2Summary!$B$4) -> 2643788 | S39: =SUMIFS(Input_Raw!Y:Y,Input_Raw!$E:$E,">="&O2Summary!$B$6,Input_Raw!$E:$E,"<="&O2Summary!$B$4) -> 2365252 | T39: =SUMIFS(Input_Raw!Z:Z,Input_Raw!$E:$E,">="&O2Summary!$B$6,Input_Raw!$E:$E,"<="&O2Summary!$B$4) -> 2472480 | U39: =SUMIFS(Input_Raw!AA:AA,Input_Raw!$E:$E,">="&O2Summary!$B$6,Input_Raw!$E:$E,"<="&O2Summary!$B$4) -> 2334607.7 | V39: =SUMIFS(Input_Raw!AB:AB,Input_Raw!$E:$E,">="&O2Summary!$B$6,Input_Raw!$E:$E,"<="&O2Summary!$B$4) -> 2426536 | W39: =SUMIFS(Input_Raw!AC:AC,Input_Raw!$E:$E,">="&O2Summary!$B$6,Input_Raw!$E:$E,"<="&O2Summary!$B$4) -> 2387790 | X39: =SUMIFS(Input_Raw!AD:AD,Input_Raw!$E:$E,">="&O2Summary!$B$6,Input_Raw!$E:$E,"<="&O2Summary!$B$4) -> 2542904.3
A40: Day Rank | B40: =RANK(B37,$B37:$X37) -> 6 | C40: =RANK(C37,$B37:$X37) -> 4 | D40: =RANK(D37,$B37:$X37) -> 20 | E40: =RANK(E37,$B37:$X37) -> 19 | F40: =RANK(F37,$B37:$X37) -> 12 | G40: =RANK(G37,$B37:$X37) -> 13 | H40: =RANK(H37,$B37:$X37) -> 21 | I40: =RANK(I37,$B37:$X37) -> 17 | ... X40: =RANK(X37,$B37:$X37) -> 2
A41: MTD Rank | B41: =RANK(B38,$B38:$X38) -> 7 | C41: =RANK(C38,$B38:$X38) -> 5 | D41: =RANK(D38,$B38:$X38) -> 22 | E41: =RANK(E38,$B38:$X38) -> 23 | F41: =RANK(F38,$B38:$X38) -> 9 | G41: =RANK(G38,$B38:$X38) -> 19 | H41: =RANK(H38,$B38:$X38) -> 21 | I41: =RANK(I38,$B38:$X38) -> 10 | ... X41: =RANK(X38,$B38:$X38) -> 4
A42: YTD Rank | B42: =RANK(B39,$B39:$X39) -> 4 | C42: =RANK(C39,$B39:$X39) -> 5 | D42: =RANK(D39,$B39:$X39) -> 19 | E42: =RANK(E39,$B39:$X39) -> 23 | F42: =RANK(F39,$B39:$X39) -> 12 | G42: =RANK(G39,$B39:$X39) -> 20 | H42: =RANK(H39,$B39:$X39) -> 21 | I42: =RANK(I39,$B39:$X39) -> 7 | ... X42: =RANK(X39,$B39:$X39) -> 6
B43: Enter Correct Hours | C43: Total Hours YTD
B44: =C44 -> 2616 | C44: =(O2Summary!B4-O2Summary!B6)*24 -> 2616
...

Sheet Daily KPI
A1: Date | B1: Financial Year | C1: Calendar Year | D1: Month Year | E1: Days | F1: Operating Hours | G1: GHI-UP (KWh/m2) | H1: GHI-Down(KWh/m2) | I1: POA-UP(KWh/m2) | J1: POA-Down(KWh/m2) | K1: Amb_Temp(°C) | L1: Mod_Temp(°C) | M1: WS_Avg(m/s) | N1: WS_Max(m/s) | O1: PA(%) | P1: MA (%) | Q1: IGA (%) | R1: EGA(%) | S1: EMA (%) | T1: TA (%) | U1: PR(%) | V1: WPR(%) | W1: CUF(%) | X1: Gen_Exp (kWh) | Y1: Mtr_Export (kWh) | Z1: Mtr_Import (kWh) | AA1: Mtr_Net_Exp (KWh) | AB1: Operational Capacity (MW) | AC1: Bugt_Resource | AD1: Bugt_Energy | AE1: Bugt PR | AF1: Bugt CUF | AG1: Bugt_PA | AH1: Bugt_EGA | AI1: Expected Energy | AJ1: Actual Energy WPR | AK1: RA (%) | AL1: Mod Clean Dry (Num) | AM1: Mod Clean Wet (Num) | AN1: Line Loss(%) | AO1: Reactive Power (%) | AP1: Bugt Line loss (%) (Wind) | AQ1: Bugt Reactive Power (%) (Wind) | AR1: Bugt Capacity | AS1: CC*Bugt
A2: 45745 | B2: =YEAR(Table13[[#This Row],[Date]])+IF(MONTH(Table13[[#This Row],[Date]])>=4,1,0) -> 2025 | C2: =YEAR(Table13[[#This Row],[Date]]) -> 2025 | D2: =Table13[[#This Row],[Date]]-DAY(Table13[[#This Row],[Date]])+1 -> 45717 | E2: =DAY(EOMONTH(A2,0)) -> 31 | F2: =IFERROR(_xlfn.XLOOKUP($A2,Input_Raw!$E:$E,Input_Raw!DC:DC),"") -> 11.483333 | M2: =IFERROR(_xlfn.XLOOKUP($A2,Input_Raw!$E:$E,Input_Raw!$BM:$BM),"") -> 4.6281532 | N2: =IFERROR(_xlfn.XLOOKUP($A2,Input_Raw!$E:$E,Input_Raw!$BN:$BN),"") -> 4.8999172 | O2: =IFERROR(P2*Q2,"") | P2: =IFERROR(1-SUMIF(WTG_BD!$F:$F,$A2,WTG_BD!$AA:$AA)/($AA2+SUMIF(WTG_BD!$F:$F,$A2,WTG_BD!$AA:$AA)),"") | Q2: =IFERROR(1-SUMIF(IGA_BD!$F:$F,$A2,IGA_BD!$W:$W)/($AA2+SUMIF(IGA_BD!$F:$F,$A2,IGA_BD!$W:$W)),"") | R2: =IFERROR(1-SUMIF(Grid_BD!$F:$F,$A2,Grid_BD!$Y:$Y)/($AA2+SUMIF(Grid_BD!$F:$F,$A2,Grid_BD!$Y:$Y)),"") | W2: =IFERROR(X2/(24*AR2*1000),"") | X2: =IFERROR(_xlfn.XLOOKUP($A2,Input_Raw!$E:$E,Input_Raw!BG:BG),"") -> 161352 | Y2: =IFERROR(_xlfn.XLOOKUP($A2,Input_Raw!$E:$E,Input_Raw!DF:DF),"") | Z2: =IFERROR(_xlfn.XLOOKUP(A2,Input_Raw!E:E,Input_Raw!CT:CT)/_xlfn.XLOOKUP(A2,Input_Raw!E:E,Input_Raw!CS:CS)*Table13[[#This Row],[Mtr_Export (kWh)]],"") | AA2: =IFERROR(Y2-Z2,"") | AB2: =IFERROR(_xlfn.XLOOKUP($A2,Input_Raw!$E:$E,Input_Raw!$CZ:$CZ),"") -> 50.6 | AC2: =IFERROR(_xlfn.XLOOKUP($D2,'Modelling New'!$D:$D,'Modelling New'!$J:$J),"") -> 5.9681801 | AD2: =IFERROR(_xlfn.XLOOKUP($D2,'Modelling New'!$D:$D,'Modelling New'!$T:$T)*1000,"") -> 280595.01 | AF2: =IFERROR(_xlfn.XLOOKUP($D2,'Modelling New'!$D:$D,'Modelling New'!$W:$W),"") -> 0.23105649 | AG2: =IFERROR(_xlfn.XLOOKUP($D2,'Modelling New'!$D:$D,'Modelling New'!$AE:$AE),"") -> 0.9554985 | AH2: =IFERROR(_xlfn.XLOOKUP($D2,'Modelling New'!$D:$D,'Modelling New'!$AF:$AF),"") -> 0.995 | AI2: =IFERROR(_xlfn.XLOOKUP($A2,Input_Raw!$E:$E,Input_Raw!$DG:$DG),"") -> 0 | AN2: =IFERROR(_xlfn.XLOOKUP($A2,Input_Raw!$E:$E,Input_Raw!$CY:$CY),"") | AO2: =IFERROR((_xlfn.XLOOKUP($A2,'WTG Reactive Power'!$A:$A,'WTG Reactive Power'!AB:AB))/X2,"") -> 0.0031099707 | AP2: =IFERROR(_xlfn.XLOOKUP($D2,'Modelling New'!$D:$D,'Modelling New'!AK:AK),"") -> 0.05 | AQ2: =IFERROR(_xlfn.XLOOKUP($D2,'Modelling New'!$D:$D,'Modelling New'!AL:AL),"") -> 0.05 | AR2: Pass@123
