Workbook
Name MF_Cap_HCCB: 'Basic Data'!$V$9
Name MF_Cap_O2RE10: 'Basic Data'!$V$12
Name MF_Cap_O2RE6: 'Basic Data'!$V$11
Name MF_Cap_Pepsico: 'Basic Data'!$V$10

Sheet Daily Dashboard
A3: Month:- April - 2025
A4: Month | B4: 45839
A5: Date | B5: 45869
A6: Operation Year | B6: Year_3
A7: Year Start Date | B7: 45748
A8: Year End Date | B8: 46112
A10: Sr. No. | B10: Particular | C10: Target | D10: Measured | E10: Deviation | F10: Remarks
A11: 1 | B11: E_Grid Daily (MWh) | C11: =_xlfn.XLOOKUP($B$5,'Daily KPI'!$A:$A,'Daily KPI'!$AD:$AD,0)/1000 -> 77.476763 | D11: =_xlfn.XLOOKUP($B$5,'Daily KPI'!$A:$A,'Daily KPI'!$AA:$AA,0)/1000 -> 88.0204 | E11: =-(C11-D11)/C11 -> 0.13608773
B12: E_Grid MTD(MWh) | C12: ='Monthly KPI'!$E$4 -> 2401.7797 | D12: ='Monthly KPI'!F4 -> 2199.5125 | E12: =-(C12-D12)/C12 -> -0.084215537
B13: E_Grid YTD (MWh) | C13: ='Annual KPI'!$E$4 -> 12466.606 | D13: ='Annual KPI'!F4 -> 11129.463 | E13: =-(C13-D13)/C13 -> -0.10725795
A14: 2 | B14: CUF Daily(%) | C14: =_xlfn.XLOOKUP($B$5,'Daily KPI'!$A:$A,'Daily KPI'!$AF:$AF,0) -> 0.13283073 | D14: =_xlfn.XLOOKUP($B$5,'Daily KPI'!$A:$A,'Daily KPI'!$W:$W,0) -> 0.15090736 | E14: =-(C14-D14)/C14 -> 0.13608773
B15: CUF MTD(%) | C15: ='Monthly KPI'!I4 -> 0.13283073 | D15: ='Monthly KPI'!J4 -> 0.12164432 | E15: =-(C15-D15)/C15 -> -0.084215537
B16: CUF YTD(%) | C16: ='Annual KPI'!I4 -> 0.17519249 | D16: ='Annual KPI'!J4 -> 0.1564017 | E16: =-(C16-D16)/C16 -> -0.10725795
A17: 3 | B17: PR_Daily (%) | C17: =_xlfn.XLOOKUP($B$5,'Daily KPI'!$A:$A,'Daily KPI'!$AE:$AE) -> 0.72347044 | D17: =_xlfn.XLOOKUP($B$5,'Daily KPI'!$A:$A,'Daily KPI'!$U:$U,0) -> 0.80691686 | E17: =-(C17-D17)/C17 -> 0.11534185
B18: PR_MTD (%) | C18: ='Monthly KPI'!$G$4 -> 0.72347044 | D18: ='Monthly KPI'!H4 -> 0.79732057 | E18: =-(C18-D18)/C18 -> 0.10207761
B19: PR_YTD (%) | C19: ='Annual KPI'!$G$4 -> 0.74192017 | D19: ='Annual KPI'!H4 -> 0.76032491 | E19: =-(C19-D19)/C19 -> 0.024806896
A20: 4 | B20: POA Daily (KWh/m2) | C20: =_xlfn.XLOOKUP($B$5,'Daily KPI'!$A:$A,'Daily KPI'!$AC:$AC,0) -> 4.4064516 | D20: =_xlfn.XLOOKUP($B$5,'Daily KPI'!$A:$A,'Daily KPI'!$I:$I,0) -> 4.4884137 | E20: =-(C20-D20)/C20 -> 0.018600468
B21: POA MTD(KWh/m2) | C21: ='Monthly KPI'!$C$4 -> 136.6 | D21: ='Monthly KPI'!D4 -> 113.50939 | E21: =-(C21-D21)/C21 -> -0.16903814
B22: POA YTD(KWh/m2) | C22: ='Annual KPI'!$C$4 -> 691.4 | D22: ='Annual KPI'!D4 -> 602.30064 | E22: =-(C22-D22)/C22 -> -0.12886803
A23: 5 | B23: PA Daily (KWh/m2) | C23: =_xlfn.XLOOKUP($B$5,'Daily KPI'!$A:$A,'Daily KPI'!$AG:$AG) -> 0.995 | D23: =_xlfn.XLOOKUP($B$5,'Daily KPI'!$A:$A,'Daily KPI'!$O:$O,0) -> 0.99937336 | E23: =-(C23-D23)/C23 -> 0.0043953318
B24: PA MTD(KWh/m2) | C24: =_xlfn.XLOOKUP($B$4,'Modelling New'!$D:$D,'Modelling New'!$AE:$AE) -> 0.995 | D24: ='Monthly KPI'!N4 -> 0.96254936 | E24: =-(C24-D24)/C24 -> -0.032613711
B25: PA YTD(KWh/m2) | C25: =_xlfn.XLOOKUP($B$4,'Modelling New'!$D:$D,'Modelling New'!$AE:$AE) -> 0.995 | D25: ='Annual KPI'!N4 -> 0.96898566 | E25: =-(C25-D25)/C25 -> -0.026145067
A26: 6 | B26: GA Daily (KWh/m2) | C26: =_xlfn.XLOOKUP($B$5,'Daily KPI'!$A:$A,'Daily KPI'!$AH:$AH) -> 0.9975 | D26: =_xlfn.XLOOKUP($B$5,'Daily KPI'!$A:$A,'Daily KPI'!$R:$R,0) -> 1 | E26: =-(C26-D26)/C26 -> 0.0025062657
B27: GA MTD(KWh/m2) | C27: =_xlfn.XLOOKUP($B$4,'Modelling New'!$D:$D,'Modelling New'!$AF:$AF) -> 0.995 | D27: ='Monthly KPI'!L4 -> 1 | E27: =-(C27-D27)/C27 -> 0.0050251256
B28: GA YTD(KWh/m2) | C28: =_xlfn.XLOOKUP($B$4,'Modelling New'!$D:$D,'Modelling New'!$AF:$AF) -> 0.995 | D28: ='Annual KPI'!L4 -> 0.99209933 | E28: =-(C28-D28)/C28 -> -0.0029152449
A31: Performance Summary PSEGPL Solar
A32: Month | B32: =B4 -> 45839
A33: Date | B33: =B5 -> 45869
A34: Operation Year | B34: =B6 -> Year_3
A35: Year Start Date | B35: =B7 -> 45748
A36: Year End Date | B36: =B8 -> 46112
A38: SPV | B38: Particular | C38: Target | D38: Measured | E38: Deviation | F38: Remarks
A39: O2R6 | B39: E_Grid MTD(MWh) | C39: =_xlfn.XLOOKUP($B$32,'Modelling New'!$D:$D,'Modelling New'!$U:$U)*1000*_xlfn.XLOOKUP('Daily Dashboard'!A39,'Basic Data'!$AA$2:$AA$3,'Basic Data'!$AC$2:$AC$3) -> 1834354.6 | D39: =SUMIFS(RD[O2R6],RD[Month Year],$B$32) -> 951767.3 | E39: =D39/C39-1 -> -0.48114322
A40: O2R10 | B40: E_Grid MTD(MWh) | C40: =_xlfn.XLOOKUP($B$32,'Modelling New'!$D:$D,'Modelling New'!$U:$U)*1000*_xlfn.XLOOKUP('Daily Dashboard'!A40,'Basic Data'!$AA$2:$AA$3,'Basic Data'!$AC$2:$AC$3) -> 567425.11 | D40: =SUMIFS(RD[O2R10],RD[Month Year],$B$32) -> 286704.83 | E40: =D40/C40-1 -> -0.49472657
A41: PSEGPL | B41: E_Grid MTD(MWh) | C41: =_xlfn.XLOOKUP($B$32,'Modelling New'!$D:$D,'Modelling New'!$U:$U)*1000 -> 2401779.7 | D41: =SUMIFS(RD[PSEGPL],RD[Month Year],$B$32) -> 984435 | E41: =D41/C41-1 -> -0.59012268

Sheet Annual KPI
A1: Till Date | B1: ='Daily Dashboard'!B5 -> 45869 | C1: ='Daily Dashboard'!B4 -> 45839
A2: 20 MW PSEGPL Performance Summary-YTD
A3: Year | B3: Days | C3: Estimated POA(KWh/m2) | D3: Measured POA (KWh/m2) | E3: Budgeted Energy (MWh) | F3: Measured Energy (MWh) | G3: Targt PR (%) | H3: Measured PR(%) | I3: Target DC CUF (%) | J3: Measured DC CUF (%) | K3: Target GA (%) | L3: Measured GA (%) | M3: Target PA (%) | N3: Measured PA (%)
A4: =YEAR($B$1)+IF(MONTH($B$1)>=4,1,0) -> 2026 | B4: =$B$1-('Daily Dashboard'!$B$7)+1 -> 122 | C4: =_xlfn.XLOOKUP($C$1,'Modelling New'!$D:$D,'Modelling New'!$S:$S,0) -> 691.4 | D4: =SUMIFS('Daily KPI'!$I:$I,'Daily KPI'!$B:$B,'Annual KPI'!$A$4,'Daily KPI'!$A:$A,"<="&'Annual KPI'!$B$1) -> 602.30064 | E4: =_xlfn.XLOOKUP($C$1,'Modelling New'!$D:$D,'Modelling New'!$V:$V,0) -> 12466.606 | F4: =SUMIFS('Daily KPI'!$AA:$AA,'Daily KPI'!$B:$B,'Annual KPI'!$A$4,'Daily KPI'!$A:$A,"<="&'Annual KPI'!$B$1)/1000 -> 11129.463 | G4: =IFERROR(E4/C4/_xlfn.XLOOKUP($C$1,'Modelling New'!$D:$D,'Modelling New'!$AA:$AA,0),"") -> 0.74192017 | H4: =IFERROR(F4/D4/_xlfn.XLOOKUP($C$1,'Modelling New'!$D:$D,'Modelling New'!$AA:$AA,0),"") -> 0.76032491 | I4: =IFERROR(E4/(B4*24*_xlfn.XLOOKUP($C$1,'Modelling New'!$D:$D,'Modelling New'!$AA:$AA,0)),"") -> 0.17519249 | J4: =IFERROR(F4/(B4*24*_xlfn.XLOOKUP($C$1,'Modelling New'!$D:$D,'Modelling New'!$AA:$AA,0)),"") -> 0.1564017 | K4: =_xlfn.XLOOKUP($C$1,'Modelling New'!$D:$D,'Modelling New'!$AF:$AF) -> 0.995 | L4: =AVERAGEIFS('Daily KPI'!$R:$R,'Daily KPI'!$B:$B,'Annual KPI'!$A$4,'Daily KPI'!$A:$A,"<="&'Annual KPI'!$B$1) -> 0.99209933 | M4: =_xlfn.XLOOKUP($C$1,'Modelling New'!$D:$D,'Modelling New'!$AE:$AE) -> 0.995 | N4: =AVERAGEIFS('Daily KPI'!$O:$O,'Daily KPI'!$B:$B,'Annual KPI'!$A$4,'Daily KPI'!$A:$A,"<="&'Annual KPI'!$B$1) -> 0.96898566
A8: 20 MW PSEGPL Performance Summary-Monthwise
A9: Year | B9: Days | C9: Estimated POA(KWh/m2) | D9: Measured POA (KWh/m2) | E9: Budgeted Energy (MWh) | F9: Measured Energy (MWh) | G9: Targt PR (%) | H9: Measured PR(%) | I9: Target DC CUF (%) | J9: Measured DC CUF (%) | K9: Target GA (%) | L9: Measured GA (%) | M9: Target PA (%) | N9: Measured PA (%)
A10: 45748 | B10: =_xlfn.XLOOKUP($A10,'Modelling New'!D:D,'Modelling New'!$Q:$Q) -> 30 | C10: =_xlfn.XLOOKUP($A10,'Modelling New'!$D:$D,'Modelling New'!R:R) -> 198.7 | D10: =SUMIF('Daily KPI'!$D:$D,$A10,'Daily KPI'!$I:$I) -> 193.36262 | E10: =_xlfn.XLOOKUP($A10,'Modelling New'!$D:$D,'Modelling New'!$U:$U) -> 3614.9982 | F10: =SUMIF('Daily KPI'!$D:$D,A10,'Daily KPI'!$AA:$AA)/1000 -> 3484.3116 | G10: =IFERROR(E10/C10/_xlfn.XLOOKUP($A10,'Modelling New'!$D:$D,'Modelling New'!$AA:$AA),"") -> 0.7485978 | H10: =IFERROR(F10/D10/_xlfn.XLOOKUP($A10,'Modelling New'!$D:$D,'Modelling New'!$AA:$AA),"") -> 0.74145156 | I10: =IFERROR(E10/(B10*24*_xlfn.XLOOKUP($A10,'Modelling New'!$D:$D,'Modelling New'!$AA:$AA)),"") -> 0.2065922 | J10: =IFERROR(F10/(B10*24*_xlfn.XLOOKUP($A10,'Modelling New'!$D:$D,'Modelling New'!$AA:$AA)),"") -> 0.19912364 | K10: 0.995 | L10: =IFERROR(AVERAGEIF('Daily KPI'!$D:$D,A10,'Daily KPI'!$R:$R),"") -> 0.99127859 | M10: 0.995 | N10: =IFERROR(AVERAGEIF('Daily KPI'!$D:$D,$A10,'Daily KPI'!$O:$O),"") -> 0.99854271
A11: 45778 | B11: =_xlfn.XLOOKUP($A11,'Modelling New'!D:D,'Modelling New'!$Q:$Q) -> 31 | C11: =_xlfn.XLOOKUP($A11,'Modelling New'!$D:$D,'Modelling New'!R:R) -> 202.4 | D11: =SUMIF('Daily KPI'!$D:$D,$A11,'Daily KPI'!$I:$I) -> 155.78806 | E11: =_xlfn.XLOOKUP($A11,'Modelling New'!$D:$D,'Modelling New'!$U:$U) -> 3717.0772 | F11: =SUMIF('Daily KPI'!$D:$D,A11,'Daily KPI'!$AA:$AA)/1000 -> 2819.3512 | G11: =IFERROR(E11/C11/_xlfn.XLOOKUP($A11,'Modelling New'!$D:$D,'Modelling New'!$AA:$AA),"") -> 0.75566517 | H11: =IFERROR(F11/D11/_xlfn.XLOOKUP($A11,'Modelling New'!$D:$D,'Modelling New'!$AA:$AA),"") -> 0.74465197 | I11: =IFERROR(E11/(B11*24*_xlfn.XLOOKUP($A11,'Modelling New'!$D:$D,'Modelling New'!$AA:$AA)),"") -> 0.20557343 | J11: =IFERROR(F11/(B11*24*_xlfn.XLOOKUP($A11,'Modelling New'!$D:$D,'Modelling New'!$AA:$AA)),"") -> 0.15592457 | K11: 0.995 | L11: =IFERROR(AVERAGEIF('Daily KPI'!$D:$D,A11,'Daily KPI'!$R:$R),"") -> 0.98732249 | M11: 0.995 | N11: =IFERROR(AVERAGEIF('Daily KPI'!$D:$D,$A11,'Daily KPI'!$O:$O),"") -> 0.97654466
A12: 45809 | B12: =_xlfn.XLOOKUP($A12,'Modelling New'!D:D,'Modelling New'!$Q:$Q) -> 30 | C12: =_xlfn.XLOOKUP($A12,'Modelling New'!$D:$D,'Modelling New'!R:R) -> 153.7 | D12: =SUMIF('Daily KPI'!$D:$D,$A12,'Daily KPI'!$I:$I) -> 139.64057 | E12: =_xlfn.XLOOKUP($A12,'Modelling New'!$D:$D,'Modelling New'!$U:$U) -> 2732.7507 | F12: =SUMIF('Daily KPI'!$D:$D,A12,'Daily KPI'!$AA:$AA)/1000 -> 2626.2879 | G12: =IFERROR(E12/C12/_xlfn.XLOOKUP($A12,'Modelling New'!$D:$D,'Modelling New'!$AA:$AA),"") -> 0.73158447 | H12: =IFERROR(F12/D12/_xlfn.XLOOKUP($A12,'Modelling New'!$D:$D,'Modelling New'!$AA:$AA),"") -> 0.77387183 | I12: =IFERROR(E12/(B12*24*_xlfn.XLOOKUP($A12,'Modelling New'!$D:$D,'Modelling New'!$AA:$AA)),"") -> 0.15617296 | J12: =IFERROR(F12/(B12*24*_xlfn.XLOOKUP($A12,'Modelling New'!$D:$D,'Modelling New'!$AA:$AA)),"") -> 0.15008876 | K12: 0.995 | L12: =IFERROR(AVERAGEIF('Daily KPI'!$D:$D,A12,'Daily KPI'!$R:$R),"") -> 0.98969212 | M12: 0.995 | N12: =IFERROR(AVERAGEIF('Daily KPI'!$D:$D,$A12,'Daily KPI'!$O:$O),"") -> 0.93826848
A13: 45839 | B13: =_xlfn.XLOOKUP($A13,'Modelling New'!D:D,'Modelling New'!$Q:$Q) -> 31 | C13: =_xlfn.XLOOKUP($A13,'Modelling New'!$D:$D,'Modelling New'!R:R) -> 136.6 | D13: =SUMIF('Daily KPI'!$D:$D,$A13,'Daily KPI'!$I:$I) -> 113.50939 | E13: =_xlfn.XLOOKUP($A13,'Modelling New'!$D:$D,'Modelling New'!$U:$U) -> 2401.7797 | F13: =SUMIF('Daily KPI'!$D:$D,A13,'Daily KPI'!$AA:$AA)/1000 -> 2199.5125 | G13: =IFERROR(E13/C13/_xlfn.XLOOKUP($A13,'Modelling New'!$D:$D,'Modelling New'!$AA:$AA),"") -> 0.72347044 | H13: =IFERROR(F13/D13/_xlfn.XLOOKUP($A13,'Modelling New'!$D:$D,'Modelling New'!$AA:$AA),"") -> 0.79732057 | I13: =IFERROR(E13/(B13*24*_xlfn.XLOOKUP($A13,'Modelling New'!$D:$D,'Modelling New'!$AA:$AA)),"") -> 0.13283073 | J13: =IFERROR(F13/(B13*24*_xlfn.XLOOKUP($A13,'Modelling New'!$D:$D,'Modelling New'!$AA:$AA)),"") -> 0.12164432 | K13: 0.995 | L13: =IFERROR(AVERAGEIF('Daily KPI'!$D:$D,A13,'Daily KPI'!$R:$R),"") -> 1 | M13: 0.995 | N13: =IFERROR(AVERAGEIF('Daily KPI'!$D:$D,$A13,'Daily KPI'!$O:$O),"") -> 0.96254936
A14: 45870 | B14: =_xlfn.XLOOKUP($A14,'Modelling New'!D:D,'Modelling New'!$Q:$Q) -> 3 | C14: =_xlfn.XLOOKUP($A14,'Modelling New'!$D:$D,'Modelling New'!R:R) -> 12.522581 | D14: =SUMIF('Daily KPI'!$D:$D,$A14,'Daily KPI'!$I:$I) -> 15.697651 | E14: =_xlfn.XLOOKUP($A14,'Modelling New'!$D:$D,'Modelling New'!$U:$U) -> 234.20164 | F14: =SUMIF('Daily KPI'!$D:$D,A14,'Daily KPI'!$AA:$AA)/1000 -> 303.2173 | G14: =IFERROR(E14/C14/_xlfn.XLOOKUP($A14,'Modelling New'!$D:$D,'Modelling New'!$AA:$AA),"") -> 0.76954571 | H14: =IFERROR(F14/D14/_xlfn.XLOOKUP($A14,'Modelling New'!$D:$D,'Modelling New'!$AA:$AA),"") -> 0.79479959 | I14: =IFERROR(E14/(B14*24*_xlfn.XLOOKUP($A14,'Modelling New'!$D:$D,'Modelling New'!$AA:$AA)),"") -> 0.13384303 | J14: =IFERROR(F14/(B14*24*_xlfn.XLOOKUP($A14,'Modelling New'!$D:$D,'Modelling New'!$AA:$AA)),"") -> 0.17328454 | K14: 0.995 | L14: =IFERROR(AVERAGEIF('Daily KPI'!$D:$D,A14,'Daily KPI'!$R:$R),"") -> 1 | M14: 0.995 | N14: =IFERROR(AVERAGEIF('Daily KPI'!$D:$D,$A14,'Daily KPI'!$O:$O),"") -> 0.98953902
A15: 45901 | B15: =_xlfn.XLOOKUP($A15,'Modelling New'!D:D,'Modelling New'!$Q:$Q) -> 0 | C15: =_xlfn.XLOOKUP($A15,'Modelling New'!$D:$D,'Modelling New'!R:R) -> 0 | D15: =SUMIF('Daily KPI'!$D:$D,$A15,'Daily KPI'!$I:$I) -> 0 | E15: =_xlfn.XLOOKUP($A15,'Modelling New'!$D:$D,'Modelling New'!$U:$U) -> 0 | F15: =SUMIF('Daily KPI'!$D:$D,A15,'Daily KPI'!$AA:$AA)/1000 -> 0 | G15: =IFERROR(E15/C15/_xlfn.XLOOKUP($A15,'Modelling New'!$D:$D,'Modelling New'!$AA:$AA),"") | H15: =IFERROR(F15/D15/_xlfn.XLOOKUP($A15,'Modelling New'!$D:$D,'Modelling New'!$AA:$AA),"") | I15: =IFERROR(E15/(B15*24*_xlfn.XLOOKUP($A15,'Modelling New'!$D:$D,'Modelling New'!$AA:$AA)),"") | J15: =IFERROR(F15/(B15*24*_xlfn.XLOOKUP($A15,'Modelling New'!$D:$D,'Modelling New'!$AA:$AA)),"") | K15: 0.995 | L15: =IFERROR(AVERAGEIF('Daily KPI'!$D:$D,A15,'Daily KPI'!$R:$R),"") | M15: 0.995 | N15: =IFERROR(AVERAGEIF('Daily KPI'!$D:$D,$A15,'Daily KPI'!$O:$O),"")
A16: 45931 | B16: =_xlfn.XLOOKUP($A16,'Modelling New'!D:D,'Modelling New'!$Q:$Q) -> 0 | C16: =_xlfn.XLOOKUP($A16,'Modelling New'!$D:$D,'Modelling New'!R:R) -> 0 | D16: =SUMIF('Daily KPI'!$D:$D,$A16,'Daily KPI'!$I:$I) -> 0 | E16: =_xlfn.XLOOKUP($A16,'Modelling New'!$D:$D,'Modelling New'!$U:$U) -> 0 | F16: =SUMIF('Daily KPI'!$D:$D,A16,'Daily KPI'!$AA:$AA)/1000 -> 0 | G16: =IFERROR(E16/C16/_xlfn.XLOOKUP($A16,'Modelling New'!$D:$D,'Modelling New'!$AA:$AA),"") | H16: =IFERROR(F16/D16/_xlfn.XLOOKUP($A16,'Modelling New'!$D:$D,'Modelling New'!$AA:$AA),"") | I16: =IFERROR(E16/(B16*24*_xlfn.XLOOKUP($A16,'Modelling New'!$D:$D,'Modelling New'!$AA:$AA)),"") | J16: =IFERROR(F16/(B16*24*_xlfn.XLOOKUP($A16,'Modelling New'!$D:$D,'Modelling New'!$AA:$AA)),"") | K16: 0.995 | L16: =IFERROR(AVERAGEIF('Daily KPI'!$D:$D,A16,'Daily KPI'!$R:$R),"") | M16: 0.995 | N16: =IFERROR(AVERAGEIF('Daily KPI'!$D:$D,$A16,'Daily KPI'!$O:$O),"")
A17: 45962 | B17: =_xlfn.XLOOKUP($A17,'Modelling New'!D:D,'Modelling New'!$Q:$Q) -> 0 | C17: =_xlfn.XLOOKUP($A17,'Modelling New'!$D:$D,'Modelling New'!R:R) -> 0 | D17: =SUMIF('Daily KPI'!$D:$D,$A17,'Daily KPI'!$I:$I) -> 0 | E17: =_xlfn.XLOOKUP($A17,'Modelling New'!$D:$D,'Modelling New'!$U:$U) -> 0 | F17: =SUMIF('Daily KPI'!$D:$D,A17,'Daily KPI'!$AA:$AA)/1000 -> 0 | G17: =IFERROR(E17/C17/_xlfn.XLOOKUP($A17,'Modelling New'!$D:$D,'Modelling New'!$AA:$AA),"") | H17: =IFERROR(F17/D17/_xlfn.XLOOKUP($A17,'Modelling New'!$D:$D,'Modelling New'!$AA:$AA),"") | I17: =IFERROR(E17/(B17*24*_xlfn.XLOOKUP($A17,'Modelling New'!$D:$D,'Modelling New'!$AA:$AA)),"") | J17: =IFERROR(F17/(B17*24*_xlfn.XLOOKUP($A17,'Modelling New'!$D:$D,'Modelling New'!$AA:$AA)),"") | K17: 0.995 | L17: =IFERROR(AVERAGEIF('Daily KPI'!$D:$D,A17,'Daily KPI'!$R:$R),"") | M17: 0.995 | N17: =IFERROR(AVERAGEIF('Daily KPI'!$D:$D,$A17,'Daily KPI'!$O:$O),"")
A18: 45992 | B18: =_xlfn.XLOOKUP($A18,'Modelling New'!D:D,'Modelling New'!$Q:$Q) -> 0 | C18: =_xlfn.XLOOKUP($A18,'Modelling New'!$D:$D,'Modelling New'!R:R) -> 0 | D18: =SUMIF('Daily KPI'!$D:$D,$A18,'Daily KPI'!$I:$I) -> 0 | E18: =_xlfn.XLOOKUP($A18,'Modelling New'!$D:$D,'Modelling New'!$U:$U) -> 0 | F18: =SUMIF('Daily KPI'!$D:$D,A18,'Daily KPI'!$AA:$AA)/1000 -> 0 | G18: =IFERROR(E18/C18/_xlfn.XLOOKUP($A18,'Modelling New'!$D:$D,'Modelling New'!$AA:$AA),"") | H18: =IFERROR(F18/D18/_xlfn.XLOOKUP($A18,'Modelling New'!$D:$D,'Modelling New'!$AA:$AA),"") | I18: =IFERROR(E18/(B18*24*_xlfn.XLOOKUP($A18,'Modelling New'!$D:$D,'Modelling New'!$AA:$AA)),"") | J18: =IFERROR(F18/(B18*24*_xlfn.XLOOKUP($A18,'Modelling New'!$D:$D,'Modelling New'!$AA:$AA)),"") | K18: 0.995 | L18: =IFERROR(AVERAGEIF('Daily KPI'!$D:$D,A18,'Daily KPI'!$R:$R),"") | M18: 0.995 | N18: =IFERROR(AVERAGEIF('Daily KPI'!$D:$D,$A18,'Daily KPI'!$O:$O),"")
A19: 46023 | B19: =_xlfn.XLOOKUP($A19,'Modelling New'!D:D,'Modelling New'!$Q:$Q) -> 0 | C19: =_xlfn.XLOOKUP($A19,'Modelling New'!$D:$D,'Modelling New'!R:R) -> 0 | D19: =SUMIF('Daily KPI'!$D:$D,$A19,'Daily KPI'!$I:$I) -> 0 | E19: =_xlfn.XLOOKUP($A19,'Modelling New'!$D:$D,'Modelling New'!$U:$U) -> 0 | F19: =SUMIF('Daily KPI'!$D:$D,A19,'Daily KPI'!$AA:$AA)/1000 -> 0 | G19: =IFERROR(E19/C19/_xlfn.XLOOKUP($A19,'Modelling New'!$D:$D,'Modelling New'!$AA:$AA),"") | H19: =IFERROR(F19/D19/_xlfn.XLOOKUP($A19,'Modelling New'!$D:$D,'Modelling New'!$AA:$AA),"") | I19: =IFERROR(E19/(B19*24*_xlfn.XLOOKUP($A19,'Modelling New'!$D:$D,'Modelling New'!$AA:$AA)),"") | J19: =IFERROR(F19/(B19*24*_xlfn.XLOOKUP($A19,'Modelling New'!$D:$D,'Modelling New'!$AA:$AA)),"") | K19: 0.995 | L19: =IFERROR(AVERAGEIF('Daily KPI'!$D:$D,A19,'Daily KPI'!$R:$R),"") | M19: 0.995 | N19: =IFERROR(AVERAGEIF('Daily KPI'!$D:$D,$A19,'Daily KPI'!$O:$O),"")
A20: 46054 | B20: =_xlfn.XLOOKUP($A20,'Modelling New'!D:D,'Modelling New'!$Q:$Q) -> 0 | C20: =_xlfn.XLOOKUP($A20,'Modelling New'!$D:$D,'Modelling New'!R:R) -> 0 | D20: =SUMIF('Daily KPI'!$D:$D,$A20,'Daily KPI'!$I:$I) -> 0 | E20: =_xlfn.XLOOKUP($A20,'Modelling New'!$D:$D,'Modelling New'!$U:$U) -> 0 | F20: =SUMIF('Daily KPI'!$D:$D,A20,'Daily KPI'!$AA:$AA)/1000 -> 0 | G20: =IFERROR(E20/C20/_xlfn.XLOOKUP($A20,'Modelling New'!$D:$D,'Modelling New'!$AA:$AA),"") | H20: =IFERROR(F20/D20/_xlfn.XLOOKUP($A20,'Modelling New'!$D:$D,'Modelling New'!$AA:$AA),"") | I20: =IFERROR(E20/(B20*24*_xlfn.XLOOKUP($A20,'Modelling New'!$D:$D,'Modelling New'!$AA:$AA)),"") | J20: =IFERROR(F20/(B20*24*_xlfn.XLOOKUP($A20,'Modelling New'!$D:$D,'Modelling New'!$AA:$AA)),"") | K20: 0.995 | L20: =IFERROR(AVERAGEIF('Daily KPI'!$D:$D,A20,'Daily KPI'!$R:$R),"") | M20: 0.995 | N20: =IFERROR(AVERAGEIF('Daily KPI'!$D:$D,$A20,'Daily KPI'!$O:$O),"")
A21: 46082 | B21: =_xlfn.XLOOKUP($A21,'Modelling New'!D:D,'Modelling New'!$Q:$Q) -> 0 | C21: =_xlfn.XLOOKUP($A21,'Modelling New'!$D:$D,'Modelling New'!R:R) -> 0 | D21: =SUMIF('Daily KPI'!$D:$D,$A21,'Daily KPI'!$I:$I) -> 0 | E21: =_xlfn.XLOOKUP($A21,'Modelling New'!$D:$D,'Modelling New'!$U:$U) -> 0 | F21: =SUMIF('Daily KPI'!$D:$D,A21,'Daily KPI'!$AA:$AA)/1000 -> 0 | G21: =IFERROR(E21/C21/_xlfn.XLOOKUP($A21,'Modelling New'!$D:$D,'Modelling New'!$AA:$AA),"") | H21: =IFERROR(F21/D21/_xlfn.XLOOKUP($A21,'Modelling New'!$D:$D,'Modelling New'!$AA:$AA),"") | I21: =IFERROR(E21/(B21*24*_xlfn.XLOOKUP($A21,'Modelling New'!$D:$D,'Modelling New'!$AA:$AA)),"") | J21: =IFERROR(F21/(B21*24*_xlfn.XLOOKUP($A21,'Modelling New'!$D:$D,'Modelling New'!$AA:$AA)),"") | K21: 0.995 | L21: =IFERROR(AVERAGEIF('Daily KPI'!$D:$D,A21,'Daily KPI'!$R:$R),"") | M21: 0.995 | N21: =IFERROR(AVERAGEIF('Daily KPI'!$D:$D,$A21,'Daily KPI'!$O:$O),"")

Sheet Sheet1
A1: L0bour & staff not responding
A2: PM activity pending assign to team bu not doing
A3: Tools are missing
A4: All tools given to team but they are haruntaka ta
A5: all man power doing only 8 hrs duty
A6: Also not doing PTW
A7: ALSO NOT MAINTAING
A8: no one are techincal persion
A9: GC pending due expences
A10: Also spare not avilable yet at site
A11: SCADA is not operating
A12: Internet issues
... A15: WMS Problems issue

Sheet Monthly KPI
A1: Till Date | B1: ='Daily Dashboard'!B5 -> 45869
A2: 20 MW PSEGPL Performance Summary
B3: Days | C3: Estimated POA(KWh/m2) | D3: Measured POA (KWh/m2) | E3: Budgeted Energy (MWh) | F3: Measured Energy (MWh) | G3: Targt PR (%) | H3: Measured PR(%) | I3: Target DC CUF (%) | J3: Measured DC CUF (%) | K3: Target GA (%) | L3: Measured GA (%) | M3: Target PA (%) | N3: Measured PA (%)
A4: ='Daily Dashboard'!B4 -> 45839 | B4: =DAY(B1) -> 31 | C4: =_xlfn.XLOOKUP($A$4,'Modelling New'!$D:$D,'Modelling New'!$R:$R,0) -> 136.6 | D4: =SUMIF('Daily KPI'!$D:$D,$A$4,'Daily KPI'!$I:$I) -> 113.50939 | E4: =_xlfn.XLOOKUP($A$4,'Modelling New'!$D:$D,'Modelling New'!$U:$U,0) -> 2401.7797 | F4: =SUMIF('Daily KPI'!$D:$D,'Monthly KPI'!$A$4,'Daily KPI'!$AA:$AA)/1000 -> 2199.5125 | G4: =IFERROR(E4/C4/_xlfn.XLOOKUP($A$4,'Modelling New'!$D:$D,'Modelling New'!$N:$N,0),"") -> 0.72347044 | H4: =IFERROR(F4/D4/_xlfn.XLOOKUP($B$1,'Daily KPI'!$A:$A,'Daily KPI'!$AR:$AR,0),"") -> 0.79732057 | I4: =IFERROR(E4/(B4*24*_xlfn.XLOOKUP($A$4,'Modelling New'!$D:$D,'Modelling New'!$N:$N,0)),"") -> 0.13283073 | J4: =IFERROR(F4/(B4*24*_xlfn.XLOOKUP($A$4,'Modelling New'!$D:$D,'Modelling New'!$N:$N,0)),"") -> 0.12164432 | K4: =_xlfn.XLOOKUP($A$4,'Modelling New'!$D:$D,'Modelling New'!$AF:$AF) -> 0.995 | L4: =IFERROR(AVERAGEIF('Daily KPI'!$D:$D,'Monthly KPI'!$A$4,'Daily KPI'!$R:$R),"") -> 1 | M4: =_xlfn.XLOOKUP($A$4,'Modelling New'!$D:$D,'Modelling New'!$AE:$AE) -> 0.995 | N4: =AVERAGEIF('Daily KPI'!$D:$D,$A$4,'Daily KPI'!$O:$O) -> 0.96254936
A6: Start Date | B6: =B7-6 -> 45863
A7: End Date | B7: =B1 -> 45869
A8: 20 MW PSEGPL Performance Summary
A9: Year | B9: Days | C9: Estimated POA(KWh/m2) | D9: Measured POA (KWh/m2) | E9: Budgeted Energy (MWh) | F9: Measured Energy (MWh) | G9: Targt PR (%) | H9: Measured PR(%) | I9: Target DC CUF (%) | J9: Measured DC CUF (%) | K9: Target GA (%) | L9: Measured GA (%) | M9: Target PA (%) | N9: Measured PA (%)
A10: =A4 -> 45839 | B10: =(B7-B6)+1 -> 7 | C10: =SUMIFS('Daily KPI'!$AC:$AC,'Daily KPI'!$A:$A,">="&$B$6,'Daily KPI'!$A:$A,"<="&$B$7) -> 30.845161 | D10: =SUMIFS('Daily KPI'!$I:$I,'Daily KPI'!$A:$A,">="&$B$6,'Daily KPI'!$A:$A,"<="&$B$7) -> 20.775786 | E10: =SUMIFS('Daily KPI'!$AD:$AD,'Daily KPI'!$A:$A,">="&$B$6,'Daily KPI'!$A:$A,"<="&$B$7)/1000 -> 542.33734 | F10: =SUMIFS('Daily KPI'!$AA:$AA,'Daily KPI'!$A:$A,">="&$B$6,'Daily KPI'!$A:$A,"<="&$B$7)/1000 -> 408.0923 | G10: =IFERROR(E10/C10/_xlfn.XLOOKUP($A$4,'Modelling New'!$D:$D,'Modelling New'!$N:$N,0),"") -> 0.72347044 | H10: =IFERROR(F10/D10/_xlfn.XLOOKUP($A$4,'Modelling New'!$D:$D,'Modelling New'!$N:$N,0),"") -> 0.80823801 | I10: =IFERROR(E10/(B10*24*_xlfn.XLOOKUP($A$4,'Modelling New'!$D:$D,'Modelling New'!$N:$N,0)),"") -> 0.13283073 | J10: =IFERROR(F10/(B10*24*_xlfn.XLOOKUP($A$4,'Modelling New'!$D:$D,'Modelling New'!$N:$N,0)),"") -> 0.099951069 | K10: =_xlfn.XLOOKUP($A$10,'Modelling New'!$D:$D,'Modelling New'!$AF:$AF) -> 0.995 | L10: =AVERAGEIFS('Daily KPI'!$R:$R,'Daily KPI'!$A:$A,">="&$B$6,'Daily KPI'!$A:$A,"<="&$B$7) -> 1 | M10: =_xlfn.XLOOKUP($A$10,'Modelling New'!$D:$D,'Modelling New'!$AE:$AE) -> 0.995 | N10: =AVERAGEIFS('Daily KPI'!$O:$O,'Daily KPI'!$A:$A,">="&$B$6,'Daily KPI'!$A:$A,"<="&$B$7) -> 0.96085377

Sheet Daily KPI
A1: Date | B1: Financial Year | C1: Calendar Year | D1: Month Year | E1: Days | F1: Operating Hours | G1: GHI-UP (KWh/m2) | H1: GHI-Down(KWh/m2) | I1: POA-UP(KWh/m2) | J1: POA-Down(KWh/m2) | K1: Amb_Temp(°C) | L1: Mod_Temp(°C) | M1: WS_Avg(m/s) | N1: WS_Max(m/s) | O1: PA(%) | P1: MA (%) | Q1: IGA (%) | R1: EGA(%) | S1: EMA (%) | T1: TA (%) | U1: PR(%) | V1: WPR(%) | W1: CUF(%) | X1: Gen_Exp (kWh) | Y1: Mtr_Export (kWh) | Z1: Mtr_Import (kWh) | AA1: Mtr_Net_Exp (KWh) | AB1: Operational Capacity (MW) | AC1: Bugt_Resource | AD1: Bugt_Energy | AE1: Bugt PR | AF1: Bugt CUF | AG1: Bugt_PA | AH1: Bugt_EGA | AI1: Expected Energy | AJ1: Actual Energy WPR | AK1: RA (%) | AL1: Mod Clean Dry (Num) | AM1: Mod Clean Wet (Num) | AN1: Line Loss(%) | AO1: Reactive Power (%) | AP1: Bugt Line loss (%) (Wind) | AQ1: Bugt Reactive Power (%) (Wind) | AR1: Bugt Capacity | AS1: CC*Bugt
A2: 45745 | B2: =YEAR(Daily_KPI[[#This Row],[Date]])+IF(MONTH(Daily_KPI[[#This Row],[Date]])>=4,1,0) -> 2025 | C2: =YEAR(Daily_KPI[[#This Row],[Date]]) -> 2025 | D2: =Daily_KPI[[#This Row],[Date]]-DAY(Daily_KPI[[#This Row],[Date]])+1 -> 45717 | E2: =DAY(EOMONTH(A2,0)) -> 31 | F2: =IFERROR(_xlfn.XLOOKUP($A2,'Raw Data'!$A:$A,'Raw Data'!$BR:$BR),"") -> 11.533333 | G2: =IFERROR(_xlfn.XLOOKUP($A2,'Raw Data'!$A:$A,'Raw Data'!$AO:$AO),"") -> 0 | I2: =IFERROR(_xlfn.XLOOKUP($A2,'Raw Data'!$A:$A,'Raw Data'!$AR:$AR),"") -> 6.156401 | K2: =IFERROR(_xlfn.XLOOKUP($A2,'Raw Data'!$A:$A,'Raw Data'!$AV:$AV),"") -> 0 | L2: =IFERROR(_xlfn.XLOOKUP($A2,'Raw Data'!$A:$A,'Raw Data'!$AW:$AW),"") -> 0 | M2: =IFERROR(_xlfn.XLOOKUP($A2,'Raw Data'!$A:$A,'Raw Data'!$AX:$AX),"") -> 0 | N2: =IFERROR(_xlfn.XLOOKUP($A2,'Raw Data'!$A:$A,'Raw Data'!$AY:$AY),"") -> 0 | O2: =IFERROR(1-(SUMIF('Plant BD'!$B:$B,A2,'Plant BD'!$AE:$AE)/(AA2+SUMIF('Plant BD'!$B:$B,A2,'Plant BD'!$AE:$AE))),"") | R2: =IFERROR(1-(SUMIF('Grid BD'!$B:$B,$A2,'Grid BD'!$AD:$AD)/($AA2+SUMIF('Grid BD'!$B:$B,$A2,'Grid BD'!AD:AD))),"") | U2: =IFERROR(AA2/I2/AB2/1000,"") | W2: =IFERROR(AA2/(24*AR2*1000),"") | X2: =IFERROR(_xlfn.XLOOKUP($A2,'Raw Data'!$A:$A,'Raw Data'!$BA:$BA),"") -> 114708 | Y2: =IFERROR(_xlfn.XLOOKUP($A2,'Raw Data'!$A:$A,'Raw Data'!BJ:BJ),"") | Z2: =IFERROR(_xlfn.XLOOKUP($A2,'Raw Data'!$A:$A,'Raw Data'!BK:BK),"") | AA2: =IFERROR(_xlfn.XLOOKUP($A2,'Raw Data'!$A:$A,'Raw Data'!BL:BL),"") | AB2: =IFERROR(_xlfn.XLOOKUP($A2,'Raw Data'!$A:$A,'Raw Data'!$H:$H),"") -> 24.3031 | AC2: =IFERROR(_xlfn.XLOOKUP($D2,'Modelling New'!$D:$D,'Modelling New'!$P:$P),"") -> 6.9 | AD2: =IFERROR(_xlfn.XLOOKUP($D2,'Modelling New'!$D:$D,'Modelling New'!$T:$T)*1000,"") -> 129014.29 | AE2: =IFERROR(_xlfn.XLOOKUP($D2,'Modelling New'!$D:$D,'Modelling New'!$O:$O),"") -> 0.76935548 | AF2: =IFERROR(_xlfn.XLOOKUP($D2,'Modelling New'!$D:$D,'Modelling New'!$W:$W),"") -> 0.2211897 | AG2: =IFERROR(_xlfn.XLOOKUP($D2,'Modelling New'!$D:$D,'Modelling New'!AE:AE),"") -> 0.995 | AH2: 0.9975 | AR2: =IFERROR(_xlfn.XLOOKUP($D2,'Modelling New'!$D:$D,'Modelling New'!$N:$N),"") -> 24.3031
A3: =A2+1 -> 45746 | B3: =YEAR(Daily_KPI[[#This Row],[Date]])+IF(MONTH(Daily_KPI[[#This Row],[Date]])>=4,1,0) -> 2025 | C3: =YEAR(Daily_KPI[[#This Row],[Date]]) -> 2025 | D3: =Daily_KPI[[#This Row],[Date]]-DAY(Daily_KPI[[#This Row],[Date]])+1 -> 45717 | E3: =DAY(EOMONTH(A3,0)) -> 31 | F3: =IFERROR(_xlfn.XLOOKUP($A3,'Raw Data'!$A:$A,'Raw Data'!$BR:$BR),"") -> 11.55 | G3: =IFERROR(_xlfn.XLOOKUP($A3,'Raw Data'!$A:$A,'Raw Data'!$AO:$AO),"") -> 0 | I3: =IFERROR(_xlfn.XLOOKUP($A3,'Raw Data'!$A:$A,'Raw Data'!$AR:$AR),"") -> 5.1168365 | K3: =IFERROR(_xlfn.XLOOKUP($A3,'Raw Data'!$A:$A,'Raw Data'!$AV:$AV),"") -> 0 | L3: =IFERROR(_xlfn.XLOOKUP($A3,'Raw Data'!$A:$A,'Raw Data'!$AW:$AW),"") -> 0 | M3: =IFERROR(_xlfn.XLOOKUP($A3,'Raw Data'!$A:$A,'Raw Data'!$AX:$AX),"") -> 0 | N3: =IFERROR(_xlfn.XLOOKUP($A3,'Raw Data'!$A:$A,'Raw Data'!$AY:$AY),"") -> 0 | O3: =IFERROR(1-(SUMIF('Plant BD'!$B:$B,A3,'Plant BD'!$AE:$AE)/(AA3+SUMIF('Plant BD'!$B:$B,A3,'Plant BD'!$AE:$AE))),"") -> 1 | R3: =IFERROR(1-(SUMIF('Grid BD'!$B:$B,$A3,'Grid BD'!$AD:$AD)/($AA3+SUMIF('Grid BD'!$B:$B,$A3,'Grid BD'!AD:AD))),"") -> 1 | U3: =IFERROR(AA3/I3/AB3/1000,"") -> 0.73891664 | W3: =IFERROR(AA3/(24*AR3*1000),"") -> 0.15753815 | X3: =IFERROR(_xlfn.XLOOKUP($A3,'Raw Data'!$A:$A,'Raw Data'!$BA:$BA),"") -> 93388 | Y3: =IFERROR(_xlfn.XLOOKUP($A3,'Raw Data'!$A:$A,'Raw Data'!BJ:BJ),"") -> 92817.68 | Z3: =IFERROR(_xlfn.XLOOKUP($A3,'Raw Data'!$A:$A,'Raw Data'!BK:BK),"") -> 929.71 | AA3: =IFERROR(_xlfn.XLOOKUP($A3,'Raw Data'!$A:$A,'Raw Data'!BL:BL),"") -> 91887.97 | AB3: =IFERROR(_xlfn.XLOOKUP($A3,'Raw Data'!$A:$A,'Raw Data'!$H:$H),"") -> 24.3031 | AC3: =IFERROR(_xlfn.XLOOKUP($D3,'Modelling New'!$D:$D,'Modelling New'!$P:$P),"") -> 6.9 | AD3: =IFERROR(_xlfn.XLOOKUP($D3,'Modelling New'!$D:$D,'Modelling New'!$T:$T)*1000,"") -> 129014.29 | AE3: =IFERROR(_xlfn.XLOOKUP($D3,'Modelling New'!$D:$D,'Modelling New'!$O:$O),"") -> 0.76935548 | AF3: =IFERROR(_xlfn.XLOOKUP($D3,'Modelling New'!$D:$D,'Modelling New'!$W:$W),"") -> 0.2211897 | AG3: =IFERROR(_xlfn.XLOOKUP($D3,'Modelling New'!$D:$D,'Modelling New'!AE:AE),"") -> 0.995 | AH3: 0.9975 | AR3: =IFERROR(_xlfn.XLOOKUP($D3,'Modelling New'!$D:$D,'Modelling New'!$N:$N),"") -> 24.3031
A4: =A3+1 -> 45747 | B4: =YEAR(Daily_KPI[[#This Row],[Date]])+IF(MONTH(Daily_KPI[[#This Row],[Date]])>=4,1,0) -> 2025 | C4: =YEAR(Daily_KPI[[#This Row],[Date]]) -> 2025 | D4: =Daily_KPI[[#This Row],[Date]]-DAY(Daily_KPI[[#This Row],[Date]])+1 -> 45717 | E4: =DAY(EOMONTH(A4,0)) -> 31 | F4: =IFERROR(_xlfn.XLOOKUP($A4,'Raw Data'!$A:$A,'Raw Data'!$BR:$BR),"") -> 10.8 | G4: =IFERROR(_xlfn.XLOOKUP($A4,'Raw Data'!$A:$A,'Raw Data'!$AO:$AO),"") -> 0 | I4: =IFERROR(_xlfn.XLOOKUP($A4,'Raw Data'!$A:$A,'Raw Data'!$AR:$AR),"") -> 4.7331787 | K4: =IFERROR(_xlfn.XLOOKUP($A4,'Raw Data'!$A:$A,'Raw Data'!$AV:$AV),"") -> 0 | L4: =IFERROR(_xlfn.XLOOKUP($A4,'Raw Data'!$A:$A,'Raw Data'!$AW:$AW),"") -> 0 | M4: =IFERROR(_xlfn.XLOOKUP($A4,'Raw Data'!$A:$A,'Raw Data'!$AX:$AX),"") -> 0 | N4: =IFERROR(_xlfn.XLOOKUP($A4,'Raw Data'!$A:$A,'Raw Data'!$AY:$AY),"") -> 0 | O4: =IFERROR(1-(SUMIF('Plant BD'!$B:$B,A4,'Plant BD'!$AE:$AE)/(AA4+SUMIF('Plant BD'!$B:$B,A4,'Plant BD'!$AE:$AE))),"") -> 1 | R4: =IFERROR(1-(SUMIF('Grid BD'!$B:$B,$A4,'Grid BD'!$AD:$AD)/($AA4+SUMIF('Grid BD'!$B:$B,$A4,'Grid BD'!AD:AD))),"") -> 1 | U4: =IFERROR(AA4/I4/AB4/1000,"") -> 0.75533233 | W4: =IFERROR(AA4/(24*AR4*1000),"") -> 0.14896346 | X4: =IFERROR(_xlfn.XLOOKUP($A4,'Raw Data'!$A:$A,'Raw Data'!$BA:$BA),"") -> 88492 | Y4: =IFERROR(_xlfn.XLOOKUP($A4,'Raw Data'!$A:$A,'Raw Data'!BJ:BJ),"") -> 87966.57 | Z4: =IFERROR(_xlfn.XLOOKUP($A4,'Raw Data'!$A:$A,'Raw Data'!BK:BK),"") -> 1080 | AA4: =IFERROR(_xlfn.XLOOKUP($A4,'Raw Data'!$A:$A,'Raw Data'!BL:BL),"") -> 86886.57 | AB4: =IFERROR(_xlfn.XLOOKUP($A4,'Raw Data'!$A:$A,'Raw Data'!$H:$H),"") -> 24.3031 | AC4: =IFERROR(_xlfn.XLOOKUP($D4,'Modelling New'!$D:$D,'Modelling New'!$P:$P),"") -> 6.9 | AD4: =IFERROR(_xlfn.XLOOKUP($D4,'Modelling New'!$D:$D,'Modelling New'!$T:$T)*1000,"") -> 129014.29 | AE4: =IFERROR(_xlfn.XLOOKUP($D4,'Modelling New'!$D:$D,'Modelling New'!$O:$O),"") -> 0.76935548 | AF4: =IFERROR(_xlfn.XLOOKUP($D4,'Modelling New'!$D:$D,'Modelling New'!$W:$W),"") -> 0.2211897 | AG4: =IFERROR(_xlfn.XLOOKUP($D4,'Modelling New'!$D:$D,'Modelling New'!AE:AE),"") -> 0.995 | AH4: 0.9975 | AR4: =IFERROR(_xlfn.XLOOKUP($D4,'Modelling New'!$D:$D,'Modelling New'!$N:$N),"") -> 24.3031
A5: =A4+1 -> 45748 | B5: =YEAR(Daily_KPI[[#This Row],[Date]])+IF(MONTH(Daily_KPI[[#This Row],[Date]])>=4,1,0) -> 2026 | C5: =YEAR(Daily_KPI[[#This Row],[Date]]) -> 2025 | D5: =Daily_KPI[[#This Row],[Date]]-DAY(Daily_KPI[[#This Row],[Date]])+1 -> 45748 | E5: =DAY(EOMONTH(A5,0)) -> 30 | F5: =IFERROR(_xlfn.XLOOKUP($A5,'Raw Data'!$A:$A,'Raw Data'!$BR:$BR),"") -> 10.766667 | G5: =IFERROR(_xlfn.XLOOKUP($A5,'Raw Data'!$A:$A,'Raw Data'!$AO:$AO),"") -> 0 | I5: =IFERROR(_xlfn.XLOOKUP($A5,'Raw Data'!$A:$A,'Raw Data'!$AR:$AR),"") -> 2.8415894 | K5: =IFERROR(_xlfn.XLOOKUP($A5,'Raw Data'!$A:$A,'Raw Data'!$AV:$AV),"") -> 0 | L5: =IFERROR(_xlfn.XLOOKUP($A5,'Raw Data'!$A:$A,'Raw Data'!$AW:$AW),"") -> 0 | M5: =IFERROR(_xlfn.XLOOKUP($A5,'Raw Data'!$A:$A,'Raw Data'!$AX:$AX),"") -> 0 | N5: =IFERROR(_xlfn.XLOOKUP($A5,'Raw Data'!$A:$A,'Raw Data'!$AY:$AY),"") -> 0 | O5: =IFERROR(1-(SUMIF('Plant BD'!$B:$B,A5,'Plant BD'!$AE:$AE)/(AA5+SUMIF('Plant BD'!$B:$B,A5,'Plant BD'!$AE:$AE))),"") -> 1 | R5: =IFERROR(1-(SUMIF('Grid BD'!$B:$B,$A5,'Grid BD'!$AD:$AD)/($AA5+SUMIF('Grid BD'!$B:$B,$A5,'Grid BD'!AD:AD))),"") -> 1 | U5: =IFERROR(AA5/I5/AB5/1000,"") -> 0.98076612 | W5: =IFERROR(AA5/(24*AR5*1000),"") -> 0.11612227 | X5: =IFERROR(_xlfn.XLOOKUP($A5,'Raw Data'!$A:$A,'Raw Data'!$BA:$BA),"") -> 69057 | Y5: =IFERROR(_xlfn.XLOOKUP($A5,'Raw Data'!$A:$A,'Raw Data'!BJ:BJ),"") -> 68717.68 | Z5: =IFERROR(_xlfn.XLOOKUP($A5,'Raw Data'!$A:$A,'Raw Data'!BK:BK),"") -> 986.53 | AA5: =IFERROR(_xlfn.XLOOKUP($A5,'Raw Data'!$A:$A,'Raw Data'!BL:BL),"") -> 67731.15 | AB5: =IFERROR(_xlfn.XLOOKUP($A5,'Raw Data'!$A:$A,'Raw Data'!$H:$H),"") -> 24.3031 | AC5: =IFERROR(_xlfn.XLOOKUP($D5,'Modelling New'!$D:$D,'Modelling New'!$P:$P),"") -> 6.6233333 | AD5: =IFERROR(_xlfn.XLOOKUP($D5,'Modelling New'!$D:$D,'Modelling New'!$T:$T)*1000,"") -> 120499.94 | AE5: =IFERROR(_xlfn.XLOOKUP($D5,'Modelling New'!$D:$D,'Modelling New'!$O:$O),"") -> 0.7485978 | AF5: =IFERROR(_xlfn.XLOOKUP($D5,'Modelling New'!$D:$D,'Modelling New'!$W:$W),"") -> 0.2065922 | AG5: =IFERROR(_xlfn.XLOOKUP($D5,'Modelling New'!$D:$D,'Modelling New'!AE:AE),"") -> 0.995 | AH5: 0.9975 | AR5: =IFERROR(_xlfn.XLOOKUP($D5,'Modelling New'!$D:$D,'Modelling New'!$N:$N),"") -> 24.3031
A6: =A5+1 -> 45749 | B6: =YEAR(Daily_KPI[[#This Row],[Date]])+IF(MONTH(Daily_KPI[[#This Row],[Date]])>=4,1,0) -> 2026 | C6: =YEAR(Daily_KPI[[#This Row],[Date]]) -> 2025 | D6: =Daily_KPI[[#This Row],[Date]]-DAY(Daily_KPI[[#This Row],[Date]])+1 -> 45748 | E6: =DAY(EOMONTH(A6,0)) -> 30 | F6: =IFERROR(_xlfn.XLOOKUP($A6,'Raw Data'!$A:$A,'Raw Data'!$BR:$BR),"") -> 10.95 | G6: =IFERROR(_xlfn.XLOOKUP($A6,'Raw Data'!$A:$A,'Raw Data'!$AO:$AO),"") -> 0 | I6: =IFERROR(_xlfn.XLOOKUP($A6,'Raw Data'!$A:$A,'Raw Data'!$AR:$AR),"") -> 2.7152776 | K6: =IFERROR(_xlfn.XLOOKUP($A6,'Raw Data'!$A:$A,'Raw Data'!$AV:$AV),"") -> 0 | L6: =IFERROR(_xlfn.XLOOKUP($A6,'Raw Data'!$A:$A,'Raw Data'!$AW:$AW),"") -> 0 | M6: =IFERROR(_xlfn.XLOOKUP($A6,'Raw Data'!$A:$A,'Raw Data'!$AX:$AX),"") -> 0 | N6: =IFERROR(_xlfn.XLOOKUP($A6,'Raw Data'!$A:$A,'Raw Data'!$AY:$AY),"") -> 0 | O6: =IFERROR(1-(SUMIF('Plant BD'!$B:$B,A6,'Plant BD'!$AE:$AE)/(AA6+SUMIF('Plant BD'!$B:$B,A6,'Plant BD'!$AE:$AE))),"") -> 1 | R6: =IFERROR(1-(SUMIF('Grid BD'!$B:$B,$A6,'Grid BD'!$AD:$AD)/($AA6+SUMIF('Grid BD'!$B:$B,$A6,'Grid BD'!AD:AD))),"") -> 1 | U6: =IFERROR(AA6/I6/AB6/1000,"") -> 0.76670266 | W6: =IFERROR(AA6/(24*AR6*1000),"") -> 0.086742106 | X6: =IFERROR(_xlfn.XLOOKUP($A6,'Raw Data'!$A:$A,'Raw Data'!$BA:$BA),"") -> 51978 | Y6: =IFERROR(_xlfn.XLOOKUP($A6,'Raw Data'!$A:$A,'Raw Data'!BJ:BJ),"") -> 51509.18 | Z6: =IFERROR(_xlfn.XLOOKUP($A6,'Raw Data'!$A:$A,'Raw Data'!BK:BK),"") -> 914.73 | AA6: =IFERROR(_xlfn.XLOOKUP($A6,'Raw Data'!$A:$A,'Raw Data'!BL:BL),"") -> 50594.45 | AB6: =IFERROR(_xlfn.XLOOKUP($A6,'Raw Data'!$A:$A,'Raw Data'!$H:$H),"") -> 24.3031 | AC6: =IFERROR(_xlfn.XLOOKUP($D6,'Modelling New'!$D:$D,'Modelling New'!$P:$P),"") -> 6.6233333 | AD6: =IFERROR(_xlfn.XLOOKUP($D6,'Modelling New'!$D:$D,'Modelling New'!$T:$T)*1000,"") -> 120499.94 | AE6: =IFERROR(_xlfn.XLOOKUP($D6,'Modelling New'!$D:$D,'Modelling New'!$O:$O),"") -> 0.7485978 | AF6: =IFERROR(_xlfn.XLOOKUP($D6,'Modelling New'!$D:$D,'Modelling New'!$W:$W),"") -> 0.2065922 | AG6: =IFERROR(_xlfn.XLOOKUP($D6,'Modelling New'!$D:$D,'Modelling New'!AE:AE),"") -> 0.995 | AH6: 0.9975 | AR6: =IFERROR(_xlfn.XLOOKUP($D6,'Modelling New'!$D:$D,'Modelling New'!$N:$N),"") -> 24.3031
A7: =A6+1 -> 45750 | B7: =YEAR(Daily_KPI[[#This Row],[Date]])+IF(MONTH(Daily_KPI[[#This Row],[Date]])>=4,1,0) -> 2026 | C7: =YEAR(Daily_KPI[[#This Row],[Date]]) -> 2025 | D7: =Daily_KPI[[#This Row],[Date]]-DAY(Daily_KPI[[#This Row],[Date]])+1 -> 45748 | E7: =DAY(EOMONTH(A7,0)) -> 30 | F7: =IFERROR(_xlfn.XLOOKUP($A7,'Raw Data'!$A:$A,'Raw Data'!$BR:$BR),"") -> 11.483333 | G7: =IFERROR(_xlfn.XLOOKUP($A7,'Raw Data'!$A:$A,'Raw Data'!$AO:$AO),"") -> 0 | I7: =IFERROR(_xlfn.XLOOKUP($A7,'Raw Data'!$A:$A,'Raw Data'!$AR:$AR),"") -> 6.1 | K7: =IFERROR(_xlfn.XLOOKUP($A7,'Raw Data'!$A:$A,'Raw Data'!$AV:$AV),"") -> 0 | L7: =IFERROR(_xlfn.XLOOKUP($A7,'Raw Data'!$A:$A,'Raw Data'!$AW:$AW),"") -> 0 | M7: =IFERROR(_xlfn.XLOOKUP($A7,'Raw Data'!$A:$A,'Raw Data'!$AX:$AX),"") -> 0 | N7: =IFERROR(_xlfn.XLOOKUP($A7,'Raw Data'!$A:$A,'Raw Data'!$AY:$AY),"") -> 0 | O7: =IFERROR(1-(SUMIF('Plant BD'!$B:$B,A7,'Plant BD'!$AE:$AE)/(AA7+SUMIF('Plant BD'!$B:$B,A7,'Plant BD'!$AE:$AE))),"") -> 1 | R7: =IFERROR(1-(SUMIF('Grid BD'!$B:$B,$A7,'Grid BD'!$AD:$AD)/($AA7+SUMIF('Grid BD'!$B:$B,$A7,'Grid BD'!AD:AD))),"") -> 1 | U7: =IFERROR(AA7/I7/AB7/1000,"") -> 0.75662755 | W7: =IFERROR(AA7/(24*AR7*1000),"") -> 0.1923095 | X7: =IFERROR(_xlfn.XLOOKUP($A7,'Raw Data'!$A:$A,'Raw Data'!$BA:$BA),"") -> 113949.2 | Y7: =IFERROR(_xlfn.XLOOKUP($A7,'Raw Data'!$A:$A,'Raw Data'!BJ:BJ),"") -> 112987.24 | Z7: =IFERROR(_xlfn.XLOOKUP($A7,'Raw Data'!$A:$A,'Raw Data'!BK:BK),"") -> 818.03 | AA7: =IFERROR(_xlfn.XLOOKUP($A7,'Raw Data'!$A:$A,'Raw Data'!BL:BL),"") -> 112169.21 | AB7: =IFERROR(_xlfn.XLOOKUP($A7,'Raw Data'!$A:$A,'Raw Data'!$H:$H),"") -> 24.3031 | AC7: =IFERROR(_xlfn.XLOOKUP($D7,'Modelling New'!$D:$D,'Modelling New'!$P:$P),"") -> 6.6233333 | AD7: =IFERROR(_xlfn.XLOOKUP($D7,'Modelling New'!$D:$D,'Modelling New'!$T:$T)*1000,"") -> 120499.94 | AE7: =IFERROR(_xlfn.XLOOKUP($D7,'Modelling New'!$D:$D,'Modelling New'!$O:$O),"") -> 0.7485978 | AF7: =IFERROR(_xlfn.XLOOKUP($D7,'Modelling New'!$D:$D,'Modelling New'!$W:$W),"") -> 0.2065922 | AG7: =IFERROR(_xlfn.XLOOKUP($D7,'Modelling New'!$D:$D,'Modelling New'!AE:AE),"") -> 0.995 | AH7: 0.9975 | AR7: =IFERROR(_xlfn.XLOOKUP($D7,'Modelling New'!$D:$D,'Modelling New'!$N:$N),"") -> 24.3031
A8: =A7+1 -> 45751 | B8: =YEAR(Daily_KPI[[#This Row],[Date]])+IF(MONTH(Daily_KPI[[#This Row],[Date]])>=4,1,0) -> 2026 | C8: =YEAR(Daily_KPI[[#This Row],[Date]]) -> 2025 | D8: =Daily_KPI[[#This Row],[Date]]-DAY(Daily_KPI[[#This Row],[Date]])+1 -> 45748 | E8: =DAY(EOMONTH(A8,0)) -> 30 | F8: =IFERROR(_xlfn.XLOOKUP($A8,'Raw Data'!$A:$A,'Raw Data'!$BR:$BR),"") -> 11.766667 | G8: =IFERROR(_xlfn.XLOOKUP($A8,'Raw Data'!$A:$A,'Raw Data'!$AO:$AO),"") -> 0 | I8: =IFERROR(_xlfn.XLOOKUP($A8,'Raw Data'!$A:$A,'Raw Data'!$AR:$AR),"") -> 6.6389506 | K8: =IFERROR(_xlfn.XLOOKUP($A8,'Raw Data'!$A:$A,'Raw Data'!$AV:$AV),"") -> 0 | L8: =IFERROR(_xlfn.XLOOKUP($A8,'Raw Data'!$A:$A,'Raw Data'!$AW:$AW),"") -> 0 | M8: =IFERROR(_xlfn.XLOOKUP($A8,'Raw Data'!$A:$A,'Raw Data'!$AX:$AX),"") -> 0 | N8: =IFERROR(_xlfn.XLOOKUP($A8,'Raw Data'!$A:$A,'Raw Data'!$AY:$AY),"") -> 0 | O8: =IFERROR(1-(SUMIF('Plant BD'!$B:$B,A8,'Plant BD'!$AE:$AE)/(AA8+SUMIF('Plant BD'!$B:$B,A8,'Plant BD'!$AE:$AE))),"") -> 1 | R8: =IFERROR(1-(SUMIF('Grid BD'!$B:$B,$A8,'Grid BD'!$AD:$AD)/($AA8+SUMIF('Grid BD'!$B:$B,$A8,'Grid BD'!AD:AD))),"") -> 1 | U8: =IFERROR(AA8/I8/AB8/1000,"") -> 0.76827545 | W8: =IFERROR(AA8/(24*AR8*1000),"") -> 0.21252261 | X8: =IFERROR(_xlfn.XLOOKUP($A8,'Raw Data'!$A:$A,'Raw Data'!$BA:$BA),"") -> 126119.5 | Y8: =IFERROR(_xlfn.XLOOKUP($A8,'Raw Data'!$A:$A,'Raw Data'!BJ:BJ),"") -> 124940.59 | Z8: =IFERROR(_xlfn.XLOOKUP($A8,'Raw Data'!$A:$A,'Raw Data'!BK:BK),"") -> 981.59 | AA8: =IFERROR(_xlfn.XLOOKUP($A8,'Raw Data'!$A:$A,'Raw Data'!BL:BL),"") -> 123959 | AB8: =IFERROR(_xlfn.XLOOKUP($A8,'Raw Data'!$A:$A,'Raw Data'!$H:$H),"") -> 24.3031 | AC8: =IFERROR(_xlfn.XLOOKUP($D8,'Modelling New'!$D:$D,'Modelling New'!$P:$P),"") -> 6.6233333 | AD8: =IFERROR(_xlfn.XLOOKUP($D8,'Modelling New'!$D:$D,'Modelling New'!$T:$T)*1000,"") -> 120499.94 | AE8: =IFERROR(_xlfn.XLOOKUP($D8,'Modelling New'!$D:$D,'Modelling New'!$O:$O),"") -> 0.7485978 | AF8: =IFERROR(_xlfn.XLOOKUP($D8,'Modelling New'!$D:$D,'Modelling New'!$W:$W),"") -> 0.2065922 | AG8: =IFERROR(_xlfn.XLOOKUP($D8,'Modelling New'!$D:$D,'Modelling New'!AE:AE),"") -> 0.995 | AH8: 0.9975 | AR8: =IFERROR(_xlfn.XLOOKUP($D8,'Modelling New'!$D:$D,'Modelling New'!$N:$N),"") -> 24.3031
A9: =A8+1 -> 45752 | B9: =YEAR(Daily_KPI[[#This Row],[Date]])+IF(MONTH(Daily_KPI[[#This Row],[Date]])>=4,1,0) -> 2026 | C9: =YEAR(Daily_KPI[[#This Row],[Date]]) -> 2025 | D9: =Daily_KPI[[#This Row],[Date]]-DAY(Daily_KPI[[#This Row],[Date]])+1 -> 45748 | E9: =DAY(EOMONTH(A9,0)) -> 30 | F9: =IFERROR(_xlfn.XLOOKUP($A9,'Raw Data'!$A:$A,'Raw Data'!$BR:$BR),"") -> 11.75 | G9: =IFERROR(_xlfn.XLOOKUP($A9,'Raw Data'!$A:$A,'Raw Data'!$AO:$AO),"") -> 0 | I9: =IFERROR(_xlfn.XLOOKUP($A9,'Raw Data'!$A:$A,'Raw Data'!$AR:$AR),"") -> 6.7642129 | K9: =IFERROR(_xlfn.XLOOKUP($A9,'Raw Data'!$A:$A,'Raw Data'!$AV:$AV),"") -> 0 | L9: =IFERROR(_xlfn.XLOOKUP($A9,'Raw Data'!$A:$A,'Raw Data'!$AW:$AW),"") -> 0 | M9: =IFERROR(_xlfn.XLOOKUP($A9,'Raw Data'!$A:$A,'Raw Data'!$AX:$AX),"") -> 0 | N9: =IFERROR(_xlfn.XLOOKUP($A9,'Raw Data'!$A:$A,'Raw Data'!$AY:$AY),"") -> 0 | O9: =IFERROR(1-(SUMIF('Plant BD'!$B:$B,A9,'Plant BD'!$AE:$AE)/(AA9+SUMIF('Plant BD'!$B:$B,A9,'Plant BD'!$AE:$AE))),"") -> 1 | R9: =IFERROR(1-(SUMIF('Grid BD'!$B:$B,$A9,'Grid BD'!$AD:$AD)/($AA9+SUMIF('Grid BD'!$B:$B,$A9,'Grid BD'!AD:AD))),"") -> 1 | U9: =IFERROR(AA9/I9/AB9/1000,"") -> 0.75722229 | W9: =IFERROR(AA9/(24*AR9*1000),"") -> 0.2134172 | X9: =IFERROR(_xlfn.XLOOKUP($A9,'Raw Data'!$A:$A,'Raw Data'!$BA:$BA),"") -> 126571 | Y9: =IFERROR(_xlfn.XLOOKUP($A9,'Raw Data'!$A:$A,'Raw Data'!BJ:BJ),"") -> 125301.07 | Z9: =IFERROR(_xlfn.XLOOKUP($A9,'Raw Data'!$A:$A,'Raw Data'!BK:BK),"") -> 820.28 | AA9: =IFERROR(_xlfn.XLOOKUP($A9,'Raw Data'!$A:$A,'Raw Data'!BL:BL),"") -> 124480.79 | AB9: =IFERROR(_xlfn.XLOOKUP($A9,'Raw Data'!$A:$A,'Raw Data'!$H:$H),"") -> 24.3031 | AC9: =IFERROR(_xlfn.XLOOKUP($D9,'Modelling New'!$D:$D,'Modelling New'!$P:$P),"") -> 6.6233333 | AD9: =IFERROR(_xlfn.XLOOKUP($D9,'Modelling New'!$D:$D,'Modelling New'!$T:$T)*1000,"") -> 120499.94 | AE9: =IFERROR(_xlfn.XLOOKUP($D9,'Modelling New'!$D:$D,'Modelling New'!$O:$O),"") -> 0.7485978 | AF9: =IFERROR(_xlfn.XLOOKUP($D9,'Modelling New'!$D:$D,'Modelling New'!$W:$W),"") -> 0.2065922 | AG9: =IFERROR(_xlfn.XLOOKUP($D9,'Modelling New'!$D:$D,'Modelling New'!AE:AE),"") -> 0.995 | AH9: 0.9975 | AR9: =IFERROR(_xlfn.XLOOKUP($D9,'Modelling New'!$D:$D,'Modelling New'!$N:$N),"") -> 24.3031
A10: =A9+1 -> 45753 | B10: =YEAR(Daily_KPI[[#This Row],[Date]])+IF(MONTH(Daily_KPI[[#This Row],[Date]])>=4,1,0) -> 2026 | C10: =YEAR(Daily_KPI[[#This Row],[Date]]) -> 2025 | D10: =Daily_KPI[[#This Row],[Date]]-DAY(Daily_KPI[[#This Row],[Date]])+1 -> 45748 | E10: =DAY(EOMONTH(A10,0)) -> 30 | F10: =IFERROR(_xlfn.XLOOKUP($A10,'Raw Data'!$A:$A,'Raw Data'!$BR:$BR),"") -> 11.8 | G10: =IFERROR(_xlfn.XLOOKUP($A10,'Raw Data'!$A:$A,'Raw Data'!$AO:$AO),"") -> 0 | I10: =IFERROR(_xlfn.XLOOKUP($A10,'Raw Data'!$A:$A,'Raw Data'!$AR:$AR),"") -> 6.9511528 | K10: =IFERROR(_xlfn.XLOOKUP($A10,'Raw Data'!$A:$A,'Raw Data'!$AV:$AV),"") -> 0 | L10: =IFERROR(_xlfn.XLOOKUP($A10,'Raw Data'!$A:$A,'Raw Data'!$AW:$AW),"") -> 0 | M10: =IFERROR(_xlfn.XLOOKUP($A10,'Raw Data'!$A:$A,'Raw Data'!$AX:$AX),"") -> 0 | N10: =IFERROR(_xlfn.XLOOKUP($A10,'Raw Data'!$A:$A,'Raw Data'!$AY:$AY),"") -> 0 | O10: =IFERROR(1-(SUMIF('Plant BD'!$B:$B,A10,'Plant BD'!$AE:$AE)/(AA10+SUMIF('Plant BD'!$B:$B,A10,'Plant BD'!$AE:$AE))),"") -> 1 | R10: =IFERROR(1-(SUMIF('Grid BD'!$B:$B,$A10,'Grid BD'!$AD:$AD)/($AA10+SUMIF('Grid BD'!$B:$B,$A10,'Grid BD'!AD:AD))),"") -> 1 | U10: =IFERROR(AA10/I10/AB10/1000,"") -> 0.75143978 | W10: =IFERROR(AA10/(24*AR10*1000),"") -> 0.21764053 | X10: =IFERROR(_xlfn.XLOOKUP($A10,'Raw Data'!$A:$A,'Raw Data'!$BA:$BA),"") -> 129103 | Y10: =IFERROR(_xlfn.XLOOKUP($A10,'Raw Data'!$A:$A,'Raw Data'!BJ:BJ),"") -> 127602.03 | Z10: =IFERROR(_xlfn.XLOOKUP($A10,'Raw Data'!$A:$A,'Raw Data'!BK:BK),"") -> 657.88 | AA10: =IFERROR(_xlfn.XLOOKUP($A10,'Raw Data'!$A:$A,'Raw Data'!BL:BL),"") -> 126944.15 | AB10: =IFERROR(_xlfn.XLOOKUP($A10,'Raw Data'!$A:$A,'Raw Data'!$H:$H),"") -> 24.3031 | AC10: =IFERROR(_xlfn.XLOOKUP($D10,'Modelling New'!$D:$D,'Modelling New'!$P:$P),"") -> 6.6233333 | AD10: =IFERROR(_xlfn.XLOOKUP($D10,'Modelling New'!$D:$D,'Modelling New'!$T:$T)*1000,"") -> 120499.94 | AE10: =IFERROR(_xlfn.XLOOKUP($D10,'Modelling New'!$D:$D,'Modelling New'!$O:$O),"") -> 0.7485978 | AF10: =IFERROR(_xlfn.XLOOKUP($D10,'Modelling New'!$D:$D,'Modelling New'!$W:$W),"") -> 0.2065922 | AG10: =IFERROR(_xlfn.XLOOKUP($D10,'Modelling New'!$D:$D,'Modelling New'!AE:AE),"") -> 0.995 | AH10: 0.9975 | AR10: =IFERROR(_xlfn.XLOOKUP($D10,'Modelling New'!$D:$D,'Modelling New'!$N:$N),"") -> 24.3031
A11: =A10+1 -> 45754 | B11: =YEAR(Daily_KPI[[#This Row],[Date]])+IF(MONTH(Daily_KPI[[#This Row],[Date]])>=4,1,0) -> 2026 | C11: =YEAR(Daily_KPI[[#This Row],[Date]]) -> 2025 | D11: =Daily_KPI[[#This Row],[Date]]-DAY(Daily_KPI[[#This Row],[Date]])+1 -> 45748 | E11: =DAY(EOMONTH(A11,0)) -> 30 | F11: =IFERROR(_xlfn.XLOOKUP($A11,'Raw Data'!$A:$A,'Raw Data'!$BR:$BR),"") -> 11.883333 | G11: =IFERROR(_xlfn.XLOOKUP($A11,'Raw Data'!$A:$A,'Raw Data'!$AO:$AO),"") -> 0 | I11: =IFERROR(_xlfn.XLOOKUP($A11,'Raw Data'!$A:$A,'Raw Data'!$AR:$AR),"") -> 6.9981049 | K11: =IFERROR(_xlfn.XLOOKUP($A11,'Raw Data'!$A:$A,'Raw Data'!$AV:$AV),"") -> 0 | L11: =IFERROR(_xlfn.XLOOKUP($A11,'Raw Data'!$A:$A,'Raw Data'!$AW:$AW),"") -> 0 | M11: =IFERROR(_xlfn.XLOOKUP($A11,'Raw Data'!$A:$A,'Raw Data'!$AX:$AX),"") -> 0 | N11: =IFERROR(_xlfn.XLOOKUP($A11,'Raw Data'!$A:$A,'Raw Data'!$AY:$AY),"") -> 0 | O11: =IFERROR(1-(SUMIF('Plant BD'!$B:$B,A11,'Plant BD'!$AE:$AE)/(AA11+SUMIF('Plant BD'!$B:$B,A11,'Plant BD'!$AE:$AE))),"") -> 1 | R11: =IFERROR(1-(SUMIF('Grid BD'!$B:$B,$A11,'Grid BD'!$AD:$AD)/($AA11+SUMIF('Grid BD'!$B:$B,$A11,'Grid BD'!AD:AD))),"") -> 1 | U11: =IFERROR(AA11/I11/AB11/1000,"") -> 0.74321141 | W11: =IFERROR(AA11/(24*AR11*1000),"") -> 0.21671131 | X11: =IFERROR(_xlfn.XLOOKUP($A11,'Raw Data'!$A:$A,'Raw Data'!$BA:$BA),"") -> 128983 | Y11: =IFERROR(_xlfn.XLOOKUP($A11,'Raw Data'!$A:$A,'Raw Data'!BJ:BJ),"") -> 127518.12 | Z11: =IFERROR(_xlfn.XLOOKUP($A11,'Raw Data'!$A:$A,'Raw Data'!BK:BK),"") -> 1115.96 | AA11: =IFERROR(_xlfn.XLOOKUP($A11,'Raw Data'!$A:$A,'Raw Data'!BL:BL),"") -> 126402.16 | AB11: =IFERROR(_xlfn.XLOOKUP($A11,'Raw Data'!$A:$A,'Raw Data'!$H:$H),"") -> 24.3031 | AC11: =IFERROR(_xlfn.XLOOKUP($D11,'Modelling New'!$D:$D,'Modelling New'!$P:$P),"") -> 6.6233333 | AD11: =IFERROR(_xlfn.XLOOKUP($D11,'Modelling New'!$D:$D,'Modelling New'!$T:$T)*1000,"") -> 120499.94 | AE11: =IFERROR(_xlfn.XLOOKUP($D11,'Modelling New'!$D:$D,'Modelling New'!$O:$O),"") -> 0.7485978 | AF11: =IFERROR(_xlfn.XLOOKUP($D11,'Modelling New'!$D:$D,'Modelling New'!$W:$W),"") -> 0.2065922 | AG11: =IFERROR(_xlfn.XLOOKUP($D11,'Modelling New'!$D:$D,'Modelling New'!AE:AE),"") -> 0.995 | AH11: 0.9975 | AR11: =IFERROR(_xlfn.XLOOKUP($D11,'Modelling New'!$D:$D,'Modelling New'!$N:$N),"") -> 24.3031
A12: =A11+1 -> 45755 | B12: =YEAR(Daily_KPI[[#This Row],[Date]])+IF(MONTH(Daily_KPI[[#This Row],[Date]])>=4,1,0) -> 2026 | C12: =YEAR(Daily_KPI[[#This Row],[Date]]) -> 2025 | D12: =Daily_KPI[[#This Row],[Date]]-DAY(Daily_KPI[[#This Row],[Date]])+1 -> 45748 | E12: =DAY(EOMONTH(A12,0)) -> 30 | F12: =IFERROR(_xlfn.XLOOKUP($A12,'Raw Data'!$A:$A,'Raw Data'!$BR:$BR),"") -> 11.883333 | G12: =IFERROR(_xlfn.XLOOKUP($A12,'Raw Data'!$A:$A,'Raw Data'!$AO:$AO),"") -> 0 | I12: =IFERROR(_xlfn.XLOOKUP($A12,'Raw Data'!$A:$A,'Raw Data'!$AR:$AR),"") -> 6.8258023 | K12: =IFERROR(_xlfn.XLOOKUP($A12,'Raw Data'!$A:$A,'Raw Data'!$AV:$AV),"") -> 0 | L12: =IFERROR(_xlfn.XLOOKUP($A12,'Raw Data'!$A:$A,'Raw Data'!$AW:$AW),"") -> 0 | M12: =IFERROR(_xlfn.XLOOKUP($A12,'Raw Data'!$A:$A,'Raw Data'!$AX:$AX),"") -> 0 | N12: =IFERROR(_xlfn.XLOOKUP($A12,'Raw Data'!$A:$A,'Raw Data'!$AY:$AY),"") -> 0 | O12: =IFERROR(1-(SUMIF('Plant BD'!$B:$B,A12,'Plant BD'!$AE:$AE)/(AA12+SUMIF('Plant BD'!$B:$B,A12,'Plant BD'!$AE:$AE))),"") -> 1 | R12: =IFERROR(1-(SUMIF('Grid BD'!$B:$B,$A12,'Grid BD'!$AD:$AD)/($AA12+SUMIF('Grid BD'!$B:$B,$A12,'Grid BD'!AD:AD))),"") -> 1 | U12: =IFERROR(AA12/I12/AB12/1000,"") -> 0.74961271 | W12: =IFERROR(AA12/(24*AR12*1000),"") -> 0.21319617 | X12: =IFERROR(_xlfn.XLOOKUP($A12,'Raw Data'!$A:$A,'Raw Data'!$BA:$BA),"") -> 126836 | Y12: =IFERROR(_xlfn.XLOOKUP($A12,'Raw Data'!$A:$A,'Raw Data'!BJ:BJ),"") -> 125388.02 | Z12: =IFERROR(_xlfn.XLOOKUP($A12,'Raw Data'!$A:$A,'Raw Data'!BK:BK),"") -> 1036.15 | AA12: =IFERROR(_xlfn.XLOOKUP($A12,'Raw Data'!$A:$A,'Raw Data'!BL:BL),"") -> 124351.87 | AB12: =IFERROR(_xlfn.XLOOKUP($A12,'Raw Data'!$A:$A,'Raw Data'!$H:$H),"") -> 24.3031 | AC12: =IFERROR(_xlfn.XLOOKUP($D12,'Modelling New'!$D:$D,'Modelling New'!$P:$P),"") -> 6.6233333 | AD12: =IFERROR(_xlfn.XLOOKUP($D12,'Modelling New'!$D:$D,'Modelling New'!$T:$T)*1000,"") -> 120499.94 | AE12: =IFERROR(_xlfn.XLOOKUP($D12,'Modelling New'!$D:$D,'Modelling New'!$O:$O),"") -> 0.7485978 | AF12: =IFERROR(_xlfn.XLOOKUP($D12,'Modelling New'!$D:$D,'Modelling New'!$W:$W),"") -> 0.2065922 | AG12: =IFERROR(_xlfn.XLOOKUP($D12,'Modelling New'!$D:$D,'Modelling New'!AE:AE),"") -> 0.995 | AH12: 0.9975 | AR12: =IFERROR(_xlfn.XLOOKUP($D12,'Modelling New'!$D:$D,'Modelling New'!$N:$N),"") -> 24.3031
A13: =A12+1 -> 45756 | B13: =YEAR(Daily_KPI[[#This Row],[Date]])+IF(MONTH(Daily_KPI[[#This Row],[Date]])>=4,1,0) -> 2026 | C13: =YEAR(Daily_KPI[[#This Row],[Date]]) -> 2025 | D13: =Daily_KPI[[#This Row],[Date]]-DAY(Daily_KPI[[#This Row],[Date]])+1 -> 45748 | E13: =DAY(EOMONTH(A13,0)) -> 30 | F13: =IFERROR(_xlfn.XLOOKUP($A13,'Raw Data'!$A:$A,'Raw Data'!$BR:$BR),"") -> 11.916667 | G13: =IFERROR(_xlfn.XLOOKUP($A13,'Raw Data'!$A:$A,'Raw Data'!$AO:$AO),"") -> 0 | I13: =IFERROR(_xlfn.XLOOKUP($A13,'Raw Data'!$A:$A,'Raw Data'!$AR:$AR),"") -> 6.6833015 | K13: =IFERROR(_xlfn.XLOOKUP($A13,'Raw Data'!$A:$A,'Raw Data'!$AV:$AV),"") -> 0 | L13: =IFERROR(_xlfn.XLOOKUP($A13,'Raw Data'!$A:$A,'Raw Data'!$AW:$AW),"") -> 0 | M13: =IFERROR(_xlfn.XLOOKUP($A13,'Raw Data'!$A:$A,'Raw Data'!$AX:$AX),"") -> 0 | N13: =IFERROR(_xlfn.XLOOKUP($A13,'Raw Data'!$A:$A,'Raw Data'!$AY:$AY),"") -> 0 | O13: =IFERROR(1-(SUMIF('Plant BD'!$B:$B,A13,'Plant BD'!$AE:$AE)/(AA13+SUMIF('Plant BD'!$B:$B,A13,'Plant BD'!$AE:$AE))),"") -> 1 | R13: =IFERROR(1-(SUMIF('Grid BD'!$B:$B,$A13,'Grid BD'!$AD:$AD)/($AA13+SUMIF('Grid BD'!$B:$B,$A13,'Grid BD'!AD:AD))),"") -> 1 | U13: =IFERROR(AA13/I13/AB13/1000,"") -> 0.74128836 | W13: =IFERROR(AA13/(24*AR13*1000),"") -> 0.20642723 | X13: =IFERROR(_xlfn.XLOOKUP($A13,'Raw Data'!$A:$A,'Raw Data'!$BA:$BA),"") -> 122236 | Y13: =IFERROR(_xlfn.XLOOKUP($A13,'Raw Data'!$A:$A,'Raw Data'!BJ:BJ),"") -> 121028.97 | Z13: =IFERROR(_xlfn.XLOOKUP($A13,'Raw Data'!$A:$A,'Raw Data'!BK:BK),"") -> 625.25 | AA13: =IFERROR(_xlfn.XLOOKUP($A13,'Raw Data'!$A:$A,'Raw Data'!BL:BL),"") -> 120403.72 | AB13: =IFERROR(_xlfn.XLOOKUP($A13,'Raw Data'!$A:$A,'Raw Data'!$H:$H),"") -> 24.3031 | AC13: =IFERROR(_xlfn.XLOOKUP($D13,'Modelling New'!$D:$D,'Modelling New'!$P:$P),"") -> 6.6233333 | AD13: =IFERROR(_xlfn.XLOOKUP($D13,'Modelling New'!$D:$D,'Modelling New'!$T:$T)*1000,"") -> 120499.94 | AE13: =IFERROR(_xlfn.XLOOKUP($D13,'Modelling New'!$D:$D,'Modelling New'!$O:$O),"") -> 0.7485978 | AF13: =IFERROR(_xlfn.XLOOKUP($D13,'Modelling New'!$D:$D,'Modelling New'!$W:$W),"") -> 0.2065922 | AG13: =IFERROR(_xlfn.XLOOKUP($D13,'Modelling New'!$D:$D,'Modelling New'!AE:AE),"") -> 0.995 | AH13: 0.9975 | AR13: =IFERROR(_xlfn.XLOOKUP($D13,'Modelling New'!$D:$D,'Modelling New'!$N:$N),"") -> 24.3031
A14: =A13+1 -> 45757 | B14: =YEAR(Daily_KPI[[#This Row],[Date]])+IF(MONTH(Daily_KPI[[#This Row],[Date]])>=4,1,0) -> 2026 | C14: =YEAR(Daily_KPI[[#This Row],[Date]]) -> 2025 | D14: =Daily_KPI[[#This Row],[Date]]-DAY(Daily_KPI[[#This Row],[Date]])+1 -> 45748 | E14: =DAY(EOMONTH(A14,0)) -> 30 | F14: =IFERROR(_xlfn.XLOOKUP($A14,'Raw Data'!$A:$A,'Raw Data'!$BR:$BR),"") -> 11.866667 | G14: =IFERROR(_xlfn.XLOOKUP($A14,'Raw Data'!$A:$A,'Raw Data'!$AO:$AO),"") -> 0 | I14: =IFERROR(_xlfn.XLOOKUP($A14,'Raw Data'!$A:$A,'Raw Data'!$AR:$AR),"") -> 6.3952928 | K14: =IFERROR(_xlfn.XLOOKUP($A14,'Raw Data'!$A:$A,'Raw Data'!$AV:$AV),"") -> 0 | L14: =IFERROR(_xlfn.XLOOKUP($A14,'Raw Data'!$A:$A,'Raw Data'!$AW:$AW),"") -> 0 | M14: =IFERROR(_xlfn.XLOOKUP($A14,'Raw Data'!$A:$A,'Raw Data'!$AX:$AX),"") -> 0 | N14: =IFERROR(_xlfn.XLOOKUP($A14,'Raw Data'!$A:$A,'Raw Data'!$AY:$AY),"") -> 0 | O14: =IFERROR(1-(SUMIF('Plant BD'!$B:$B,A14,'Plant BD'!$AE:$AE)/(AA14+SUMIF('Plant BD'!$B:$B,A14,'Plant BD'!$AE:$AE))),"") -> 1 | R14: =IFERROR(1-(SUMIF('Grid BD'!$B:$B,$A14,'Grid BD'!$AD:$AD)/($AA14+SUMIF('Grid BD'!$B:$B,$A14,'Grid BD'!AD:AD))),"") -> 1 | U14: =IFERROR(AA14/I14/AB14/1000,"") -> 0.76035956 | W14: =IFERROR(AA14/(24*AR14*1000),"") -> 0.20261342 | X14: =IFERROR(_xlfn.XLOOKUP($A14,'Raw Data'!$A:$A,'Raw Data'!$BA:$BA),"") -> 120303 | Y14: =IFERROR(_xlfn.XLOOKUP($A14,'Raw Data'!$A:$A,'Raw Data'!BJ:BJ),"") -> 119078.44 | Z14: =IFERROR(_xlfn.XLOOKUP($A14,'Raw Data'!$A:$A,'Raw Data'!BK:BK),"") -> 899.22 | AA14: =IFERROR(_xlfn.XLOOKUP($A14,'Raw Data'!$A:$A,'Raw Data'!BL:BL),"") -> 118179.22 | AB14: =IFERROR(_xlfn.XLOOKUP($A14,'Raw Data'!$A:$A,'Raw Data'!$H:$H),"") -> 24.3031 | AC14: =IFERROR(_xlfn.XLOOKUP($D14,'Modelling New'!$D:$D,'Modelling New'!$P:$P),"") -> 6.6233333 | AD14: =IFERROR(_xlfn.XLOOKUP($D14,'Modelling New'!$D:$D,'Modelling New'!$T:$T)*1000,"") -> 120499.94 | AE14: =IFERROR(_xlfn.XLOOKUP($D14,'Modelling New'!$D:$D,'Modelling New'!$O:$O),"") -> 0.7485978 | AF14: =IFERROR(_xlfn.XLOOKUP($D14,'Modelling New'!$D:$D,'Modelling New'!$W:$W),"") -> 0.2065922 | AG14: =IFERROR(_xlfn.XLOOKUP($D14,'Modelling New'!$D:$D,'Modelling New'!AE:AE),"") -> 0.995 | AH14: 0.9975 | AR14: =IFERROR(_xlfn.XLOOKUP($D14,'Modelling New'!$D:$D,'Modelling New'!$N:$N),"") -> 24.3031
... A369: =A368+1 -> 46112 | B369: =YEAR(Daily_KPI[[#This Row],[Date]])+IF(MONTH(Daily_KPI[[#This Row],[Date]])>=4,1,0) -> 2026 | C369: =YEAR(Daily_KPI[[#This Row],[Date]]) -> 2026 | D369: =Daily_KPI[[#This Row],[Date]]-DAY(Daily_KPI[[#This Row],[Date]])+1 -> 46082 | E369: =DAY(EOMONTH(A369,0)) -> 31 | F369: =IFERROR(_xlfn.XLOOKUP($A369,'Raw Data'!$A:$A,'Raw Data'!$BR:$BR),"") | G369: =IFERROR(_xlfn.XLOOKUP($A369,'Raw Data'!$A:$A,'Raw Data'!$AO:$AO),"") | I369: =IFERROR(_xlfn.XLOOKUP($A369,'Raw Data'!$A:$A,'Raw Data'!$AR:$AR),"") | K369: =IFERROR(_xlfn.XLOOKUP($A369,'Raw Data'!$A:$A,'Raw Data'!$AV:$AV),"") | L369: =IFERROR(_xlfn.XLOOKUP($A369,'Raw Data'!$A:$A,'Raw Data'!$AW:$AW),"") | M369: =IFERROR(_xlfn.XLOOKUP($A369,'Raw Data'!$A:$A,'Raw Data'!$AX:$AX),"") | N369: =IFERROR(_xlfn.XLOOKUP($A369,'Raw Data'!$A:$A,'Raw Data'!$AY:$AY),"") | O369: =IFERROR(1-(SUMIF('Plant BD'!$B:$B,A369,'Plant BD'!$AE:$AE)/(AA369+SUMIF('Plant BD'!$B:$B,A369,'Plant BD'!$AE:$AE))),"") | R369: =IFERROR(1-(SUMIF('Grid BD'!$B:$B,$A369,'Grid BD'!$AD:$AD)/($AA369+SUMIF('Grid BD'!$B:$B,$A369,'Grid BD'!AD:AD))),"") | U369: =IFERROR(AA369/I369/AB369/1000,"") | W369: =IFERROR(AA369/(24*AR369*1000),"") | X369: =IFERROR(_xlfn.XLOOKUP($A369,'Raw Data'!$A:$A,'Raw Data'!$BA:$BA),"") | Y369: =IFERROR(_xlfn.XLOOKUP($A369,'Raw Data'!$A:$A,'Raw Data'!BJ:BJ),"") | Z369: =IFERROR(_xlfn.XLOOKUP($A369,'Raw Data'!$A:$A,'Raw Data'!BK:BK),"") | AA369: =IFERROR(_xlfn.XLOOKUP($A369,'Raw Data'!$A:$A,'Raw Data'!BL:BL),"") | AB369: =IFERROR(_xlfn.XLOOKUP($A369,'Raw Data'!$A:$A,'Raw Data'!$H:$H),"") | AC369: =IFERROR(_xlfn.XLOOKUP($D369,'Modelling New'!$D:$D,'Modelling New'!$P:$P),"") -> 6.9 | AD369: =IFERROR(_xlfn.XLOOKUP($D369,'Modelling New'!$D:$D,'Modelling New'!$T:$T)*1000,"") -> 124131.1 | AE369: =IFERROR(_xlfn.XLOOKUP($D369,'Modelling New'!$D:$D,'Modelling New'!$O:$O),"") -> 0.74023536 | AF369: =IFERROR(_xlfn.XLOOKUP($D369,'Modelling New'!$D:$D,'Modelling New'!$W:$W),"") -> 0.21281767 | AG369: =IFERROR(_xlfn.XLOOKUP($D369,'Modelling New'!$D:$D,'Modelling New'!AE:AE),"") -> 0.995 | AH369: 0.9975 | AR369: =IFERROR(_xlfn.XLOOKUP($D369,'Modelling New'!$D:$D,'Modelling New'!$N:$N),"") -> 24.3031

Sheet Inv_SY_Dev
A1: Finacial Year | B1: Start Month | C1: Calendor Year | D1: Contrcatual Year | E1: Operating Year | F1: Date | G1: G1 Inv1 | H1: G1 Inv2 | I1: G2 Inv3 | J1: G2 Inv4 | K1: G3 Inv5 | L1: G3 Inv6 | M1: G4 Inv7 | N1: G4 Inv8 | O1: G5 Inv9 | P1: G5 Inv10 | Q1: IS1_Inv1_M1 | R1: IS1_Inv1_M2 | S1: IS1_Inv1_M3 | T1: IS1_Inv1_M4 | U1: IS1_Inv2_M1 | V1: IS1_Inv2_M2 | W1: IS1_Inv2_M3 | X1: IS1_Inv2_M4 | Y1: IS2_Inv1 | Z1: IS1_Inv2
A2: FY2022-23 | C2: 2000 | D2: Year_1 | E2: Year_1 | F2: ='Daily Dashboard'!B5-32 -> 45837 | G2: =IFERROR(Inv_SY!F4/Inv_SY!$P4-1,"") -> -0.0096439461 | H2: =IFERROR(Inv_SY!G4/Inv_SY!$P4-1,"") -> -0.016940444 | I2: =IFERROR(Inv_SY!H4/Inv_SY!$P4-1,"") -> -0.013579136 | J2: =IFERROR(Inv_SY!I4/Inv_SY!$P4-1,"") -> -0.021579567 | K2: =IFERROR(Inv_SY!J4/Inv_SY!$P4-1,"") -> -0.0080496898 | L2: =IFERROR(Inv_SY!K4/Inv_SY!$P4-1,"") -> -0.015552336 | M2: =IFERROR(Inv_SY!L4/Inv_SY!$P4-1,"") -> 0.014498324 | N2: =IFERROR(Inv_SY!M4/Inv_SY!$P4-1,"") -> 0.039545924 | ... P2: =IFERROR(Inv_SY!O4/Inv_SY!$P4-1,"") -> 0.030363815 | Q2: =IFERROR(Inv_SY!Q4/Inv_SY!$AA4-1,"") -> -0.0014145019 | R2: =IFERROR(Inv_SY!R4/Inv_SY!$AA4-1,"") -> -0.019545455 | S2: =IFERROR(Inv_SY!S4/Inv_SY!$AA4-1,"") -> 0.041453563 | T2: =IFERROR(Inv_SY!T4/Inv_SY!$AA4-1,"") -> 0.014967046 | U2: =IFERROR(Inv_SY!U4/Inv_SY!$AA4-1,"") -> 0.0023010105 | V2: =IFERROR(Inv_SY!V4/Inv_SY!$AA4-1,"") -> 0.0014219742 | W2: =IFERROR(Inv_SY!W4/Inv_SY!$AA4-1,"") -> -0.0086599316 | X2: =IFERROR(Inv_SY!X4/Inv_SY!$AA4-1,"") -> -0.02675763 | ... Z2: =IFERROR(Inv_SY!Z4/Inv_SY!$AA4-1,"") -> -0.0070478756
A3: FY2022-23 | C3: 2000 | D3: Year_1 | E3: Year_1 | F3: =F2+1 -> 45838 | G3: =IFERROR(Inv_SY!F5/Inv_SY!$P5-1,"") -> -0.0061620013 | H3: =IFERROR(Inv_SY!G5/Inv_SY!$P5-1,"") -> -0.0093521214 | I3: =IFERROR(Inv_SY!H5/Inv_SY!$P5-1,"") -> -0.01023056 | J3: =IFERROR(Inv_SY!I5/Inv_SY!$P5-1,"") -> -0.0094339194 | K3: =IFERROR(Inv_SY!J5/Inv_SY!$P5-1,"") -> -0.026504796 | L3: =IFERROR(Inv_SY!K5/Inv_SY!$P5-1,"") -> -0.0090023002 | M3: =IFERROR(Inv_SY!L5/Inv_SY!$P5-1,"") -> 0.0124323 | N3: =IFERROR(Inv_SY!M5/Inv_SY!$P5-1,"") -> 0.032674244 | ... P3: =IFERROR(Inv_SY!O5/Inv_SY!$P5-1,"") -> 0.024537126 | Q3: =IFERROR(Inv_SY!Q5/Inv_SY!$AA5-1,"") -> 0.0057981013 | R3: =IFERROR(Inv_SY!R5/Inv_SY!$AA5-1,"") -> -0.017885329 | S3: =IFERROR(Inv_SY!S5/Inv_SY!$AA5-1,"") -> 0.035707191 | T3: =IFERROR(Inv_SY!T5/Inv_SY!$AA5-1,"") -> 0.0078039484 | U3: =IFERROR(Inv_SY!U5/Inv_SY!$AA5-1,"") -> -0.0012910881 | V3: =IFERROR(Inv_SY!V5/Inv_SY!$AA5-1,"") -> 0.0037102055 | W3: =IFERROR(Inv_SY!W5/Inv_SY!$AA5-1,"") -> 0.00024882142 | X3: =IFERROR(Inv_SY!X5/Inv_SY!$AA5-1,"") -> -0.014037197 | ... Z3: =IFERROR(Inv_SY!Z5/Inv_SY!$AA5-1,"") -> -0.014561761
A4: FY2022-23 | C4: 2000 | D4: Year_1 | E4: Year_1 | F4: =F3+1 -> 45839 | G4: =IFERROR(Inv_SY!F6/Inv_SY!$P6-1,"") -> -0.014887637 | H4: =IFERROR(Inv_SY!G6/Inv_SY!$P6-1,"") -> -0.013338718 | I4: =IFERROR(Inv_SY!H6/Inv_SY!$P6-1,"") -> -0.013338718 | J4: =IFERROR(Inv_SY!I6/Inv_SY!$P6-1,"") -> -0.010386505 | K4: =IFERROR(Inv_SY!J6/Inv_SY!$P6-1,"") -> -0.011170232 | L4: =IFERROR(Inv_SY!K6/Inv_SY!$P6-1,"") -> -0.010461818 | M4: =IFERROR(Inv_SY!L6/Inv_SY!$P6-1,"") -> 0.01713721 | N4: =IFERROR(Inv_SY!M6/Inv_SY!$P6-1,"") -> 0.035710377 | ... P4: =IFERROR(Inv_SY!O6/Inv_SY!$P6-1,"") -> 0.021770108 | Q4: =IFERROR(Inv_SY!Q6/Inv_SY!$AA6-1,"") -> -0.0012588704 | R4: =IFERROR(Inv_SY!R6/Inv_SY!$AA6-1,"") -> -0.023148039 | S4: =IFERROR(Inv_SY!S6/Inv_SY!$AA6-1,"") -> 0.033736374 | T4: =IFERROR(Inv_SY!T6/Inv_SY!$AA6-1,"") -> 0.0066823401 | U4: =IFERROR(Inv_SY!U6/Inv_SY!$AA6-1,"") -> -0.0029610332 | V4: =IFERROR(Inv_SY!V6/Inv_SY!$AA6-1,"") -> -0.0011900731 | W4: =IFERROR(Inv_SY!W6/Inv_SY!$AA6-1,"") -> -0.0050557743 | X4: =IFERROR(Inv_SY!X6/Inv_SY!$AA6-1,"") -> -0.020725987 | ... Z4: =IFERROR(Inv_SY!Z6/Inv_SY!$AA6-1,"") -> 0.0031657115
A5: FY2022-23 | C5: 2000 | D5: Year_1 | E5: Year_1 | F5: =F4+1 -> 45840 | G5: =IFERROR(Inv_SY!F7/Inv_SY!$P7-1,"") -> -0.01454274 | H5: =IFERROR(Inv_SY!G7/Inv_SY!$P7-1,"") -> -0.018052204 | I5: =IFERROR(Inv_SY!H7/Inv_SY!$P7-1,"") -> -0.024168697 | J5: =IFERROR(Inv_SY!I7/Inv_SY!$P7-1,"") -> -0.018514476 | K5: =IFERROR(Inv_SY!J7/Inv_SY!$P7-1,"") -> -0.010007434 | L5: =IFERROR(Inv_SY!K7/Inv_SY!$P7-1,"") -> -0.015472198 | M5: =IFERROR(Inv_SY!L7/Inv_SY!$P7-1,"") -> 0.0092917414 | N5: =IFERROR(Inv_SY!M7/Inv_SY!$P7-1,"") -> 0.035993529 | ... P5: =IFERROR(Inv_SY!O7/Inv_SY!$P7-1,"") -> 0.044416241 | Q5: =IFERROR(Inv_SY!Q7/Inv_SY!$AA7-1,"") -> 0.007046114 | R5: =IFERROR(Inv_SY!R7/Inv_SY!$AA7-1,"") -> -0.01312032 | S5: =IFERROR(Inv_SY!S7/Inv_SY!$AA7-1,"") -> 0.04475367 | T5: =IFERROR(Inv_SY!T7/Inv_SY!$AA7-1,"") -> 0.01804576 | U5: =IFERROR(Inv_SY!U7/Inv_SY!$AA7-1,"") -> 0.0079199518 | V5: =IFERROR(Inv_SY!V7/Inv_SY!$AA7-1,"") -> 0.0065791618 | W5: =IFERROR(Inv_SY!W7/Inv_SY!$AA7-1,"") -> 0.0017802345 | X5: =IFERROR(Inv_SY!X7/Inv_SY!$AA7-1,"") -> -0.01549676 | ... Z5: =IFERROR(Inv_SY!Z7/Inv_SY!$AA7-1,"") -> -0.037398326
