Workbook

Sheet Dashboard
A1: Performance Summary of JPPL 50 MW Agra as on date and YTD
A2: Month | B2: 45839
A3: Date | B3: 45861
A4: Operation Year | B4: FY26
A5: Year Start Date | B5: 45748
A6: Year End Date | B6: 46112
A8: Sr. No. | B8: Particular | C8: Target | D8: Measured | E8: Deviation | F8: Remarks
A9: 1 | B9: E_Grid Daily (MWh) | C9: =_xlfn.XLOOKUP($B$3,'Daily KPI'!$A:$A,'Daily KPI'!$AD:$AD,0)/1000 -> 224.11207 | D9: =_xlfn.XLOOKUP(B3,'Daily KPI'!$A:$A,'Daily KPI'!$AA:$AA,0)/1000 -> 110.75433 | E9: =-(C9-D9)/C9 -> -0.50580828
B10: E_Grid MTD(MWh) | C10: =Monthly_KPI!E4 -> 5154.5775 | D10: =Monthly_KPI!F4 -> 4981.0177 | E10: =-(C10-D10)/C10 -> -0.033671007
B11: E_Grid YTD (MWh) | C11: =Annual_KPI!E4 -> 33310.432 | D11: =Annual_KPI!F4 -> 31524.436 | E11: =-(C11-D11)/C11 -> -0.053616712
A12: 2 | B12: CUF Daily(%) | C12: =_xlfn.XLOOKUP($B$3,'Daily KPI'!$A:$A,'Daily KPI'!$AF:$AF,0) -> 0.13988469 | D12: =_xlfn.XLOOKUP($B$3,'Daily KPI'!$A:$A,'Daily KPI'!$W:$W,0) -> 0.069135036 | E12: =-(C12-D12)/C12 -> -0.50577126
B13: CUF MTD(%) | C13: =Monthly_KPI!I4 -> 0.13988469 | D13: =Monthly_KPI!J4 -> 0.13517464 | E13: =-(C13-D13)/C13 -> -0.033671007
B14: CUF YTD(%) | C14: =Annual_KPI!I4 -> 0.18238133 | D14: =Annual_KPI!J4 -> 0.17260264 | E14: =-(C14-D14)/C14 -> -0.053616712
A15: 3 | B15: PR_Daily (%) | C15: =_xlfn.XLOOKUP($B$3,'Daily KPI'!$A:$A,'Daily KPI'!$AE:$AE,0) -> 0.77092009 | D15: =_xlfn.XLOOKUP($B$3,'Daily KPI'!$A:$A,'Daily KPI'!$U:$U,0) -> 0.7901147 | E15: =-(C15-D15)/C15 -> 0.02489831
B16: PR_MTD (%) | C16: =Monthly_KPI!G4 -> 0.77092009 | D16: =Monthly_KPI!H4 -> 0.77652616 | E16: =-(C16-D16)/C16 -> 0.0072719205
B17: PR_YTD (%) | C17: =Annual_KPI!G4 -> 0.76117263 | D17: =Annual_KPI!H4 -> 0.76143282 | E17: =-(C17-D17)/C17 -> 0.00034182407
A18: 4 | B18: POA Daily (KWh/m2) | C18: =_xlfn.XLOOKUP($B$3,'Daily KPI'!$A:$A,'Daily KPI'!$AC:$AC,0) -> 4.3548387 | D18: =_xlfn.XLOOKUP($B$3,'Daily KPI'!$A:$A,'Daily KPI'!$I:$I,0) -> 2.1 | E18: =-(C18-D18)/C18 -> -0.51777778
B19: POA MTD(KWh/m2) | C19: =Monthly_KPI!C4 -> 100.16129 | D19: =Monthly_KPI!D4 -> 96.09 | E19: =-(C19-D19)/C19 -> -0.040647343
B20: POA YTD(KWh/m2) | C20: =Annual_KPI!C4 -> 655.56129 | D20: =Annual_KPI!D4 -> 620.20025 | E20: =-(C20-D20)/C20 -> -0.053940098
A21: 5 | B21: PA Daily | C21: =_xlfn.XLOOKUP($B$3,'Daily KPI'!$A:$A,'Daily KPI'!$AG:$AG) -> 0.995 | D21: =_xlfn.XLOOKUP($B$3,'Daily KPI'!$A:$A,'Daily KPI'!$O:$O,0) -> 0.99866903 | E21: =-(C21-D21)/C21 -> 0.003687464
B22: PA MTD | C22: =_xlfn.XLOOKUP($B$2,'Modelling New'!$D:$D,'Modelling New'!$AE:$AE) -> 0.995 | D22: =Monthly_KPI!N4 -> 0.99739878 | E22: =-(C22-D22)/C22 -> 0.002410832
B23: PA YTD | C23: =_xlfn.XLOOKUP($B$2,'Modelling New'!$D:$D,'Modelling New'!$AE:$AE) -> 0.995 | D23: =Annual_KPI!N4 -> 0.98911738 | E23: =-(C23-D23)/C23 -> -0.0059121859
A24: 6 | B24: GA Daily | C24: =_xlfn.XLOOKUP($B$3,'Daily KPI'!$A:$A,'Daily KPI'!$AH:$AH) -> 0.995 | D24: =_xlfn.XLOOKUP($B$3,'Daily KPI'!$A:$A,'Daily KPI'!$R:$R,0) -> 1 | E24: =-(C24-D24)/C24 -> 0.0050251256
B25: GA MTD | C25: =_xlfn.XLOOKUP($B$2,'Modelling New'!$D:$D,'Modelling New'!$AF:$AF) -> 0.995 | D25: =Monthly_KPI!L4 -> 1 | E25: =-(C25-D25)/C25 -> 0.0050251256
B26: GA YTD | C26: =_xlfn.XLOOKUP($B$2,'Modelling New'!$D:$D,'Modelling New'!$AF:$AF) -> 0.995 | D26: =Annual_KPI!L4 -> 1 | E26: =-(C26-D26)/C26 -> 0.0050251256

Sheet Annual_KPI
A1: Till Date | B1: =Dashboard!B3 -> 45861 | C1: =Dashboard!B2 -> 45839
A2: JPPL 50 MW Performance Summary-YTD
A3: Year | B3: Days | C3: Estimated POA(KWh/m2) | D3: Measured POA (KWh/m2) | E3: Budgeted Energy (MWh) | F3: Measured Energy (MWh) | G3: Targt PR (%) | H3: Measured PR(%) | I3: Target DC CUF (%) | J3: Measured DC CUF (%) | K3: Target GA (%) | L3: Measured GA (%) | M3: Target PA (%) | N3: Measured PA (%) | O3: WPR_Eac | P3: WPR_Edc
A4: =YEAR($B$1)+IF(MONTH($B$1)>=4,1,0) -> 2026 | B4: =($B$1-Dashboard!$B$5)+1 -> 114 | C4: =_xlfn.XLOOKUP($C$1,'Modelling New'!$D:$D,'Modelling New'!$S:$S,0) -> 655.56129 | D4: =IFERROR(SUMIFS('Daily KPI'!$I:$I,'Daily KPI'!$B:$B,$A$4),"") -> 620.20025 | E4: =_xlfn.XLOOKUP($C$1,'Modelling New'!$D:$D,'Modelling New'!$V:$V,0) -> 33310.432 | F4: =IFERROR(SUMIFS('Daily KPI'!$AA:$AA,'Daily KPI'!$B:$B,$A$4)/1000,"") -> 31524.436 | G4: =IFERROR(E4/C4/'Modelling New'!$AQ$1,"") -> 0.76117263 | H4: =IFERROR(F4/D4/'Modelling New'!$AQ$1,"") -> 0.76143282 | I4: =IFERROR(E4/(B4*24*'Modelling New'!$AQ$1),"") -> 0.18238133 | J4: =IFERROR(F4/(B4*24*'Modelling New'!$AQ$1),"") -> 0.17260264 | K4: =_xlfn.XLOOKUP($C$1,'Modelling New'!$D:$D,'Modelling New'!$AF:$AF) -> 0.995 | L4: =IFERROR(AVERAGEIFS('Daily KPI'!$R:$R,'Daily KPI'!$B:$B,$A4),"") -> 1 | M4: =_xlfn.XLOOKUP($C$1,'Modelling New'!$D:$D,'Modelling New'!$AE:$AE) -> 0.995 | N4: =IFERROR(AVERAGEIFS('Daily KPI'!$O:$O,'Daily KPI'!$B:$B,$A4,'Daily KPI'!$A:$A,"<="&$B$1),"") -> 0.98911738 | O4: =SUMIFS(Raw_Data!$KO:$KO,Raw_Data!$C:$C,$A$4,Raw_Data!$B:$B,"<="&$B$1,Raw_Data!$B:$B,">="&Dashboard!$B$5)/1000 -> 0 | P4: =SUMIFS(Raw_Data!$KP:$KP,Raw_Data!$C:$C,$A$4,Raw_Data!$B:$B,"<="&$B$1,Raw_Data!$B:$B,">="&Dashboard!$B$5)/1000 -> 0
A7: JPPL 50 MW Performance Summary-Monthwise
A9: Year | B9: Days | C9: Estimated POA(KWh/m2) | D9: Measured POA (KWh/m2) | E9: Budgeted Energy (MWh) | F9: Measured Energy (MWh) | G9: Targt PR (%) | H9: Measured PR(%) | I9: Target DC CUF (%) | J9: Measured DC CUF (%) | K9: Target GA (%) | L9: Measured GA (%) | M9: Target PA (%) | N9: Measured PA (%) | O9: WPR_Eac | P9: WPR_Edc
A10: 45748 | B10: =_xlfn.XLOOKUP($A10,'Modelling New'!$D:$D,'Modelling New'!$Q:$Q) -> 30 | C10: =_xlfn.XLOOKUP($A10,'Modelling New'!$D:$D,'Modelling New'!$R:$R) -> 206.6 | D10: =SUMIF('Daily KPI'!$D:$D,$A10,'Daily KPI'!$I:$I) -> 181.39025 | E10: =_xlfn.XLOOKUP($A10,'Modelling New'!$D:$D,'Modelling New'!$U:$U) -> 10495.263 | F10: =SUMIF('Daily KPI'!$D:$D,A10,'Daily KPI'!$AA:$AA)/1000 -> 9324.465 | G10: =IFERROR(E10/C10/'Modelling New'!$AQ$1,"") -> 0.76099043 | H10: =IFERROR(F10/D10/'Modelling New'!$AQ$1,"") -> 0.77006287 | I10: =IFERROR(E10/(B10*24*'Modelling New'!$AQ$1),"") -> 0.21836198 | J10: =IFERROR(F10/(B10*24*'Modelling New'!$AQ$1),"") -> 0.19400263 | K10: =_xlfn.XLOOKUP($A10,'Modelling New'!$D:$D,'Modelling New'!$AF:$AF) -> 0.995 | L10: =IFERROR(AVERAGEIF('Daily KPI'!$D:$D,$A10,'Daily KPI'!$R:$R),"") -> 1 | M10: =_xlfn.XLOOKUP($A10,'Modelling New'!$D:$D,'Modelling New'!$AE:$AE) -> 0.995 | N10: =IFERROR(AVERAGEIF('Daily KPI'!$D:$D,$A10,'Daily KPI'!$O:$O),"") -> 0.99686749 | O10: =SUMIF(RD[Month Year],A10,RD[WPR_Eac])/1000 -> 0 | P10: =SUMIF(RD[Month Year],A10,RD[WPR_Edc])/1000 -> 0
A11: 45778 | B11: =_xlfn.XLOOKUP($A11,'Modelling New'!$D:$D,'Modelling New'!$Q:$Q) -> 31 | C11: =_xlfn.XLOOKUP($A11,'Modelling New'!$D:$D,'Modelling New'!$R:$R) -> 191.7 | D11: =SUMIF('Daily KPI'!$D:$D,$A11,'Daily KPI'!$I:$I) -> 182.72 | E11: =_xlfn.XLOOKUP($A11,'Modelling New'!$D:$D,'Modelling New'!$U:$U) -> 9688.8168 | F11: =SUMIF('Daily KPI'!$D:$D,A11,'Daily KPI'!$AA:$AA)/1000 -> 8998.9708 | G11: =IFERROR(E11/C11/'Modelling New'!$AQ$1,"") -> 0.7571202 | H11: =IFERROR(F11/D11/'Modelling New'!$AQ$1,"") -> 0.73777333 | I11: =IFERROR(E11/(B11*24*'Modelling New'!$AQ$1),"") -> 0.19508057 | J11: =IFERROR(F11/(B11*24*'Modelling New'!$AQ$1),"") -> 0.18119078 | K11: =_xlfn.XLOOKUP($A11,'Modelling New'!$D:$D,'Modelling New'!$AF:$AF) -> 0.995 | L11: =IFERROR(AVERAGEIF('Daily KPI'!$D:$D,$A11,'Daily KPI'!$R:$R),"") -> 1 | M11: =_xlfn.XLOOKUP($A11,'Modelling New'!$D:$D,'Modelling New'!$AE:$AE) -> 0.995 | N11: =IFERROR(AVERAGEIF('Daily KPI'!$D:$D,$A11,'Daily KPI'!$O:$O),"") -> 0.97376066 | O11: =SUMIF(RD[Month Year],A11,RD[WPR_Eac])/1000 -> 0 | P11: =SUMIF(RD[Month Year],A11,RD[WPR_Edc])/1000 -> 0
A12: 45809 | B12: =_xlfn.XLOOKUP($A12,'Modelling New'!$D:$D,'Modelling New'!$Q:$Q) -> 30 | C12: =_xlfn.XLOOKUP($A12,'Modelling New'!$D:$D,'Modelling New'!$R:$R) -> 157.1 | D12: =SUMIF('Daily KPI'!$D:$D,$A12,'Daily KPI'!$I:$I) -> 160 | E12: =_xlfn.XLOOKUP($A12,'Modelling New'!$D:$D,'Modelling New'!$U:$U) -> 7971.775 | F12: =SUMIF('Daily KPI'!$D:$D,A12,'Daily KPI'!$AA:$AA)/1000 -> 8219.9827 | G12: =IFERROR(E12/C12/'Modelling New'!$AQ$1,"") -> 0.76014256 | H12: =IFERROR(F12/D12/'Modelling New'!$AQ$1,"") -> 0.76960366 | I12: =IFERROR(E12/(B12*24*'Modelling New'!$AQ$1),"") -> 0.16585888 | J12: =IFERROR(F12/(B12*24*'Modelling New'!$AQ$1),"") -> 0.17102303 | K12: =_xlfn.XLOOKUP($A12,'Modelling New'!$D:$D,'Modelling New'!$AF:$AF) -> 0.995 | L12: =IFERROR(AVERAGEIF('Daily KPI'!$D:$D,$A12,'Daily KPI'!$R:$R),"") -> 1 | M12: =_xlfn.XLOOKUP($A12,'Modelling New'!$D:$D,'Modelling New'!$AE:$AE) -> 0.995 | N12: =IFERROR(AVERAGEIF('Daily KPI'!$D:$D,$A12,'Daily KPI'!$O:$O),"") -> 0.99088679 | O12: =SUMIF(RD[Month Year],A12,RD[WPR_Eac])/1000 -> 0 | P12: =SUMIF(RD[Month Year],A12,RD[WPR_Edc])/1000 -> 0
A13: 45839 | B13: =_xlfn.XLOOKUP($A13,'Modelling New'!$D:$D,'Modelling New'!$Q:$Q) -> 23 | C13: =_xlfn.XLOOKUP($A13,'Modelling New'!$D:$D,'Modelling New'!$R:$R) -> 100.16129 | D13: =SUMIF('Daily KPI'!$D:$D,$A13,'Daily KPI'!$I:$I) -> 96.09 | E13: =_xlfn.XLOOKUP($A13,'Modelling New'!$D:$D,'Modelling New'!$U:$U) -> 5154.5775 | F13: =SUMIF('Daily KPI'!$D:$D,A13,'Daily KPI'!$AA:$AA)/1000 -> 4981.0177 | G13: =IFERROR(E13/C13/'Modelling New'!$AQ$1,"") -> 0.77092009 | H13: =IFERROR(F13/D13/'Modelling New'!$AQ$1,"") -> 0.77652616 | I13: =IFERROR(E13/(B13*24*'Modelling New'!$AQ$1),"") -> 0.13988469 | J13: =IFERROR(F13/(B13*24*'Modelling New'!$AQ$1),"") -> 0.13517464 | K13: =_xlfn.XLOOKUP($A13,'Modelling New'!$D:$D,'Modelling New'!$AF:$AF) -> 0.995 | L13: =IFERROR(AVERAGEIF('Daily KPI'!$D:$D,$A13,'Daily KPI'!$R:$R),"") -> 1 | M13: =_xlfn.XLOOKUP($A13,'Modelling New'!$D:$D,'Modelling New'!$AE:$AE) -> 0.995 | N13: =IFERROR(AVERAGEIF('Daily KPI'!$D:$D,$A13,'Daily KPI'!$O:$O),"") -> 0.99739878 | O13: =SUMIF(RD[Month Year],A13,RD[WPR_Eac])/1000 -> 0 | P13: =SUMIF(RD[Month Year],A13,RD[WPR_Edc])/1000 -> 0
A14: 45870 | B14: =_xlfn.XLOOKUP($A14,'Modelling New'!$D:$D,'Modelling New'!$Q:$Q) -> 0 | C14: =_xlfn.XLOOKUP($A14,'Modelling New'!$D:$D,'Modelling New'!$R:$R) -> 0 | D14: =SUMIF('Daily KPI'!$D:$D,$A14,'Daily KPI'!$I:$I) -> 0 | E14: =_xlfn.XLOOKUP($A14,'Modelling New'!$D:$D,'Modelling New'!$U:$U) -> 0 | F14: =SUMIF('Daily KPI'!$D:$D,A14,'Daily KPI'!$AA:$AA)/1000 -> 0 | G14: =IFERROR(E14/C14/'Modelling New'!$AQ$1,"") | H14: =IFERROR(F14/D14/'Modelling New'!$AQ$1,"") | I14: =IFERROR(E14/(B14*24*'Modelling New'!$AQ$1),"") | J14: =IFERROR(F14/(B14*24*'Modelling New'!$AQ$1),"") | K14: =_xlfn.XLOOKUP($A14,'Modelling New'!$D:$D,'Modelling New'!$AF:$AF) -> 0.995 | L14: =IFERROR(AVERAGEIF('Daily KPI'!$D:$D,$A14,'Daily KPI'!$R:$R),"") | M14: =_xlfn.XLOOKUP($A14,'Modelling New'!$D:$D,'Modelling New'!$AE:$AE) -> 0.995 | N14: =IFERROR(AVERAGEIF('Daily KPI'!$D:$D,$A14,'Daily KPI'!$O:$O),"") | O14: =SUMIF(RD[Month Year],A14,RD[WPR_Eac])/1000 -> 0 | P14: =SUMIF(RD[Month Year],A14,RD[WPR_Edc])/1000 -> 0
A15: 45901 | B15: =_xlfn.XLOOKUP($A15,'Modelling New'!$D:$D,'Modelling New'!$Q:$Q) -> 0 | C15: =_xlfn.XLOOKUP($A15,'Modelling New'!$D:$D,'Modelling New'!$R:$R) -> 0 | D15: =SUMIF('Daily KPI'!$D:$D,$A15,'Daily KPI'!$I:$I) -> 0 | E15: =_xlfn.XLOOKUP($A15,'Modelling New'!$D:$D,'Modelling New'!$U:$U) -> 0 | F15: =SUMIF('Daily KPI'!$D:$D,A15,'Daily KPI'!$AA:$AA)/1000 -> 0 | G15: =IFERROR(E15/C15/'Modelling New'!$AQ$1,"") | H15: =IFERROR(F15/D15/'Modelling New'!$AQ$1,"") | I15: =IFERROR(E15/(B15*24*'Modelling New'!$AQ$1),"") | J15: =IFERROR(F15/(B15*24*'Modelling New'!$AQ$1),"") | K15: =_xlfn.XLOOKUP($A15,'Modelling New'!$D:$D,'Modelling New'!$AF:$AF) -> 0.995 | L15: =IFERROR(AVERAGEIF('Daily KPI'!$D:$D,$A15,'Daily KPI'!$R:$R),"") | M15: =_xlfn.XLOOKUP($A15,'Modelling New'!$D:$D,'Modelling New'!$AE:$AE) -> 0.995 | N15: =IFERROR(AVERAGEIF('Daily KPI'!$D:$D,$A15,'Daily KPI'!$O:$O),"") | O15: =SUMIF(RD[Month Year],A15,RD[WPR_Eac])/1000 -> 0 | P15: =SUMIF(RD[Month Year],A15,RD[WPR_Edc])/1000 -> 0
A16: 45931 | B16: =_xlfn.XLOOKUP($A16,'Modelling New'!$D:$D,'Modelling New'!$Q:$Q) -> 0 | C16: =_xlfn.XLOOKUP($A16,'Modelling New'!$D:$D,'Modelling New'!$R:$R) -> 0 | D16: =SUMIF('Daily KPI'!$D:$D,$A16,'Daily KPI'!$I:$I) -> 0 | E16: =_xlfn.XLOOKUP($A16,'Modelling New'!$D:$D,'Modelling New'!$U:$U) -> 0 | F16: =SUMIF('Daily KPI'!$D:$D,A16,'Daily KPI'!$AA:$AA)/1000 -> 0 | G16: =IFERROR(E16/C16/'Modelling New'!$AQ$1,"") | H16: =IFERROR(F16/D16/'Modelling New'!$AQ$1,"") | I16: =IFERROR(E16/(B16*24*'Modelling New'!$AQ$1),"") | J16: =IFERROR(F16/(B16*24*'Modelling New'!$AQ$1),"") | K16: =_xlfn.XLOOKUP($A16,'Modelling New'!$D:$D,'Modelling New'!$AF:$AF) -> 0.995 | L16: =IFERROR(AVERAGEIF('Daily KPI'!$D:$D,$A16,'Daily KPI'!$R:$R),"") | M16: =_xlfn.XLOOKUP($A16,'Modelling New'!$D:$D,'Modelling New'!$AE:$AE) -> 0.995 | N16: =IFERROR(AVERAGEIF('Daily KPI'!$D:$D,$A16,'Daily KPI'!$O:$O),"") | O16: =SUMIF(RD[Month Year],A16,RD[WPR_Eac])/1000 -> 0 | P16: =SUMIF(RD[Month Year],A16,RD[WPR_Edc])/1000 -> 0
A17: 45962 | B17: =_xlfn.XLOOKUP($A17,'Modelling New'!$D:$D,'Modelling New'!$Q:$Q) -> 0 | C17: =_xlfn.XLOOKUP($A17,'Modelling New'!$D:$D,'Modelling New'!$R:$R) -> 0 | D17: =SUMIF('Daily KPI'!$D:$D,$A17,'Daily KPI'!$I:$I) -> 0 | E17: =_xlfn.XLOOKUP($A17,'Modelling New'!$D:$D,'Modelling New'!$U:$U) -> 0 | F17: =SUMIF('Daily KPI'!$D:$D,A17,'Daily KPI'!$AA:$AA)/1000 -> 0 | G17: =IFERROR(E17/C17/'Modelling New'!$AQ$1,"") | H17: =IFERROR(F17/D17/'Modelling New'!$AQ$1,"") | I17: =IFERROR(E17/(B17*24*'Modelling New'!$AQ$1),"") | J17: =IFERROR(F17/(B17*24*'Modelling New'!$AQ$1),"") | K17: =_xlfn.XLOOKUP($A17,'Modelling New'!$D:$D,'Modelling New'!$AF:$AF) -> 0.995 | L17: =IFERROR(AVERAGEIF('Daily KPI'!$D:$D,$A17,'Daily KPI'!$R:$R),"") | M17: =_xlfn.XLOOKUP($A17,'Modelling New'!$D:$D,'Modelling New'!$AE:$AE) -> 0.995 | N17: =IFERROR(AVERAGEIF('Daily KPI'!$D:$D,$A17,'Daily KPI'!$O:$O),"") | O17: =SUMIF(RD[Month Year],A17,RD[WPR_Eac])/1000 -> 0 | P17: =SUMIF(RD[Month Year],A17,RD[WPR_Edc])/1000 -> 0
A18: 45992 | B18: =_xlfn.XLOOKUP($A18,'Modelling New'!$D:$D,'Modelling New'!$Q:$Q) -> 0 | C18: =_xlfn.XLOOKUP($A18,'Modelling New'!$D:$D,'Modelling New'!$R:$R) -> 0 | D18: =SUMIF('Daily KPI'!$D:$D,$A18,'Daily KPI'!$I:$I) -> 0 | E18: =_xlfn.XLOOKUP($A18,'Modelling New'!$D:$D,'Modelling New'!$U:$U) -> 0 | F18: =SUMIF('Daily KPI'!$D:$D,A18,'Daily KPI'!$AA:$AA)/1000 -> 0 | G18: =IFERROR(E18/C18/'Modelling New'!$AQ$1,"") | H18: =IFERROR(F18/D18/'Modelling New'!$AQ$1,"") | I18: =IFERROR(E18/(B18*24*'Modelling New'!$AQ$1),"") | J18: =IFERROR(F18/(B18*24*'Modelling New'!$AQ$1),"") | K18: =_xlfn.XLOOKUP($A18,'Modelling New'!$D:$D,'Modelling New'!$AF:$AF) -> 0.995 | L18: =IFERROR(AVERAGEIF('Daily KPI'!$D:$D,$A18,'Daily KPI'!$R:$R),"") | M18: =_xlfn.XLOOKUP($A18,'Modelling New'!$D:$D,'Modelling New'!$AE:$AE) -> 0.995 | N18: =IFERROR(AVERAGEIF('Daily KPI'!$D:$D,$A18,'Daily KPI'!$O:$O),"") | O18: =SUMIF(RD[Month Year],A18,RD[WPR_Eac])/1000 -> 0 | P18: =SUMIF(RD[Month Year],A18,RD[WPR_Edc])/1000 -> 0
A19: 46023 | B19: =_xlfn.XLOOKUP($A19,'Modelling New'!$D:$D,'Modelling New'!$Q:$Q) -> 0 | C19: =_xlfn.XLOOKUP($A19,'Modelling New'!$D:$D,'Modelling New'!$R:$R) -> 0 | D19: =SUMIF('Daily KPI'!$D:$D,$A19,'Daily KPI'!$I:$I) -> 0 | E19: =_xlfn.XLOOKUP($A19,'Modelling New'!$D:$D,'Modelling New'!$U:$U) -> 0 | F19: =SUMIF('Daily KPI'!$D:$D,A19,'Daily KPI'!$AA:$AA)/1000 -> 0 | G19: =IFERROR(E19/C19/'Modelling New'!$AQ$1,"") | H19: =IFERROR(F19/D19/'Modelling New'!$AQ$1,"") | I19: =IFERROR(E19/(B19*24*'Modelling New'!$AQ$1),"") | J19: =IFERROR(F19/(B19*24*'Modelling New'!$AQ$1),"") | K19: =_xlfn.XLOOKUP($A19,'Modelling New'!$D:$D,'Modelling New'!$AF:$AF) -> 0.995 | L19: =IFERROR(AVERAGEIF('Daily KPI'!$D:$D,$A19,'Daily KPI'!$R:$R),"") | M19: =_xlfn.XLOOKUP($A19,'Modelling New'!$D:$D,'Modelling New'!$AE:$AE) -> 0.995 | N19: =IFERROR(AVERAGEIF('Daily KPI'!$D:$D,$A19,'Daily KPI'!$O:$O),"") | O19: =SUMIF(RD[Month Year],A19,RD[WPR_Eac])/1000 -> 0 | P19: =SUMIF(RD[Month Year],A19,RD[WPR_Edc])/1000 -> 0
A20: 46054 | B20: =_xlfn.XLOOKUP($A20,'Modelling New'!$D:$D,'Modelling New'!$Q:$Q) -> 0 | C20: =_xlfn.XLOOKUP($A20,'Modelling New'!$D:$D,'Modelling New'!$R:$R) -> 0 | D20: =SUMIF('Daily KPI'!$D:$D,$A20,'Daily KPI'!$I:$I) -> 0 | E20: =_xlfn.XLOOKUP($A20,'Modelling New'!$D:$D,'Modelling New'!$U:$U) -> 0 | F20: =SUMIF('Daily KPI'!$D:$D,A20,'Daily KPI'!$AA:$AA)/1000 -> 0 | G20: =IFERROR(E20/C20/'Modelling New'!$AQ$1,"") | H20: =IFERROR(F20/D20/'Modelling New'!$AQ$1,"") | I20: =IFERROR(E20/(B20*24*'Modelling New'!$AQ$1),"") | J20: =IFERROR(F20/(B20*24*'Modelling New'!$AQ$1),"") | K20: =_xlfn.XLOOKUP($A20,'Modelling New'!$D:$D,'Modelling New'!$AF:$AF) -> 0.995 | L20: =IFERROR(AVERAGEIF('Daily KPI'!$D:$D,$A20,'Daily KPI'!$R:$R),"") | M20: =_xlfn.XLOOKUP($A20,'Modelling New'!$D:$D,'Modelling New'!$AE:$AE) -> 0.995 | N20: =IFERROR(AVERAGEIF('Daily KPI'!$D:$D,$A20,'Daily KPI'!$O:$O),"") | O20: =SUMIF(RD[Month Year],A20,RD[WPR_Eac])/1000 -> 0 | P20: =SUMIF(RD[Month Year],A20,RD[WPR_Edc])/1000 -> 0
A21: 46082 | B21: =_xlfn.XLOOKUP($A21,'Modelling New'!$D:$D,'Modelling New'!$Q:$Q) -> 0 | C21: =_xlfn.XLOOKUP($A21,'Modelling New'!$D:$D,'Modelling New'!$R:$R) -> 0 | D21: =SUMIF('Daily KPI'!$D:$D,$A21,'Daily KPI'!$I:$I) -> 0 | E21: =_xlfn.XLOOKUP($A21,'Modelling New'!$D:$D,'Modelling New'!$U:$U) -> 0 | F21: =SUMIF('Daily KPI'!$D:$D,A21,'Daily KPI'!$AA:$AA)/1000 -> 0 | G21: =IFERROR(E21/C21/'Modelling New'!$AQ$1,"") | H21: =IFERROR(F21/D21/'Modelling New'!$AQ$1,"") | I21: =IFERROR(E21/(B21*24*'Modelling New'!$AQ$1),"") | J21: =IFERROR(F21/(B21*24*'Modelling New'!$AQ$1),"") | K21: =_xlfn.XLOOKUP($A21,'Modelling New'!$D:$D,'Modelling New'!$AF:$AF) -> 0.995 | L21: =IFERROR(AVERAGEIF('Daily KPI'!$D:$D,$A21,'Daily KPI'!$R:$R),"") | M21: =_xlfn.XLOOKUP($A21,'Modelling New'!$D:$D,'Modelling New'!$AE:$AE) -> 0.995 | N21: =IFERROR(AVERAGEIF('Daily KPI'!$D:$D,$A21,'Daily KPI'!$O:$O),"") | O21: =SUMIF(RD[Month Year],A21,RD[WPR_Eac])/1000 -> 0 | P21: =SUMIF(RD[Month Year],A21,RD[WPR_Edc])/1000 -> 0

Sheet Monthly_KPI
A1: Till Date | B1: =Dashboard!B3 -> 45861
A2: JPPL 50 MW Performance Summary
A3: Year | B3: Days | C3: Estimated POA(KWh/m2) | D3: Measured POA (KWh/m2) | E3: Budgeted Energy (MWh) | F3: Measured Energy (MWh) | G3: Targt PR (%) | H3: Measured PR(%) | I3: Target DC CUF (%) | J3: Measured DC CUF (%) | K3: Target GA (%) | L3: Measured GA (%) | M3: Target PA (%) | N3: Measured PA (%) | O3: WPR_Eac | P3: WPR_Edc
A4: =Dashboard!B2 -> 45839 | B4: =DAY(B1) -> 23 | C4: =_xlfn.XLOOKUP($A$4,'Modelling New'!$D:$D,'Modelling New'!$R:$R,0) -> 100.16129 | D4: =SUMIF('Daily KPI'!$D:$D,$A4,'Daily KPI'!$I:$I) -> 96.09 | E4: =_xlfn.XLOOKUP($A$4,'Modelling New'!$D:$D,'Modelling New'!$U:$U,0) -> 5154.5775 | F4: =SUMIF('Daily KPI'!$D:$D,$A4,'Daily KPI'!$AA:$AA)/1000 -> 4981.0177 | G4: =IFERROR(E4/C4/'Modelling New'!$AQ$1,"") -> 0.77092009 | H4: =IFERROR(F4/D4/'Modelling New'!$AQ$1,"") -> 0.77652616 | I4: =IFERROR(E4/(B4*24*'Modelling New'!$AQ$1),"") -> 0.13988469 | J4: =IFERROR(F4/(B4*24*'Modelling New'!$AQ$1),"") -> 0.13517464 | K4: =_xlfn.XLOOKUP($A$4,'Modelling New'!$D:$D,'Modelling New'!$AF:$AF) -> 0.995 | L4: =IFERROR(AVERAGEIF('Daily KPI'!$D:$D,$A4,'Daily KPI'!$R:$R),"") -> 1 | M4: =_xlfn.XLOOKUP($A$4,'Modelling New'!$D:$D,'Modelling New'!$AE:$AE) -> 0.995 | N4: =IFERROR(AVERAGEIF('Daily KPI'!$D:$D,$A4,'Daily KPI'!$O:$O),"") -> 0.99739878 | O4: =SUMIF(RD[Month Year],$A4,RD[WPR_Eac]) -> 0 | P4: =SUMIF(RD[Month Year],$A4,RD[WPR_Edc]) -> 0
A7: Start Date | B7: =B8-6 -> 45855
A8: End Date | B8: =B1 -> 45861
A9: JPPL50 MW Performance Summary
A10: Year | B10: Days | C10: Estimated POA(KWh/m2) | D10: Measured POA (KWh/m2) | E10: Budgeted Energy (MWh) | F10: Measured Energy (MWh) | G10: Targt PR (%) | H10: Measured PR(%) | I10: Target DC CUF (%) | J10: Measured DC CUF (%) | K10: Target GA (%) | L10: Measured GA (%) | M10: Target PA (%) | N10: Measured PA (%) | O10: WPR_Eac | P10: WPR_Edc
A11: =A4 -> 45839 | B11: =(B8-B7)+1 -> 7 | C11: =IFERROR(SUMIFS('Daily KPI'!$AC:$AC,'Daily KPI'!$A:$A,">="&$B$7,'Daily KPI'!$A:$A,"<="&$B$8),"") -> 30.483871 | D11: =SUMIFS('Daily KPI'!$I:$I,'Daily KPI'!$A:$A,">="&$B$7,'Daily KPI'!$A:$A,"<="&$B$8) -> 28.27 | E11: =IFERROR(SUMIFS('Daily KPI'!$AD:$AD,'Daily KPI'!$A:$A,">="&$B$7,'Daily KPI'!$A:$A,"<="&$B$8),"")/1000 -> 1568.7845 | F11: =SUMIFS('Daily KPI'!$AA:$AA,'Daily KPI'!$A:$A,">="&$B$7,'Daily KPI'!$A:$A,"<="&$B$8)/1000 -> 1475.4415 | G11: =IFERROR(E11/C11/'Modelling New'!$AQ$1,"") -> 0.77092009 | H11: =IFERROR(F11/D11/'Modelling New'!$AQ$1,"") -> 0.78183007 | I11: =IFERROR(E11/($B$11*24*'Modelling New'!$AQ$1),"") -> 0.13988469 | J11: =IFERROR(F11/($B$11*24*'Modelling New'!$AQ$1),"") -> 0.13156153 | K11: =_xlfn.XLOOKUP($A$11,'Modelling New'!$D:$D,'Modelling New'!$AF:$AF) -> 0.995 | L11: =AVERAGEIFS('Daily KPI'!$R:$R,'Daily KPI'!$A:$A,">="&$B$7,'Daily KPI'!$A:$A,"<="&$B$8) -> 1 | M11: =_xlfn.XLOOKUP($A$11,'Modelling New'!$D:$D,'Modelling New'!$AE:$AE) -> 0.995 | N11: =AVERAGEIFS('Daily KPI'!$O:$O,'Daily KPI'!$A:$A,">="&$B$7,'Daily KPI'!$A:$A,"<="&$B$8) -> 0.99883132 | O11: =SUMIFS(RD[WPR_Eac],RD[Date],">="&$B$7,RD[Date],"<="&$B$8) -> 0 | P11: =SUMIFS(RD[WPR_Edc],RD[Date],">="&$B$7,RD[Date],"<="&$B$8) -> 0

Sheet Grass_Ct
A2: Sr. No. | B2: Date | C2: Finacial Year | D2: Calendor Year | E2: Contrcatual Year | F2: Operating Year | G2: Month Year | H2: Days | I2: Cycle Number | J2: Resources | K2: Blk1 | L2: Blk2 | M2: Blk3 | N2: Blk4 | O2: Blk5 | P2: Blk6 | Q2: Blk7 | R2: Blk8 | S2: Total No.Table GC done | T2: Mrthod of Cutting | U2: Remarks for the day
A3: 1 | B3: 45200 | C3: =YEAR(GC[[#This Row],[Date]])+IF(MONTH(GC[[#This Row],[Date]])>=4,1,0) -> 2024 | D3: =YEAR(GC[[#This Row],[Date]]) -> 2023 | E3: Year_2 | F3: Year_2 | G3: =TEXT(GC[[#This Row],[Date]],"mmm-yy") -> Oct-23 | H3: =DAY(EOMONTH(GC[[#This Row],[Month Year]],0)) -> 31 | S3: =SUM(GC[[#This Row],[Blk1]:[Blk8]]) -> 0 | T3: =PROPER(GC[[#This Row],[Resources]])
A4: 2 | B4: =B3+1 -> 45201 | C4: =YEAR(GC[[#This Row],[Date]])+IF(MONTH(GC[[#This Row],[Date]])>=4,1,0) -> 2024 | D4: =YEAR(GC[[#This Row],[Date]]) -> 2023 | E4: Year_2 | F4: Year_2 | G4: =TEXT(GC[[#This Row],[Date]],"mmm-yy") -> Oct-23 | H4: =DAY(EOMONTH(GC[[#This Row],[Month Year]],0)) -> 31 | S4: =SUM(GC[[#This Row],[Blk1]:[Blk8]]) -> 0 | T4: =PROPER(GC[[#This Row],[Resources]])
A5: 3 | B5: =B4+1 -> 45202 | C5: =YEAR(GC[[#This Row],[Date]])+IF(MONTH(GC[[#This Row],[Date]])>=4,1,0) -> 2024 | D5: =YEAR(GC[[#This Row],[Date]]) -> 2023 | E5: Year_2 | F5: Year_2 | G5: =TEXT(GC[[#This Row],[Date]],"mmm-yy") -> Oct-23 | H5: =DAY(EOMONTH(GC[[#This Row],[Month Year]],0)) -> 31 | S5: =SUM(GC[[#This Row],[Blk1]:[Blk8]]) -> 0 | T5: =PROPER(GC[[#This Row],[Resources]])
A6: 4 | B6: =B5+1 -> 45203 | C6: =YEAR(GC[[#This Row],[Date]])+IF(MONTH(GC[[#This Row],[Date]])>=4,1,0) -> 2024 | D6: =YEAR(GC[[#This Row],[Date]]) -> 2023 | E6: Year_2 | F6: Year_2 | G6: =TEXT(GC[[#This Row],[Date]],"mmm-yy") -> Oct-23 | H6: =DAY(EOMONTH(GC[[#This Row],[Month Year]],0)) -> 31 | S6: =SUM(GC[[#This Row],[Blk1]:[Blk8]]) -> 0 | T6: =PROPER(GC[[#This Row],[Resources]])
A7: 5 | B7: =B6+1 -> 45204 | C7: =YEAR(GC[[#This Row],[Date]])+IF(MONTH(GC[[#This Row],[Date]])>=4,1,0) -> 2024 | D7: =YEAR(GC[[#This Row],[Date]]) -> 2023 | E7: Year_2 | F7: Year_2 | G7: =TEXT(GC[[#This Row],[Date]],"mmm-yy") -> Oct-23 | H7: =DAY(EOMONTH(GC[[#This Row],[Month Year]],0)) -> 31 | S7: =SUM(GC[[#This Row],[Blk1]:[Blk8]]) -> 0 | T7: =PROPER(GC[[#This Row],[Resources]])
A8: 6 | B8: =B7+1 -> 45205 | C8: =YEAR(GC[[#This Row],[Date]])+IF(MONTH(GC[[#This Row],[Date]])>=4,1,0) -> 2024 | D8: =YEAR(GC[[#This Row],[Date]]) -> 2023 | E8: Year_2 | F8: Year_2 | G8: =TEXT(GC[[#This Row],[Date]],"mmm-yy") -> Oct-23 | H8: =DAY(EOMONTH(GC[[#This Row],[Month Year]],0)) -> 31 | S8: =SUM(GC[[#This Row],[Blk1]:[Blk8]]) -> 0 | T8: =PROPER(GC[[#This Row],[Resources]])
A9: 7 | B9: =B8+1 -> 45206 | C9: =YEAR(GC[[#This Row],[Date]])+IF(MONTH(GC[[#This Row],[Date]])>=4,1,0) -> 2024 | D9: =YEAR(GC[[#This Row],[Date]]) -> 2023 | E9: Year_2 | F9: Year_2 | G9: =TEXT(GC[[#This Row],[Date]],"mmm-yy") -> Oct-23 | H9: =DAY(EOMONTH(GC[[#This Row],[Month Year]],0)) -> 31 | S9: =SUM(GC[[#This Row],[Blk1]:[Blk8]]) -> 0 | T9: =PROPER(GC[[#This Row],[Resources]])
A10: 8 | B10: =B9+1 -> 45207 | C10: =YEAR(GC[[#This Row],[Date]])+IF(MONTH(GC[[#This Row],[Date]])>=4,1,0) -> 2024 | D10: =YEAR(GC[[#This Row],[Date]]) -> 2023 | E10: Year_2 | F10: Year_2 | G10: =TEXT(GC[[#This Row],[Date]],"mmm-yy") -> Oct-23 | H10: =DAY(EOMONTH(GC[[#This Row],[Month Year]],0)) -> 31 | S10: =SUM(GC[[#This Row],[Blk1]:[Blk8]]) -> 0 | T10: =PROPER(GC[[#This Row],[Resources]])
A11: 9 | B11: =B10+1 -> 45208 | C11: =YEAR(GC[[#This Row],[Date]])+IF(MONTH(GC[[#This Row],[Date]])>=4,1,0) -> 2024 | D11: =YEAR(GC[[#This Row],[Date]]) -> 2023 | E11: Year_2 | F11: Year_2 | G11: =TEXT(GC[[#This Row],[Date]],"mmm-yy") -> Oct-23 | H11: =DAY(EOMONTH(GC[[#This Row],[Month Year]],0)) -> 31 | S11: =SUM(GC[[#This Row],[Blk1]:[Blk8]]) -> 0 | T11: =PROPER(GC[[#This Row],[Resources]])
A12: 10 | B12: =B11+1 -> 45209 | C12: =YEAR(GC[[#This Row],[Date]])+IF(MONTH(GC[[#This Row],[Date]])>=4,1,0) -> 2024 | D12: =YEAR(GC[[#This Row],[Date]]) -> 2023 | E12: Year_2 | F12: Year_2 | G12: =TEXT(GC[[#This Row],[Date]],"mmm-yy") -> Oct-23 | H12: =DAY(EOMONTH(GC[[#This Row],[Month Year]],0)) -> 31 | S12: =SUM(GC[[#This Row],[Blk1]:[Blk8]]) -> 0 | T12: =PROPER(GC[[#This Row],[Resources]])
A13: 11 | B13: =B12+1 -> 45210 | C13: =YEAR(GC[[#This Row],[Date]])+IF(MONTH(GC[[#This Row],[Date]])>=4,1,0) -> 2024 | D13: =YEAR(GC[[#This Row],[Date]]) -> 2023 | E13: Year_2 | F13: Year_2 | G13: =TEXT(GC[[#This Row],[Date]],"mmm-yy") -> Oct-23 | H13: =DAY(EOMONTH(GC[[#This Row],[Month Year]],0)) -> 31 | S13: =SUM(GC[[#This Row],[Blk1]:[Blk8]]) -> 0 | T13: =PROPER(GC[[#This Row],[Resources]])
A14: 12 | B14: =B13+1 -> 45211 | C14: =YEAR(GC[[#This Row],[Date]])+IF(MONTH(GC[[#This Row],[Date]])>=4,1,0) -> 2024 | D14: =YEAR(GC[[#This Row],[Date]]) -> 2023 | E14: Year_2 | F14: Year_2 | G14: =TEXT(GC[[#This Row],[Date]],"mmm-yy") -> Oct-23 | H14: =DAY(EOMONTH(GC[[#This Row],[Month Year]],0)) -> 31 | S14: =SUM(GC[[#This Row],[Blk1]:[Blk8]]) -> 0 | T14: =PROPER(GC[[#This Row],[Resources]])
A15: 13 | B15: =B14+1 -> 45212 | C15: =YEAR(GC[[#This Row],[Date]])+IF(MONTH(GC[[#This Row],[Date]])>=4,1,0) -> 2024 | D15: =YEAR(GC[[#This Row],[Date]]) -> 2023 | E15: Year_2 | F15: Year_2 | G15: =TEXT(GC[[#This Row],[Date]],"mmm-yy") -> Oct-23 | H15: =DAY(EOMONTH(GC[[#This Row],[Month Year]],0)) -> 31 | S15: =SUM(GC[[#This Row],[Blk1]:[Blk8]]) -> 0 | T15: =PROPER(GC[[#This Row],[Resources]])
... A155: 153 | B155: =B154+1 -> 45352 | C155: =YEAR(GC[[#This Row],[Date]])+IF(MONTH(GC[[#This Row],[Date]])>=4,1,0) -> 2024 | D155: =YEAR(GC[[#This Row],[Date]]) -> 2024 | E155: Year_2 | F155: Year_2 | G155: =TEXT(GC[[#This Row],[Date]],"mmm-yy") -> Mar-24 | H155: =DAY(EOMONTH(GC[[#This Row],[Month Year]],0)) -> 31 | S155: =SUM(GC[[#This Row],[Blk1]:[Blk8]]) -> 0 | T155: =PROPER(GC[[#This Row],[Resources]])
A156: 154 | B156: =B155+1 -> 45353 | C156: =YEAR(GC[[#This Row],[Date]])+IF(MONTH(GC[[#This Row],[Date]])>=4,1,0) -> 2024 | D156: =YEAR(GC[[#This Row],[Date]]) -> 2024 | E156: Year_2 | F156: Year_2 | G156: =TEXT(GC[[#This Row],[Date]],"mmm-yy") -> Mar-24 | H156: =DAY(EOMONTH(GC[[#This Row],[Month Year]],0)) -> 31 | S156: =SUM(GC[[#This Row],[Blk1]:[Blk8]]) -> 0 | T156: =PROPER(GC[[#This Row],[Resources]]) | U156: Grass cutting in Block 8 by Rotavator
A157: 155 | B157: =B156+1 -> 45354 | C157: =YEAR(GC[[#This Row],[Date]])+IF(MONTH(GC[[#This Row],[Date]])>=4,1,0) -> 2024 | D157: =YEAR(GC[[#This Row],[Date]]) -> 2024 | E157: Year_2 | F157: Year_2 | G157: =TEXT(GC[[#This Row],[Date]],"mmm-yy") -> Mar-24 | H157: =DAY(EOMONTH(GC[[#This Row],[Month Year]],0)) -> 31 | S157: =SUM(GC[[#This Row],[Blk1]:[Blk8]]) -> 0 | T157: =PROPER(GC[[#This Row],[Resources]]) | U157: Grass cutting in Block 8 by Rotavator
A158: 156 | B158: =B157+1 -> 45355 | C158: =YEAR(GC[[#This Row],[Date]])+IF(MONTH(GC[[#This Row],[Date]])>=4,1,0) -> 2024 | D158: =YEAR(GC[[#This Row],[Date]]) -> 2024 | E158: Year_2 | F158: Year_2 | G158: =TEXT(GC[[#This Row],[Date]],"mmm-yy") -> Mar-24 | H158: =DAY(EOMONTH(GC[[#This Row],[Month Year]],0)) -> 31 | S158: =SUM(GC[[#This Row],[Blk1]:[Blk8]]) -> 0 | T158: =PROPER(GC[[#This Row],[Resources]]) | U158: Grass cutting in Block 8 by Rotavator
A159: 157 | B159: =B158+1 -> 45356 | C159: =YEAR(GC[[#This Row],[Date]])+IF(MONTH(GC[[#This Row],[Date]])>=4,1,0) -> 2024 | D159: =YEAR(GC[[#This Row],[Date]]) -> 2024 | E159: Year_2 | F159: Year_2 | G159: =TEXT(GC[[#This Row],[Date]],"mmm-yy") -> Mar-24 | H159: =DAY(EOMONTH(GC[[#This Row],[Month Year]],0)) -> 31 | S159: =SUM(GC[[#This Row],[Blk1]:[Blk8]]) -> 0 | T159: =PROPER(GC[[#This Row],[Resources]]) | U159: Grass cutting in Block 8 by Rotavator
A160: 158 | B160: =B159+1 -> 45357 | C160: =YEAR(GC[[#This Row],[Date]])+IF(MONTH(GC[[#This Row],[Date]])>=4,1,0) -> 2024 | D160: =YEAR(GC[[#This Row],[Date]]) -> 2024 | E160: Year_2 | F160: Year_2 | G160: =TEXT(GC[[#This Row],[Date]],"mmm-yy") -> Mar-24 | H160: =DAY(EOMONTH(GC[[#This Row],[Month Year]],0)) -> 31 | S160: =SUM(GC[[#This Row],[Blk1]:[Blk8]]) -> 0 | T160: =PROPER(GC[[#This Row],[Resources]]) | U160: Grass cutting in Block 8 by Rotavator
A161: 159 | B161: =B160+1 -> 45358 | C161: =YEAR(GC[[#This Row],[Date]])+IF(MONTH(GC[[#This Row],[Date]])>=4,1,0) -> 2024 | D161: =YEAR(GC[[#This Row],[Date]]) -> 2024 | E161: Year_2 | F161: Year_2 | G161: =TEXT(GC[[#This Row],[Date]],"mmm-yy") -> Mar-24 | H161: =DAY(EOMONTH(GC[[#This Row],[Month Year]],0)) -> 31 | S161: =SUM(GC[[#This Row],[Blk1]:[Blk8]]) -> 0 | T161: =PROPER(GC[[#This Row],[Resources]]) | U161: Grass cutting in Block 8 by Rotavator
A162: 160 | B162: =B161+1 -> 45359 | C162: =YEAR(GC[[#This Row],[Date]])+IF(MONTH(GC[[#This Row],[Date]])>=4,1,0) -> 2024 | D162: =YEAR(GC[[#This Row],[Date]]) -> 2024 | E162: Year_2 | F162: Year_2 | G162: =TEXT(GC[[#This Row],[Date]],"mmm-yy") -> Mar-24 | H162: =DAY(EOMONTH(GC[[#This Row],[Month Year]],0)) -> 31 | S162: =SUM(GC[[#This Row],[Blk1]:[Blk8]]) -> 0 | T162: =PROPER(GC[[#This Row],[Resources]])
A163: 161 | B163: =B162+1 -> 45360 | C163: =YEAR(GC[[#This Row],[Date]])+IF(MONTH(GC[[#This Row],[Date]])>=4,1,0) -> 2024 | D163: =YEAR(GC[[#This Row],[Date]]) -> 2024 | E163: Year_2 | F163: Year_2 | G163: =TEXT(GC[[#This Row],[Date]],"mmm-yy") -> Mar-24 | H163: =DAY(EOMONTH(GC[[#This Row],[Month Year]],0)) -> 31 | S163: =SUM(GC[[#This Row],[Blk1]:[Blk8]]) -> 0 | T163: =PROPER(GC[[#This Row],[Resources]])
A164: 162 | B164: =B163+1 -> 45361 | C164: =YEAR(GC[[#This Row],[Date]])+IF(MONTH(GC[[#This Row],[Date]])>=4,1,0) -> 2024 | D164: =YEAR(GC[[#This Row],[Date]]) -> 2024 | E164: Year_2 | F164: Year_2 | G164: =TEXT(GC[[#This Row],[Date]],"mmm-yy") -> Mar-24 | H164: =DAY(EOMONTH(GC[[#This Row],[Month Year]],0)) -> 31 | S164: =SUM(GC[[#This Row],[Blk1]:[Blk8]]) -> 0 | T164: =PROPER(GC[[#This Row],[Resources]])
A165: 163 | B165: =B164+1 -> 45362 | C165: =YEAR(GC[[#This Row],[Date]])+IF(MONTH(GC[[#This Row],[Date]])>=4,1,0) -> 2024 | D165: =YEAR(GC[[#This Row],[Date]]) -> 2024 | E165: Year_2 | F165: Year_2 | G165: =TEXT(GC[[#This Row],[Date]],"mmm-yy") -> Mar-24 | H165: =DAY(EOMONTH(GC[[#This Row],[Month Year]],0)) -> 31 | S165: =SUM(GC[[#This Row],[Blk1]:[Blk8]]) -> 0 | T165: =PROPER(GC[[#This Row],[Resources]])
A166: 164 | B166: =B165+1 -> 45363 | C166: =YEAR(GC[[#This Row],[Date]])+IF(MONTH(GC[[#This Row],[Date]])>=4,1,0) -> 2024 | D166: =YEAR(GC[[#This Row],[Date]]) -> 2024 | E166: Year_2 | F166: Year_2 | G166: =TEXT(GC[[#This Row],[Date]],"mmm-yy") -> Mar-24 | H166: =DAY(EOMONTH(GC[[#This Row],[Month Year]],0)) -> 31 | S166: =SUM(GC[[#This Row],[Blk1]:[Blk8]]) -> 0 | T166: =PROPER(GC[[#This Row],[Resources]])
A167: 165 | B167: =B166+1 -> 45364 | C167: =YEAR(GC[[#This Row],[Date]])+IF(MONTH(GC[[#This Row],[Date]])>=4,1,0) -> 2024 | D167: =YEAR(GC[[#This Row],[Date]]) -> 2024 | E167: Year_2 | F167: Year_2 | G167: =TEXT(GC[[#This Row],[Date]],"mmm-yy") -> Mar-24 | H167: =DAY(EOMONTH(GC[[#This Row],[Month Year]],0)) -> 31 | S167: =SUM(GC[[#This Row],[Blk1]:[Blk8]]) -> 0 | T167: =PROPER(GC[[#This Row],[Resources]])
A168: 166 | B168: =B167+1 -> 45365 | C168: =YEAR(GC[[#This Row],[Date]])+IF(MONTH(GC[[#This Row],[Date]])>=4,1,0) -> 2024 | D168: =YEAR(GC[[#This Row],[Date]]) -> 2024 | E168: Year_2 | F168: Year_2 | G168: =TEXT(GC[[#This Row],[Date]],"mmm-yy") -> Mar-24 | H168: =DAY(EOMONTH(GC[[#This Row],[Month Year]],0)) -> 31 | S168: =SUM(GC[[#This Row],[Blk1]:[Blk8]]) -> 0 | T168: =PROPER(GC[[#This Row],[Resources]])
A169: 167 | B169: =B168+1 -> 45366 | C169: =YEAR(GC[[#This Row],[Date]])+IF(MONTH(GC[[#This Row],[Date]])>=4,1,0) -> 2024 | D169: =YEAR(GC[[#This Row],[Date]]) -> 2024 | E169: Year_2 | F169: Year_2 | G169: =TEXT(GC[[#This Row],[Date]],"mmm-yy") -> Mar-24 | H169: =DAY(EOMONTH(GC[[#This Row],[Month Year]],0)) -> 31 | S169: =SUM(GC[[#This Row],[Blk1]:[Blk8]]) -> 0 | T169: =PROPER(GC[[#This Row],[Resources]])
A170: 168 | B170: =B169+1 -> 45367 | C170: =YEAR(GC[[#This Row],[Date]])+IF(MONTH(GC[[#This Row],[Date]])>=4,1,0) -> 2024 | D170: =YEAR(GC[[#This Row],[Date]]) -> 2024 | E170: Year_2 | F170: Year_2 | G170: =TEXT(GC[[#This Row],[Date]],"mmm-yy") -> Mar-24 | H170: =DAY(EOMONTH(GC[[#This Row],[Month Year]],0)) -> 31 | S170: =SUM(GC[[#This Row],[Blk1]:[Blk8]]) -> 0 | T170: =PROPER(GC[[#This Row],[Resources]])
A171: 169 | B171: =B170+1 -> 45368 | C171: =YEAR(GC[[#This Row],[Date]])+IF(MONTH(GC[[#This Row],[Date]])>=4,1,0) -> 2024 | D171: =YEAR(GC[[#This Row],[Date]]) -> 2024 | E171: Year_2 | F171: Year_2 | G171: =TEXT(GC[[#This Row],[Date]],"mmm-yy") -> Mar-24 | H171: =DAY(EOMONTH(GC[[#This Row],[Month Year]],0)) -> 31 | S171: =SUM(GC[[#This Row],[Blk1]:[Blk8]]) -> 0 | T171: =PROPER(GC[[#This Row],[Resources]])
A172: 170 | B172: =B171+1 -> 45369 | C172: =YEAR(GC[[#This Row],[Date]])+IF(MONTH(GC[[#This Row],[Date]])>=4,1,0) -> 2024 | D172: =YEAR(GC[[#This Row],[Date]]) -> 2024 | E172: Year_2 | F172: Year_2 | G172: =TEXT(GC[[#This Row],[Date]],"mmm-yy") -> Mar-24 | H172: =DAY(EOMONTH(GC[[#This Row],[Month Year]],0)) -> 31 | S172: =SUM(GC[[#This Row],[Blk1]:[Blk8]]) -> 0 | T172: =PROPER(GC[[#This Row],[Resources]])
A173: 171 | B173: =B172+1 -> 45370 | C173: =YEAR(GC[[#This Row],[Date]])+IF(MONTH(GC[[#This Row],[Date]])>=4,1,0) -> 2024 | D173: =YEAR(GC[[#This Row],[Date]]) -> 2024 | E173: Year_2 | F173: Year_2 | G173: =TEXT(GC[[#This Row],[Date]],"mmm-yy") -> Mar-24 | H173: =DAY(EOMONTH(GC[[#This Row],[Month Year]],0)) -> 31 | S173: =SUM(GC[[#This Row],[Blk1]:[Blk8]]) -> 0 | T173: =PROPER(GC[[#This Row],[Resources]])
... A185: 183 | B185: =B184+1 -> 45382 | C185: =YEAR(GC[[#This Row],[Date]])+IF(MONTH(GC[[#This Row],[Date]])>=4,1,0) -> 2024 | D185: =YEAR(GC[[#This Row],[Date]]) -> 2024 | E185: Year_2 | F185: Year_2 | G185: =TEXT(GC[[#This Row],[Date]],"mmm-yy") -> Mar-24 | H185: =DAY(EOMONTH(GC[[#This Row],[Month Year]],0)) -> 31 | S185: =SUM(GC[[#This Row],[Blk1]:[Blk8]]) -> 0 | T185: =PROPER(GC[[#This Row],[Resources]])
A186: 184 | B186: =B185+1 -> 45383 | C186: 2024 | D186: =YEAR(GC[[#This Row],[Date]]) -> 2024 | E186: Year_2 | F186: Year_2 | G186: =TEXT(GC[[#This Row],[Date]],"mmm-yy") -> Apr-24 | H186: =DAY(EOMONTH(GC[[#This Row],[Month Year]],0)) -> 30 | S186: =SUM(GC[[#This Row],[Blk1]:[Blk8]]) -> 0 | T186: =PROPER(GC[[#This Row],[Resources]])
A187: 185 | B187: =B186+1 -> 45384 | C187: 2024 | D187: =YEAR(GC[[#This Row],[Date]]) -> 2024 | E187: Year_2 | F187: Year_2 | G187: =TEXT(GC[[#This Row],[Date]],"mmm-yy") -> Apr-24 | H187: =DAY(EOMONTH(GC[[#This Row],[Month Year]],0)) -> 30 | S187: =SUM(GC[[#This Row],[Blk1]:[Blk8]]) -> 0 | T187: =PROPER(GC[[#This Row],[Resources]])
A188: 186 | B188: =B187+1 -> 45385 | C188: 2024 | D188: =YEAR(GC[[#This Row],[Date]]) -> 2024 | E188: Year_2 | F188: Year_2 | G188: =TEXT(GC[[#This Row],[Date]],"mmm-yy") -> Apr-24 | H188: =DAY(EOMONTH(GC[[#This Row],[Month Year]],0)) -> 30 | S188: =SUM(GC[[#This Row],[Blk1]:[Blk8]]) -> 0 | T188: =PROPER(GC[[#This Row],[Resources]])
A189: 187 | B189: =B188+1 -> 45386 | C189: 2024 | D189: =YEAR(GC[[#This Row],[Date]]) -> 2024 | E189: Year_2 | F189: Year_2 | G189: =TEXT(GC[[#This Row],[Date]],"mmm-yy") -> Apr-24 | H189: =DAY(EOMONTH(GC[[#This Row],[Month Year]],0)) -> 30 | S189: =SUM(GC[[#This Row],[Blk1]:[Blk8]]) -> 0 | T189: =PROPER(GC[[#This Row],[Resources]])
A190: 188 | B190: =B189+1 -> 45387 | C190: 2024 | D190: =YEAR(GC[[#This Row],[Date]]) -> 2024 | E190: Year_2 | F190: Year_2 | G190: =TEXT(GC[[#This Row],[Date]],"mmm-yy") -> Apr-24 | H190: =DAY(EOMONTH(GC[[#This Row],[Month Year]],0)) -> 30 | S190: =SUM(GC[[#This Row],[Blk1]:[Blk8]]) -> 0 | T190: =PROPER(GC[[#This Row],[Resources]])
A191: 189 | B191: =B190+1 -> 45388 | C191: 2024 | D191: =YEAR(GC[[#This Row],[Date]]) -> 2024 | E191: Year_2 | F191: Year_2 | G191: =TEXT(GC[[#This Row],[Date]],"mmm-yy") -> Apr-24 | H191: =DAY(EOMONTH(GC[[#This Row],[Month Year]],0)) -> 30 | S191: =SUM(GC[[#This Row],[Blk1]:[Blk8]]) -> 0 | T191: =PROPER(GC[[#This Row],[Resources]])
...

Sheet Mod_CL
A2: Sr. No. | B2: Date | C2: Finacial Year | D2: Calendor Year | E2: Contrcatual Year | F2: Operating Year | G2: Month Year | H2: Days | I2: Cycle Number | J2: Resources | K2: Blk1 | L2: Blk2 | M2: Blk3 | N2: Blk4 | O2: Blk5 | P2: Blk6 | Q2: Blk7 | R2: Blk8 | S2: Total NO. Module cleaned | T2: Morning Start Time | U2: Morning End Time | V2: Evening Start Time | W2: Evening End time | X2: Brush/MOP Replcemnet | Y2: Water Test Report | Z2: Remarks for the day
A3: 1 | B3: 45200 | C3: =YEAR(MC[[#This Row],[Date]])+IF(MONTH(MC[[#This Row],[Date]])>=4,1,0) -> 2024 | D3: =YEAR(MC[[#This Row],[Date]]) -> 2023 | E3: Year_2 | F3: Year_2 | G3: =TEXT(MC[[#This Row],[Date]],"mmm-yy") -> Oct-23 | H3: =DAY(EOMONTH(MC[[#This Row],[Month Year]],0)) -> 31 | R3: =120*50 -> 6000 | S3: =SUM(MC[[#This Row],[Blk1]:[Blk8]]) -> 6000
A4: 2 | B4: =B3+1 -> 45201 | C4: =YEAR(MC[[#This Row],[Date]])+IF(MONTH(MC[[#This Row],[Date]])>=4,1,0) -> 2024 | D4: =YEAR(MC[[#This Row],[Date]]) -> 2023 | E4: Year_2 | F4: Year_2 | G4: =TEXT(MC[[#This Row],[Date]],"mmm-yy") -> Oct-23 | H4: =DAY(EOMONTH(MC[[#This Row],[Month Year]],0)) -> 31 | R4: =120*50 -> 6000 | S4: =SUM(MC[[#This Row],[Blk1]:[Blk8]]) -> 6000
A5: 3 | B5: =B4+1 -> 45202 | C5: =YEAR(MC[[#This Row],[Date]])+IF(MONTH(MC[[#This Row],[Date]])>=4,1,0) -> 2024 | D5: =YEAR(MC[[#This Row],[Date]]) -> 2023 | E5: Year_2 | F5: Year_2 | G5: =TEXT(MC[[#This Row],[Date]],"mmm-yy") -> Oct-23 | H5: =DAY(EOMONTH(MC[[#This Row],[Month Year]],0)) -> 31 | R5: =120*50 -> 6000 | S5: =SUM(MC[[#This Row],[Blk1]:[Blk8]]) -> 6000
A6: 4 | B6: =B5+1 -> 45203 | C6: =YEAR(MC[[#This Row],[Date]])+IF(MONTH(MC[[#This Row],[Date]])>=4,1,0) -> 2024 | D6: =YEAR(MC[[#This Row],[Date]]) -> 2023 | E6: Year_2 | F6: Year_2 | G6: =TEXT(MC[[#This Row],[Date]],"mmm-yy") -> Oct-23 | H6: =DAY(EOMONTH(MC[[#This Row],[Month Year]],0)) -> 31 | R6: =120*50 -> 6000 | S6: =SUM(MC[[#This Row],[Blk1]:[Blk8]]) -> 6000
A7: 5 | B7: =B6+1 -> 45204 | C7: =YEAR(MC[[#This Row],[Date]])+IF(MONTH(MC[[#This Row],[Date]])>=4,1,0) -> 2024 | D7: =YEAR(MC[[#This Row],[Date]]) -> 2023 | E7: Year_2 | F7: Year_2 | G7: =TEXT(MC[[#This Row],[Date]],"mmm-yy") -> Oct-23 | H7: =DAY(EOMONTH(MC[[#This Row],[Month Year]],0)) -> 31 | R7: =120*50 -> 6000 | S7: =SUM(MC[[#This Row],[Blk1]:[Blk8]]) -> 6000
A8: 6 | B8: =B7+1 -> 45205 | C8: =YEAR(MC[[#This Row],[Date]])+IF(MONTH(MC[[#This Row],[Date]])>=4,1,0) -> 2024 | D8: =YEAR(MC[[#This Row],[Date]]) -> 2023 | E8: Year_2 | F8: Year_2 | G8: =TEXT(MC[[#This Row],[Date]],"mmm-yy") -> Oct-23 | H8: =DAY(EOMONTH(MC[[#This Row],[Month Year]],0)) -> 31 | R8: =120*50 -> 6000 | S8: =SUM(MC[[#This Row],[Blk1]:[Blk8]]) -> 6000
A9: 7 | B9: =B8+1 -> 45206 | C9: =YEAR(MC[[#This Row],[Date]])+IF(MONTH(MC[[#This Row],[Date]])>=4,1,0) -> 2024 | D9: =YEAR(MC[[#This Row],[Date]]) -> 2023 | E9: Year_2 | F9: Year_2 | G9: =TEXT(MC[[#This Row],[Date]],"mmm-yy") -> Oct-23 | H9: =DAY(EOMONTH(MC[[#This Row],[Month Year]],0)) -> 31 | R9: =120*50 -> 6000 | S9: =SUM(MC[[#This Row],[Blk1]:[Blk8]]) -> 6000
A10: 8 | B10: =B9+1 -> 45207 | C10: =YEAR(MC[[#This Row],[Date]])+IF(MONTH(MC[[#This Row],[Date]])>=4,1,0) -> 2024 | D10: =YEAR(MC[[#This Row],[Date]]) -> 2023 | E10: Year_2 | F10: Year_2 | G10: =TEXT(MC[[#This Row],[Date]],"mmm-yy") -> Oct-23 | H10: =DAY(EOMONTH(MC[[#This Row],[Month Year]],0)) -> 31 | R10: =120*50 -> 6000 | S10: =SUM(MC[[#This Row],[Blk1]:[Blk8]]) -> 6000
A11: 9 | B11: =B10+1 -> 45208 | C11: =YEAR(MC[[#This Row],[Date]])+IF(MONTH(MC[[#This Row],[Date]])>=4,1,0) -> 2024 | D11: =YEAR(MC[[#This Row],[Date]]) -> 2023 | E11: Year_2 | F11: Year_2 | G11: =TEXT(MC[[#This Row],[Date]],"mmm-yy") -> Oct-23 | H11: =DAY(EOMONTH(MC[[#This Row],[Month Year]],0)) -> 31 | R11: =120*50 -> 6000 | S11: =SUM(MC[[#This Row],[Blk1]:[Blk8]]) -> 6000
A12: 10 | B12: =B11+1 -> 45209 | C12: =YEAR(MC[[#This Row],[Date]])+IF(MONTH(MC[[#This Row],[Date]])>=4,1,0) -> 2024 | D12: =YEAR(MC[[#This Row],[Date]]) -> 2023 | E12: Year_2 | F12: Year_2 | G12: =TEXT(MC[[#This Row],[Date]],"mmm-yy") -> Oct-23 | H12: =DAY(EOMONTH(MC[[#This Row],[Month Year]],0)) -> 31 | R12: =120*50 -> 6000 | S12: =SUM(MC[[#This Row],[Blk1]:[Blk8]]) -> 6000
A13: 11 | B13: =B12+1 -> 45210 | C13: =YEAR(MC[[#This Row],[Date]])+IF(MONTH(MC[[#This Row],[Date]])>=4,1,0) -> 2024 | D13: =YEAR(MC[[#This Row],[Date]]) -> 2023 | E13: Year_2 | F13: Year_2 | G13: =TEXT(MC[[#This Row],[Date]],"mmm-yy") -> Oct-23 | H13: =DAY(EOMONTH(MC[[#This Row],[Month Year]],0)) -> 31 | R13: =120*50 -> 6000 | S13: =SUM(MC[[#This Row],[Blk1]:[Blk8]]) -> 6000
A14: 12 | B14: =B13+1 -> 45211 | C14: =YEAR(MC[[#This Row],[Date]])+IF(MONTH(MC[[#This Row],[Date]])>=4,1,0) -> 2024 | D14: =YEAR(MC[[#This Row],[Date]]) -> 2023 | E14: Year_2 | F14: Year_2 | G14: =TEXT(MC[[#This Row],[Date]],"mmm-yy") -> Oct-23 | H14: =DAY(EOMONTH(MC[[#This Row],[Month Year]],0)) -> 31 | R14: =120*50 -> 6000 | S14: =SUM(MC[[#This Row],[Blk1]:[Blk8]]) -> 6000
A15: 13 | B15: =B14+1 -> 45212 | C15: =YEAR(MC[[#This Row],[Date]])+IF(MONTH(MC[[#This Row],[Date]])>=4,1,0) -> 2024 | D15: =YEAR(MC[[#This Row],[Date]]) -> 2023 | E15: Year_2 | F15: Year_2 | G15: =TEXT(MC[[#This Row],[Date]],"mmm-yy") -> Oct-23 | H15: =DAY(EOMONTH(MC[[#This Row],[Month Year]],0)) -> 31 | R15: =120*50 -> 6000 | S15: =SUM(MC[[#This Row],[Blk1]:[Blk8]]) -> 6000
... A129: 127 | B129: =B128+1 -> 45326 | C129: =YEAR(MC[[#This Row],[Date]])+IF(MONTH(MC[[#This Row],[Date]])>=4,1,0) -> 2024 | D129: =YEAR(MC[[#This Row],[Date]]) -> 2024 | E129: Year_2 | F129: Year_2 | G129: =TEXT(MC[[#This Row],[Date]],"mmm-yy") -> Feb-24 | H129: =DAY(EOMONTH(MC[[#This Row],[Month Year]],0)) -> 28 | R129: =120*50 -> 6000 | S129: =SUM(MC[[#This Row],[Blk1]:[Blk8]]) -> 6000
A130: 127 | B130: =B129+1 -> 45327 | C130: =YEAR(MC[[#This Row],[Date]])+IF(MONTH(MC[[#This Row],[Date]])>=4,1,0) -> 2024 | D130: =YEAR(MC[[#This Row],[Date]]) -> 2024 | E130: Year_2 | F130: Year_2 | G130: =TEXT(MC[[#This Row],[Date]],"mmm-yy") -> Feb-24 | H130: =DAY(EOMONTH(MC[[#This Row],[Month Year]],0)) -> 28 | R130: =120*50 -> 6000 | S130: =SUM(MC[[#This Row],[Blk1]:[Blk8]]) -> 6000 | V130: 0.16666667 | W130: 0.375 | X130: MOP
A131: 127 | B131: =B130+1 -> 45328 | C131: =YEAR(MC[[#This Row],[Date]])+IF(MONTH(MC[[#This Row],[Date]])>=4,1,0) -> 2024 | D131: =YEAR(MC[[#This Row],[Date]]) -> 2024 | E131: Year_2 | F131: Year_2 | G131: =TEXT(MC[[#This Row],[Date]],"mmm-yy") -> Feb-24 | H131: =DAY(EOMONTH(MC[[#This Row],[Month Year]],0)) -> 28 | R131: =120*50 -> 6000 | S131: =SUM(MC[[#This Row],[Blk1]:[Blk8]]) -> 6000 | V131: 0.16666667 | W131: 0.375 | X131: MOP
A132: 127 | B132: =B131+1 -> 45329 | C132: =YEAR(MC[[#This Row],[Date]])+IF(MONTH(MC[[#This Row],[Date]])>=4,1,0) -> 2024 | D132: =YEAR(MC[[#This Row],[Date]]) -> 2024 | E132: Year_2 | F132: Year_2 | G132: =TEXT(MC[[#This Row],[Date]],"mmm-yy") -> Feb-24 | H132: =DAY(EOMONTH(MC[[#This Row],[Month Year]],0)) -> 28 | R132: =120*50 -> 6000 | S132: =SUM(MC[[#This Row],[Blk1]:[Blk8]]) -> 6000 | V132: 0.16666667 | W132: 0.375 | X132: MOP
A133: 127 | B133: =B132+1 -> 45330 | C133: =YEAR(MC[[#This Row],[Date]])+IF(MONTH(MC[[#This Row],[Date]])>=4,1,0) -> 2024 | D133: =YEAR(MC[[#This Row],[Date]]) -> 2024 | E133: Year_2 | F133: Year_2 | G133: =TEXT(MC[[#This Row],[Date]],"mmm-yy") -> Feb-24 | H133: =DAY(EOMONTH(MC[[#This Row],[Month Year]],0)) -> 28 | R133: =120*50 -> 6000 | S133: =SUM(MC[[#This Row],[Blk1]:[Blk8]]) -> 6000 | V133: 0.16666667 | W133: 0.375 | X133: MOP
A134: 127 | B134: =B133+1 -> 45331 | C134: =YEAR(MC[[#This Row],[Date]])+IF(MONTH(MC[[#This Row],[Date]])>=4,1,0) -> 2024 | D134: =YEAR(MC[[#This Row],[Date]]) -> 2024 | E134: Year_2 | F134: Year_2 | G134: =TEXT(MC[[#This Row],[Date]],"mmm-yy") -> Feb-24 | H134: =DAY(EOMONTH(MC[[#This Row],[Month Year]],0)) -> 28 | R134: =120*50 -> 6000 | S134: =SUM(MC[[#This Row],[Blk1]:[Blk8]]) -> 6000 | V134: 0.16666667 | W134: 0.375 | X134: MOP
A135: 127 | B135: =B134+1 -> 45332 | C135: =YEAR(MC[[#This Row],[Date]])+IF(MONTH(MC[[#This Row],[Date]])>=4,1,0) -> 2024 | D135: =YEAR(MC[[#This Row],[Date]]) -> 2024 | E135: Year_2 | F135: Year_2 | G135: =TEXT(MC[[#This Row],[Date]],"mmm-yy") -> Feb-24 | H135: =DAY(EOMONTH(MC[[#This Row],[Month Year]],0)) -> 28 | R135: =120*50 -> 6000 | S135: =SUM(MC[[#This Row],[Blk1]:[Blk8]]) -> 6000 | V135: 0.16666667 | W135: 0.375 | X135: MOP
A136: 127 | B136: =B135+1 -> 45333 | C136: =YEAR(MC[[#This Row],[Date]])+IF(MONTH(MC[[#This Row],[Date]])>=4,1,0) -> 2024 | D136: =YEAR(MC[[#This Row],[Date]]) -> 2024 | E136: Year_2 | F136: Year_2 | G136: =TEXT(MC[[#This Row],[Date]],"mmm-yy") -> Feb-24 | H136: =DAY(EOMONTH(MC[[#This Row],[Month Year]],0)) -> 28 | R136: =120*50 -> 6000 | S136: =SUM(MC[[#This Row],[Blk1]:[Blk8]]) -> 6000 | V136: 0.16666667 | W136: 0.375 | X136: MOP | Z136: Cleaning Stop due to Fanbalt Broken
A137: 127 | B137: =B136+1 -> 45334 | C137: =YEAR(MC[[#This Row],[Date]])+IF(MONTH(MC[[#This Row],[Date]])>=4,1,0) -> 2024 | D137: =YEAR(MC[[#This Row],[Date]]) -> 2024 | E137: Year_2 | F137: Year_2 | G137: =TEXT(MC[[#This Row],[Date]],"mmm-yy") -> Feb-24 | H137: =DAY(EOMONTH(MC[[#This Row],[Month Year]],0)) -> 28 | R137: =120*50 -> 6000 | S137: =SUM(MC[[#This Row],[Blk1]:[Blk8]]) -> 6000 | V137: 0.16666667 | W137: 0.375 | X137: MOP
A138: 127 | B138: =B137+1 -> 45335 | C138: =YEAR(MC[[#This Row],[Date]])+IF(MONTH(MC[[#This Row],[Date]])>=4,1,0) -> 2024 | D138: =YEAR(MC[[#This Row],[Date]]) -> 2024 | E138: Year_2 | F138: Year_2 | G138: =TEXT(MC[[#This Row],[Date]],"mmm-yy") -> Feb-24 | H138: =DAY(EOMONTH(MC[[#This Row],[Month Year]],0)) -> 28 | R138: =120*50 -> 6000 | S138: =SUM(MC[[#This Row],[Blk1]:[Blk8]]) -> 6000 | V138: 0.16666667 | W138: 0.375 | X138: MOP
A139: 127 | B139: =B138+1 -> 45336 | C139: =YEAR(MC[[#This Row],[Date]])+IF(MONTH(MC[[#This Row],[Date]])>=4,1,0) -> 2024 | D139: =YEAR(MC[[#This Row],[Date]]) -> 2024 | E139: Year_2 | F139: Year_2 | G139: =TEXT(MC[[#This Row],[Date]],"mmm-yy") -> Feb-24 | H139: =DAY(EOMONTH(MC[[#This Row],[Month Year]],0)) -> 28 | R139: =120*50 -> 6000 | S139: =SUM(MC[[#This Row],[Blk1]:[Blk8]]) -> 6000 | Z139: Cleaning not done due to marriage in vendor's family
A140: 127 | B140: =B139+1 -> 45337 | C140: =YEAR(MC[[#This Row],[Date]])+IF(MONTH(MC[[#This Row],[Date]])>=4,1,0) -> 2024 | D140: =YEAR(MC[[#This Row],[Date]]) -> 2024 | E140: Year_2 | F140: Year_2 | G140: =TEXT(MC[[#This Row],[Date]],"mmm-yy") -> Feb-24 | H140: =DAY(EOMONTH(MC[[#This Row],[Month Year]],0)) -> 28 | R140: =120*50 -> 6000 | S140: =SUM(MC[[#This Row],[Blk1]:[Blk8]]) -> 6000 | Z140: Cleaning not done due to marriage in vendor's family
A141: 139 | B141: =B140+1 -> 45338 | C141: =YEAR(MC[[#This Row],[Date]])+IF(MONTH(MC[[#This Row],[Date]])>=4,1,0) -> 2024 | D141: =YEAR(MC[[#This Row],[Date]]) -> 2024 | E141: Year_2 | F141: Year_2 | G141: =TEXT(MC[[#This Row],[Date]],"mmm-yy") -> Feb-24 | H141: =DAY(EOMONTH(MC[[#This Row],[Month Year]],0)) -> 28 | R141: =120*50 -> 6000 | S141: =SUM(MC[[#This Row],[Blk1]:[Blk8]]) -> 6000 | V141: 0.16666667 | W141: 0.375 | X141: MOP | Z141: Cleaning stop due to Tractor pulli Broken
A142: 140 | B142: =B141+1 -> 45339 | C142: =YEAR(MC[[#This Row],[Date]])+IF(MONTH(MC[[#This Row],[Date]])>=4,1,0) -> 2024 | D142: =YEAR(MC[[#This Row],[Date]]) -> 2024 | E142: Year_2 | F142: Year_2 | G142: =TEXT(MC[[#This Row],[Date]],"mmm-yy") -> Feb-24 | H142: =DAY(EOMONTH(MC[[#This Row],[Month Year]],0)) -> 28 | R142: =120*50 -> 6000 | S142: =SUM(MC[[#This Row],[Blk1]:[Blk8]]) -> 6000 | Z142: Cleaning Stop due to Tractor under breakdown
A143: 141 | B143: =B142+1 -> 45340 | C143: =YEAR(MC[[#This Row],[Date]])+IF(MONTH(MC[[#This Row],[Date]])>=4,1,0) -> 2024 | D143: =YEAR(MC[[#This Row],[Date]]) -> 2024 | E143: Year_2 | F143: Year_2 | G143: =TEXT(MC[[#This Row],[Date]],"mmm-yy") -> Feb-24 | H143: =DAY(EOMONTH(MC[[#This Row],[Month Year]],0)) -> 28 | R143: =120*50 -> 6000 | S143: =SUM(MC[[#This Row],[Blk1]:[Blk8]]) -> 6000 | Z143: Cleaning Stop due to Tractor under breakdown
A144: 142 | B144: =B143+1 -> 45341 | C144: =YEAR(MC[[#This Row],[Date]])+IF(MONTH(MC[[#This Row],[Date]])>=4,1,0) -> 2024 | D144: =YEAR(MC[[#This Row],[Date]]) -> 2024 | E144: Year_2 | F144: Year_2 | G144: =TEXT(MC[[#This Row],[Date]],"mmm-yy") -> Feb-24 | H144: =DAY(EOMONTH(MC[[#This Row],[Month Year]],0)) -> 28 | R144: =120*50 -> 6000 | S144: =SUM(MC[[#This Row],[Blk1]:[Blk8]]) -> 6000 | V144: 0.16666667 | W144: 0.375 | X144: MOP
A145: 143 | B145: =B144+1 -> 45342 | C145: =YEAR(MC[[#This Row],[Date]])+IF(MONTH(MC[[#This Row],[Date]])>=4,1,0) -> 2024 | D145: =YEAR(MC[[#This Row],[Date]]) -> 2024 | E145: Year_2 | F145: Year_2 | G145: =TEXT(MC[[#This Row],[Date]],"mmm-yy") -> Feb-24 | H145: =DAY(EOMONTH(MC[[#This Row],[Month Year]],0)) -> 28 | R145: =120*50 -> 6000 | S145: =SUM(MC[[#This Row],[Blk1]:[Blk8]]) -> 6000 | V145: 0.20833333 | W145: 0.45833333 | X145: MOP
A146: 144 | B146: =B145+1 -> 45343 | C146: =YEAR(MC[[#This Row],[Date]])+IF(MONTH(MC[[#This Row],[Date]])>=4,1,0) -> 2024 | D146: =YEAR(MC[[#This Row],[Date]]) -> 2024 | E146: Year_2 | F146: Year_2 | G146: =TEXT(MC[[#This Row],[Date]],"mmm-yy") -> Feb-24 | H146: =DAY(EOMONTH(MC[[#This Row],[Month Year]],0)) -> 28 | R146: =120*50 -> 6000 | S146: =SUM(MC[[#This Row],[Blk1]:[Blk8]]) -> 6000 | T146: 0.22916667 | U146: 0.39583333 | V146: 0.6875 | W146: 0.95833333 | X146: MOP
A147: 145 | B147: =B146+1 -> 45344 | C147: =YEAR(MC[[#This Row],[Date]])+IF(MONTH(MC[[#This Row],[Date]])>=4,1,0) -> 2024 | D147: =YEAR(MC[[#This Row],[Date]]) -> 2024 | E147: Year_2 | F147: Year_2 | G147: =TEXT(MC[[#This Row],[Date]],"mmm-yy") -> Feb-24 | H147: =DAY(EOMONTH(MC[[#This Row],[Month Year]],0)) -> 28 | R147: =120*50 -> 6000 | S147: =SUM(MC[[#This Row],[Blk1]:[Blk8]]) -> 6000 | T147: 0.22916667 | U147: 0.39583333 | V147: 0.6875 | W147: 0.95833333 | X147: MOP
A148: 146 | B148: =B147+1 -> 45345 | C148: =YEAR(MC[[#This Row],[Date]])+IF(MONTH(MC[[#This Row],[Date]])>=4,1,0) -> 2024 | D148: =YEAR(MC[[#This Row],[Date]]) -> 2024 | E148: Year_2 | F148: Year_2 | G148: =TEXT(MC[[#This Row],[Date]],"mmm-yy") -> Feb-24 | H148: =DAY(EOMONTH(MC[[#This Row],[Month Year]],0)) -> 28 | R148: =120*50 -> 6000 | S148: =SUM(MC[[#This Row],[Blk1]:[Blk8]]) -> 6000 | T148: 0.22916667 | U148: 0.39583333 | V148: 0.6875 | W148: 0.95833333 | X148: MOP
A149: 147 | B149: =B148+1 -> 45346 | C149: =YEAR(MC[[#This Row],[Date]])+IF(MONTH(MC[[#This Row],[Date]])>=4,1,0) -> 2024 | D149: =YEAR(MC[[#This Row],[Date]]) -> 2024 | E149: Year_2 | F149: Year_2 | G149: =TEXT(MC[[#This Row],[Date]],"mmm-yy") -> Feb-24 | H149: =DAY(EOMONTH(MC[[#This Row],[Month Year]],0)) -> 28 | R149: =120*50 -> 6000 | S149: =SUM(MC[[#This Row],[Blk1]:[Blk8]]) -> 6000 | T149: 0.22916667 | U149: 0.39583333 | V149: 0.6875 | W149: 0.95833333 | X149: MOP
A150: 148 | B150: =B149+1 -> 45347 | C150: =YEAR(MC[[#This Row],[Date]])+IF(MONTH(MC[[#This Row],[Date]])>=4,1,0) -> 2024 | D150: =YEAR(MC[[#This Row],[Date]]) -> 2024 | E150: Year_2 | F150: Year_2 | G150: =TEXT(MC[[#This Row],[Date]],"mmm-yy") -> Feb-24 | H150: =DAY(EOMONTH(MC[[#This Row],[Month Year]],0)) -> 28 | R150: =120*50 -> 6000 | S150: =SUM(MC[[#This Row],[Blk1]:[Blk8]]) -> 6000 | T150: 0.22916667 | U150: 0.39583333 | V150: 0.6875 | W150: 0.95833333 | X150: MOP
A151: 149 | B151: =B150+1 -> 45348 | C151: =YEAR(MC[[#This Row],[Date]])+IF(MONTH(MC[[#This Row],[Date]])>=4,1,0) -> 2024 | D151: =YEAR(MC[[#This Row],[Date]]) -> 2024 | E151: Year_2 | F151: Year_2 | G151: =TEXT(MC[[#This Row],[Date]],"mmm-yy") -> Feb-24 | H151: =DAY(EOMONTH(MC[[#This Row],[Month Year]],0)) -> 28 | R151: =120*50 -> 6000 | S151: =SUM(MC[[#This Row],[Blk1]:[Blk8]]) -> 6000 | T151: 0.22916667 | U151: 0.39583333 | V151: 0.6875 | W151: 0.95833333 | X151: MOP
A152: 150 | B152: =B151+1 -> 45349 | C152: =YEAR(MC[[#This Row],[Date]])+IF(MONTH(MC[[#This Row],[Date]])>=4,1,0) -> 2024 | D152: =YEAR(MC[[#This Row],[Date]]) -> 2024 | E152: Year_2 | F152: Year_2 | G152: =TEXT(MC[[#This Row],[Date]],"mmm-yy") -> Feb-24 | H152: =DAY(EOMONTH(MC[[#This Row],[Month Year]],0)) -> 28 | R152: =120*50 -> 6000 | S152: =SUM(MC[[#This Row],[Blk1]:[Blk8]]) -> 6000 | T152: 0.22916667 | U152: 0.39583333 | V152: 0.6875 | W152: 0.95833333 | X152: MOP
A153: 151 | B153: =B152+1 -> 45350 | C153: =YEAR(MC[[#This Row],[Date]])+IF(MONTH(MC[[#This Row],[Date]])>=4,1,0) -> 2024 | D153: =YEAR(MC[[#This Row],[Date]]) -> 2024 | E153: Year_2 | F153: Year_2 | G153: =TEXT(MC[[#This Row],[Date]],"mmm-yy") -> Feb-24 | H153: =DAY(EOMONTH(MC[[#This Row],[Month Year]],0)) -> 28 | R153: =120*50 -> 6000 | S153: =SUM(MC[[#This Row],[Blk1]:[Blk8]]) -> 6000 | T153: 0.22916667 | U153: 0.39583333 | V153: 0.6875 | W153: 0.95833333 | X153: MOP
A154: 152 | B154: =B153+1 -> 45351 | C154: =YEAR(MC[[#This Row],[Date]])+IF(MONTH(MC[[#This Row],[Date]])>=4,1,0) -> 2024 | D154: =YEAR(MC[[#This Row],[Date]]) -> 2024 | E154: Year_2 | F154: Year_2 | G154: =TEXT(MC[[#This Row],[Date]],"mmm-yy") -> Feb-24 | H154: =DAY(EOMONTH(MC[[#This Row],[Month Year]],0)) -> 28 | R154: =120*50 -> 6000 | S154: =SUM(MC[[#This Row],[Blk1]:[Blk8]]) -> 6000 | T154: 0.22916667 | U154: 0.39583333 | V154: 0.6875 | W154: 0.95833333 | X154: MOP
...

Sheet Raw_Data
B2: 1 | C2: =B2+1 -> 2 | D2: =C2+1 -> 3 | E2: =D2+1 -> 4 | F2: =E2+1 -> 5 | G2: =F2+1 -> 6 | H2: =G2+1 -> 7 | I2: =H2+1 -> 8 | J2: =I2+1 -> 9 | ... BV2: =BU2+1 -> 73 | BW2: 74 | BX2: 75 | BY2: =BX2+1 -> 76 | BZ2: =BY2+1 -> 77 | CA2: =BZ2+1 -> 78 | CB2: =CA2+1 -> 79 | CC2: =CB2+1 -> 80 | CD2: =CC2+1 -> 81 | CE2: =CD2+1 -> 82 | CF2: =CE2+1 -> 83 | ... KQ2: =KP2+1 -> 302
