Workbook

Sheet Daily Dashboard
A1: 10 MW ES Energy Private Limited Performance Summary
A2: Month | B2: 45870
A3: Date | B3: 45871
A4: Operation Year | B4: FY2025-26
A5: Year Start Date | B5: 45748
A6: Year End Date | B6: 46112
A8: Sr. No. | B8: Particular | C8: Target | D8: Measured | E8: Deviation | F8: Remarks
A9: 1 | B9: E_Grid Daily (MWh) | C9: =_xlfn.XLOOKUP($B$3,'Daily KPI'!$A:$A,'Daily KPI'!AD:AD)/1000 -> 33.012257 | D9: =_xlfn.XLOOKUP($B$3,'Daily KPI'!$A:$A,'Daily KPI'!AA:AA)/1000 -> 42.33402 | E9: =-(C9-D9)/C9 -> 0.2823728
B10: E_Grid MTD(MWh) | C10: =_xlfn.XLOOKUP($B$2,'Modelling New'!$D:$D,'Modelling New'!U:U) -> 66.024514 | D10: ='Monthly KPI'!$F$4 -> 71.42796 | E10: =-(C10-D10)/C10 -> 0.081840004
B11: E_Grid YTD (MWh) | C11: =_xlfn.XLOOKUP($B$2,'Modelling New'!$D:$D,'Modelling New'!V:V) -> 5321.2008 | D11: ='Annual KPI'!$F$4 -> 4932.9495 | E11: =-(C11-D11)/C11 -> -0.072963089
A12: 2 | B12: CUF Daily(%) | C12: =_xlfn.XLOOKUP($B3,'Daily KPI'!$A:$A,'Daily KPI'!$AF:$AF) -> 0.13091374 | D12: =_xlfn.XLOOKUP($B$3,'Daily KPI'!$A:$A,'Daily KPI'!W:W) -> 0.16788022 | E12: =-(C12-D12)/C12 -> 0.2823728
B13: CUF MTD(%) | C13: =_xlfn.XLOOKUP($B$2,'Modelling New'!$D:$D,'Modelling New'!X:X) -> 0.13091374 | D13: ='Monthly KPI'!J4 -> 0.14162772 | E13: =-(C13-D13)/C13 -> 0.081840004
B14: CUF YTD(%) | C14: =_xlfn.XLOOKUP($B$2,'Modelling New'!$D:$D,'Modelling New'!Y:Y) -> 0.17017587 | D14: ='Annual KPI'!J4 -> 0.15775932 | E14: =-(C14-D14)/C14 -> -0.072963089
A15: 3 | B15: PR_Daily (%) | C15: =_xlfn.XLOOKUP($B$3,'Daily KPI'!$A:$A,'Daily KPI'!AE:AE) -> 0.70656621 | D15: =_xlfn.XLOOKUP($B$3,'Daily KPI'!$A:$A,'Daily KPI'!U:U) -> 0.71501781 | E15: =-(C15-D15)/C15 -> 0.011961507
B16: PR_MTD (%) | C16: ='Monthly KPI'!$G$4 -> 0.70656621 | D16: ='Monthly KPI'!$H$4 -> 0.7171024 | E16: =-(C16-D16)/C16 -> 0.014911825
B17: PR_YTD (%) | C17: ='Annual KPI'!$G$4 -> 0.6829102 | D17: ='Annual KPI'!$H$4 -> 0.71620009 | E17: =-(C17-D17)/C17 -> 0.048747098
A18: 4 | B18: POA Daily (KWh/m2) | C18: =_xlfn.XLOOKUP($B$3,'Daily KPI'!$A:$A,'Daily KPI'!AC:AC) -> 4.4467593 | D18: =_xlfn.XLOOKUP($B$3,'Daily KPI'!$A:$A,'Daily KPI'!I:I) -> 5.635 | E18: =-(C18-D18)/C18 -> 0.26721499
B19: POA MTD(KWh/m2) | C19: =_xlfn.XLOOKUP($B$2,'Modelling New'!$D:$D,'Modelling New'!R:R) -> 8.8935185 | D19: ='Monthly KPI'!$D$4 -> 9.48 | E19: =-(C19-D19)/C19 -> 0.065944822
B20: POA YTD(KWh/m2) | C20: =_xlfn.XLOOKUP($B$2,'Modelling New'!$D:$D,'Modelling New'!S:S) -> 741.59588 | D20: ='Annual KPI'!$D$4 -> 655.5315 | E20: =-(C20-D20)/C20 -> -0.11605294
A21: 5 | B21: PA Daily (%) | C21: =_xlfn.XLOOKUP($B$3,'Daily KPI'!$A:$A,'Daily KPI'!AG:AG) -> 0.995 | D21: =_xlfn.XLOOKUP($B$3,'Daily KPI'!$A:$A,'Daily KPI'!O:O) -> 0.99180021 | E21: =-(C21-D21)/C21 -> -0.0032158693
B22: PA MTD(%) | C22: =_xlfn.XLOOKUP($B$2,'Modelling New'!$D:$D,'Modelling New'!AD:AD) -> 0.995 | D22: ='Monthly KPI'!$N$4 -> 0.99590011 | E22: =-(C22-D22)/C22 -> 0.00090462814
B23: PA YTD(%) | C23: =_xlfn.XLOOKUP($B$2,'Modelling New'!$D:$D,'Modelling New'!AD:AD) -> 0.995 | D23: ='Annual KPI'!$N$4 -> 0.99394742 | E23: =-(C23-D23)/C23 -> -0.0010578728
A24: 6 | B24: GA Daily (%) | C24: =_xlfn.XLOOKUP($B$3,'Daily KPI'!$A:$A,'Daily KPI'!AH:AH) -> 0.997 | D24: =_xlfn.XLOOKUP($B$3,'Daily KPI'!$A:$A,'Daily KPI'!R:R) -> 1 | E24: =-(C24-D24)/C24 -> 0.0030090271
B25: GA MTD(%) | C25: =_xlfn.XLOOKUP($B$2,'Modelling New'!$D:$D,'Modelling New'!AE:AE) -> 0.997 | D25: ='Monthly KPI'!$L$4 -> 1 | E25: =-(C25-D25)/C25 -> 0.0030090271
B26: GA YTD(%) | C26: =_xlfn.XLOOKUP($B$2,'Modelling New'!$D:$D,'Modelling New'!AE:AE) -> 0.997 | D26: ='Annual KPI'!$L$4 -> 0.9917799 | E26: =-(C26-D26)/C26 -> -0.005235807
A27: 7 | B27: TA Daily (%) | C27: =_xlfn.XLOOKUP($B$2,'Modelling New'!$D:$D,'Modelling New'!AF:AF) -> 0.999 | D27: =_xlfn.XLOOKUP($B$3,'Daily KPI'!$A:$A,'Daily KPI'!T:T) -> 1 | E27: =-(C27-D27)/C27 -> 0.001001001
B28: TA MTD(%) | C28: =_xlfn.XLOOKUP($B$2,'Modelling New'!$D:$D,'Modelling New'!AF:AF) -> 0.999 | D28: ='Monthly KPI'!$P$4 -> 1 | E28: =-(C28-D28)/C28 -> 0.001001001
B29: TA YTD(%) | C29: =_xlfn.XLOOKUP($B$2,'Modelling New'!$D:$D,'Modelling New'!AF:AF) -> 0.999 | D29: ='Annual KPI'!$P$4 -> 1 | E29: =-(C29-D29)/C29 -> 0.001001001

Sheet Modelling New
A1: Sr. No. | B1: Month Name | C1: Month Number | D1: Month | E1: CY | F1: FY | G1: No. of Days in Month | H1: GHI | I1: POA | J1: WS | K1: Tamb | L1: Tmod | M1: Egrid (MWh) | N1: Bugt_Capacity | O1: PR | P1: Daily POA | Q1: Days Operated | R1: MTD POA | S1: YTD POA | T1: Daily Energy (MWh) | U1: MTD Energy (MWh) | V1: YTD Energy (MWh) | W1: Bugt CUF (%) | X1: Bugt CUF (%) MTD | Y1: Bugt CUF (%)YTD | Z1: Ave. Cap MTD | AA1: Ave. Cap YTD | AB1: CC Energy MTD | AC1: WS_YTD | AD1: Bugt PA | AE1: Bugt EGA | AF1: Bugt TA | AG1: Bugt MA | AH1: Bugt IGA | AI1: Corelation | AJ1: Bugt Line loss | AK1: Bugt Reactive Power | AL1: Bugt Capacity | AM1: CC*Bugt | AO1: DC Capacity | AP1: 10.507
A2: 1 | B2: April | C2: 4 | D2: 44652 | E2: =YEAR(D2) -> 2022 | F2: FY23 | G2: =DAY(EOMONTH(D2,0)) -> 30 | H2: 192.7392 | I2: 227.6882 | K2: 27.499986 | M2: 1670.3636 | N2: 10.507 | O2: =M2/I2/N2 -> 0.69821915 | P2: =I2/G2 -> 7.5896068 | Q2: =COUNTIFS('Daily KPI'!D:D,D2,'Daily KPI'!K:K,">0") -> 0 | R2: =I2/G2*Q2 -> 0 | S2: =SUMIF($F$2:F2,F2,$R$2:R2) -> 0 | T2: =M2/G2 -> 55.678787 | U2: =M2/G2*Q2 -> 0 | V2: =SUMIF($F$2:F2,F2,$U$2:U2) -> 0 | W2: =T2/(24*N2) -> 0.22080037 | X2: =IFERROR(U2/(24*N2*Q2),"") | Y2: =IFERROR(V2/(24*N2*SUMIFS($Q:$Q,$F:$F,$F2,$D:$D,"<="&D2)),"") | Z2: =IFERROR(AVERAGEIF('Daily KPI'!D:D,Table14[[#This Row],[Month]],'Daily KPI'!AB:AB),"") | AA2: =IFERROR(AVERAGEIF($F$2:F2,F2,$Z$2:Z2),"") | AD2: 0.995 | AE2: 0.997 | AF2: 0.999 | AW2: 1670363.6 | AX2: =AW2/1000 -> 1670.3636
A3: =A2+1 -> 2 | B3: May | C3: 5 | D3: 44682 | E3: =YEAR(D3) -> 2022 | F3: FY23 | G3: =DAY(EOMONTH(D3,0)) -> 31 | H3: 184.49337 | I3: 215.54431 | K3: 26.700081 | M3: 1602.1141 | N3: 10.507 | O3: =M3/I3/N3 -> 0.70742132 | P3: =I3/G3 -> 6.9530422 | Q3: =COUNTIFS('Daily KPI'!D:D,D3,'Daily KPI'!K:K,">0") -> 0 | R3: =I3/G3*Q3 -> 0 | S3: =SUMIF($F$2:F3,F3,$R$2:R3) -> 0 | T3: =M3/G3 -> 51.681099 | U3: =M3/G3*Q3 -> 0 | V3: =SUMIF($F$2:F3,F3,$U$2:U3) -> 0 | W3: =T3/(24*N3) -> 0.2049471 | X3: =IFERROR(U3/(24*N3*Q3),"") | Y3: =IFERROR(V3/(24*N3*SUMIFS($Q:$Q,$F:$F,$F3,$D:$D,"<="&D3)),"") | Z3: =IFERROR(AVERAGEIF('Daily KPI'!D:D,Table14[[#This Row],[Month]],'Daily KPI'!AB:AB),"") | AA3: =IFERROR(AVERAGEIF($F$2:F3,F3,$Z$2:Z3),"") | AD3: 0.995 | AE3: 0.997 | AF3: 0.999 | AW3: 1602114.1 | AX3: =AW3/1000 -> 1602.1141
A4: =A3+1 -> 3 | B4: June | C4: 6 | D4: 44713 | E4: =YEAR(D4) -> 2022 | F4: FY23 | G4: =DAY(EOMONTH(D4,0)) -> 30 | H4: 140.1651 | I4: 157.11702 | K4: 24.699889 | M4: 1181.2419 | N4: 10.507 | O4: =M4/I4/N4 -> 0.71554492 | P4: =I4/G4 -> 5.237234 | Q4: =COUNTIFS('Daily KPI'!D:D,D4,'Daily KPI'!K:K,">0") -> 0 | R4: =I4/G4*Q4 -> 0 | S4: =SUMIF($F$2:F4,F4,$R$2:R4) -> 0 | T4: =M4/G4 -> 39.374732 | U4: =M4/G4*Q4 -> 0 | V4: =SUMIF($F$2:F4,F4,$U$2:U4) -> 0 | W4: =T4/(24*N4) -> 0.15614484 | X4: =IFERROR(U4/(24*N4*Q4),"") | Y4: =IFERROR(V4/(24*N4*SUMIFS($Q:$Q,$F:$F,$F4,$D:$D,"<="&D4)),"") | Z4: =IFERROR(AVERAGEIF('Daily KPI'!D:D,Table14[[#This Row],[Month]],'Daily KPI'!AB:AB),"") | AA4: =IFERROR(AVERAGEIF($F$2:F4,F4,$Z$2:Z4),"") | AD4: 0.995 | AE4: 0.997 | AF4: 0.999 | AW4: 1181241.9 | AX4: =AW4/1000 -> 1181.2419
A5: =A4+1 -> 4 | B5: July | C5: 7 | D5: 44743 | E5: =YEAR(D5) -> 2022 | F5: FY23 | G5: =DAY(EOMONTH(D5,0)) -> 31 | H5: 122.3162 | I5: 132.35283 | K5: 23.799973 | M5: 991.36824 | N5: 10.507 | O5: =M5/I5/N5 -> 0.71289083 | P5: =I5/G5 -> 4.2694462 | Q5: =COUNTIFS('Daily KPI'!D:D,D5,'Daily KPI'!K:K,">0") -> 0 | R5: =I5/G5*Q5 -> 0 | S5: =SUMIF($F$2:F5,F5,$R$2:R5) -> 0 | T5: =M5/G5 -> 31.979621 | U5: =M5/G5*Q5 -> 0 | V5: =SUMIF($F$2:F5,F5,$U$2:U5) -> 0 | W5: =T5/(24*N5) -> 0.12681871 | X5: =IFERROR(U5/(24*N5*Q5),"") | Y5: =IFERROR(V5/(24*N5*SUMIFS($Q:$Q,$F:$F,$F5,$D:$D,"<="&D5)),"") | Z5: =IFERROR(AVERAGEIF('Daily KPI'!D:D,Table14[[#This Row],[Month]],'Daily KPI'!AB:AB),"") | AA5: =IFERROR(AVERAGEIF($F$2:F5,F5,$Z$2:Z5),"") | AD5: 0.995 | AE5: 0.997 | AF5: 0.999 | AW5: 991368.24 | AX5: =AW5/1000 -> 991.36824
A6: =A5+1 -> 5 | B6: August | C6: 8 | D6: 44774 | E6: =YEAR(D6) -> 2022 | F6: FY23 | G6: =DAY(EOMONTH(D6,0)) -> 31 | H6: 126.29284 | I6: 137.84954 | K6: 23.600054 | M6: 1037.7429 | N6: 10.507 | O6: =M6/I6/N6 -> 0.71648275 | P6: =I6/G6 -> 4.4467593 | Q6: =COUNTIFS('Daily KPI'!D:D,D6,'Daily KPI'!K:K,">0") -> 0 | R6: =I6/G6*Q6 -> 0 | S6: =SUMIF($F$2:F6,F6,$R$2:R6) -> 0 | T6: =M6/G6 -> 33.475578 | U6: =M6/G6*Q6 -> 0 | V6: =SUMIF($F$2:F6,F6,$U$2:U6) -> 0 | W6: =T6/(24*N6) -> 0.1327511 | X6: =IFERROR(U6/(24*N6*Q6),"") | Y6: =IFERROR(V6/(24*N6*SUMIFS($Q:$Q,$F:$F,$F6,$D:$D,"<="&D6)),"") | Z6: =IFERROR(AVERAGEIF('Daily KPI'!D:D,Table14[[#This Row],[Month]],'Daily KPI'!AB:AB),"") | AA6: =IFERROR(AVERAGEIF($F$2:F6,F6,$Z$2:Z6),"") | AD6: 0.995 | AE6: 0.997 | AF6: 0.999 | AO6: For wind EGA | AP6: 0.995 | AW6: 1037742.9 | AX6: =AW6/1000 -> 1037.7429
A7: =A6+1 -> 6 | B7: September | C7: 9 | D7: 44805 | E7: =YEAR(D7) -> 2022 | F7: FY23 | G7: =DAY(EOMONTH(D7,0)) -> 30 | H7: 144.04475 | I7: 163.04046 | K7: 23.700139 | M7: 1224.9917 | N7: 10.507 | O7: =M7/I7/N7 -> 0.71508721 | P7: =I7/G7 -> 5.4346819 | Q7: =COUNTIFS('Daily KPI'!D:D,D7,'Daily KPI'!K:K,">0") -> 0 | R7: =I7/G7*Q7 -> 0 | S7: =SUMIF($F$2:F7,F7,$R$2:R7) -> 0 | T7: =M7/G7 -> 40.833055 | U7: =M7/G7*Q7 -> 0 | V7: =SUMIF($F$2:F7,F7,$U$2:U7) -> 0 | W7: =T7/(24*N7) -> 0.16192798 | X7: =IFERROR(U7/(24*N7*Q7),"") | Y7: =IFERROR(V7/(24*N7*SUMIFS($Q:$Q,$F:$F,$F7,$D:$D,"<="&D7)),"") | Z7: =IFERROR(AVERAGEIF('Daily KPI'!D:D,Table14[[#This Row],[Month]],'Daily KPI'!AB:AB),"") | AA7: =IFERROR(AVERAGEIF($F$2:F7,F7,$Z$2:Z7),"") | AD7: 0.995 | AE7: 0.997 | AF7: 0.999 | AO7: Wind PA equal Bugt PA for wind | AW7: 1224991.7 | AX7: =AW7/1000 -> 1224.9917
A8: =A7+1 -> 7 | B8: October | C8: 10 | D8: 44835 | E8: =YEAR(D8) -> 2022 | F8: FY23 | G8: =DAY(EOMONTH(D8,0)) -> 31 | H8: 146.56699 | I8: 169.41865 | K8: 23.399852 | M8: 1279.2413 | N8: 10.507 | O8: =M8/I8/N8 -> 0.71864186 | P8: =I8/G8 -> 5.4651178 | Q8: =COUNTIFS('Daily KPI'!D:D,D8,'Daily KPI'!K:K,">0") -> 0 | R8: =I8/G8*Q8 -> 0 | S8: =SUMIF($F$2:F8,F8,$R$2:R8) -> 0 | T8: =M8/G8 -> 41.265848 | U8: =M8/G8*Q8 -> 0 | V8: =SUMIF($F$2:F8,F8,$U$2:U8) -> 0 | W8: =T8/(24*N8) -> 0.16364427 | X8: =IFERROR(U8/(24*N8*Q8),"") | Y8: =IFERROR(V8/(24*N8*SUMIFS($Q:$Q,$F:$F,$F8,$D:$D,"<="&D8)),"") | Z8: =IFERROR(AVERAGEIF('Daily KPI'!D:D,Table14[[#This Row],[Month]],'Daily KPI'!AB:AB),"") | AA8: =IFERROR(AVERAGEIF($F$2:F8,F8,$Z$2:Z8),"") | AD8: 0.995 | AE8: 0.997 | AF8: 0.999 | AW8: 1279241.3 | AX8: =AW8/1000 -> 1279.2413
A9: =A8+1 -> 8 | B9: November | C9: 11 | D9: 44866 | E9: =YEAR(D9) -> 2022 | F9: FY23 | G9: =DAY(EOMONTH(D9,0)) -> 30 | H9: 136.38301 | I9: 157.92066 | K9: 22.499958 | M9: 1206.6168 | N9: 10.507 | O9: =M9/I9/N9 -> 0.72719635 | P9: =I9/G9 -> 5.2640218 | Q9: =COUNTIFS('Daily KPI'!D:D,D9,'Daily KPI'!K:K,">0") -> 0 | R9: =I9/G9*Q9 -> 0 | S9: =SUMIF($F$2:F9,F9,$R$2:R9) -> 0 | T9: =M9/G9 -> 40.220559 | U9: =M9/G9*Q9 -> 0 | V9: =SUMIF($F$2:F9,F9,$U$2:U9) -> 0 | W9: =T9/(24*N9) -> 0.15949906 | X9: =IFERROR(U9/(24*N9*Q9),"") | Y9: =IFERROR(V9/(24*N9*SUMIFS($Q:$Q,$F:$F,$F9,$D:$D,"<="&D9)),"") | Z9: =IFERROR(AVERAGEIF('Daily KPI'!D:D,Table14[[#This Row],[Month]],'Daily KPI'!AB:AB),"") | AA9: =IFERROR(AVERAGEIF($F$2:F9,F9,$Z$2:Z9),"") | AD9: 0.995 | AE9: 0.997 | AF9: 0.999 | AW9: 1206616.8 | AX9: =AW9/1000 -> 1206.6168
A10: =A9+1 -> 9 | B10: December | C10: 12 | D10: 44896 | E10: =YEAR(D10) -> 2022 | F10: FY23 | G10: =DAY(EOMONTH(D10,0)) -> 31 | H10: 149.37928 | I10: 175.8024 | K10: 21.49297 | M10: 1343.1158 | N10: 10.507 | O10: =M10/I10/N10 -> 0.72712644 | P10: =I10/G10 -> 5.6710452 | Q10: =COUNTIFS('Daily KPI'!D:D,D10,'Daily KPI'!K:K,">0") -> 0 | R10: =I10/G10*Q10 -> 0 | S10: =SUMIF($F$2:F10,F10,$R$2:R10) -> 0 | T10: =M10/G10 -> 43.326318 | U10: =M10/G10*Q10 -> 0 | V10: =SUMIF($F$2:F10,F10,$U$2:U10) -> 0 | W10: =T10/(24*N10) -> 0.17181529 | X10: =IFERROR(U10/(24*N10*Q10),"") | Y10: =IFERROR(V10/(24*N10*SUMIFS($Q:$Q,$F:$F,$F10,$D:$D,"<="&D10)),"") | Z10: =IFERROR(AVERAGEIF('Daily KPI'!D:D,Table14[[#This Row],[Month]],'Daily KPI'!AB:AB),"") | AA10: =IFERROR(AVERAGEIF($F$2:F10,F10,$Z$2:Z10),"") | AD10: 0.995 | AE10: 0.997 | AF10: 0.999 | AW10: 1343115.8 | AX10: =AW10/1000 -> 1343.1158
A11: =A10+1 -> 10 | B11: January | C11: 1 | D11: 44927 | E11: =YEAR(D11) -> 2023 | F11: FY23 | G11: =DAY(EOMONTH(D11,0)) -> 31 | H11: 172.65915 | I11: 210.74159 | K11: 22.099987 | M11: 1607.364 | N11: 10.507 | O11: =M11/I11/N11 -> 0.72591417 | P11: =I11/G11 -> 6.7981157 | Q11: =COUNTIFS('Daily KPI'!D:D,D11,'Daily KPI'!K:K,">0") -> 0 | R11: =I11/G11*Q11 -> 0 | S11: =SUMIF($F$2:F11,F11,$R$2:R11) -> 0 | T11: =M11/G11 -> 51.850453 | U11: =M11/G11*Q11 -> 0 | V11: =SUMIF($F$2:F11,F11,$U$2:U11) -> 0 | W11: =T11/(24*N11) -> 0.20561869 | X11: =IFERROR(U11/(24*N11*Q11),"") | Y11: =IFERROR(V11/(24*N11*SUMIFS($Q:$Q,$F:$F,$F11,$D:$D,"<="&D11)),"") | Z11: =IFERROR(AVERAGEIF('Daily KPI'!D:D,Table14[[#This Row],[Month]],'Daily KPI'!AB:AB),"") | AA11: =IFERROR(AVERAGEIF($F$2:F11,F11,$Z$2:Z11),"") | AD11: 0.995 | AE11: 0.997 | AF11: 0.999 | AW11: 1607364 | AX11: =AW11/1000 -> 1607.364
A12: =A11+1 -> 11 | B12: February | C12: 2 | D12: 44958 | E12: =YEAR(D12) -> 2023 | F12: FY23 | G12: =DAY(EOMONTH(D12,0)) -> 28 | H12: 174.40611 | I12: 212.78878 | K12: 24.199896 | M12: 1596.8641 | N12: 10.507 | O12: =M12/I12/N12 -> 0.71423397 | P12: =I12/G12 -> 7.5995994 | Q12: =COUNTIFS('Daily KPI'!D:D,D12,'Daily KPI'!K:K,">0") -> 0 | R12: =I12/G12*Q12 -> 0 | S12: =SUMIF($F$2:F12,F12,$R$2:R12) -> 0 | T12: =M12/G12 -> 57.030861 | U12: =M12/G12*Q12 -> 0 | V12: =SUMIF($F$2:F12,F12,$U$2:U12) -> 0 | W12: =T12/(24*N12) -> 0.22616217 | X12: =IFERROR(U12/(24*N12*Q12),"") | Y12: =IFERROR(V12/(24*N12*SUMIFS($Q:$Q,$F:$F,$F12,$D:$D,"<="&D12)),"") | Z12: =IFERROR(AVERAGEIF('Daily KPI'!D:D,Table14[[#This Row],[Month]],'Daily KPI'!AB:AB),"") | AA12: =IFERROR(AVERAGEIF($F$2:F12,F12,$Z$2:Z12),"") | AD12: 0.995 | AE12: 0.997 | AF12: 0.999 | AW12: 1596864.1 | AX12: =AW12/1000 -> 1596.8641
A13: =A12+1 -> 12 | B13: March | C13: 3 | D13: 44986 | E13: =YEAR(D13) -> 2023 | F13: FY23 | G13: =DAY(EOMONTH(D13,0)) -> 31 | H13: 205.4467 | I13: 247.38206 | K13: 26.700255 | M13: 1826.9875 | N13: 10.507 | O13: =M13/I13/N13 -> 0.7028921 | P13: =I13/G13 -> 7.9800663 | Q13: =COUNTIFS('Daily KPI'!D:D,D13,'Daily KPI'!K:K,">0") -> 0 | R13: =I13/G13*Q13 -> 0 | S13: =SUMIF($F$2:F13,F13,$R$2:R13) -> 0 | T13: =M13/G13 -> 58.935082 | U13: =M13/G13*Q13 -> 0 | V13: =SUMIF($F$2:F13,F13,$U$2:U13) -> 0 | W13: =T13/(24*N13) -> 0.23371356 | X13: =IFERROR(U13/(24*N13*Q13),"") | Y13: =IFERROR(V13/(24*N13*SUMIFS($Q:$Q,$F:$F,$F13,$D:$D,"<="&D13)),"") | Z13: =IFERROR(AVERAGEIF('Daily KPI'!D:D,Table14[[#This Row],[Month]],'Daily KPI'!AB:AB),"") | AA13: =IFERROR(AVERAGEIF($F$2:F13,F13,$Z$2:Z13),"") | AD13: 0.995 | AE13: 0.997 | AF13: 0.999 | AW13: 1826987.5 | AX13: =AW13/1000 -> 1826.9875
A14: =A13+1 -> 13 | B14: =B2 -> April | C14: =C2 -> 4 | D14: 45017 | E14: =YEAR(D14) -> 2023 | F14: FY24 | G14: =DAY(EOMONTH(D14,0)) -> 30 | H14: =H2 -> 192.7392 | I14: =I2 -> 227.6882 | K14: =K2 -> 27.499986 | M14: 1610 | N14: 10.507 | O14: =M14/I14/N14 -> 0.6729869 | P14: =I14/G14 -> 7.5896068 | Q14: =COUNTIFS('Daily KPI'!D:D,D14,'Daily KPI'!K:K,">0") -> 0 | R14: =I14/G14*Q14 -> 0 | S14: =SUMIF($F$2:F14,F14,$R$2:R14) -> 0 | T14: =M14/G14 -> 53.666667 | U14: =M14/G14*Q14 -> 0 | V14: =SUMIF($F$2:F14,F14,$U$2:U14) -> 0 | W14: =T14/(24*N14) -> 0.21282108 | X14: =IFERROR(U14/(24*N14*Q14),"") | Y14: =IFERROR(V14/(24*N14*SUMIFS($Q:$Q,$F:$F,$F14,$D:$D,"<="&D14)),"") | Z14: =IFERROR(AVERAGEIF('Daily KPI'!D:D,Table14[[#This Row],[Month]],'Daily KPI'!AB:AB),"") | AA14: =IFERROR(AVERAGEIF($F$2:F14,F14,$Z$2:Z14),"") | AD14: 0.995 | AE14: 0.997 | AF14: 0.999 | AW14: 1610000 | AX14: =AW14/1000 -> 1610
A15: =A14+1 -> 14 | B15: =B3 -> May | C15: =C3 -> 5 | D15: 45047 | E15: =YEAR(D15) -> 2023 | F15: FY24 | G15: =DAY(EOMONTH(D15,0)) -> 31 | H15: =H3 -> 184.49337 | I15: =I3 -> 215.54431 | K15: =K3 -> 26.700081 | M15: 1600 | N15: 10.507 | O15: =M15/I15/N15 -> 0.70648784 | P15: =I15/G15 -> 6.9530422 | Q15: =COUNTIFS('Daily KPI'!D:D,D15,'Daily KPI'!K:K,">0") -> 0 | R15: =I15/G15*Q15 -> 0 | S15: =SUMIF($F$2:F15,F15,$R$2:R15) -> 0 | T15: =M15/G15 -> 51.612903 | U15: =M15/G15*Q15 -> 0 | V15: =SUMIF($F$2:F15,F15,$U$2:U15) -> 0 | W15: =T15/(24*N15) -> 0.20467666 | X15: =IFERROR(U15/(24*N15*Q15),"") | Y15: =IFERROR(V15/(24*N15*SUMIFS($Q:$Q,$F:$F,$F15,$D:$D,"<="&D15)),"") | Z15: =IFERROR(AVERAGEIF('Daily KPI'!D:D,Table14[[#This Row],[Month]],'Daily KPI'!AB:AB),"") | AA15: =IFERROR(AVERAGEIF($F$2:F15,F15,$Z$2:Z15),"") | AD15: 0.995 | AE15: 0.997 | AF15: 0.999 | AW15: 1600000 | AX15: =AW15/1000 -> 1600
A16: =A15+1 -> 15 | B16: =B4 -> June | C16: =C4 -> 6 | D16: 45078 | E16: =YEAR(D16) -> 2023 | F16: FY24 | G16: =DAY(EOMONTH(D16,0)) -> 30 | H16: =H4 -> 140.1651 | I16: =I4 -> 157.11702 | K16: =K4 -> 24.699889 | M16: 1140 | N16: 10.507 | O16: =M16/I16/N16 -> 0.69056234 | P16: =I16/G16 -> 5.237234 | Q16: =COUNTIFS('Daily KPI'!D:D,D16,'Daily KPI'!K:K,">0") -> 0 | R16: =I16/G16*Q16 -> 0 | S16: =SUMIF($F$2:F16,F16,$R$2:R16) -> 0 | T16: =M16/G16 -> 38 | U16: =M16/G16*Q16 -> 0 | V16: =SUMIF($F$2:F16,F16,$U$2:U16) -> 0 | W16: =T16/(24*N16) -> 0.15069319 | X16: =IFERROR(U16/(24*N16*Q16),"") | Y16: =IFERROR(V16/(24*N16*SUMIFS($Q:$Q,$F:$F,$F16,$D:$D,"<="&D16)),"") | Z16: =IFERROR(AVERAGEIF('Daily KPI'!D:D,Table14[[#This Row],[Month]],'Daily KPI'!AB:AB),"") | AA16: =IFERROR(AVERAGEIF($F$2:F16,F16,$Z$2:Z16),"") | AD16: 0.995 | AE16: 0.997 | AF16: 0.999 | AW16: 1140000 | AX16: =AW16/1000 -> 1140
A17: =A16+1 -> 16 | B17: =B5 -> July | C17: =C5 -> 7 | D17: 45108 | E17: =YEAR(D17) -> 2023 | F17: FY24 | G17: =DAY(EOMONTH(D17,0)) -> 31 | H17: =H5 -> 122.3162 | I17: =I5 -> 132.35283 | K17: =K5 -> 23.799973 | M17: 990 | N17: 10.507 | O17: =M17/I17/N17 -> 0.71190693 | P17: =I17/G17 -> 4.2694462 | Q17: =COUNTIFS('Daily KPI'!D:D,D17,'Daily KPI'!K:K,">0") -> 0 | R17: =I17/G17*Q17 -> 0 | S17: =SUMIF($F$2:F17,F17,$R$2:R17) -> 0 | T17: =M17/G17 -> 31.935484 | U17: =M17/G17*Q17 -> 0 | V17: =SUMIF($F$2:F17,F17,$U$2:U17) -> 0 | W17: =T17/(24*N17) -> 0.12664368 | X17: =IFERROR(U17/(24*N17*Q17),"") | Y17: =IFERROR(V17/(24*N17*SUMIFS($Q:$Q,$F:$F,$F17,$D:$D,"<="&D17)),"") | Z17: =IFERROR(AVERAGEIF('Daily KPI'!D:D,Table14[[#This Row],[Month]],'Daily KPI'!AB:AB),"") | AA17: =IFERROR(AVERAGEIF($F$2:F17,F17,$Z$2:Z17),"") | AD17: 0.995 | AE17: 0.997 | AF17: 0.999 | AW17: 990000 | AX17: =AW17/1000 -> 990
A18: =A17+1 -> 17 | B18: =B6 -> August | C18: =C6 -> 8 | D18: 45139 | E18: =YEAR(D18) -> 2023 | F18: FY24 | G18: =DAY(EOMONTH(D18,0)) -> 31 | H18: =H6 -> 126.29284 | I18: =I6 -> 137.84954 | K18: =K6 -> 23.600054 | M18: 1040 | N18: 10.507 | O18: =M18/I18/N18 -> 0.71804109 | P18: =I18/G18 -> 4.4467593 | Q18: =COUNTIFS('Daily KPI'!D:D,D18,'Daily KPI'!K:K,">0") -> 0 | R18: =I18/G18*Q18 -> 0 | S18: =SUMIF($F$2:F18,F18,$R$2:R18) -> 0 | T18: =M18/G18 -> 33.548387 | U18: =M18/G18*Q18 -> 0 | V18: =SUMIF($F$2:F18,F18,$U$2:U18) -> 0 | W18: =T18/(24*N18) -> 0.13303983 | X18: =IFERROR(U18/(24*N18*Q18),"") | Y18: =IFERROR(V18/(24*N18*SUMIFS($Q:$Q,$F:$F,$F18,$D:$D,"<="&D18)),"") | Z18: =IFERROR(AVERAGEIF('Daily KPI'!D:D,Table14[[#This Row],[Month]],'Daily KPI'!AB:AB),"") | AA18: =IFERROR(AVERAGEIF($F$2:F18,F18,$Z$2:Z18),"") | AD18: 0.995 | AE18: 0.997 | AF18: 0.999 | AW18: 1040000 | AX18: =AW18/1000 -> 1040
A19: =A18+1 -> 18 | B19: =B7 -> September | C19: =C7 -> 9 | D19: 45170 | E19: =YEAR(D19) -> 2023 | F19: FY24 | G19: =DAY(EOMONTH(D19,0)) -> 30 | H19: =H7 -> 144.04475 | I19: =I7 -> 163.04046 | K19: =K7 -> 23.700139 | M19: 1180 | N19: 10.507 | O19: =M19/I19/N19 -> 0.68882339 | P19: =I19/G19 -> 5.4346819 | Q19: =COUNTIFS('Daily KPI'!D:D,D19,'Daily KPI'!K:K,">0") -> 0 | R19: =I19/G19*Q19 -> 0 | S19: =SUMIF($F$2:F19,F19,$R$2:R19) -> 0 | T19: =M19/G19 -> 39.333333 | U19: =M19/G19*Q19 -> 0 | V19: =SUMIF($F$2:F19,F19,$U$2:U19) -> 0 | W19: =T19/(24*N19) -> 0.15598067 | X19: =IFERROR(U19/(24*N19*Q19),"") | Y19: =IFERROR(V19/(24*N19*SUMIFS($Q:$Q,$F:$F,$F19,$D:$D,"<="&D19)),"") | Z19: =IFERROR(AVERAGEIF('Daily KPI'!D:D,Table14[[#This Row],[Month]],'Daily KPI'!AB:AB),"") | AA19: =IFERROR(AVERAGEIF($F$2:F19,F19,$Z$2:Z19),"") | AD19: 0.995 | AE19: 0.997 | AF19: 0.999 | AW19: 1180000 | AX19: =AW19/1000 -> 1180
A20: =A19+1 -> 19 | B20: =B8 -> October | C20: =C8 -> 10 | D20: 45200 | E20: =YEAR(D20) -> 2023 | F20: FY24 | G20: =DAY(EOMONTH(D20,0)) -> 31 | H20: =H8 -> 146.56699 | I20: =I8 -> 169.41865 | K20: =K8 -> 23.399852 | M20: 1680 | N20: 10.507 | O20: =M20/I20/N20 -> 0.94377687 | P20: =I20/G20 -> 5.4651178 | Q20: =COUNTIFS('Daily KPI'!D:D,D20,'Daily KPI'!K:K,">0") -> 0 | R20: =I20/G20*Q20 -> 0 | S20: =SUMIF($F$2:F20,F20,$R$2:R20) -> 0 | T20: =M20/G20 -> 54.193548 | U20: =M20/G20*Q20 -> 0 | V20: =SUMIF($F$2:F20,F20,$U$2:U20) -> 0 | W20: =T20/(24*N20) -> 0.21491049 | X20: =IFERROR(U20/(24*N20*Q20),"") | Y20: =IFERROR(V20/(24*N20*SUMIFS($Q:$Q,$F:$F,$F20,$D:$D,"<="&D20)),"") | Z20: =IFERROR(AVERAGEIF('Daily KPI'!D:D,Table14[[#This Row],[Month]],'Daily KPI'!AB:AB),"") | AA20: =IFERROR(AVERAGEIF($F$2:F20,F20,$Z$2:Z20),"") | AD20: 0.995 | AE20: 0.997 | AF20: 0.999 | AW20: 1680000 | AX20: =AW20/1000 -> 1680
A21: =A20+1 -> 20 | B21: =B9 -> November | C21: =C9 -> 11 | D21: 45231 | E21: =YEAR(D21) -> 2023 | F21: FY24 | G21: =DAY(EOMONTH(D21,0)) -> 30 | H21: =H9 -> 136.38301 | I21: =I9 -> 157.92066 | K21: =K9 -> 22.499958 | M21: 1530 | N21: 10.507 | O21: =M21/I21/N21 -> 0.92209095 | P21: =I21/G21 -> 5.2640218 | Q21: =COUNTIFS('Daily KPI'!D:D,D21,'Daily KPI'!K:K,">0") -> 0 | R21: =I21/G21*Q21 -> 0 | S21: =SUMIF($F$2:F21,F21,$R$2:R21) -> 0 | T21: =M21/G21 -> 51 | U21: =M21/G21*Q21 -> 0 | V21: =SUMIF($F$2:F21,F21,$U$2:U21) -> 0 | W21: =T21/(24*N21) -> 0.20224612 | X21: =IFERROR(U21/(24*N21*Q21),"") | Y21: =IFERROR(V21/(24*N21*SUMIFS($Q:$Q,$F:$F,$F21,$D:$D,"<="&D21)),"") | Z21: =IFERROR(AVERAGEIF('Daily KPI'!D:D,Table14[[#This Row],[Month]],'Daily KPI'!AB:AB),"") | AA21: =IFERROR(AVERAGEIF($F$2:F21,F21,$Z$2:Z21),"") | AD21: 0.995 | AE21: 0.997 | AF21: 0.999 | AW21: 1530000 | AX21: =AW21/1000 -> 1530
A22: =A21+1 -> 21 | B22: =B10 -> December | C22: =C10 -> 12 | D22: 45261 | E22: =YEAR(D22) -> 2023 | F22: FY24 | G22: =DAY(EOMONTH(D22,0)) -> 31 | H22: =H10 -> 149.37928 | I22: =I10 -> 175.8024 | K22: =K10 -> 21.49297 | M22: 1760 | N22: 10.507 | O22: =M22/I22/N22 -> 0.9528162 | P22: =I22/G22 -> 5.6710452 | Q22: =COUNTIFS('Daily KPI'!D:D,D22,'Daily KPI'!K:K,">0") -> 0 | R22: =I22/G22*Q22 -> 0 | S22: =SUMIF($F$2:F22,F22,$R$2:R22) -> 0 | T22: =M22/G22 -> 56.774194 | U22: =M22/G22*Q22 -> 0 | V22: =SUMIF($F$2:F22,F22,$U$2:U22) -> 0 | W22: =T22/(24*N22) -> 0.22514432 | X22: =IFERROR(U22/(24*N22*Q22),"") | Y22: =IFERROR(V22/(24*N22*SUMIFS($Q:$Q,$F:$F,$F22,$D:$D,"<="&D22)),"") | Z22: =IFERROR(AVERAGEIF('Daily KPI'!D:D,Table14[[#This Row],[Month]],'Daily KPI'!AB:AB),"") | AA22: =IFERROR(AVERAGEIF($F$2:F22,F22,$Z$2:Z22),"") | AD22: 0.995 | AE22: 0.997 | AF22: 0.999 | AW22: 1760000 | AX22: =AW22/1000 -> 1760
A23: =A22+1 -> 22 | B23: =B11 -> January | C23: =C11 -> 1 | D23: 45292 | E23: =YEAR(D23) -> 2024 | F23: FY24 | G23: =DAY(EOMONTH(D23,0)) -> 31 | H23: =H11 -> 172.65915 | I23: =I11 -> 210.74159 | K23: =K11 -> 22.099987 | M23: 2110 | N23: 10.507 | O23: =M23/I23/N23 -> 0.95291349 | P23: =I23/G23 -> 6.7981157 | Q23: =COUNTIFS('Daily KPI'!D:D,D23,'Daily KPI'!K:K,">0") -> 0 | R23: =I23/G23*Q23 -> 0 | S23: =SUMIF($F$2:F23,F23,$R$2:R23) -> 0 | T23: =M23/G23 -> 68.064516 | U23: =M23/G23*Q23 -> 0 | V23: =SUMIF($F$2:F23,F23,$U$2:U23) -> 0 | W23: =T23/(24*N23) -> 0.26991734 | X23: =IFERROR(U23/(24*N23*Q23),"") | Y23: =IFERROR(V23/(24*N23*SUMIFS($Q:$Q,$F:$F,$F23,$D:$D,"<="&D23)),"") | Z23: =IFERROR(AVERAGEIF('Daily KPI'!D:D,Table14[[#This Row],[Month]],'Daily KPI'!AB:AB),"") | AA23: =IFERROR(AVERAGEIF($F$2:F23,F23,$Z$2:Z23),"") | AD23: 0.995 | AE23: 0.997 | AF23: 0.999 | AW23: 2110000 | AX23: =AW23/1000 -> 2110
A24: =A23+1 -> 23 | B24: =B12 -> February | C24: =C12 -> 2 | D24: 45323 | E24: =YEAR(D24) -> 2024 | F24: FY24 | G24: =DAY(EOMONTH(D24,0)) -> 29 | H24: =H12 -> 174.40611 | I24: =I12 -> 212.78878 | K24: =K12 -> 24.199896 | M24: 1960 | N24: 10.507 | O24: =M24/I24/N24 -> 0.87665479 | P24: =I24/G24 -> 7.3375442 | Q24: =COUNTIFS('Daily KPI'!D:D,D24,'Daily KPI'!K:K,">0") -> 0 | R24: =I24/G24*Q24 -> 0 | S24: =SUMIF($F$2:F24,F24,$R$2:R24) -> 0 | T24: =M24/G24 -> 67.586207 | U24: =M24/G24*Q24 -> 0 | V24: =SUMIF($F$2:F24,F24,$U$2:U24) -> 0 | W24: =T24/(24*N24) -> 0.26802055 | X24: =IFERROR(U24/(24*N24*Q24),"") | Y24: =IFERROR(V24/(24*N24*SUMIFS($Q:$Q,$F:$F,$F24,$D:$D,"<="&D24)),"") | Z24: =IFERROR(AVERAGEIF('Daily KPI'!D:D,Table14[[#This Row],[Month]],'Daily KPI'!AB:AB),"") | AA24: =IFERROR(AVERAGEIF($F$2:F24,F24,$Z$2:Z24),"") | AD24: 0.995 | AE24: 0.997 | AF24: 0.999 | AW24: 1960000 | AX24: =AW24/1000 -> 1960
A25: =A24+1 -> 24 | B25: =B13 -> March | C25: =C13 -> 3 | D25: 45352 | E25: =YEAR(D25) -> 2024 | F25: FY24 | G25: =DAY(EOMONTH(D25,0)) -> 31 | H25: =H13 -> 205.4467 | I25: =I13 -> 247.38206 | K25: =K13 -> 26.700255 | M25: 2400 | N25: 10.507 | O25: =M25/I25/N25 -> 0.92334567 | P25: =I25/G25 -> 7.9800663 | Q25: =COUNTIFS('Daily KPI'!D:D,D25,'Daily KPI'!K:K,">0") -> 0 | R25: =I25/G25*Q25 -> 0 | S25: =SUMIF($F$2:F25,F25,$R$2:R25) -> 0 | T25: =M25/G25 -> 77.419355 | U25: =M25/G25*Q25 -> 0 | V25: =SUMIF($F$2:F25,F25,$U$2:U25) -> 0 | W25: =T25/(24*N25) -> 0.30701499 | X25: =IFERROR(U25/(24*N25*Q25),"") | Y25: =IFERROR(V25/(24*N25*SUMIFS($Q:$Q,$F:$F,$F25,$D:$D,"<="&D25)),"") | Z25: =IFERROR(AVERAGEIF('Daily KPI'!D:D,Table14[[#This Row],[Month]],'Daily KPI'!AB:AB),"") | AA25: =IFERROR(AVERAGEIF($F$2:F25,F25,$Z$2:Z25),"") | AD25: 0.995 | AE25: 0.997 | AF25: 0.999 | AW25: 2400000 | AX25: =AW25/1000 -> 2400
A26: =A25+1 -> 25 | B26: =B14 -> April | C26: 4 | D26: 45383 | E26: =YEAR(D26) -> 2024 | F26: FY25 | G26: =DAY(EOMONTH(D26,0)) -> 30 | H26: =H14 -> 192.7392 | I26: =I14 -> 227.6882 | K26: =K14 -> 27.499986 | M26: 1598.2 | N26: 10.507 | O26: =M26/I26/N26 -> 0.66805445 | P26: =I26/G26 -> 7.5896068 | Q26: =COUNTIFS('Daily KPI'!D:D,D26,'Daily KPI'!K:K,">0") -> 0 | R26: =I26/G26*Q26 -> 0 | S26: =SUMIF($F$2:F26,F26,$R$2:R26) -> 0 | T26: =M26/G26 -> 53.273333 | U26: =M26/G26*Q26 -> 0 | V26: =SUMIF($F$2:F26,F26,$U$2:U26) -> 0 | W26: =T26/(24*N26) -> 0.21126128 | X26: =IFERROR(U26/(24*N26*Q26),"") | Y26: =IFERROR(V26/(24*N26*SUMIFS($Q:$Q,$F:$F,$F26,$D:$D,"<="&D26)),"") | Z26: =IFERROR(AVERAGEIF('Daily KPI'!D:D,Table14[[#This Row],[Month]],'Daily KPI'!AB:AB),"") | AA26: =IFERROR(AVERAGEIF($F$2:F26,F26,$Z$2:Z26),"") | AD26: 0.995 | AE26: 0.997 | AF26: 0.999 | AW26: 1598200 | AX26: =AW26/1000 -> 1598.2
A27: =A26+1 -> 26 | B27: =B15 -> May | C27: 5 | D27: 45413 | E27: =YEAR(D27) -> 2024 | F27: FY25 | G27: =DAY(EOMONTH(D27,0)) -> 31 | H27: =H15 -> 184.49337 | I27: =I15 -> 215.54431 | K27: =K15 -> 26.700081 | M27: 1587.9 | N27: 10.507 | O27: =M27/I27/N27 -> 0.70114502 | P27: =I27/G27 -> 6.9530422 | Q27: =COUNTIFS('Daily KPI'!D:D,D27,'Daily KPI'!K:K,">0") -> 0 | R27: =I27/G27*Q27 -> 0 | S27: =SUMIF($F$2:F27,F27,$R$2:R27) -> 0 | T27: =M27/G27 -> 51.222581 | U27: =M27/G27*Q27 -> 0 | V27: =SUMIF($F$2:F27,F27,$U$2:U27) -> 0 | W27: =T27/(24*N27) -> 0.20312879 | X27: =IFERROR(U27/(24*N27*Q27),"") | Y27: =IFERROR(V27/(24*N27*SUMIFS($Q:$Q,$F:$F,$F27,$D:$D,"<="&D27)),"") | Z27: =IFERROR(AVERAGEIF('Daily KPI'!D:D,Table14[[#This Row],[Month]],'Daily KPI'!AB:AB),"") | AA27: =IFERROR(AVERAGEIF($F$2:F27,F27,$Z$2:Z27),"") | AD27: 0.995 | AE27: 0.997 | AF27: 0.999 | AW27: 1587900 | AX27: =AW27/1000 -> 1587.9
A28: =A27+1 -> 27 | B28: =B16 -> June | C28: 6 | D28: 45444 | E28: =YEAR(D28) -> 2024 | F28: FY25 | G28: =DAY(EOMONTH(D28,0)) -> 30 | H28: =H16 -> 140.1651 | I28: =I16 -> 157.11702 | K28: =K16 -> 24.699889 | M28: 1131.6 | N28: 10.507 | O28: =M28/I28/N28 -> 0.68547398 | P28: =I28/G28 -> 5.237234 | Q28: =COUNTIFS('Daily KPI'!D:D,D28,'Daily KPI'!K:K,">0") -> 0 | R28: =I28/G28*Q28 -> 0 | S28: =SUMIF($F$2:F28,F28,$R$2:R28) -> 0 | T28: =M28/G28 -> 37.72 | U28: =M28/G28*Q28 -> 0 | V28: =SUMIF($F$2:F28,F28,$U$2:U28) -> 0 | W28: =T28/(24*N28) -> 0.14958282 | X28: =IFERROR(U28/(24*N28*Q28),"") | Y28: =IFERROR(V28/(24*N28*SUMIFS($Q:$Q,$F:$F,$F28,$D:$D,"<="&D28)),"") | Z28: =IFERROR(AVERAGEIF('Daily KPI'!D:D,Table14[[#This Row],[Month]],'Daily KPI'!AB:AB),"") | AA28: =IFERROR(AVERAGEIF($F$2:F28,F28,$Z$2:Z28),"") | AD28: 0.995 | AE28: 0.997 | AF28: 0.999 | AW28: 1131600 | AX28: =AW28/1000 -> 1131.6
A29: =A28+1 -> 28 | B29: =B17 -> July | C29: 7 | D29: 45474 | E29: =YEAR(D29) -> 2024 | F29: FY25 | G29: =DAY(EOMONTH(D29,0)) -> 31 | H29: =H17 -> 122.3162 | I29: =I17 -> 132.35283 | K29: =K17 -> 23.799973 | M29: 982.5 | N29: 10.507 | O29: =M29/I29/N29 -> 0.70651369 | P29: =I29/G29 -> 4.2694462 | Q29: =COUNTIFS('Daily KPI'!D:D,D29,'Daily KPI'!K:K,">0") -> 0 | R29: =I29/G29*Q29 -> 0 | S29: =SUMIF($F$2:F29,F29,$R$2:R29) -> 0 | T29: =M29/G29 -> 31.693548 | U29: =M29/G29*Q29 -> 0 | V29: =SUMIF($F$2:F29,F29,$U$2:U29) -> 0 | W29: =T29/(24*N29) -> 0.12568426 | X29: =IFERROR(U29/(24*N29*Q29),"") | Y29: =IFERROR(V29/(24*N29*SUMIFS($Q:$Q,$F:$F,$F29,$D:$D,"<="&D29)),"") | Z29: =IFERROR(AVERAGEIF('Daily KPI'!D:D,Table14[[#This Row],[Month]],'Daily KPI'!AB:AB),"") | AA29: =IFERROR(AVERAGEIF($F$2:F29,F29,$Z$2:Z29),"") | AD29: 0.995 | AE29: 0.997 | AF29: 0.999 | AW29: 982500 | AX29: =AW29/1000 -> 982.5
A30: =A29+1 -> 29 | B30: =B18 -> August | C30: 8 | D30: 45505 | E30: =YEAR(D30) -> 2024 | F30: FY25 | G30: =DAY(EOMONTH(D30,0)) -> 31 | H30: =H18 -> 126.29284 | I30: =I18 -> 137.84954 | K30: =K18 -> 23.600054 | M30: 1032.2 | N30: 10.507 | O30: =M30/I30/N30 -> 0.71265578 | P30: =I30/G30 -> 4.4467593 | Q30: =COUNTIFS('Daily KPI'!D:D,D30,'Daily KPI'!K:K,">0") -> 0 | R30: =I30/G30*Q30 -> 0 | S30: =SUMIF($F$2:F30,F30,$R$2:R30) -> 0 | T30: =M30/G30 -> 33.296774 | U30: =M30/G30*Q30 -> 0 | V30: =SUMIF($F$2:F30,F30,$U$2:U30) -> 0 | W30: =T30/(24*N30) -> 0.13204203 | X30: =IFERROR(U30/(24*N30*Q30),"") | Y30: =IFERROR(V30/(24*N30*SUMIFS($Q:$Q,$F:$F,$F30,$D:$D,"<="&D30)),"") | Z30: =IFERROR(AVERAGEIF('Daily KPI'!D:D,Table14[[#This Row],[Month]],'Daily KPI'!AB:AB),"") | AA30: =IFERROR(AVERAGEIF($F$2:F30,F30,$Z$2:Z30),"") | AD30: 0.995 | AE30: 0.997 | AF30: 0.999 | AW30: 1032200 | AX30: =AW30/1000 -> 1032.2
A31: =A30+1 -> 30 | B31: =B19 -> September | C31: 9 | D31: 45536 | E31: =YEAR(D31) -> 2024 | F31: FY25 | G31: =DAY(EOMONTH(D31,0)) -> 30 | H31: =H19 -> 144.04475 | I31: =I19 -> 163.04046 | K31: =K19 -> 23.700139 | M31: 1171.3 | N31: 10.507 | O31: =M31/I31/N31 -> 0.68374478 | P31: =I31/G31 -> 5.4346819 | Q31: =COUNTIFS('Daily KPI'!D:D,D31,'Daily KPI'!K:K,">0") -> 0 | R31: =I31/G31*Q31 -> 0 | S31: =SUMIF($F$2:F31,F31,$R$2:R31) -> 0 | T31: =M31/G31 -> 39.043333 | U31: =M31/G31*Q31 -> 0 | V31: =SUMIF($F$2:F31,F31,$U$2:U31) -> 0 | W31: =T31/(24*N31) -> 0.15483064 | X31: =IFERROR(U31/(24*N31*Q31),"") | Y31: =IFERROR(V31/(24*N31*SUMIFS($Q:$Q,$F:$F,$F31,$D:$D,"<="&D31)),"") | Z31: =IFERROR(AVERAGEIF('Daily KPI'!D:D,Table14[[#This Row],[Month]],'Daily KPI'!AB:AB),"") | AA31: =IFERROR(AVERAGEIF($F$2:F31,F31,$Z$2:Z31),"") | AD31: 0.995 | AE31: 0.997 | AF31: 0.999 | AW31: 1171300 | AX31: =AW31/1000 -> 1171.3
A32: =A31+1 -> 31 | B32: =B20 -> October | C32: 10 | D32: 45566 | E32: =YEAR(D32) -> 2024 | F32: FY25 | G32: =DAY(EOMONTH(D32,0)) -> 31 | H32: =H20 -> 146.56699 | I32: =I20 -> 169.41865 | K32: =K20 -> 23.399852 | M32: 1280.3 | N32: 10.507 | O32: =M32/I32/N32 -> 0.71923662 | P32: =I32/G32 -> 5.4651178 | Q32: =COUNTIFS('Daily KPI'!D:D,D32,'Daily KPI'!K:K,">0") -> 0 | R32: =I32/G32*Q32 -> 0 | S32: =SUMIF($F$2:F32,F32,$R$2:R32) -> 0 | T32: =M32/G32 -> 41.3 | U32: =M32/G32*Q32 -> 0 | V32: =SUMIF($F$2:F32,F32,$U$2:U32) -> 0 | W32: =T32/(24*N32) -> 0.1637797 | X32: =IFERROR(U32/(24*N32*Q32),"") | Y32: =IFERROR(V32/(24*N32*SUMIFS($Q:$Q,$F:$F,$F32,$D:$D,"<="&D32)),"") | Z32: =IFERROR(AVERAGEIF('Daily KPI'!D:D,Table14[[#This Row],[Month]],'Daily KPI'!AB:AB),"") | AA32: =IFERROR(AVERAGEIF($F$2:F32,F32,$Z$2:Z32),"") | AD32: 0.995 | AE32: 0.997 | AF32: 0.999 | AW32: 1280300 | AX32: =AW32/1000 -> 1280.3
A33: =A32+1 -> 32 | B33: =B21 -> November | C33: 11 | D33: 45597 | E33: =YEAR(D33) -> 2024 | F33: FY25 | G33: =DAY(EOMONTH(D33,0)) -> 30 | H33: =H21 -> 136.38301 | I33: =I21 -> 157.92066 | K33: =K21 -> 22.499958 | M33: 1171.3 | N33: 10.507 | O33: =M33/I33/N33 -> 0.70591185 | P33: =I33/G33 -> 5.2640218 | Q33: =COUNTIFS('Daily KPI'!D:D,D33,'Daily KPI'!K:K,">0") -> 0 | R33: =I33/G33*Q33 -> 0 | S33: =SUMIF($F$2:F33,F33,$R$2:R33) -> 0 | T33: =M33/G33 -> 39.043333 | U33: =M33/G33*Q33 -> 0 | V33: =SUMIF($F$2:F33,F33,$U$2:U33) -> 0 | W33: =T33/(24*N33) -> 0.15483064 | X33: =IFERROR(U33/(24*N33*Q33),"") | Y33: =IFERROR(V33/(24*N33*SUMIFS($Q:$Q,$F:$F,$F33,$D:$D,"<="&D33)),"") | Z33: =IFERROR(AVERAGEIF('Daily KPI'!D:D,Table14[[#This Row],[Month]],'Daily KPI'!AB:AB),"") | AA33: =IFERROR(AVERAGEIF($F$2:F33,F33,$Z$2:Z33),"") | AD33: 0.995 | AE33: 0.997 | AF33: 0.999 | AW33: 1171300 | AX33: =AW33/1000 -> 1171.3
A34: =A33+1 -> 33 | B34: =B22 -> December | C34: 12 | D34: 45627 | E34: =YEAR(D34) -> 2024 | F34: FY25 | G34: =DAY(EOMONTH(D34,0)) -> 31 | H34: =H22 -> 149.37928 | I34: =I22 -> 175.8024 | K34: =K22 -> 21.49297 | M34: 1349.7 | N34: 10.507 | O34: =M34/I34/N34 -> 0.73069092 | P34: =I34/G34 -> 5.6710452 | Q34: =COUNTIFS('Daily KPI'!D:D,D34,'Daily KPI'!K:K,">0") -> 0 | R34: =I34/G34*Q34 -> 0 | S34: =SUMIF($F$2:F34,F34,$R$2:R34) -> 0 | T34: =M34/G34 -> 43.53871 | U34: =M34/G34*Q34 -> 0 | V34: =SUMIF($F$2:F34,F34,$U$2:U34) -> 0 | W34: =T34/(24*N34) -> 0.17265755 | X34: =IFERROR(U34/(24*N34*Q34),"") | Y34: =IFERROR(V34/(24*N34*SUMIFS($Q:$Q,$F:$F,$F34,$D:$D,"<="&D34)),"") | Z34: =IFERROR(AVERAGEIF('Daily KPI'!D:D,Table14[[#This Row],[Month]],'Daily KPI'!AB:AB),"") | AA34: =IFERROR(AVERAGEIF($F$2:F34,F34,$Z$2:Z34),"") | AD34: 0.995 | AE34: 0.997 | AF34: 0.999 | AW34: 1349700 | AX34: =AW34/1000 -> 1349.7
A35: =A34+1 -> 34 | B35: =B23 -> January | C35: 1 | D35: 45658 | E35: =YEAR(D35) -> 2025 | F35: FY25 | G35: =DAY(EOMONTH(D35,0)) -> 31 | H35: =H23 -> 172.65915 | I35: =I23 -> 210.74159 | K35: =K23 -> 22.099987 | M35: 1607.8 | N35: 10.507 | O35: =M35/I35/N35 -> 0.72611105 | P35: =I35/G35 -> 6.7981157 | Q35: =COUNTIFS('Daily KPI'!D:D,D35,'Daily KPI'!K:K,">0") -> 0 | R35: =I35/G35*Q35 -> 0 | S35: =SUMIF($F$2:F35,F35,$R$2:R35) -> 0 | T35: =M35/G35 -> 51.864516 | U35: =M35/G35*Q35 -> 0 | V35: =SUMIF($F$2:F35,F35,$U$2:U35) -> 0 | W35: =T35/(24*N35) -> 0.20567446 | X35: =IFERROR(U35/(24*N35*Q35),"") | Y35: =IFERROR(V35/(24*N35*SUMIFS($Q:$Q,$F:$F,$F35,$D:$D,"<="&D35)),"") | Z35: =IFERROR(AVERAGEIF('Daily KPI'!D:D,Table14[[#This Row],[Month]],'Daily KPI'!AB:AB),"") | AA35: =IFERROR(AVERAGEIF($F$2:F35,F35,$Z$2:Z35),"") | AD35: 0.995 | AE35: 0.997 | AF35: 0.999 | AW35: 1607800 | AX35: =AW35/1000 -> 1607.8
A36: =A35+1 -> 35 | B36: =B24 -> February | C36: 2 | D36: 45689 | E36: =YEAR(D36) -> 2025 | F36: FY25 | G36: =DAY(EOMONTH(D36,0)) -> 28 | H36: =H24 -> 174.40611 | I36: =I24 -> 212.78878 | K36: =K24 -> 24.199896 | M36: 1479.9 | N36: 10.507 | O36: =M36/I36/N36 -> 0.66191909 | P36: =I36/G36 -> 7.5995994 | Q36: =COUNTIFS('Daily KPI'!D:D,D36,'Daily KPI'!K:K,">0") -> 0 | R36: =I36/G36*Q36 -> 0 | S36: =SUMIF($F$2:F36,F36,$R$2:R36) -> 0 | T36: =M36/G36 -> 52.853571 | U36: =M36/G36*Q36 -> 0 | V36: =SUMIF($F$2:F36,F36,$U$2:U36) -> 0 | W36: =T36/(24*N36) -> 0.20959666 | X36: =IFERROR(U36/(24*N36*Q36),"") | Y36: =IFERROR(V36/(24*N36*SUMIFS($Q:$Q,$F:$F,$F36,$D:$D,"<="&D36)),"") | Z36: =IFERROR(AVERAGEIF('Daily KPI'!D:D,Table14[[#This Row],[Month]],'Daily KPI'!AB:AB),"") | AA36: =IFERROR(AVERAGEIF($F$2:F36,F36,$Z$2:Z36),"") | AD36: 0.995 | AE36: 0.997 | AF36: 0.999 | AW36: 1479900 | AX36: =AW36/1000 -> 1479.9
A37: =A36+1 -> 36 | B37: =B25 -> March | C37: 3 | D37: 45717 | E37: =YEAR(D37) -> 2025 | F37: FY25 | G37: =DAY(EOMONTH(D37,0)) -> 31 | H37: =H25 -> 205.4467 | I37: =I25 -> 247.38206 | K37: =K25 -> 26.700255 | M37: 1826.1 | N37: 10.507 | O37: =M37/I37/N37 -> 0.70255063 | P37: =I37/G37 -> 7.9800663 | Q37: =COUNTIFS('Daily KPI'!D:D,D37,'Daily KPI'!K:K,">0") -> 3 | R37: =I37/G37*Q37 -> 23.940199 | S37: =SUMIF($F$2:F37,F37,$R$2:R37) -> 23.940199 | T37: =M37/G37 -> 58.906452 | U37: =M37/G37*Q37 -> 176.71935 | V37: =SUMIF($F$2:F37,F37,$U$2:U37) -> 176.71935 | W37: =T37/(24*N37) -> 0.23360003 | X37: =IFERROR(U37/(24*N37*Q37),"") -> 0.23360003 | Y37: =IFERROR(V37/(24*N37*SUMIFS($Q:$Q,$F:$F,$F37,$D:$D,"<="&D37)),"") -> 0.23360003 | Z37: =IFERROR(AVERAGEIF('Daily KPI'!D:D,Table14[[#This Row],[Month]],'Daily KPI'!AB:AB),"") -> 10.507 | AA37: =IFERROR(AVERAGEIF($F$2:F37,F37,$Z$2:Z37),"") -> 10.507 | AD37: 0.995 | AE37: 0.997 | AF37: 0.999 | AW37: 1826100 | AX37: =AW37/1000 -> 1826.1
A38: =A37+1 -> 37 | B38: =B26 -> April | C38: =C26 -> 4 | D38: 45748 | E38: =YEAR(D38) -> 2025 | F38: FY26 | G38: =DAY(EOMONTH(D38,0)) -> 30 | H38: =H26 -> 192.7392 | I38: =I26 -> 227.6882 | K38: =K26 -> 27.499986 | M38: 1584.5717 | N38: 10.507 | O38: =M38/I38/N38 -> 0.66235776 | P38: =I38/G38 -> 7.5896068 | Q38: =COUNTIFS('Daily KPI'!D:D,D38,'Daily KPI'!K:K,">0") -> 30 | R38: =I38/G38*Q38 -> 227.6882 | S38: =SUMIF($F$2:F38,F38,$R$2:R38) -> 227.6882 | T38: =M38/G38 -> 52.819056 | U38: =M38/G38*Q38 -> 1584.5717 | V38: =SUMIF($F$2:F38,F38,$U$2:U38) -> 1584.5717 | W38: =T38/(24*N38) -> 0.20945979 | X38: =IFERROR(U38/(24*N38*Q38),"") -> 0.20945979 | Y38: =IFERROR(V38/(24*N38*SUMIFS($Q:$Q,$F:$F,$F38,$D:$D,"<="&D38)),"") -> 0.20945979 | Z38: =IFERROR(AVERAGEIF('Daily KPI'!D:D,Table14[[#This Row],[Month]],'Daily KPI'!AB:AB),"") -> 10.507 | AA38: =IFERROR(AVERAGEIF($F$2:F38,F38,$Z$2:Z38),"") -> 10.507 | AD38: 0.995 | AE38: 0.997 | AF38: 0.999
A39: =A38+1 -> 38 | B39: =B27 -> May | C39: =C27 -> 5 | D39: 45778 | E39: =YEAR(D39) -> 2025 | F39: FY26 | G39: =DAY(EOMONTH(D39,0)) -> 31 | H39: =H27 -> 184.49337 | I39: =I27 -> 215.54431 | K39: =K27 -> 26.700081 | M39: 1574.4307 | N39: 10.507 | O39: =M39/I39/N39 -> 0.69519759 | P39: =I39/G39 -> 6.9530422 | Q39: =COUNTIFS('Daily KPI'!D:D,D39,'Daily KPI'!K:K,">0") -> 31 | R39: =I39/G39*Q39 -> 215.54431 | S39: =SUMIF($F$2:F49,F39,$R$2:R49) -> 741.59588 | T39: =M39/G39 -> 50.788087 | U39: =M39/G39*Q39 -> 1574.4307 | V39: =SUMIF($F$2:F49,F39,$U$2:U49) -> 5321.2008 | W39: =T39/(24*N39) -> 0.20140576 | X39: =IFERROR(U39/(24*N39*Q39),"") -> 0.20140576 | Y39: =IFERROR(V39/(24*N39*SUMIFS($Q:$Q,$F:$F,$F39,$D:$D,"<="&D39)),"") -> 0.34593128 | Z39: =IFERROR(AVERAGEIF('Daily KPI'!D:D,Table14[[#This Row],[Month]],'Daily KPI'!AB:AB),"") -> 10.507 | AA39: =IFERROR(AVERAGEIF($F$2:F39,F39,$Z$2:Z39),"") -> 10.507 | AD39: 0.995 | AE39: 0.997 | AF39: 0.999
A40: =A39+1 -> 39 | B40: =B28 -> June | C40: =C28 -> 6 | D40: 45809 | E40: =YEAR(D40) -> 2025 | F40: FY26 | G40: =DAY(EOMONTH(D40,0)) -> 30 | H40: =H28 -> 140.1651 | I40: =I28 -> 157.11702 | K40: =K28 -> 24.699889 | M40: 1121.9949 | N40: 10.507 | O40: =M40/I40/N40 -> 0.67965561 | P40: =I40/G40 -> 5.237234 | Q40: =COUNTIFS('Daily KPI'!D:D,D40,'Daily KPI'!K:K,">0") -> 30 | R40: =I40/G40*Q40 -> 157.11702 | S40: =SUMIF($F$2:F40,F40,$R$2:R40) -> 600.34953 | T40: =M40/G40 -> 37.399829 | U40: =M40/G40*Q40 -> 1121.9949 | V40: =SUMIF($F$2:F40,F40,$U$2:U40) -> 4280.9973 | W40: =T40/(24*N40) -> 0.14831314 | X40: =IFERROR(U40/(24*N40*Q40),"") -> 0.14831314 | Y40: =IFERROR(V40/(24*N40*SUMIFS($Q:$Q,$F:$F,$F40,$D:$D,"<="&D40)),"") -> 0.18655787 | Z40: =IFERROR(AVERAGEIF('Daily KPI'!D:D,Table14[[#This Row],[Month]],'Daily KPI'!AB:AB),"") -> 10.507 | AA40: =IFERROR(AVERAGEIF($F$2:F40,F40,$Z$2:Z40),"") -> 10.507 | AD40: 0.995 | AE40: 0.997 | AF40: 0.999
...

Sheet CMS_Data
B4: Daily
B6: Tagname | C6: Date | D6: Target | E6: Actual | F6: Difference
B7: E Grid Target | C7: ='Daily Dashboard'!B3 -> 45871 | D7: ='Daily Dashboard'!C9 -> 33.012257 | E7: ='Daily Dashboard'!D9 -> 42.33402 | F7: =D7-E7 -> -9.3217632
B8: Shadding | C8: =$C$7 -> 45871 | D8: 0 | E8: 0 | F8: 0
B9: Soiling | C9: =$C$7 -> 45871 | D9: 0 | E9: 0 | F9: 0
B10: IAM | C10: =$C$7 -> 45871 | D10: 0 | E10: 0 | F10: 0
B11: Bifacial Gain | C11: =$C$7 -> 45871 | D11: 0 | E11: 0 | F11: 0
B12: Temperature | C12: =$C$7 -> 45871 | D12: 0 | E12: 0 | F12: 0
B13: Mismatch | C13: =$C$7 -> 45871 | D13: 0 | E13: 0 | F13: 0
B14: DC Ohmic | C14: =$C$7 -> 45871 | D14: 0 | E14: 0 | F14: 0
B15: AC Ohmic | C15: =$C$7 -> 45871 | D15: 0 | E15: 0 | F15: 0
B16: Inverter Conversion | C16: =$C$7 -> 45871 | D16: 0 | E16: 0 | F16: 0
B17: MPPT Mismatch | C17: =$C$7 -> 45871 | D17: 0 | E17: 0 | F17: 0
B18: Clipping Loss | C18: =$C$7 -> 45871 | D18: 0 | E18: 0 | F18: 0
B19: Curtailment Order | C19: =$C$7 -> 45871 | D19: 0 | E19: 0 | F19: 0
B20: Reactive Power | C20: =$C$7 -> 45871 | D20: 0 | E20: 0 | F20: 0
B21: Plant Uptime | C21: =$C$7 -> 45871 | D21: ='Daily Dashboard'!C21*100 -> 99.5 | E21: ='Daily Dashboard'!D21*100 -> 99.180021 | F21: =E21-D21 -> -0.319979 | G21: =(F21/100)*$D$7 -> -0.10563229
B22: Grid Uptime | C22: =$C$7 -> 45871 | D22: ='Daily Dashboard'!C24*100 -> 99.7 | E22: ='Daily Dashboard'!D24*100 -> 100 | F22: =E22-D22 -> 0.3 | G22: =(F22/100)*$D$7 -> 0.09903677
B23: Tracker Uptime | C23: =$C$7 -> 45871 | D23: ='Daily Dashboard'!C27*100 -> 99.9 | E23: ='Daily Dashboard'!D27*100 -> 100 | F23: =E23-D23 -> 0.1 | G23: =((F23/100)*$D$7)*20% -> 0.0066024514
B24: Tracker Gain | C24: =$C$7 -> 45871 | D24: 0 | E24: 0 | F24: 0
B25: Dc Unbalanced Load | C25: =$C$7 -> 45871 | D25: 0 | E25: 0 | F25: 0
B26: Measured | C26: =$C$7 -> 45871 | D26: ='Daily Dashboard'!$D$9 -> 42.33402 | E26: ='Daily Dashboard'!$D$9 -> 42.33402 | F26: ='Daily Dashboard'!$D$9 -> 42.33402
B27: Repowering Delay | C27: =$C$7 -> 45871 | D27: 0 | E27: 0 | F27: 0
B28: Capacity Shortfall | C28: =$C$7 -> 45871 | D28: 0 | E28: 0 | F28: 0
B29: PR | C29: =$C$7 -> 45871 | D29: 0 | E29: =-(F7+G30)+(SUM(G21:G23)) -> 0.50040017 | F29: =E29 -> 0.50040017
B30: POA | C30: =$C$7 -> 45871 | D30: ='Daily Dashboard'!C18 -> 4.4467593 | E30: ='Daily Dashboard'!D18 -> 5.635 | F30: =E30-D30 -> 1.1882407 | G30: =(F30/D30)*D7 -> 8.82137

Sheet Monthly KPI
A1: Till Date | B1: ='Daily Dashboard'!B3 -> 45871
A2: ES Energy Private Limited Performance Summary
A3: Year | B3: Days | C3: Estimated POA(KWh/m2) | D3: Measured POA (KWh/m2) | E3: Budgeted Energy (MWh) | F3: Measured Energy (MWh) | G3: Targt PR (%) | H3: Measured PR(%) | I3: Target DC CUF (%) | J3: Measured DC CUF (%) | K3: Target GA (%) | L3: Measured GA (%) | M3: Target PA (%) | N3: Measured PA (%) | O3: Target TA (%) | P3: Measured TA (%)
A4: ='Daily Dashboard'!$B$2 -> 45870 | B4: =DAY(B1) -> 2 | C4: =_xlfn.XLOOKUP($A4,'Modelling New'!$D:$D,'Modelling New'!R:R) -> 8.8935185 | D4: =SUMIF('Daily KPI'!$D:$D,A4,'Daily KPI'!I:I) -> 9.48 | E4: =_xlfn.XLOOKUP($A4,'Modelling New'!$D:$D,'Modelling New'!U:U) -> 66.024514 | F4: =SUMIF('Daily KPI'!$D:$D,'Monthly KPI'!$A4,'Daily KPI'!AA:AA)/1000 -> 71.42796 | G4: =IFERROR(E4/C4/'Modelling New'!$AP$1,"") -> 0.70656621 | H4: =IFERROR(F4/D4/'Modelling New'!$AP$1,"") -> 0.7171024 | I4: =IFERROR(E4/(B4*24*'Modelling New'!$AP$1),"") -> 0.13091374 | J4: =IFERROR(F4/(B4*24*'Modelling New'!$AP$1),"") -> 0.14162772 | K4: =_xlfn.XLOOKUP($A4,'Modelling New'!D:D,'Modelling New'!AE:AE) -> 0.997 | L4: =IFERROR(AVERAGEIF('Daily KPI'!$D:$D,'Monthly KPI'!$A4,'Daily KPI'!R:R),"") -> 1 | M4: =_xlfn.XLOOKUP($A4,'Modelling New'!D:D,'Modelling New'!AD:AD) -> 0.995 | N4: =IFERROR(AVERAGEIF('Daily KPI'!$D:$D,'Monthly KPI'!$A4,'Daily KPI'!O:O),"") -> 0.99590011 | O4: =_xlfn.XLOOKUP($A4,'Modelling New'!$D:$D,'Modelling New'!AF:AF) -> 0.999 | P4: =IFERROR(AVERAGEIF('Daily KPI'!$D:$D,'Monthly KPI'!$A4,'Daily KPI'!T:T),"") -> 1
A7: Start Date | B7: =B8-6 -> 45865
A8: End Date | B8: =B1 -> 45871
A9: ES Energy Private Limited Performance Summary
A10: Year | B10: Days | C10: Estimated POA(KWh/m2) | D10: Measured POA (KWh/m2) | E10: Budgeted Energy (MWh) | F10: Measured Energy (MWh) | G10: Targt PR (%) | H10: Measured PR(%) | I10: Target DC CUF (%) | J10: Measured DC CUF (%) | K10: Target GA (%) | L10: Measured GA (%) | M10: Target PA (%) | N10: Measured PA (%) | O10: Target TA (%) | P10: Measured TA (%)
A11: =A4 -> 45870 | B11: =(B8-B7)+1 -> 7 | C11: =SUMIFS('Daily KPI'!AC:AC,'Daily KPI'!$A:$A,">="&$B$7,'Daily KPI'!$A:$A,"<="&$B$8) -> 30.24075 | D11: =SUMIFS('Daily KPI'!I:I,'Daily KPI'!$A:$A,">="&$B$7,'Daily KPI'!$A:$A,"<="&$B$8) -> 25.72 | E11: =SUMIFS('Daily KPI'!AD:AD,'Daily KPI'!$A:$A,">="&$B$7,'Daily KPI'!$A:$A,"<="&$B$8)/1000 -> 223.15016 | F11: =SUMIFS('Daily KPI'!AA:AA,'Daily KPI'!$A:$A,">="&$B$7,'Daily KPI'!$A:$A,"<="&$B$8)/1000 -> 200.02136 | G11: =IFERROR(E11/C11/'Modelling New'!$AP$1,"") -> 0.70230525 | H11: =IFERROR(F11/D11/'Modelling New'!$AP$1,"") -> 0.74016182 | I11: =IFERROR(E11/(B11*24*'Modelling New'!$AP$1),"") -> 0.12641808 | J11: =IFERROR(F11/(B11*24*'Modelling New'!$AP$1),"") -> 0.11331525 | K11: =_xlfn.XLOOKUP($A11,'Modelling New'!$D:$D,'Modelling New'!AE:AE) -> 0.997 | L11: =AVERAGEIFS('Daily KPI'!R:R,'Daily KPI'!$A:$A,">="&$B$7,'Daily KPI'!$A:$A,"<="&$B$8) -> 1 | M11: =_xlfn.XLOOKUP($A11,'Modelling New'!$D:$D,'Modelling New'!AD:AD) -> 0.995 | N11: =AVERAGEIFS('Daily KPI'!O:O,'Daily KPI'!$A:$A,">="&$B$7,'Daily KPI'!$A:$A,"<="&$B$8) -> 0.99783697 | O11: =_xlfn.XLOOKUP($A11,'Modelling New'!D:D,'Modelling New'!AF:AF) -> 0.999 | P11: =AVERAGEIFS('Daily KPI'!T:T,'Daily KPI'!$A:$A,">="&$B$7,'Daily KPI'!$A:$A,"<="&$B$8) -> 1

Sheet Daily KPI
A1: Date | B1: Financial Year | C1: Calendar Year | D1: Month Year | E1: Days | F1: Operating Hours | G1: GHI-UP (KWh/m2) | H1: GHI-Down(KWh/m2) | I1: POA-UP(KWh/m2) | J1: POA-Down(KWh/m2) | K1: Amb_Temp(°C) | L1: Mod_Temp(°C) | M1: WS_Avg(m/s) | N1: WS_Max(m/s) | O1: PA(%) | P1: MA (%) | Q1: IGA (%) | R1: EGA(%) | S1: EMA (%) | T1: TA (%) | U1: PR(%) | V1: WPR(%) | W1: CUF(%) | X1: Gen_Exp (kWh) | Y1: Mtr_Export (kWh) | Z1: Mtr_Import (kWh) | AA1: Mtr_Net_Exp (KWh) | AB1: Operational Capacity (MW) | AC1: Bugt_Resource | AD1: Bugt_Energy | AE1: Bugt PR | AF1: Bugt CUF | AG1: Bugt_PA | AH1: Bugt_EGA | AI1: Expected Energy | AJ1: Actual Energy WPR | AK1: RA (%) | AL1: Mod Clean Dry (Num) | AM1: Mod Clean Wet (Num) | AN1: Line Loss(%) | AO1: Reactive Power (%) | AP1: Bugt Line loss (%) (Wind) | AQ1: Bugt Reactive Power (%) (Wind) | AR1: Bugt Capacity | AS1: CC*Bugt
A2: 45745 | B2: =YEAR(Table13[[#This Row],[Date]])+IF(MONTH(Table13[[#This Row],[Date]])>=4,1,0) -> 2025 | C2: =YEAR(Table13[[#This Row],[Date]]) -> 2025 | D2: =Table13[[#This Row],[Date]]-DAY(Table13[[#This Row],[Date]])+1 -> 45717 | E2: =DAY(EOMONTH(A2,0)) -> 31 | F2: {=IFERROR(_xlfn.XLOOKUP(Table13[[#This Row],[Date]],Raw_Data[[#All],[Date]],Raw_Data[[#All],[Operating Hours]]),"")} -> 12 | G2: =IFERROR(_xlfn.XLOOKUP($A2,'Raw Data'!$G:$G,'Raw Data'!S:S)/1000,"") -> 6.6 | I2: =IFERROR(_xlfn.XLOOKUP($A2,'Raw Data'!$G:$G,'Raw Data'!AF:AF)/1000,"") -> 7.375 | K2: =IFERROR(_xlfn.XLOOKUP($A2,'Raw Data'!$G:$G,'Raw Data'!W:W),"") -> 30.493778 | L2: =IFERROR(_xlfn.XLOOKUP($A2,'Raw Data'!$G:$G,'Raw Data'!X:X),"") -> 46.458636 | M2: =IFERROR(_xlfn.XLOOKUP($A2,'Raw Data'!$G:$G,'Raw Data'!Y:Y),"") -> 0.67533815 | N2: =IFERROR(_xlfn.XLOOKUP($A2,'Raw Data'!$G:$G,'Raw Data'!Z:Z),"") -> 0.69938042 | O2: =IFERROR(1-SUMIF('Plant BD'!$H:$H,$A2,'Plant BD'!$AE:$AE)/($AA2+SUMIF('Plant BD'!$H:$H,$A2,'Plant BD'!$AE:$AE)),"") | R2: =IFERROR(1-SUMIF('Grid BD'!$H:$H,$A2,'Grid BD'!$AD:$AD)/($AA2+SUMIF('Grid BD'!$H:$H,$A2,'Grid BD'!$AD:$AD)),"") | T2: =IFERROR(1-SUMIF(Tracker_BD!H:H,$A2,Tracker_BD!AI:AI)/$F2,"") -> 1 | U2: =IFERROR(AA2/(I2*1000)/AB2,"") | W2: =IFERROR(AA2/(24*1000*AR2),"") | X2: =IFERROR(_xlfn.XLOOKUP($A2,'Raw Data'!$G:$G,'Raw Data'!AB:AB),"") -> 51086 | Y2: =IFERROR(_xlfn.XLOOKUP($A2,'Raw Data'!$G:$G,'Raw Data'!AC:AC),"") | Z2: =IFERROR(_xlfn.XLOOKUP($A2,'Raw Data'!$G:$G,'Raw Data'!AD:AD),"") | AA2: =IFERROR(_xlfn.XLOOKUP($A2,'Raw Data'!$G:$G,'Raw Data'!AE:AE),"") | AB2: =_xlfn.XLOOKUP($D2,'Modelling New'!D:D,'Modelling New'!N:N) -> 10.507 | AC2: =IFERROR(_xlfn.XLOOKUP($D2,'Modelling New'!$D:$D,'Modelling New'!P:P),"") -> 7.9800663 | AD2: =IFERROR(_xlfn.XLOOKUP($D2,'Modelling New'!$D:$D,'Modelling New'!T:T)*1000,"") -> 58906.452 | AE2: =IFERROR(AD2/AC2/AB2/1000,"") -> 0.70255063 | AF2: =IFERROR(_xlfn.XLOOKUP($D2,'Modelling New'!$D:$D,'Modelling New'!W:W),"") -> 0.23360003 | AG2: =IFERROR(_xlfn.XLOOKUP($D2,'Modelling New'!$D:$D,'Modelling New'!AD:AD),"") -> 0.995 | AH2: =IFERROR(_xlfn.XLOOKUP($D2,'Modelling New'!$D:$D,'Modelling New'!AE:AE),"") -> 0.997 | AR2: =IFERROR(_xlfn.XLOOKUP($D2,'Modelling New'!$D:$D,'Modelling New'!$N:$N),"") -> 10.507
A3: =A2+1 -> 45746 | B3: =YEAR(Table13[[#This Row],[Date]])+IF(MONTH(Table13[[#This Row],[Date]])>=4,1,0) -> 2025 | C3: =YEAR(Table13[[#This Row],[Date]]) -> 2025 | D3: =Table13[[#This Row],[Date]]-DAY(Table13[[#This Row],[Date]])+1 -> 45717 | E3: =DAY(EOMONTH(A3,0)) -> 31 | F3: {=IFERROR(_xlfn.XLOOKUP(Table13[[#This Row],[Date]],Raw_Data[[#All],[Date]],Raw_Data[[#All],[Operating Hours]]),"")} -> 12.016667 | G3: =IFERROR(_xlfn.XLOOKUP($A3,'Raw Data'!$G:$G,'Raw Data'!S:S)/1000,"") -> 6.48 | I3: =IFERROR(_xlfn.XLOOKUP($A3,'Raw Data'!$G:$G,'Raw Data'!AF:AF)/1000,"") -> 7.35 | K3: =IFERROR(_xlfn.XLOOKUP($A3,'Raw Data'!$G:$G,'Raw Data'!W:W),"") -> 30.195025 | L3: =IFERROR(_xlfn.XLOOKUP($A3,'Raw Data'!$G:$G,'Raw Data'!X:X),"") -> 46.433191 | M3: =IFERROR(_xlfn.XLOOKUP($A3,'Raw Data'!$G:$G,'Raw Data'!Y:Y),"") -> 0.77068708 | N3: =IFERROR(_xlfn.XLOOKUP($A3,'Raw Data'!$G:$G,'Raw Data'!Z:Z),"") -> 3.0955796 | O3: =IFERROR(1-SUMIF('Plant BD'!$H:$H,$A3,'Plant BD'!$AE:$AE)/($AA3+SUMIF('Plant BD'!$H:$H,$A3,'Plant BD'!$AE:$AE)),"") -> 0.99412885 | R3: =IFERROR(1-SUMIF('Grid BD'!$H:$H,$A3,'Grid BD'!$AD:$AD)/($AA3+SUMIF('Grid BD'!$H:$H,$A3,'Grid BD'!$AD:$AD)),"") -> 1 | T3: =IFERROR(1-SUMIF(Tracker_BD!H:H,$A3,Tracker_BD!AI:AI)/$F3,"") -> 1 | U3: =IFERROR(AA3/(I3*1000)/AB3,"") -> 0.69065974 | W3: =IFERROR(AA3/(24*1000*AR3),"") -> 0.21151455 | X3: =IFERROR(_xlfn.XLOOKUP($A3,'Raw Data'!$G:$G,'Raw Data'!AB:AB),"") -> 50755 | Y3: =IFERROR(_xlfn.XLOOKUP($A3,'Raw Data'!$G:$G,'Raw Data'!AC:AC),"") -> 53644.4 | Z3: =IFERROR(_xlfn.XLOOKUP($A3,'Raw Data'!$G:$G,'Raw Data'!AD:AD),"") -> 307.2 | AA3: =IFERROR(_xlfn.XLOOKUP($A3,'Raw Data'!$G:$G,'Raw Data'!AE:AE),"") -> 53337.2 | AB3: =_xlfn.XLOOKUP($D3,'Modelling New'!D:D,'Modelling New'!N:N) -> 10.507 | AC3: =IFERROR(_xlfn.XLOOKUP($D3,'Modelling New'!$D:$D,'Modelling New'!P:P),"") -> 7.9800663 | AD3: =IFERROR(_xlfn.XLOOKUP($D3,'Modelling New'!$D:$D,'Modelling New'!T:T)*1000,"") -> 58906.452 | AE3: =IFERROR(AD3/AC3/AB3/1000,"") -> 0.70255063 | AF3: =IFERROR(_xlfn.XLOOKUP($D3,'Modelling New'!$D:$D,'Modelling New'!W:W),"") -> 0.23360003 | AG3: =IFERROR(_xlfn.XLOOKUP($D3,'Modelling New'!$D:$D,'Modelling New'!AD:AD),"") -> 0.995 | AH3: =IFERROR(_xlfn.XLOOKUP($D3,'Modelling New'!$D:$D,'Modelling New'!AE:AE),"") -> 0.997 | AR3: =IFERROR(_xlfn.XLOOKUP($D3,'Modelling New'!$D:$D,'Modelling New'!$N:$N),"") -> 10.507
A4: =A3+1 -> 45747 | B4: =YEAR(Table13[[#This Row],[Date]])+IF(MONTH(Table13[[#This Row],[Date]])>=4,1,0) -> 2025 | C4: =YEAR(Table13[[#This Row],[Date]]) -> 2025 | D4: =Table13[[#This Row],[Date]]-DAY(Table13[[#This Row],[Date]])+1 -> 45717 | E4: =DAY(EOMONTH(A4,0)) -> 31 | F4: {=IFERROR(_xlfn.XLOOKUP(Table13[[#This Row],[Date]],Raw_Data[[#All],[Date]],Raw_Data[[#All],[Operating Hours]]),"")} -> 12.066667 | G4: =IFERROR(_xlfn.XLOOKUP($A4,'Raw Data'!$G:$G,'Raw Data'!S:S)/1000,"") -> 6.12 | I4: =IFERROR(_xlfn.XLOOKUP($A4,'Raw Data'!$G:$G,'Raw Data'!AF:AF)/1000,"") -> 6.55 | K4: =IFERROR(_xlfn.XLOOKUP($A4,'Raw Data'!$G:$G,'Raw Data'!W:W),"") -> 30.040435 | L4: =IFERROR(_xlfn.XLOOKUP($A4,'Raw Data'!$G:$G,'Raw Data'!X:X),"") -> 44.9267 | M4: =IFERROR(_xlfn.XLOOKUP($A4,'Raw Data'!$G:$G,'Raw Data'!Y:Y),"") -> 0.68876265 | N4: =IFERROR(_xlfn.XLOOKUP($A4,'Raw Data'!$G:$G,'Raw Data'!Z:Z),"") -> 3.2757179 | O4: =IFERROR(1-SUMIF('Plant BD'!$H:$H,$A4,'Plant BD'!$AE:$AE)/($AA4+SUMIF('Plant BD'!$H:$H,$A4,'Plant BD'!$AE:$AE)),"") -> 1 | R4: =IFERROR(1-SUMIF('Grid BD'!$H:$H,$A4,'Grid BD'!$AD:$AD)/($AA4+SUMIF('Grid BD'!$H:$H,$A4,'Grid BD'!$AD:$AD)),"") -> 1 | T4: =IFERROR(1-SUMIF(Tracker_BD!H:H,$A4,Tracker_BD!AI:AI)/$F4,"") -> 1 | U4: =IFERROR(AA4/(I4*1000)/AB4,"") -> 0.70321828 | W4: =IFERROR(AA4/(24*1000*AR4),"") -> 0.19191999 | X4: =IFERROR(_xlfn.XLOOKUP($A4,'Raw Data'!$G:$G,'Raw Data'!AB:AB),"") -> 46606 | Y4: =IFERROR(_xlfn.XLOOKUP($A4,'Raw Data'!$G:$G,'Raw Data'!AC:AC),"") -> 48696.2 | Z4: =IFERROR(_xlfn.XLOOKUP($A4,'Raw Data'!$G:$G,'Raw Data'!AD:AD),"") -> 300.12 | AA4: =IFERROR(_xlfn.XLOOKUP($A4,'Raw Data'!$G:$G,'Raw Data'!AE:AE),"") -> 48396.08 | AB4: =_xlfn.XLOOKUP($D4,'Modelling New'!D:D,'Modelling New'!N:N) -> 10.507 | AC4: =IFERROR(_xlfn.XLOOKUP($D4,'Modelling New'!$D:$D,'Modelling New'!P:P),"") -> 7.9800663 | AD4: =IFERROR(_xlfn.XLOOKUP($D4,'Modelling New'!$D:$D,'Modelling New'!T:T)*1000,"") -> 58906.452 | AE4: =IFERROR(AD4/AC4/AB4/1000,"") -> 0.70255063 | AF4: =IFERROR(_xlfn.XLOOKUP($D4,'Modelling New'!$D:$D,'Modelling New'!W:W),"") -> 0.23360003 | AG4: =IFERROR(_xlfn.XLOOKUP($D4,'Modelling New'!$D:$D,'Modelling New'!AD:AD),"") -> 0.995 | AH4: =IFERROR(_xlfn.XLOOKUP($D4,'Modelling New'!$D:$D,'Modelling New'!AE:AE),"") -> 0.997 | AR4: =IFERROR(_xlfn.XLOOKUP($D4,'Modelling New'!$D:$D,'Modelling New'!$N:$N),"") -> 10.507
A5: =A4+1 -> 45748 | B5: =YEAR(Table13[[#This Row],[Date]])+IF(MONTH(Table13[[#This Row],[Date]])>=4,1,0) -> 2026 | C5: =YEAR(Table13[[#This Row],[Date]]) -> 2025 | D5: =Table13[[#This Row],[Date]]-DAY(Table13[[#This Row],[Date]])+1 -> 45748 | E5: =DAY(EOMONTH(A5,0)) -> 30 | F5: {=IFERROR(_xlfn.XLOOKUP(Table13[[#This Row],[Date]],Raw_Data[[#All],[Date]],Raw_Data[[#All],[Operating Hours]]),"")} -> 12.033333 | G5: =IFERROR(_xlfn.XLOOKUP($A5,'Raw Data'!$G:$G,'Raw Data'!S:S)/1000,"") -> 5.15 | I5: =IFERROR(_xlfn.XLOOKUP($A5,'Raw Data'!$G:$G,'Raw Data'!AF:AF)/1000,"") -> 5.39 | K5: =IFERROR(_xlfn.XLOOKUP($A5,'Raw Data'!$G:$G,'Raw Data'!W:W),"") -> 28.438176 | L5: =IFERROR(_xlfn.XLOOKUP($A5,'Raw Data'!$G:$G,'Raw Data'!X:X),"") -> 41.541825 | M5: =IFERROR(_xlfn.XLOOKUP($A5,'Raw Data'!$G:$G,'Raw Data'!Y:Y),"") -> 0.68870556 | N5: =IFERROR(_xlfn.XLOOKUP($A5,'Raw Data'!$G:$G,'Raw Data'!Z:Z),"") -> 0.78930177 | O5: =IFERROR(1-SUMIF('Plant BD'!$H:$H,$A5,'Plant BD'!$AE:$AE)/($AA5+SUMIF('Plant BD'!$H:$H,$A5,'Plant BD'!$AE:$AE)),"") -> 1 | R5: =IFERROR(1-SUMIF('Grid BD'!$H:$H,$A5,'Grid BD'!$AD:$AD)/($AA5+SUMIF('Grid BD'!$H:$H,$A5,'Grid BD'!$AD:$AD)),"") -> 1 | T5: =IFERROR(1-SUMIF(Tracker_BD!H:H,$A5,Tracker_BD!AI:AI)/$F5,"") -> 1 | U5: =IFERROR(AA5/(I5*1000)/AB5,"") -> 0.70387318 | W5: =IFERROR(AA5/(24*1000*AR5),"") -> 0.15807819 | X5: =IFERROR(_xlfn.XLOOKUP($A5,'Raw Data'!$G:$G,'Raw Data'!AB:AB),"") -> 39403 | Y5: =IFERROR(_xlfn.XLOOKUP($A5,'Raw Data'!$G:$G,'Raw Data'!AC:AC),"") -> 40160.4 | Z5: =IFERROR(_xlfn.XLOOKUP($A5,'Raw Data'!$G:$G,'Raw Data'!AD:AD),"") -> 298.14 | AA5: =IFERROR(_xlfn.XLOOKUP($A5,'Raw Data'!$G:$G,'Raw Data'!AE:AE),"") -> 39862.26 | AB5: =_xlfn.XLOOKUP($D5,'Modelling New'!D:D,'Modelling New'!N:N) -> 10.507 | AC5: =IFERROR(_xlfn.XLOOKUP($D5,'Modelling New'!$D:$D,'Modelling New'!P:P),"") -> 7.5896068 | AD5: =IFERROR(_xlfn.XLOOKUP($D5,'Modelling New'!$D:$D,'Modelling New'!T:T)*1000,"") -> 52819.056 | AE5: =IFERROR(AD5/AC5/AB5/1000,"") -> 0.66235776 | AF5: =IFERROR(_xlfn.XLOOKUP($D5,'Modelling New'!$D:$D,'Modelling New'!W:W),"") -> 0.20945979 | AG5: =IFERROR(_xlfn.XLOOKUP($D5,'Modelling New'!$D:$D,'Modelling New'!AD:AD),"") -> 0.995 | AH5: =IFERROR(_xlfn.XLOOKUP($D5,'Modelling New'!$D:$D,'Modelling New'!AE:AE),"") -> 0.997 | AR5: =IFERROR(_xlfn.XLOOKUP($D5,'Modelling New'!$D:$D,'Modelling New'!$N:$N),"") -> 10.507
A6: =A5+1 -> 45749 | B6: =YEAR(Table13[[#This Row],[Date]])+IF(MONTH(Table13[[#This Row],[Date]])>=4,1,0) -> 2026 | C6: =YEAR(Table13[[#This Row],[Date]]) -> 2025 | D6: =Table13[[#This Row],[Date]]-DAY(Table13[[#This Row],[Date]])+1 -> 45748 | E6: =DAY(EOMONTH(A6,0)) -> 30 | F6: {=IFERROR(_xlfn.XLOOKUP(Table13[[#This Row],[Date]],Raw_Data[[#All],[Date]],Raw_Data[[#All],[Operating Hours]]),"")} -> 11.85 | G6: =IFERROR(_xlfn.XLOOKUP($A6,'Raw Data'!$G:$G,'Raw Data'!S:S)/1000,"") -> 5.9 | I6: =IFERROR(_xlfn.XLOOKUP($A6,'Raw Data'!$G:$G,'Raw Data'!AF:AF)/1000,"") -> 6.35 | K6: =IFERROR(_xlfn.XLOOKUP($A6,'Raw Data'!$G:$G,'Raw Data'!W:W),"") -> 28.478929 | L6: =IFERROR(_xlfn.XLOOKUP($A6,'Raw Data'!$G:$G,'Raw Data'!X:X),"") -> 44.056629 | M6: =IFERROR(_xlfn.XLOOKUP($A6,'Raw Data'!$G:$G,'Raw Data'!Y:Y),"") -> 0.6846936 | N6: =IFERROR(_xlfn.XLOOKUP($A6,'Raw Data'!$G:$G,'Raw Data'!Z:Z),"") -> 1.9063103 | O6: =IFERROR(1-SUMIF('Plant BD'!$H:$H,$A6,'Plant BD'!$AE:$AE)/($AA6+SUMIF('Plant BD'!$H:$H,$A6,'Plant BD'!$AE:$AE)),"") -> 0.99719811 | R6: =IFERROR(1-SUMIF('Grid BD'!$H:$H,$A6,'Grid BD'!$AD:$AD)/($AA6+SUMIF('Grid BD'!$H:$H,$A6,'Grid BD'!$AD:$AD)),"") -> 1 | T6: =IFERROR(1-SUMIF(Tracker_BD!H:H,$A6,Tracker_BD!AI:AI)/$F6,"") -> 1 | U6: =IFERROR(AA6/(I6*1000)/AB6,"") -> 0.69345985 | W6: =IFERROR(AA6/(24*1000*AR6),"") -> 0.18347792 | X6: =IFERROR(_xlfn.XLOOKUP($A6,'Raw Data'!$G:$G,'Raw Data'!AB:AB),"") -> 44735 | Y6: =IFERROR(_xlfn.XLOOKUP($A6,'Raw Data'!$G:$G,'Raw Data'!AC:AC),"") -> 46564.5 | Z6: =IFERROR(_xlfn.XLOOKUP($A6,'Raw Data'!$G:$G,'Raw Data'!AD:AD),"") -> 297.24 | AA6: =IFERROR(_xlfn.XLOOKUP($A6,'Raw Data'!$G:$G,'Raw Data'!AE:AE),"") -> 46267.26 | AB6: =_xlfn.XLOOKUP($D6,'Modelling New'!D:D,'Modelling New'!N:N) -> 10.507 | AC6: =IFERROR(_xlfn.XLOOKUP($D6,'Modelling New'!$D:$D,'Modelling New'!P:P),"") -> 7.5896068 | AD6: =IFERROR(_xlfn.XLOOKUP($D6,'Modelling New'!$D:$D,'Modelling New'!T:T)*1000,"") -> 52819.056 | AE6: =IFERROR(AD6/AC6/AB6/1000,"") -> 0.66235776 | AF6: =IFERROR(_xlfn.XLOOKUP($D6,'Modelling New'!$D:$D,'Modelling New'!W:W),"") -> 0.20945979 | AG6: =IFERROR(_xlfn.XLOOKUP($D6,'Modelling New'!$D:$D,'Modelling New'!AD:AD),"") -> 0.995 | AH6: =IFERROR(_xlfn.XLOOKUP($D6,'Modelling New'!$D:$D,'Modelling New'!AE:AE),"") -> 0.997 | AR6: =IFERROR(_xlfn.XLOOKUP($D6,'Modelling New'!$D:$D,'Modelling New'!$N:$N),"") -> 10.507
